File: data/Rock_mag/2020_IRM_data_files/Raw_data/MPMS-XL/data/AX15-2r_FC-ZFC-RTSIRM-10K.dc.dat
[Header]
TITLE,MPMS DC Measurement
BYAPP,MPMS Measurement,2.1,Summary
FILEOPENTIME, 1578413252.030000 1/7/2020, 10:07:32 AM

INFO, APPNAME, MPMS MultiVu Application, Revision 1.61,  Build 082

INFO, NAME, AX15-2r
INFO, WEIGHT, 1.000
INFO, AREA, 1.000
INFO, LENGTH, 1.000
INFO, SHAPE, 0
INFO, COMMENT,
INFO, SEQUENCE FILE: FC-ZFC LTSIRM and RTSIRM LTD 10K.seq


INFO, BACKGROUND DATA FILE:, None


STARTUPAXIS,X,4,LINEAR,AUTO,0.000000,0.000000
STARTUPAXIS,Y1,5,LINEAR,AUTO,0.000000,0.000000


STARTUPGROUP,Longitudinal
FIELDGROUP,Longitudinal,1,2,3,4,5,6,7,8,9,15,16,17,18,27,28
FIELDGROUP,Transverse,1,2,3,4,10,11,12,13,14,19,20,21,22,27,28

PLOT_APPEARANCE,ALL,HORZ_GRID_ON,VERT_GRID_ON,MARKERS_AND_LINES

[Data]
Time,Comment,Field (Oe),Temperature (K),Long Moment (emu),Long Scan Std Dev,Long Algorithm,Long Reg Fit,Long Percent Error (%),Trans Moment (emu),Trans Scan Std Dev,Trans Algorithm,Trans Reg Fit,Trans Percent Error (%),Long Moment [w/o ABS] (emu),Long Scan Std Dev [w/o ABS],Long Reg Fit [w/o ABS],Long Percent Error [w/o ABS] (%),Trans Moment [w/o ABS] (emu),Trans Scan Std Dev [w/o ABS],Trans Reg Fit [w/o ABS],Trans Percent Error [w/o ABS] (%),Points per Scan,Scans per Measurement,Scan Length (cm),Delta Temp (K),Rot Position (deg),Error,EC Comp. Running,Using ABS,
1578413252.030,,0.000000e+000,1.000564e+001,1.987394e-005,0.000000e+000,3,9.769163e-001,0.000000e+000,,,,,,,,,,,,,,32,1,4.000000e+000,2.295780e-002,0.000000e+000,0,,0,
1578413332.960,,0.000000e+000,1.550364e+001,1.932944e-005,0.000000e+000,3,9.800428e-001,0.000000e+000,,,,,,,,,,,,,,32,1,4.000000e+000,9.156799e-001,0.000000e+000,0,,0,
1578413394.230,,0.000000e+000,2.054545e+001,1.749228e-005,0.000000e+000,3,9.738886e-001,0.000000e+000,,,,,,,,,,,,,,32,1,4.000000e+000,9.373207e-001,0.000000e+000,0,,0,
1578413454.370,,0.000000e+000,2.551702e+001,1.466928e-005,0.000000e+000,3,9.673708e-001,0.000000e+000,,,,,,,,,,,,,,32,1,4.000000e+000,9.776688e-001,0.000000e+000,0,,0,
1578413514.490,,0.000000e+000,3.052355e+001,1.547608e-005,0.000000e+000,3,9.801264e-001,0.000000e+000,,,,,,,,,,,,,,32,1,4.000000e+000,9.447784e-001,0.000000e+000,0,,0,
1578413576.470,,0.000000e+000,3.558245e+001,1.486126e-005,0.000000e+000,3,9.681075e-001,0.000000e+000,,,,,,,,,,,,,,32,1,4.000000e+000,9.156494e-001,0.000000e+000,0,,0,
1578413636.630,,0.000000e+000,4.052860e+001,1.342289e-005,0.000000e+000,3,9.592038e-001,0.000000e+000,,,,,,,,,,,,,,32,1,4.000000e+000,1.055599e+000,0.000000e+000,0,,0,
1578413696.301,,0.000000e+000,4.547305e+001,1.448316e-005,0.000000e+000,3,9.778787e-001,0.000000e+000,,,,,,,,,,,,,,32,1,4.000000e+000,9.424095e-001,0.000000e+000,0,,0,
1578413770.851,,0.000000e+000,5.164435e+001,1.380842e-005,0.000000e+000,3,9.671440e-001,0.000000e+000,,,,,,,,,,,,,,32,1,4.000000e+000,8.642387e-001,0.000000e+000,0,,0,
1578413817.811,,0.000000e+000,5.557787e+001,1.346832e-005,0.000000e+000,3,9.616063e-001,0.000000e+000,,,,,,,,,,,,,,32,1,4.000000e+000,8.966522e-001,0.000000e+000,0,,0,
1578413877.821,,0.000000e+000,6.057606e+001,1.379954e-005,0.000000e+000,3,9.689438e-001,0.000000e+000,,,,,,,,,,,,,,32,1,4.000000e+000,9.819603e-001,0.000000e+000,0,,0,
1578413937.541,,0.000000e+000,6.551173e+001,1.330951e-005,0.000000e+000,3,9.764564e-001,0.000000e+000,,,,,,,,,,,,,,32,1,4.000000e+000,9.707260e-001,0.000000e+000,0,,0,
1578413997.731,,0.000000e+000,7.062607e+001,1.299036e-005,0.000000e+000,3,9.663947e-001,0.000000e+000,,,,,,,,,,,,,,32,1,4.000000e+000,9.560623e-001,0.000000e+000,0,,0,
1578414056.791,,0.000000e+000,7.553447e+001,1.325664e-005,0.000000e+000,3,9.719942e-001,0.000000e+000,,,,,,,,,,,,,,32,1,4.000000e+000,1.013306e+000,0.000000e+000,0,,0,
1578414115.491,,0.000000e+000,8.049606e+001,1.299088e-005,0.000000e+000,3,9.742727e-001,0.000000e+000,,,,,,,,,,,,,,32,1,4.000000e+000,8.102646e-001,0.000000e+000,0,,0,
1578414177.331,,0.000000e+000,8.561617e+001,1.229560e-005,0.000000e+000,3,9.709943e-001,0.000000e+000,,,,,,,,,,,,,,32,1,4.000000e+000,9.589157e-001,0.000000e+000,0,,0,
1578414236.031,,0.000000e+000,9.057820e+001,1.262198e-005,0.000000e+000,3,9.753510e-001,0.000000e+000,,,,,,,,,,,,,,32,1,4.000000e+000,9.607239e-001,0.000000e+000,0,,0,
1578414295.341,,0.000000e+000,9.551757e+001,1.223022e-005,0.000000e+000,3,9.743572e-001,0.000000e+000,,,,,,,,,,,,,,32,1,4.000000e+000,1.028015e+000,0.000000e+000,0,,0,
1578414356.151,,0.000000e+000,1.005621e+002,1.148554e-005,0.000000e+000,3,9.560857e-001,0.000000e+000,,,,,,,,,,,,,,32,1,4.000000e+000,9.256058e-001,0.000000e+000,0,,0,
1578414414.702,,0.000000e+000,1.054893e+002,1.156802e-005,0.000000e+000,3,9.664967e-001,0.000000e+000,,,,,,,,,,,,,,32,1,4.000000e+000,8.998032e-001,0.000000e+000,0,,0,
1578414475.162,,0.000000e+000,1.105818e+002,1.084100e-005,0.000000e+000,3,9.725707e-001,0.000000e+000,,,,,,,,,,,,,,32,1,4.000000e+000,8.350983e-001,0.000000e+000,0,,0,
1578414535.252,,0.000000e+000,1.155590e+002,8.898553e-006,0.000000e+000,3,9.469916e-001,0.000000e+000,,,,,,,,,,,,,,32,1,4.000000e+000,9.776001e-001,0.000000e+000,0,,0,
1578414594.812,,0.000000e+000,1.204967e+002,7.455534e-006,0.000000e+000,3,9.514319e-001,0.000000e+000,,,,,,,,,,,,,,32,1,4.000000e+000,9.226990e-001,0.000000e+000,0,,0,
1578414654.142,,0.000000e+000,1.255664e+002,6.601618e-006,0.000000e+000,3,9.623564e-001,0.000000e+000,,,,,,,,,,,,,,32,1,4.000000e+000,9.095001e-001,0.000000e+000,0,,0,
1578414714.822,,0.000000e+000,1.305773e+002,5.823840e-006,0.000000e+000,3,9.447154e-001,0.000000e+000,,,,,,,,,,,,,,32,1,4.000000e+000,8.666992e-001,0.000000e+000,0,,0,
1578414774.722,,0.000000e+000,1.355466e+002,6.360392e-006,0.000000e+000,3,9.460774e-001,0.000000e+000,,,,,,,,,,,,,,32,1,4.000000e+000,9.944000e-001,0.000000e+000,0,,0,
1578414834.152,,0.000000e+000,1.405200e+002,6.177747e-006,0.000000e+000,3,9.586291e-001,0.000000e+000,,,,,,,,,,,,,,32,1,4.000000e+000,1.013596e+000,0.000000e+000,0,,0,
1578414893.962,,0.000000e+000,1.455900e+002,6.091382e-006,0.000000e+000,3,9.282166e-001,0.000000e+000,,,,,,,,,,,,,,32,1,4.000000e+000,9.905090e-001,0.000000e+000,0,,0,
1578414954.142,,0.000000e+000,1.505359e+002,6.062991e-006,0.000000e+000,3,9.580813e-001,0.000000e+000,,,,,,,,,,,,,,32,1,4.000000e+000,9.234009e-001,0.000000e+000,0,,0,
1578415013.042,,0.000000e+000,1.555029e+002,5.819174e-006,0.000000e+000,3,9.553899e-001,0.000000e+000,,,,,,,,,,,,,,32,1,4.000000e+000,9.317932e-001,0.000000e+000,0,,0,
1578415073.722,,0.000000e+000,1.605829e+002,5.849048e-006,0.000000e+000,3,9.490957e-001,0.000000e+000,,,,,,,,,,,,,,32,1,4.000000e+000,9.241028e-001,0.000000e+000,0,,0,
1578415133.943,,0.000000e+000,1.655706e+002,5.889281e-006,0.000000e+000,3,9.474145e-001,0.000000e+000,,,,,,,,,,,,,,32,1,4.000000e+000,9.963074e-001,0.000000e+000,0,,0,
1578415194.043,,0.000000e+000,1.706135e+002,5.737439e-006,0.000000e+000,3,9.495479e-001,0.000000e+000,,,,,,,,,,,,,,32,1,4.000000e+000,9.131012e-001,0.000000e+000,0,,0,
1578415253.843,,0.000000e+000,1.756101e+002,5.268885e-006,0.000000e+000,3,9.242336e-001,0.000000e+000,,,,,,,,,,,,,,32,1,4.000000e+000,9.735870e-001,0.000000e+000,0,,0,
1578415312.203,,0.000000e+000,1.805204e+002,5.642253e-006,0.000000e+000,3,9.532644e-001,0.000000e+000,,,,,,,,,,,,,,32,1,4.000000e+000,8.087006e-001,0.000000e+000,0,,0,
1578415373.523,,0.000000e+000,1.855941e+002,5.563134e-006,0.000000e+000,3,9.510929e-001,0.000000e+000,,,,,,,,,,,,,,32,1,4.000000e+000,8.923950e-001,0.000000e+000,0,,0,
1578415432.703,,0.000000e+000,1.905594e+002,5.125386e-006,0.000000e+000,3,9.277993e-001,0.000000e+000,,,,,,,,,,,,,,32,1,4.000000e+000,9.683075e-001,0.000000e+000,0,,0,
1578415493.243,,0.000000e+000,1.955632e+002,5.363881e-006,0.000000e+000,3,9.460488e-001,0.000000e+000,,,,,,,,,,,,,,32,1,4.000000e+000,8.749084e-001,0.000000e+000,0,,0,
1578415552.883,,0.000000e+000,2.005797e+002,5.392165e-006,0.000000e+000,3,9.508575e-001,0.000000e+000,,,,,,,,,,,,,,32,1,4.000000e+000,8.567047e-001,0.000000e+000,0,,0,
1578415612.533,,0.000000e+000,2.055572e+002,5.169102e-006,0.000000e+000,3,9.399807e-001,0.000000e+000,,,,,,,,,,,,,,32,1,4.000000e+000,8.547974e-001,0.000000e+000,0,,0,
1578415699.353,,0.000000e+000,2.127576e+002,5.189802e-006,0.000000e+000,3,9.485602e-001,0.000000e+000,,,,,,,,,,,,,,32,1,4.000000e+000,9.584045e-001,0.000000e+000,0,,0,
1578415732.583,,0.000000e+000,2.155466e+002,5.100095e-006,0.000000e+000,3,9.499849e-001,0.000000e+000,,,,,,,,,,,,,,32,1,4.000000e+000,9.361877e-001,0.000000e+000,0,,0,
1578415793.843,,0.000000e+000,2.205491e+002,4.771018e-006,0.000000e+000,3,9.269671e-001,0.000000e+000,,,,,,,,,,,,,,32,1,4.000000e+000,8.247986e-001,0.000000e+000,0,,0,
1578415851.744,,0.000000e+000,2.254627e+002,4.960826e-006,0.000000e+000,3,9.442438e-001,0.000000e+000,,,,,,,,,,,,,,32,1,4.000000e+000,7.592010e-001,0.000000e+000,0,,0,
1578415911.934,,0.000000e+000,2.305387e+002,4.947981e-006,0.000000e+000,3,9.497189e-001,0.000000e+000,,,,,,,,,,,,,,32,1,4.000000e+000,9.157104e-001,0.000000e+000,0,,0,
1578415971.864,,0.000000e+000,2.355492e+002,4.858742e-006,0.000000e+000,3,9.562685e-001,0.000000e+000,,,,,,,,,,,,,,32,1,4.000000e+000,8.351898e-001,0.000000e+000,0,,0,
1578416031.994,,0.000000e+000,2.404897e+002,4.871940e-006,0.000000e+000,3,9.521526e-001,0.000000e+000,,,,,,,,,,,,,,32,1,4.000000e+000,9.747925e-001,0.000000e+000,0,,0,
1578416090.914,,0.000000e+000,2.454662e+002,4.760102e-006,0.000000e+000,3,9.495426e-001,0.000000e+000,,,,,,,,,,,,,,32,1,4.000000e+000,8.851013e-001,0.000000e+000,0,,0,
1578416153.444,,0.000000e+000,2.506784e+002,4.509200e-006,0.000000e+000,3,9.359193e-001,0.000000e+000,,,,,,,,,,,,,,32,1,4.000000e+000,9.116974e-001,0.000000e+000,0,,0,
1578416212.044,,0.000000e+000,2.555446e+002,4.650091e-006,0.000000e+000,3,9.441035e-001,0.000000e+000,,,,,,,,,,,,,,32,1,4.000000e+000,8.818970e-001,0.000000e+000,0,,0,
1578416272.094,,0.000000e+000,2.605424e+002,4.696718e-006,0.000000e+000,3,9.528847e-001,0.000000e+000,,,,,,,,,,,,,,32,1,4.000000e+000,9.829102e-001,0.000000e+000,0,,0,
1578416333.914,,0.000000e+000,2.656697e+002,4.510552e-006,0.000000e+000,3,9.398760e-001,0.000000e+000,,,,,,,,,,,,,,32,1,4.000000e+000,9.182129e-001,0.000000e+000,0,,0,
1578416391.574,,0.000000e+000,2.705018e+002,4.569486e-006,0.000000e+000,3,9.463787e-001,0.000000e+000,,,,,,,,,,,,,,32,1,4.000000e+000,9.535217e-001,0.000000e+000,0,,0,
1578416450.694,,0.000000e+000,2.754835e+002,4.406348e-006,0.000000e+000,3,9.466537e-001,0.000000e+000,,,,,,,,,,,,,,32,1,4.000000e+000,9.653015e-001,0.000000e+000,0,,0,
1578416512.254,,0.000000e+000,2.805688e+002,4.241542e-006,0.000000e+000,3,9.444476e-001,0.000000e+000,,,,,,,,,,,,,,32,1,4.000000e+000,9.506836e-001,0.000000e+000,0,,0,
1578416571.975,,0.000000e+000,2.855558e+002,4.450042e-006,0.000000e+000,3,9.426048e-001,0.000000e+000,,,,,,,,,,,,,,32,1,4.000000e+000,9.591064e-001,0.000000e+000,0,,0,
1578416657.785,,0.000000e+000,2.926429e+002,4.223490e-006,0.000000e+000,3,9.302082e-001,0.000000e+000,,,,,,,,,,,,,,32,1,4.000000e+000,8.811035e-001,0.000000e+000,0,,0,
1578416692.945,,0.000000e+000,2.956086e+002,4.179803e-006,0.000000e+000,3,9.387772e-001,0.000000e+000,,,,,,,,,,,,,,32,1,4.000000e+000,1.030304e+000,0.000000e+000,0,,0,
1578417027.795,,0.000000e+000,3.000265e+002,4.277991e-006,0.000000e+000,3,9.479389e-001,0.000000e+000,,,,,,,,,,,,,,32,1,4.000000e+000,0.000000e+000,0.000000e+000,0,,0,
1578422110.052,,0.000000e+000,1.000859e+001,1.541078e-005,0.000000e+000,3,9.779332e-001,0.000000e+000,,,,,,,,,,,,,,32,1,4.000000e+000,2.191925e-002,0.000000e+000,0,,0,
1578422191.282,,0.000000e+000,1.549502e+001,1.459004e-005,0.000000e+000,3,9.772745e-001,0.000000e+000,,,,,,,,,,,,,,32,1,4.000000e+000,9.126701e-001,0.000000e+000,0,,0,
1578422252.232,,0.000000e+000,2.048610e+001,1.296837e-005,0.000000e+000,3,9.703977e-001,0.000000e+000,,,,,,,,,,,,,,32,1,4.000000e+000,8.451786e-001,0.000000e+000,0,,0,
1578422313.593,,0.000000e+000,2.563122e+001,1.155380e-005,0.000000e+000,3,9.410120e-001,0.000000e+000,,,,,,,,,,,,,,32,1,4.000000e+000,9.042015e-001,0.000000e+000,0,,0,
1578422373.923,,0.000000e+000,3.055655e+001,1.199294e-005,0.000000e+000,3,9.715403e-001,0.000000e+000,,,,,,,,,,,,,,32,1,4.000000e+000,1.017550e+000,0.000000e+000,0,,0,
1578422434.493,,0.000000e+000,3.558016e+001,1.159433e-005,0.000000e+000,3,9.820585e-001,0.000000e+000,,,,,,,,,,,,,,32,1,4.000000e+000,9.140434e-001,0.000000e+000,0,,0,
1578422496.533,,0.000000e+000,4.058968e+001,1.065058e-005,0.000000e+000,3,9.674568e-001,0.000000e+000,,,,,,,,,,,,,,32,1,4.000000e+000,1.039230e+000,0.000000e+000,0,,0,
1578422556.363,,0.000000e+000,4.561533e+001,1.131409e-005,0.000000e+000,3,9.687210e-001,0.000000e+000,,,,,,,,,,,,,,32,1,4.000000e+000,9.500084e-001,0.000000e+000,0,,0,
1578422616.773,,0.000000e+000,5.055666e+001,1.128123e-005,0.000000e+000,3,9.760371e-001,0.000000e+000,,,,,,,,,,,,,,32,1,4.000000e+000,9.934502e-001,0.000000e+000,0,,0,
1578422676.733,,0.000000e+000,5.557253e+001,1.067422e-005,0.000000e+000,3,9.594778e-001,0.000000e+000,,,,,,,,,,,,,,32,1,4.000000e+000,8.991699e-001,0.000000e+000,0,,0,
1578422736.593,,0.000000e+000,6.057141e+001,1.094097e-005,0.000000e+000,3,9.705124e-001,0.000000e+000,,,,,,,,,,,,,,32,1,4.000000e+000,9.880905e-001,0.000000e+000,0,,0,
1578422795.763,,0.000000e+000,6.554704e+001,1.060336e-005,0.000000e+000,3,9.750223e-001,0.000000e+000,,,,,,,,,,,,,,32,1,4.000000e+000,8.673096e-001,0.000000e+000,0,,0,
1578422856.093,,0.000000e+000,7.062495e+001,1.018073e-005,0.000000e+000,3,9.650388e-001,0.000000e+000,,,,,,,,,,,,,,32,1,4.000000e+000,9.416428e-001,0.000000e+000,0,,0,
1578422914.993,,0.000000e+000,7.549454e+001,1.066186e-005,0.000000e+000,3,9.713498e-001,0.000000e+000,,,,,,,,,,,,,,32,1,4.000000e+000,9.196777e-001,0.000000e+000,0,,0,
1578422975.824,,0.000000e+000,8.061339e+001,1.042194e-005,0.000000e+000,3,9.745625e-001,0.000000e+000,,,,,,,,,,,,,,32,1,4.000000e+000,8.800430e-001,0.000000e+000,0,,0,
1578423035.564,,0.000000e+000,8.553152e+001,9.601818e-006,0.000000e+000,3,9.558963e-001,0.000000e+000,,,,,,,,,,,,,,32,1,4.000000e+000,8.010559e-001,0.000000e+000,0,,0,
1578423094.374,,0.000000e+000,9.052809e+001,1.006525e-005,0.000000e+000,3,9.673781e-001,0.000000e+000,,,,,,,,,,,,,,32,1,4.000000e+000,8.478165e-001,0.000000e+000,0,,0,
1578423153.654,,0.000000e+000,9.545898e+001,9.944233e-006,0.000000e+000,3,9.718262e-001,0.000000e+000,,,,,,,,,,,,,,32,1,4.000000e+000,9.108353e-001,0.000000e+000,0,,0,
1578423215.194,,0.000000e+000,1.006763e+002,9.548690e-006,0.000000e+000,3,9.612481e-001,0.000000e+000,,,,,,,,,,,,,,32,1,4.000000e+000,1.023903e+000,0.000000e+000,0,,0,
1578423273.744,,0.000000e+000,1.054473e+002,9.519734e-006,0.000000e+000,3,9.649227e-001,0.000000e+000,,,,,,,,,,,,,,32,1,4.000000e+000,8.323059e-001,0.000000e+000,0,,0,
1578423333.974,,0.000000e+000,1.105620e+002,9.203191e-006,0.000000e+000,3,9.762472e-001,0.000000e+000,,,,,,,,,,,,,,32,1,4.000000e+000,1.002800e+000,0.000000e+000,0,,0,
1578423393.354,,0.000000e+000,1.155584e+002,8.389822e-006,0.000000e+000,3,9.556261e-001,0.000000e+000,,,,,,,,,,,,,,32,1,4.000000e+000,8.105011e-001,0.000000e+000,0,,0,
1578423453.454,,0.000000e+000,1.205742e+002,6.820557e-006,0.000000e+000,3,9.559739e-001,0.000000e+000,,,,,,,,,,,,,,32,1,4.000000e+000,1.056602e+000,0.000000e+000,0,,0,
1578423538.424,,0.000000e+000,1.277169e+002,6.025554e-006,0.000000e+000,3,9.469084e-001,0.000000e+000,,,,,,,,,,,,,,32,1,4.000000e+000,9.856033e-001,0.000000e+000,0,,0,
1578423572.674,,0.000000e+000,1.305959e+002,6.168262e-006,0.000000e+000,3,9.421231e-001,0.000000e+000,,,,,,,,,,,,,,32,1,4.000000e+000,9.038086e-001,0.000000e+000,0,,0,
1578423632.904,,0.000000e+000,1.354933e+002,5.999972e-006,0.000000e+000,3,9.430129e-001,0.000000e+000,,,,,,,,,,,,,,32,1,4.000000e+000,7.830963e-001,0.000000e+000,0,,0,
1578423693.265,,0.000000e+000,1.405829e+002,5.933691e-006,0.000000e+000,3,9.607078e-001,0.000000e+000,,,,,,,,,,,,,,32,1,4.000000e+000,8.876953e-001,0.000000e+000,0,,0,
1578423754.475,,0.000000e+000,1.456646e+002,5.627345e-006,0.000000e+000,3,9.409171e-001,0.000000e+000,,,,,,,,,,,,,,32,1,4.000000e+000,8.562012e-001,0.000000e+000,0,,0,
1578423839.445,,0.000000e+000,1.527924e+002,5.755487e-006,0.000000e+000,3,9.534844e-001,0.000000e+000,,,,,,,,,,,,,,32,1,4.000000e+000,9.279938e-001,0.000000e+000,0,,0,
1578423872.615,,0.000000e+000,1.555957e+002,5.684134e-006,0.000000e+000,3,9.601624e-001,0.000000e+000,,,,,,,,,,,,,,32,1,4.000000e+000,9.326019e-001,0.000000e+000,0,,0,
1578423933.105,,0.000000e+000,1.606300e+002,5.484923e-006,0.000000e+000,3,9.315753e-001,0.000000e+000,,,,,,,,,,,,,,32,1,4.000000e+000,1.009399e+000,0.000000e+000,0,,0,
1578423992.265,,0.000000e+000,1.655280e+002,5.596625e-006,0.000000e+000,3,9.556264e-001,0.000000e+000,,,,,,,,,,,,,,32,1,4.000000e+000,9.109039e-001,0.000000e+000,0,,0,
1578424052.405,,0.000000e+000,1.706135e+002,5.460243e-006,0.000000e+000,3,9.467669e-001,0.000000e+000,,,,,,,,,,,,,,32,1,4.000000e+000,9.131012e-001,0.000000e+000,0,,0,
1578424112.385,,0.000000e+000,1.756127e+002,5.454702e-006,0.000000e+000,3,9.521848e-001,0.000000e+000,,,,,,,,,,,,,,32,1,4.000000e+000,9.895020e-001,0.000000e+000,0,,0,
1578424171.355,,0.000000e+000,1.805262e+002,5.517803e-006,0.000000e+000,3,9.506799e-001,0.000000e+000,,,,,,,,,,,,,,32,1,4.000000e+000,9.748993e-001,0.000000e+000,0,,0,
1578424232.105,,0.000000e+000,1.855564e+002,5.205007e-006,0.000000e+000,3,9.449478e-001,0.000000e+000,,,,,,,,,,,,,,32,1,4.000000e+000,9.678040e-001,0.000000e+000,0,,0,
1578424292.295,,0.000000e+000,1.905990e+002,5.201473e-006,0.000000e+000,3,9.449431e-001,0.000000e+000,,,,,,,,,,,,,,32,1,4.000000e+000,8.765869e-001,0.000000e+000,0,,0,
1578424351.545,,0.000000e+000,1.955313e+002,5.226184e-006,0.000000e+000,3,9.490235e-001,0.000000e+000,,,,,,,,,,,,,,32,1,4.000000e+000,9.646912e-001,0.000000e+000,0,,0,
1578424411.676,,0.000000e+000,2.005836e+002,5.048467e-006,0.000000e+000,3,9.465140e-001,0.000000e+000,,,,,,,,,,,,,,32,1,4.000000e+000,1.038895e+000,0.000000e+000,0,,0,
1578424471.436,,0.000000e+000,2.055221e+002,4.915285e-006,0.000000e+000,3,9.398640e-001,0.000000e+000,,,,,,,,,,,,,,32,1,4.000000e+000,9.533997e-001,0.000000e+000,0,,0,
1578424530.996,,0.000000e+000,2.105425e+002,5.065668e-006,0.000000e+000,3,9.517496e-001,0.000000e+000,,,,,,,,,,,,,,32,1,4.000000e+000,9.319916e-001,0.000000e+000,0,,0,
1578424591.386,,0.000000e+000,2.155081e+002,4.972575e-006,0.000000e+000,3,9.488350e-001,0.000000e+000,,,,,,,,,,,,,,32,1,4.000000e+000,1.013199e+000,0.000000e+000,0,,0,
1578424651.946,,0.000000e+000,2.205937e+002,4.874782e-006,0.000000e+000,3,9.626762e-001,0.000000e+000,,,,,,,,,,,,,,32,1,4.000000e+000,9.140015e-001,0.000000e+000,0,,0,
1578424711.276,,0.000000e+000,2.255813e+002,4.855426e-006,0.000000e+000,3,9.420256e-001,0.000000e+000,,,,,,,,,,,,,,32,1,4.000000e+000,9.963989e-001,0.000000e+000,0,,0,
1578424771.396,,0.000000e+000,2.305298e+002,4.941163e-006,0.000000e+000,3,9.612517e-001,0.000000e+000,,,,,,,,,,,,,,32,1,4.000000e+000,9.154968e-001,0.000000e+000,0,,0,
1578424832.046,,0.000000e+000,2.355769e+002,4.584301e-006,0.000000e+000,3,9.503251e-001,0.000000e+000,,,,,,,,,,,,,,32,1,4.000000e+000,9.087982e-001,0.000000e+000,0,,0,
1578424891.386,,0.000000e+000,2.405614e+002,4.757744e-006,0.000000e+000,3,9.428957e-001,0.000000e+000,,,,,,,,,,,,,,32,1,4.000000e+000,9.848938e-001,0.000000e+000,0,,0,
1578424951.446,,0.000000e+000,2.455759e+002,4.768541e-006,0.000000e+000,3,9.499618e-001,0.000000e+000,,,,,,,,,,,,,,32,1,4.000000e+000,9.853973e-001,0.000000e+000,0,,0,
1578425010.856,,0.000000e+000,2.505595e+002,4.333090e-006,0.000000e+000,3,9.449221e-001,0.000000e+000,,,,,,,,,,,,,,32,1,4.000000e+000,9.626007e-001,0.000000e+000,0,,0,
1578425070.856,,0.000000e+000,2.555125e+002,4.569322e-006,0.000000e+000,3,9.438322e-001,0.000000e+000,,,,,,,,,,,,,,32,1,4.000000e+000,9.677124e-001,0.000000e+000,0,,0,
1578425130.337,,0.000000e+000,2.604919e+002,4.532087e-006,0.000000e+000,3,9.455293e-001,0.000000e+000,,,,,,,,,,,,,,32,1,4.000000e+000,8.819885e-001,0.000000e+000,0,,0,
1578425191.897,,0.000000e+000,2.656058e+002,4.481307e-006,0.000000e+000,3,9.300536e-001,0.000000e+000,,,,,,,,,,,,,,32,1,4.000000e+000,9.060974e-001,0.000000e+000,0,,0,
1578425250.827,,0.000000e+000,2.704898e+002,4.475883e-006,0.000000e+000,3,9.510004e-001,0.000000e+000,,,,,,,,,,,,,,32,1,4.000000e+000,9.533997e-001,0.000000e+000,0,,0,
1578425310.667,,0.000000e+000,2.755587e+002,4.349947e-006,0.000000e+000,3,9.464407e-001,0.000000e+000,,,,,,,,,,,,,,32,1,4.000000e+000,9.658813e-001,0.000000e+000,0,,0,
1578425371.297,,0.000000e+000,2.805947e+002,4.142579e-006,0.000000e+000,3,9.538071e-001,0.000000e+000,,,,,,,,,,,,,,32,1,4.000000e+000,8.727112e-001,0.000000e+000,0,,0,
1578425430.857,,0.000000e+000,2.855625e+002,4.411761e-006,0.000000e+000,3,9.489818e-001,0.000000e+000,,,,,,,,,,,,,,32,1,4.000000e+000,9.456177e-001,0.000000e+000,0,,0,
1578425490.647,,0.000000e+000,2.905690e+002,4.181999e-006,0.000000e+000,3,9.469810e-001,0.000000e+000,,,,,,,,,,,,,,32,1,4.000000e+000,8.683167e-001,0.000000e+000,0,,0,
1578425551.377,,0.000000e+000,2.955577e+002,4.169849e-006,0.000000e+000,3,9.442579e-001,0.000000e+000,,,,,,,,,,,,,,32,1,4.000000e+000,9.284058e-001,0.000000e+000,0,,0,
1578425883.688,,0.000000e+000,3.000190e+002,4.160087e-006,0.000000e+000,3,9.430095e-001,0.000000e+000,,,,,,,,,,,,,,32,1,4.000000e+000,1.498413e-002,0.000000e+000,0,,0,
1578426433.068,,0.000000e+000,3.000041e+002,7.161718e-006,0.000000e+000,3,9.675305e-001,0.000000e+000,,,,,,,,,,,,,,32,1,4.000000e+000,1.489258e-002,0.000000e+000,0,,0,
1578426720.779,,0.000000e+000,2.946678e+002,6.940624e-006,0.000000e+000,3,9.546569e-001,0.000000e+000,,,,,,,,,,,,,,32,1,4.000000e+000,5.623169e-001,0.000000e+000,0,,0,
1578426798.429,,0.000000e+000,2.893356e+002,6.968121e-006,0.000000e+000,3,9.573640e-001,0.000000e+000,,,,,,,,,,,,,,32,1,4.000000e+000,1.179901e+000,0.000000e+000,0,,0,
1578426852.269,,0.000000e+000,2.842595e+002,6.944491e-006,0.000000e+000,3,9.576284e-001,0.000000e+000,,,,,,,,,,,,,,32,1,4.000000e+000,1.445190e+000,0.000000e+000,0,,0,
1578426902.649,,0.000000e+000,2.793573e+002,6.905383e-006,0.000000e+000,3,9.577448e-001,0.000000e+000,,,,,,,,,,,,,,32,1,4.000000e+000,1.264771e+000,0.000000e+000,0,,0,
1578426953.789,,0.000000e+000,2.742491e+002,7.080990e-006,0.000000e+000,3,9.645579e-001,0.000000e+000,,,,,,,,,,,,,,32,1,4.000000e+000,1.378571e+000,0.000000e+000,0,,0,
1578427007.619,,0.000000e+000,2.692117e+002,7.030952e-006,0.000000e+000,3,9.572246e-001,0.000000e+000,,,,,,,,,,,,,,32,1,4.000000e+000,1.266510e+000,0.000000e+000,0,,0,
1578427064.859,,0.000000e+000,2.642717e+002,7.055271e-006,0.000000e+000,3,9.577062e-001,0.000000e+000,,,,,,,,,,,,,,32,1,4.000000e+000,1.184021e+000,0.000000e+000,0,,0,
1578427126.009,,0.000000e+000,2.593198e+002,7.093944e-006,0.000000e+000,3,9.627314e-001,0.000000e+000,,,,,,,,,,,,,,32,1,4.000000e+000,1.128784e+000,0.000000e+000,0,,0,
1578427189.939,,0.000000e+000,2.544472e+002,7.008930e-006,0.000000e+000,3,9.556813e-001,0.000000e+000,,,,,,,,,,,,,,32,1,4.000000e+000,1.077194e+000,0.000000e+000,0,,0,
1578427259.400,,0.000000e+000,2.494006e+002,6.959895e-006,0.000000e+000,3,9.574629e-001,0.000000e+000,,,,,,,,,,,,,,32,1,4.000000e+000,1.107803e+000,0.000000e+000,0,,0,
1578427329.430,,0.000000e+000,2.443922e+002,7.000047e-006,0.000000e+000,3,9.530064e-001,0.000000e+000,,,,,,,,,,,,,,32,1,4.000000e+000,1.084595e+000,0.000000e+000,0,,0,
1578427398.540,,0.000000e+000,2.394102e+002,6.979761e-006,0.000000e+000,3,9.540896e-001,0.000000e+000,,,,,,,,,,,,,,32,1,4.000000e+000,1.127304e+000,0.000000e+000,0,,0,
1578427464.170,,0.000000e+000,2.343759e+002,6.990818e-006,0.000000e+000,3,9.573650e-001,0.000000e+000,,,,,,,,,,,,,,32,1,4.000000e+000,1.036194e+000,0.000000e+000,0,,0,
1578427527.780,,0.000000e+000,2.292824e+002,7.010360e-006,0.000000e+000,3,9.564736e-001,0.000000e+000,,,,,,,,,,,,,,32,1,4.000000e+000,1.141190e+000,0.000000e+000,0,,0,
1578427588.920,,0.000000e+000,2.243637e+002,6.894584e-006,0.000000e+000,3,9.517874e-001,0.000000e+000,,,,,,,,,,,,,,32,1,4.000000e+000,1.153214e+000,0.000000e+000,0,,0,
1578427649.980,,0.000000e+000,2.193634e+002,7.015288e-006,0.000000e+000,3,9.574806e-001,0.000000e+000,,,,,,,,,,,,,,32,1,4.000000e+000,1.176392e+000,0.000000e+000,0,,0,
1578427711.690,,0.000000e+000,2.143313e+002,7.012334e-006,0.000000e+000,3,9.532974e-001,0.000000e+000,,,,,,,,,,,,,,32,1,4.000000e+000,1.170990e+000,0.000000e+000,0,,0,
1578427771.710,,0.000000e+000,2.094094e+002,6.923795e-006,0.000000e+000,3,9.551961e-001,0.000000e+000,,,,,,,,,,,,,,32,1,4.000000e+000,9.955902e-001,0.000000e+000,0,,0,
1578427833.310,,0.000000e+000,2.043462e+002,6.926082e-006,0.000000e+000,3,9.512617e-001,0.000000e+000,,,,,,,,,,,,,,32,1,4.000000e+000,1.187698e+000,0.000000e+000,0,,0,
1578427893.740,,0.000000e+000,1.993898e+002,6.974637e-006,0.000000e+000,3,9.544154e-001,0.000000e+000,,,,,,,,,,,,,,32,1,4.000000e+000,1.187500e+000,0.000000e+000,0,,0,
1578427954.470,,0.000000e+000,1.943423e+002,7.014345e-006,0.000000e+000,3,9.615803e-001,0.000000e+000,,,,,,,,,,,,,,32,1,4.000000e+000,1.106308e+000,0.000000e+000,0,,0,
1578428014.391,,0.000000e+000,1.893898e+002,6.928027e-006,0.000000e+000,3,9.582414e-001,0.000000e+000,,,,,,,,,,,,,,32,1,4.000000e+000,1.102509e+000,0.000000e+000,0,,0,
1578428074.991,,0.000000e+000,1.843629e+002,6.833518e-006,0.000000e+000,3,9.542165e-001,0.000000e+000,,,,,,,,,,,,,,32,1,4.000000e+000,1.105988e+000,0.000000e+000,0,,0,
1578428135.181,,0.000000e+000,1.793268e+002,6.757266e-006,0.000000e+000,3,9.583515e-001,0.000000e+000,,,,,,,,,,,,,,32,1,4.000000e+000,1.203705e+000,0.000000e+000,0,,0,
1578428194.901,,0.000000e+000,1.742906e+002,6.836569e-006,0.000000e+000,3,9.528115e-001,0.000000e+000,,,,,,,,,,,,,,32,1,4.000000e+000,1.048401e+000,0.000000e+000,0,,0,
1578428253.021,,0.000000e+000,1.694658e+002,6.775233e-006,0.000000e+000,3,9.544996e-001,0.000000e+000,,,,,,,,,,,,,,32,1,4.000000e+000,1.034897e+000,0.000000e+000,0,,0,
1578428313.611,,0.000000e+000,1.644028e+002,6.749755e-006,0.000000e+000,3,9.552344e-001,0.000000e+000,,,,,,,,,,,,,,32,1,4.000000e+000,1.039200e+000,0.000000e+000,0,,0,
1578428374.121,,0.000000e+000,1.593356e+002,6.716093e-006,0.000000e+000,3,9.521961e-001,0.000000e+000,,,,,,,,,,,,,,32,1,4.000000e+000,1.153397e+000,0.000000e+000,0,,0,
1578428432.971,,0.000000e+000,1.543290e+002,6.617910e-006,0.000000e+000,3,9.510903e-001,0.000000e+000,,,,,,,,,,,,,,32,1,4.000000e+000,1.181290e+000,0.000000e+000,0,,0,
1578428493.061,,0.000000e+000,1.492794e+002,6.458422e-006,0.000000e+000,3,9.547433e-001,0.000000e+000,,,,,,,,,,,,,,32,1,4.000000e+000,1.297913e+000,0.000000e+000,0,,0,
1578428550.441,,0.000000e+000,1.443973e+002,6.368932e-006,0.000000e+000,3,9.501796e-001,0.000000e+000,,,,,,,,,,,,,,32,1,4.000000e+000,1.098190e+000,0.000000e+000,0,,0,
1578428609.241,,0.000000e+000,1.393683e+002,6.354886e-006,0.000000e+000,3,9.483654e-001,0.000000e+000,,,,,,,,,,,,,,32,1,4.000000e+000,9.913025e-001,0.000000e+000,0,,0,
1578428668.091,,0.000000e+000,1.342639e+002,6.155207e-006,0.000000e+000,3,9.490433e-001,0.000000e+000,,,,,,,,,,,,,,32,1,4.000000e+000,1.129105e+000,0.000000e+000,0,,0,
1578428725.112,,0.000000e+000,1.294228e+002,5.969782e-006,0.000000e+000,3,9.482186e-001,0.000000e+000,,,,,,,,,,,,,,32,1,4.000000e+000,1.139801e+000,0.000000e+000,0,,0,
1578428809.012,,0.000000e+000,1.220694e+002,-9.311377e-005,0.000000e+000,3,3.648195e-001,0.000000e+000,,,,,,,,,,,,,,32,1,4.000000e+000,9.583969e-001,0.000000e+000,0,,0,
1578428880.212,,0.000000e+000,1.159114e+002,5.404579e-006,0.000000e+000,3,9.473398e-001,0.000000e+000,,,,,,,,,,,,,,32,1,4.000000e+000,9.161987e-001,0.000000e+000,0,,0,
1578428898.802,,0.000000e+000,1.143015e+002,5.116089e-006,0.000000e+000,3,9.327463e-001,0.000000e+000,,,,,,,,,,,,,,32,1,4.000000e+000,1.064003e+000,0.000000e+000,0,,0,
1578428955.542,,0.000000e+000,1.092883e+002,4.845769e-006,0.000000e+000,3,9.381509e-001,0.000000e+000,,,,,,,,,,,,,,32,1,4.000000e+000,1.305305e+000,0.000000e+000,0,,0,
1578429034.232,,0.000000e+000,1.021094e+002,4.801968e-006,0.000000e+000,3,9.315346e-001,0.000000e+000,,,,,,,,,,,,,,32,1,4.000000e+000,9.617996e-001,0.000000e+000,0,,0,
1578429064.672,,0.000000e+000,9.934183e+001,4.781528e-006,0.000000e+000,3,9.267122e-001,0.000000e+000,,,,,,,,,,,,,,32,1,4.000000e+000,1.156013e+000,0.000000e+000,0,,0,
1578429118.882,,0.000000e+000,9.425533e+001,4.657000e-006,0.000000e+000,3,9.265971e-001,0.000000e+000,,,,,,,,,,,,,,32,1,4.000000e+000,1.141380e+000,0.000000e+000,0,,0,
1578429171.342,,0.000000e+000,8.930412e+001,4.702211e-006,0.000000e+000,3,9.311664e-001,0.000000e+000,,,,,,,,,,,,,,32,1,4.000000e+000,1.289680e+000,0.000000e+000,0,,0,
1578429223.642,,0.000000e+000,8.430471e+001,4.554911e-006,0.000000e+000,3,9.376471e-001,0.000000e+000,,,,,,,,,,,,,,32,1,4.000000e+000,1.217606e+000,0.000000e+000,0,,0,
1578429274.032,,0.000000e+000,7.933005e+001,4.548582e-006,0.000000e+000,3,9.476393e-001,0.000000e+000,,,,,,,,,,,,,,32,1,4.000000e+000,1.126251e+000,0.000000e+000,0,,0,
1578429323.592,,0.000000e+000,7.434991e+001,4.652603e-006,0.000000e+000,3,9.347237e-001,0.000000e+000,,,,,,,,,,,,,,32,1,4.000000e+000,1.122452e+000,0.000000e+000,0,,0,
1578429375.452,,0.000000e+000,6.931506e+001,4.622352e-006,0.000000e+000,3,9.309481e-001,0.000000e+000,,,,,,,,,,,,,,32,1,4.000000e+000,1.224411e+000,0.000000e+000,0,,0,
1578429421.943,,0.000000e+000,6.420837e+001,4.679689e-006,0.000000e+000,3,9.322135e-001,0.000000e+000,,,,,,,,,,,,,,32,1,4.000000e+000,1.260895e+000,0.000000e+000,0,,0,
1578429467.843,,0.000000e+000,5.935939e+001,4.723230e-006,0.000000e+000,3,9.392502e-001,0.000000e+000,,,,,,,,,,,,,,32,1,4.000000e+000,1.251343e+000,0.000000e+000,0,,0,
1578429517.713,,0.000000e+000,5.439680e+001,4.693909e-006,0.000000e+000,3,9.362258e-001,0.000000e+000,,,,,,,,,,,,,,32,1,4.000000e+000,1.065147e+000,0.000000e+000,0,,0,
1578429569.463,,0.000000e+000,4.931261e+001,4.768691e-006,0.000000e+000,3,9.304913e-001,0.000000e+000,,,,,,,,,,,,,,32,1,4.000000e+000,1.229351e+000,0.000000e+000,0,,0,
1578429620.843,,0.000000e+000,4.427981e+001,4.621457e-006,0.000000e+000,3,9.430526e-001,0.000000e+000,,,,,,,,,,,,,,32,1,4.000000e+000,1.065289e+000,0.000000e+000,0,,0,
1578429669.763,,0.000000e+000,3.928796e+001,4.689621e-006,0.000000e+000,3,9.312369e-001,0.000000e+000,,,,,,,,,,,,,,32,1,4.000000e+000,1.068260e+000,0.000000e+000,0,,0,
1578429716.463,,0.000000e+000,3.423857e+001,4.698881e-006,0.000000e+000,3,9.257001e-001,0.000000e+000,,,,,,,,,,,,,,32,1,4.000000e+000,1.375549e+000,0.000000e+000,0,,0,
1578429760.873,,0.000000e+000,2.920290e+001,4.743511e-006,0.000000e+000,3,9.338769e-001,0.000000e+000,,,,,,,,,,,,,,32,1,4.000000e+000,1.377291e+000,0.000000e+000,0,,0,
1578429802.683,,0.000000e+000,2.410234e+001,4.765625e-006,0.000000e+000,3,9.375691e-001,0.000000e+000,,,,,,,,,,,,,,32,1,4.000000e+000,1.494661e+000,0.000000e+000,0,,0,
1578429861.733,,0.000000e+000,1.960398e+001,4.691274e-006,0.000000e+000,3,9.334475e-001,0.000000e+000,,,,,,,,,,,,,,32,1,4.000000e+000,7.900505e-001,0.000000e+000,0,,0,
1578429917.393,,0.000000e+000,1.391015e+001,4.914479e-006,0.000000e+000,3,9.407315e-001,0.000000e+000,,,,,,,,,,,,,,32,1,4.000000e+000,1.617110e+000,0.000000e+000,0,,0,
1578430752.334,,0.000000e+000,1.001163e+001,5.004804e-006,0.000000e+000,3,9.551483e-001,0.000000e+000,,,,,,,,,,,,,,32,1,4.000000e+000,6.999969e-004,0.000000e+000,0,,0,
1578430823.574,,0.000000e+000,1.004237e+001,4.835553e-006,0.000000e+000,3,9.523513e-001,0.000000e+000,,,,,,,,,,,,,,32,1,4.000000e+000,4.329681e-003,0.000000e+000,0,,0,
1578430903.465,,0.000000e+000,1.560890e+001,4.749327e-006,0.000000e+000,3,9.269676e-001,0.000000e+000,,,,,,,,,,,,,,32,1,4.000000e+000,9.075298e-001,0.000000e+000,0,,0,
1578430963.265,,0.000000e+000,2.052617e+001,4.769126e-006,0.000000e+000,3,9.578046e-001,0.000000e+000,,,,,,,,,,,,,,32,1,4.000000e+000,1.004791e+000,0.000000e+000,0,,0,
1578431025.165,,0.000000e+000,2.565847e+001,4.678398e-006,0.000000e+000,3,9.287023e-001,0.000000e+000,,,,,,,,,,,,,,32,1,4.000000e+000,8.956184e-001,0.000000e+000,0,,0,
1578431084.905,,0.000000e+000,3.052754e+001,4.821663e-006,0.000000e+000,3,9.465348e-001,0.000000e+000,,,,,,,,,,,,,,32,1,4.000000e+000,9.391804e-001,0.000000e+000,0,,0,
1578431146.835,,0.000000e+000,3.563973e+001,4.689424e-006,0.000000e+000,3,9.446934e-001,0.000000e+000,,,,,,,,,,,,,,32,1,4.000000e+000,9.944992e-001,0.000000e+000,0,,0,
1578431207.005,,0.000000e+000,4.058121e+001,4.819110e-006,0.000000e+000,3,9.373029e-001,0.000000e+000,,,,,,,,,,,,,,32,1,4.000000e+000,9.660301e-001,0.000000e+000,0,,0,
1578431266.025,,0.000000e+000,4.549895e+001,4.785953e-006,0.000000e+000,3,9.474841e-001,0.000000e+000,,,,,,,,,,,,,,32,1,4.000000e+000,9.527473e-001,0.000000e+000,0,,0,
1578431327.545,,0.000000e+000,5.058383e+001,8.891294e-005,0.000000e+000,3,3.384006e-001,0.000000e+000,,,,,,,,,,,,,,32,1,4.000000e+000,8.527794e-001,0.000000e+000,0,,0,
1578431387.855,,0.000000e+000,5.556992e+001,4.664801e-006,0.000000e+000,3,9.397107e-001,0.000000e+000,,,,,,,,,,,,,,32,1,4.000000e+000,9.969025e-001,0.000000e+000,0,,0,
1578431446.595,,0.000000e+000,6.050959e+001,4.751474e-006,0.000000e+000,3,9.464594e-001,0.000000e+000,,,,,,,,,,,,,,32,1,4.000000e+000,9.691010e-001,0.000000e+000,0,,0,
1578431507.265,,0.000000e+000,6.558307e+001,4.715163e-006,0.000000e+000,3,9.411156e-001,0.000000e+000,,,,,,,,,,,,,,32,1,4.000000e+000,8.717651e-001,0.000000e+000,0,,0,
1578431568.096,,0.000000e+000,7.062143e+001,4.498502e-006,0.000000e+000,3,9.469802e-001,0.000000e+000,,,,,,,,,,,,,,32,1,4.000000e+000,8.654861e-001,0.000000e+000,0,,0,
1578431626.906,,0.000000e+000,7.561868e+001,4.712136e-006,0.000000e+000,3,9.533605e-001,0.000000e+000,,,,,,,,,,,,,,32,1,4.000000e+000,9.293594e-001,0.000000e+000,0,,0,
1578431685.486,,0.000000e+000,8.048740e+001,4.688504e-006,0.000000e+000,3,9.590501e-001,0.000000e+000,,,,,,,,,,,,,,32,1,4.000000e+000,9.009781e-001,0.000000e+000,0,,0,
1578431746.106,,0.000000e+000,8.551875e+001,4.622181e-006,0.000000e+000,3,9.511706e-001,0.000000e+000,,,,,,,,,,,,,,32,1,4.000000e+000,8.615799e-001,0.000000e+000,0,,0,
1578431805.886,,0.000000e+000,9.052859e+001,4.589843e-006,0.000000e+000,3,9.437699e-001,0.000000e+000,,,,,,,,,,,,,,32,1,4.000000e+000,9.629974e-001,0.000000e+000,0,,0,
1578431864.836,,0.000000e+000,9.550316e+001,4.691860e-006,0.000000e+000,3,9.421065e-001,0.000000e+000,,,,,,,,,,,,,,32,1,4.000000e+000,9.573364e-001,0.000000e+000,0,,0,
1578431926.266,,0.000000e+000,1.006311e+002,4.767187e-006,0.000000e+000,3,9.400303e-001,0.000000e+000,,,,,,,,,,,,,,32,1,4.000000e+000,8.107986e-001,0.000000e+000,0,,0,
1578431984.886,,0.000000e+000,1.055186e+002,4.722148e-006,0.000000e+000,3,9.495783e-001,0.000000e+000,,,,,,,,,,,,,,32,1,4.000000e+000,9.001999e-001,0.000000e+000,0,,0,
1578432044.496,,0.000000e+000,1.105280e+002,4.888680e-006,0.000000e+000,3,9.457922e-001,0.000000e+000,,,,,,,,,,,,,,32,1,4.000000e+000,9.978027e-001,0.000000e+000,0,,0,
1578432105.326,,0.000000e+000,1.156051e+002,4.871130e-006,0.000000e+000,3,9.580719e-001,0.000000e+000,,,,,,,,,,,,,,32,1,4.000000e+000,8.357010e-001,0.000000e+000,0,,0,
1578432163.546,,0.000000e+000,1.204861e+002,5.028117e-006,0.000000e+000,3,9.536628e-001,0.000000e+000,,,,,,,,,,,,,,32,1,4.000000e+000,9.013977e-001,0.000000e+000,0,,0,
1578432223.776,,0.000000e+000,1.255667e+002,5.173960e-006,0.000000e+000,3,9.463993e-001,0.000000e+000,,,,,,,,,,,,,,32,1,4.000000e+000,1.000999e+000,0.000000e+000,0,,0,
1578432284.817,,0.000000e+000,1.306056e+002,5.157539e-006,0.000000e+000,3,9.508604e-001,0.000000e+000,,,,,,,,,,,,,,32,1,4.000000e+000,1.033096e+000,0.000000e+000,0,,0,
1578432344.217,,0.000000e+000,1.355595e+002,5.329070e-006,0.000000e+000,3,9.548455e-001,0.000000e+000,,,,,,,,,,,,,,32,1,4.000000e+000,9.286957e-001,0.000000e+000,0,,0,
1578432403.857,,0.000000e+000,1.405547e+002,5.401731e-006,0.000000e+000,3,9.567714e-001,0.000000e+000,,,,,,,,,,,,,,32,1,4.000000e+000,8.872986e-001,0.000000e+000,0,,0,
1578432464.667,,0.000000e+000,1.456196e+002,5.247548e-006,0.000000e+000,3,9.495029e-001,0.000000e+000,,,,,,,,,,,,,,32,1,4.000000e+000,8.707886e-001,0.000000e+000,0,,0,
1578432524.147,,0.000000e+000,1.506033e+002,5.354289e-006,0.000000e+000,3,9.568824e-001,0.000000e+000,,,,,,,,,,,,,,32,1,4.000000e+000,8.045959e-001,0.000000e+000,0,,0,
1578432583.197,,0.000000e+000,1.555367e+002,5.399081e-006,0.000000e+000,3,9.556800e-001,0.000000e+000,,,,,,,,,,,,,,32,1,4.000000e+000,9.320984e-001,0.000000e+000,0,,0,
1578432644.257,,0.000000e+000,1.606163e+002,5.351278e-006,0.000000e+000,3,9.586462e-001,0.000000e+000,,,,,,,,,,,,,,32,1,4.000000e+000,9.199982e-001,0.000000e+000,0,,0,
1578432703.037,,0.000000e+000,1.655657e+002,5.490569e-006,0.000000e+000,3,9.560865e-001,0.000000e+000,,,,,,,,,,,,,,32,1,4.000000e+000,9.206085e-001,0.000000e+000,0,,0,
1578432762.277,,0.000000e+000,1.704812e+002,5.444721e-006,0.000000e+000,3,9.562191e-001,0.000000e+000,,,,,,,,,,,,,,32,1,4.000000e+000,9.068909e-001,0.000000e+000,0,,0,
1578432824.017,,0.000000e+000,1.756443e+002,5.372539e-006,0.000000e+000,3,9.513830e-001,0.000000e+000,,,,,,,,,,,,,,32,1,4.000000e+000,9.793091e-001,0.000000e+000,0,,0,
1578432883.237,,0.000000e+000,1.805897e+002,5.454478e-006,0.000000e+000,3,9.498635e-001,0.000000e+000,,,,,,,,,,,,,,32,1,4.000000e+000,8.924103e-001,0.000000e+000,0,,0,
1578432942.247,,0.000000e+000,1.855098e+002,5.399763e-006,0.000000e+000,3,9.516633e-001,0.000000e+000,,,,,,,,,,,,,,32,1,4.000000e+000,9.674072e-001,0.000000e+000,0,,0,
1578433017.208,,0.000000e+000,1.917304e+002,5.301485e-006,0.000000e+000,3,9.404680e-001,0.000000e+000,,,,,,,,,,,,,,32,1,4.000000e+000,9.793854e-001,0.000000e+000,0,,0,
1578433062.838,,0.000000e+000,1.955505e+002,5.439952e-006,0.000000e+000,3,9.524191e-001,0.000000e+000,,,,,,,,,,,,,,32,1,4.000000e+000,9.520111e-001,0.000000e+000,0,,0,
1578433121.938,,0.000000e+000,2.004923e+002,5.433989e-006,0.000000e+000,3,9.535438e-001,0.000000e+000,,,,,,,,,,,,,,32,1,4.000000e+000,9.369965e-001,0.000000e+000,0,,0,
1578433183.048,,0.000000e+000,2.056351e+002,5.392773e-006,0.000000e+000,3,9.547506e-001,0.000000e+000,,,,,,,,,,,,,,32,1,4.000000e+000,9.403076e-001,0.000000e+000,0,,0,
1578433242.178,,0.000000e+000,2.105386e+002,5.362989e-006,0.000000e+000,3,9.587668e-001,0.000000e+000,,,,,,,,,,,,,,32,1,4.000000e+000,8.654022e-001,0.000000e+000,0,,0,
1578433301.738,,0.000000e+000,2.154963e+002,5.405703e-006,0.000000e+000,3,9.489652e-001,0.000000e+000,,,,,,,,,,,,,,32,1,4.000000e+000,9.434967e-001,0.000000e+000,0,,0,
1578433363.298,,0.000000e+000,2.205858e+002,5.401158e-006,0.000000e+000,3,9.535974e-001,0.000000e+000,,,,,,,,,,,,,,32,1,4.000000e+000,1.011093e+000,0.000000e+000,0,,0,
1578433422.418,,0.000000e+000,2.255727e+002,5.373867e-006,0.000000e+000,3,9.523396e-001,0.000000e+000,,,,,,,,,,,,,,32,1,4.000000e+000,9.117889e-001,0.000000e+000,0,,0,
1578433481.918,,0.000000e+000,2.305344e+002,5.317568e-006,0.000000e+000,3,9.517869e-001,0.000000e+000,,,,,,,,,,,,,,32,1,4.000000e+000,9.947968e-001,0.000000e+000,0,,0,
1578433542.588,,0.000000e+000,2.355675e+002,5.268094e-006,0.000000e+000,3,9.549018e-001,0.000000e+000,,,,,,,,,,,,,,32,1,4.000000e+000,8.170013e-001,0.000000e+000,0,,0,
1578433602.438,,0.000000e+000,2.405613e+002,5.409860e-006,0.000000e+000,3,9.568769e-001,0.000000e+000,,,,,,,,,,,,,,32,1,4.000000e+000,9.084015e-001,0.000000e+000,0,,0,
1578433662.088,,0.000000e+000,2.455658e+002,5.450217e-006,0.000000e+000,3,9.572967e-001,0.000000e+000,,,,,,,,,,,,,,32,1,4.000000e+000,9.057007e-001,0.000000e+000,0,,0,
1578433721.999,,0.000000e+000,2.504714e+002,5.249787e-006,0.000000e+000,3,9.449083e-001,0.000000e+000,,,,,,,,,,,,,,32,1,4.000000e+000,8.896027e-001,0.000000e+000,0,,0,
1578433782.079,,0.000000e+000,2.555768e+002,5.335202e-006,0.000000e+000,3,9.457896e-001,0.000000e+000,,,,,,,,,,,,,,32,1,4.000000e+000,9.036865e-001,0.000000e+000,0,,0,
1578433840.939,,0.000000e+000,2.604921e+002,5.397014e-006,0.000000e+000,3,9.534734e-001,0.000000e+000,,,,,,,,,,,,,,32,1,4.000000e+000,9.711914e-001,0.000000e+000,0,,0,
1578433903.219,,0.000000e+000,2.656232e+002,5.222251e-006,0.000000e+000,3,9.529902e-001,0.000000e+000,,,,,,,,,,,,,,32,1,4.000000e+000,8.945923e-001,0.000000e+000,0,,0,
1578433961.519,,0.000000e+000,2.705200e+002,5.179529e-006,0.000000e+000,3,9.454337e-001,0.000000e+000,,,,,,,,,,,,,,32,1,4.000000e+000,9.656067e-001,0.000000e+000,0,,0,
1578434022.229,,0.000000e+000,2.755337e+002,5.158462e-006,0.000000e+000,3,9.482310e-001,0.000000e+000,,,,,,,,,,,,,,32,1,4.000000e+000,1.015808e+000,0.000000e+000,0,,0,
1578434082.669,,0.000000e+000,2.806600e+002,5.316445e-006,0.000000e+000,3,9.553412e-001,0.000000e+000,,,,,,,,,,,,,,32,1,4.000000e+000,9.512024e-001,0.000000e+000,0,,0,
1578434141.369,,0.000000e+000,2.855153e+002,5.079268e-006,0.000000e+000,3,9.496912e-001,0.000000e+000,,,,,,,,,,,,,,32,1,4.000000e+000,9.588013e-001,0.000000e+000,0,,0,
1578434200.489,,0.000000e+000,2.905200e+002,5.014751e-006,0.000000e+000,3,9.565086e-001,0.000000e+000,,,,,,,,,,,,,,32,1,4.000000e+000,8.819885e-001,0.000000e+000,0,,0,
1578434262.819,,0.000000e+000,2.956666e+002,5.164520e-006,0.000000e+000,3,9.564229e-001,0.000000e+000,,,,,,,,,,,,,,32,1,4.000000e+000,9.436035e-001,0.000000e+000,0,,0,
1578434596.700,,0.000000e+000,3.000190e+002,5.119388e-006,0.000000e+000,3,9.513218e-001,0.000000e+000,,,,,,,,,,,,,,32,1,4.000000e+000,1.498413e-002,0.000000e+000,0,,0,