File: data/Rock_mag/2020_IRM_data_files/Raw_data/MPMS-XL/data/AX21-7-sc_FC-ZFC-RTSIRM-10K_5sec.dc.dc.dat
[Header]
TITLE,MPMS DC Measurement
BYAPP,MPMS Measurement,2.1,Summary
FILEOPENTIME, 1578671432.553000 1/10/2020, 9:50:32 AM

INFO, APPNAME, MPMS MultiVu Application, Revision 1.61,  Build 082

INFO, NAME, AX21-7-sc
INFO, WEIGHT, 1.000
INFO, AREA, 1.000
INFO, LENGTH, 1.000
INFO, SHAPE, 0
INFO, COMMENT,
INFO, SEQUENCE FILE: FC-ZFC LTSIRM and RTSIRM LTD (settle 5 scans).seq


INFO, BACKGROUND DATA FILE:, None


STARTUPAXIS,X,4,LINEAR,AUTO,0.000000,0.000000
STARTUPAXIS,Y1,5,LINEAR,AUTO,0.000000,0.000000


STARTUPGROUP,Longitudinal
FIELDGROUP,Longitudinal,1,2,3,4,5,6,7,8,9,15,16,17,18,27,28
FIELDGROUP,Transverse,1,2,3,4,10,11,12,13,14,19,20,21,22,27,28

PLOT_APPEARANCE,ALL,HORZ_GRID_ON,VERT_GRID_ON,MARKERS_AND_LINES

[Data]
Time,Comment,Field (Oe),Temperature (K),Long Moment (emu),Long Scan Std Dev,Long Algorithm,Long Reg Fit,Long Percent Error (%),Trans Moment (emu),Trans Scan Std Dev,Trans Algorithm,Trans Reg Fit,Trans Percent Error (%),Long Moment [w/o ABS] (emu),Long Scan Std Dev [w/o ABS],Long Reg Fit [w/o ABS],Long Percent Error [w/o ABS] (%),Trans Moment [w/o ABS] (emu),Trans Scan Std Dev [w/o ABS],Trans Reg Fit [w/o ABS],Trans Percent Error [w/o ABS] (%),Points per Scan,Scans per Measurement,Scan Length (cm),Delta Temp (K),Rot Position (deg),Error,EC Comp. Running,Using ABS,
1578671432.553,,2.500000e+004,2.999816e+002,1.894494e-003,0.000000e+000,3,9.832224e-001,0.000000e+000,,,,,,,,,,,,,,32,1,4.000000e+000,0.000000e+000,0.000000e+000,0,,0,
1578671748.624,,2.500000e+004,2.943732e+002,1.911400e-003,0.000000e+000,3,9.182499e-001,0.000000e+000,,,,,,,,,,,,,,32,1,4.000000e+000,9.494934e-001,0.000000e+000,0,,0,
1578671806.464,,2.500000e+004,2.891970e+002,2.036260e-003,0.000000e+000,3,9.820914e-001,0.000000e+000,,,,,,,,,,,,,,32,1,4.000000e+000,1.234192e+000,0.000000e+000,0,,0,
1578671854.904,,2.500000e+004,2.841187e+002,2.103745e-003,0.000000e+000,3,9.820167e-001,0.000000e+000,,,,,,,,,,,,,,32,1,4.000000e+000,1.323395e+000,0.000000e+000,0,,0,
1578671901.904,,2.500000e+004,2.792929e+002,2.171312e-003,0.000000e+000,3,9.808818e-001,0.000000e+000,,,,,,,,,,,,,,32,1,4.000000e+000,1.315796e+000,0.000000e+000,0,,0,
1578671952.694,,2.500000e+004,2.741310e+002,2.241419e-003,0.000000e+000,3,9.807087e-001,0.000000e+000,,,,,,,,,,,,,,32,1,4.000000e+000,1.340088e+000,0.000000e+000,0,,0,
1578672003.974,,2.500000e+004,2.693609e+002,2.309167e-003,0.000000e+000,3,9.807472e-001,0.000000e+000,,,,,,,,,,,,,,32,1,4.000000e+000,1.208191e+000,0.000000e+000,0,,0,
1578672061.024,,2.500000e+004,2.643234e+002,2.384992e-003,0.000000e+000,3,9.801154e-001,0.000000e+000,,,,,,,,,,,,,,32,1,4.000000e+000,1.149994e+000,0.000000e+000,0,,0,
1578672123.914,,2.500000e+004,2.593643e+002,2.509438e-003,0.000000e+000,3,9.834079e-001,0.000000e+000,,,,,,,,,,,,,,32,1,4.000000e+000,1.217712e+000,0.000000e+000,0,,0,
1578672190.514,,2.500000e+004,2.543883e+002,2.534190e-003,0.000000e+000,3,9.796199e-001,0.000000e+000,,,,,,,,,,,,,,32,1,4.000000e+000,9.807892e-001,0.000000e+000,0,,0,
1578672258.625,,2.500000e+004,2.494670e+002,2.613893e-003,0.000000e+000,3,9.796950e-001,0.000000e+000,,,,,,,,,,,,,,32,1,4.000000e+000,9.748993e-001,0.000000e+000,0,,0,
1578672328.625,,2.500000e+004,2.444709e+002,2.582514e-003,0.000000e+000,3,9.788395e-001,0.000000e+000,,,,,,,,,,,,,,32,1,4.000000e+000,9.669037e-001,0.000000e+000,0,,0,
1578672398.475,,2.500000e+004,2.394621e+002,2.779105e-003,0.000000e+000,3,9.795259e-001,0.000000e+000,,,,,,,,,,,,,,32,1,4.000000e+000,1.023499e+000,0.000000e+000,0,,0,
1578672463.335,,2.500000e+004,2.343669e+002,2.869545e-003,0.000000e+000,3,9.785540e-001,0.000000e+000,,,,,,,,,,,,,,32,1,4.000000e+000,1.072403e+000,0.000000e+000,0,,0,
1578672526.585,,2.500000e+004,2.292910e+002,2.967424e-003,0.000000e+000,3,9.793074e-001,0.000000e+000,,,,,,,,,,,,,,32,1,4.000000e+000,1.106506e+000,0.000000e+000,0,,0,
1578672587.795,,2.500000e+004,2.243889e+002,3.066107e-003,0.000000e+000,3,9.785644e-001,0.000000e+000,,,,,,,,,,,,,,32,1,4.000000e+000,1.203613e+000,0.000000e+000,0,,0,
1578672648.135,,2.500000e+004,2.193871e+002,3.170169e-003,0.000000e+000,3,9.790180e-001,0.000000e+000,,,,,,,,,,,,,,32,1,4.000000e+000,1.048508e+000,0.000000e+000,0,,0,
1578672709.475,,2.500000e+004,2.144346e+002,3.281953e-003,0.000000e+000,3,9.780506e-001,0.000000e+000,,,,,,,,,,,,,,32,1,4.000000e+000,1.118500e+000,0.000000e+000,0,,0,
1578672769.605,,2.500000e+004,2.094608e+002,3.396026e-003,0.000000e+000,3,9.781259e-001,0.000000e+000,,,,,,,,,,,,,,32,1,4.000000e+000,1.040009e+000,0.000000e+000,0,,0,
1578672831.495,,2.500000e+004,2.043773e+002,3.522646e-003,0.000000e+000,3,9.781373e-001,0.000000e+000,,,,,,,,,,,,,,32,1,4.000000e+000,1.055313e+000,0.000000e+000,0,,0,
1578672891.405,,2.500000e+004,1.993463e+002,3.649834e-003,0.000000e+000,3,9.777675e-001,0.000000e+000,,,,,,,,,,,,,,32,1,4.000000e+000,1.153702e+000,0.000000e+000,0,,0,
1578672950.605,,2.500000e+004,1.943992e+002,3.782029e-003,0.000000e+000,3,9.775643e-001,0.000000e+000,,,,,,,,,,,,,,32,1,4.000000e+000,9.924011e-001,0.000000e+000,0,,0,
1578673011.496,,2.500000e+004,1.893625e+002,3.922720e-003,0.000000e+000,3,9.782280e-001,0.000000e+000,,,,,,,,,,,,,,32,1,4.000000e+000,1.071899e+000,0.000000e+000,0,,0,
1578673070.716,,2.500000e+004,1.844061e+002,4.071234e-003,0.000000e+000,3,9.772108e-001,0.000000e+000,,,,,,,,,,,,,,32,1,4.000000e+000,1.077698e+000,0.000000e+000,0,,0,
1578673130.966,,2.500000e+004,1.793377e+002,4.229143e-003,0.000000e+000,3,9.773049e-001,0.000000e+000,,,,,,,,,,,,,,32,1,4.000000e+000,1.192795e+000,0.000000e+000,0,,0,
1578673189.826,,2.500000e+004,1.743998e+002,4.392260e-003,0.000000e+000,3,9.771994e-001,0.000000e+000,,,,,,,,,,,,,,32,1,4.000000e+000,1.101608e+000,0.000000e+000,0,,0,
1578673250.562,,2.500000e+004,1.692666e+002,4.603851e-003,0.000000e+000,3,9.654915e-001,0.000000e+000,,,,,,,,,,,,,,32,1,4.000000e+000,1.116302e+000,0.000000e+000,0,,0,
1578673308.962,,2.500000e+004,1.643824e+002,4.757000e-003,0.000000e+000,3,9.765542e-001,0.000000e+000,,,,,,,,,,,,,,32,1,4.000000e+000,1.220703e+000,0.000000e+000,0,,0,
1578673368.982,,2.500000e+004,1.593927e+002,4.959226e-003,0.000000e+000,3,9.766777e-001,0.000000e+000,,,,,,,,,,,,,,32,1,4.000000e+000,1.110199e+000,0.000000e+000,0,,0,
1578673426.842,,2.500000e+004,1.543806e+002,5.165094e-003,0.000000e+000,3,9.767170e-001,0.000000e+000,,,,,,,,,,,,,,32,1,4.000000e+000,1.044693e+000,0.000000e+000,0,,0,
1578673484.942,,2.500000e+004,1.493908e+002,5.364637e-003,0.000000e+000,3,9.768524e-001,0.000000e+000,,,,,,,,,,,,,,32,1,4.000000e+000,1.162201e+000,0.000000e+000,0,,0,
1578673544.542,,2.500000e+004,1.443828e+002,5.553031e-003,0.000000e+000,3,9.743665e-001,0.000000e+000,,,,,,,,,,,,,,32,1,4.000000e+000,1.157104e+000,0.000000e+000,0,,0,
1578673602.492,,2.500000e+004,1.393218e+002,5.887811e-003,0.000000e+000,3,9.763184e-001,0.000000e+000,,,,,,,,,,,,,,32,1,4.000000e+000,1.070389e+000,0.000000e+000,0,,0,
1578673660.862,,2.500000e+004,1.344092e+002,6.164295e-003,0.000000e+000,3,9.759079e-001,0.000000e+000,,,,,,,,,,,,,,32,1,4.000000e+000,9.886017e-001,0.000000e+000,0,,0,
1578673718.253,,2.500000e+004,1.293618e+002,6.459582e-003,0.000000e+000,3,9.714632e-001,0.000000e+000,,,,,,,,,,,,,,32,1,4.000000e+000,9.999084e-001,0.000000e+000,0,,0,
1578673776.373,,2.500000e+004,1.243186e+002,6.609831e-003,0.000000e+000,3,9.766347e-001,0.000000e+000,,,,,,,,,,,,,,32,1,4.000000e+000,1.022095e+000,0.000000e+000,0,,0,
1578673833.473,,2.500000e+004,1.193714e+002,6.636820e-003,0.000000e+000,3,9.433998e-001,0.000000e+000,,,,,,,,,,,,,,32,1,4.000000e+000,1.120705e+000,0.000000e+000,0,,0,
1578673889.883,,2.500000e+004,1.144236e+002,7.484192e-003,0.000000e+000,3,9.722623e-001,0.000000e+000,,,,,,,,,,,,,,32,1,4.000000e+000,1.140900e+000,0.000000e+000,0,,0,
1578673946.963,,2.500000e+004,1.093633e+002,7.927414e-003,0.000000e+000,3,9.752912e-001,0.000000e+000,,,,,,,,,,,,,,32,1,4.000000e+000,1.164406e+000,0.000000e+000,0,,0,
1578674002.483,,2.500000e+004,1.043815e+002,8.296971e-003,0.000000e+000,3,9.729149e-001,0.000000e+000,,,,,,,,,,,,,,32,1,4.000000e+000,1.082893e+000,0.000000e+000,0,,0,
1578674057.873,,2.500000e+004,9.932719e+001,8.865590e-003,0.000000e+000,3,9.753426e-001,0.000000e+000,,,,,,,,,,,,,,32,1,4.000000e+000,1.246307e+000,0.000000e+000,0,,0,
1578674123.103,,2.500000e+004,9.316936e+001,9.370952e-003,0.000000e+000,3,9.761021e-001,0.000000e+000,,,,,,,,,,,,,,32,1,4.000000e+000,1.016975e+000,0.000000e+000,0,,0,
1578674163.943,,2.500000e+004,8.928775e+001,9.994377e-003,0.000000e+000,3,9.743152e-001,0.000000e+000,,,,,,,,,,,,,,32,1,4.000000e+000,1.164406e+000,0.000000e+000,0,,0,
1578674217.493,,2.500000e+004,8.420094e+001,1.062174e-002,0.000000e+000,3,9.719191e-001,0.000000e+000,,,,,,,,,,,,,,32,1,4.000000e+000,1.276840e+000,0.000000e+000,0,,0,
1578674267.073,,2.500000e+004,7.941985e+001,1.140330e-002,0.000000e+000,3,9.748747e-001,0.000000e+000,,,,,,,,,,,,,,32,1,4.000000e+000,1.105675e+000,0.000000e+000,0,,0,
1578674318.163,,2.500000e+004,7.431456e+001,1.245764e-002,0.000000e+000,3,9.646549e-001,0.000000e+000,,,,,,,,,,,,,,32,1,4.000000e+000,1.220573e+000,0.000000e+000,0,,0,
1578674369.333,,2.500000e+004,6.931664e+001,1.319100e-002,0.000000e+000,3,9.745678e-001,0.000000e+000,,,,,,,,,,,,,,32,1,4.000000e+000,1.298019e+000,0.000000e+000,0,,0,
1578674416.774,,2.500000e+004,6.429431e+001,1.427397e-002,0.000000e+000,3,9.743770e-001,0.000000e+000,,,,,,,,,,,,,,32,1,4.000000e+000,1.357750e+000,0.000000e+000,0,,0,
1578674465.024,,2.500000e+004,5.914016e+001,1.556845e-002,0.000000e+000,3,9.743603e-001,0.000000e+000,,,,,,,,,,,,,,32,1,4.000000e+000,1.264023e+000,0.000000e+000,0,,0,
1578674511.774,,2.500000e+004,5.438257e+001,1.692379e-002,0.000000e+000,3,9.747532e-001,0.000000e+000,,,,,,,,,,,,,,32,1,4.000000e+000,1.198719e+000,0.000000e+000,0,,0,
1578674575.824,,2.500000e+004,4.811510e+001,1.894640e-002,0.000000e+000,3,9.750455e-001,0.000000e+000,,,,,,,,,,,,,,32,1,4.000000e+000,1.089447e+000,0.000000e+000,0,,0,
1578674613.504,,2.500000e+004,4.440600e+001,2.063579e-002,0.000000e+000,3,9.739133e-001,0.000000e+000,,,,,,,,,,,,,,32,1,4.000000e+000,1.166859e+000,0.000000e+000,0,,0,
1578674664.754,,2.500000e+004,3.926542e+001,2.321247e-002,0.000000e+000,3,9.737889e-001,0.000000e+000,,,,,,,,,,,,,,32,1,4.000000e+000,1.146751e+000,0.000000e+000,0,,0,
1578674711.994,,2.500000e+004,3.436581e+001,2.640763e-002,0.000000e+000,3,9.734606e-001,0.000000e+000,,,,,,,,,,,,,,32,1,4.000000e+000,1.227219e+000,0.000000e+000,0,,0,
1578674758.534,,2.500000e+004,2.920589e+001,3.081221e-002,0.000000e+000,3,9.726480e-001,0.000000e+000,,,,,,,,,,,,,,32,1,4.000000e+000,1.228170e+000,0.000000e+000,0,,0,
1578674801.434,,2.500000e+004,2.416145e+001,3.709846e-002,0.000000e+000,3,9.732160e-001,0.000000e+000,,,,,,,,,,,,,,32,1,4.000000e+000,1.617239e+000,0.000000e+000,0,,0,
1578674857.344,,2.500000e+004,1.968109e+001,4.480271e-002,0.000000e+000,3,9.716907e-001,0.000000e+000,,,,,,,,,,,,,,32,1,4.000000e+000,5.327206e-001,0.000000e+000,0,,0,
1578674946.404,,2.500000e+004,1.252708e+001,6.557235e-002,0.000000e+000,3,9.724605e-001,0.000000e+000,,,,,,,,,,,,,,32,1,4.000000e+000,1.908540e+000,0.000000e+000,0,,0,
1578676369.486,,2.500000e+004,9.998993e+000,8.003351e-002,0.000000e+000,3,9.708114e-001,0.000000e+000,,,,,,,,,,,,,,32,1,4.000000e+000,3.421402e-002,0.000000e+000,0,,0,
1578676957.507,,0.000000e+000,1.001193e+001,2.447862e-004,2.138667e-005,3,9.475989e-001,8.736878e+000,,,,,,,,,,,,,,32,5,4.000000e+000,1.056795e-001,0.000000e+000,0,,0,
1578677151.177,,0.000000e+000,1.498422e+001,2.158490e-004,1.587563e-005,3,9.241461e-001,7.354973e+000,,,,,,,,,,,,,,32,5,4.000000e+000,6.867981e-002,0.000000e+000,0,,0,
1578677367.888,,0.000000e+000,2.000065e+001,1.422221e-004,1.261206e-006,3,9.937483e-001,8.867866e-001,,,,,,,,,,,,,,32,5,4.000000e+000,8.790970e-003,0.000000e+000,0,,0,
1578677580.798,,0.000000e+000,2.500016e+001,1.059718e-004,3.717314e-005,3,9.272753e-001,3.507833e+001,,,,,,,,,,,,,,32,5,4.000000e+000,2.210045e-002,0.000000e+000,0,,0,
1578677798.038,,0.000000e+000,3.000117e+001,5.711887e-005,5.187276e-007,3,9.836284e-001,9.081546e-001,,,,,,,,,,,,,,32,5,4.000000e+000,3.389359e-003,0.000000e+000,0,,0,
1578678019.719,,0.000000e+000,3.500247e+001,2.849137e-005,2.833993e-005,3,7.822925e-001,9.946849e+001,,,,,,,,,,,,,,32,5,4.000000e+000,4.428864e-003,0.000000e+000,0,,0,
1578678258.419,,0.000000e+000,4.000361e+001,1.226389e-005,4.880948e-005,3,8.156666e-001,3.979934e+002,,,,,,,,,,,,,,32,5,4.000000e+000,5.619049e-003,0.000000e+000,0,,0,
1578678502.109,,0.000000e+000,4.500576e+001,2.995805e-005,2.189197e-007,3,9.706880e-001,7.307541e-001,,,,,,,,,,,,,,32,5,4.000000e+000,2.072144e-002,0.000000e+000,0,,0,
1578678727.220,,0.000000e+000,5.002491e+001,2.725023e-005,1.560455e-007,3,9.672731e-001,5.726393e-001,,,,,,,,,,,,,,32,5,4.000000e+000,4.444885e-002,0.000000e+000,0,,0,
1578678947.700,,0.000000e+000,5.503918e+001,8.280791e-006,3.846143e-005,3,7.924714e-001,4.644656e+002,,,,,,,,,,,,,,32,5,4.000000e+000,6.060028e-002,0.000000e+000,0,,0,
1578679173.070,,0.000000e+000,6.004936e+001,1.449354e-005,2.122732e-005,3,7.740787e-001,1.464605e+002,,,,,,,,,,,,,,32,5,4.000000e+000,6.772995e-002,0.000000e+000,0,,0,
1578679452.751,,0.000000e+000,6.501572e+001,2.272400e-005,6.075268e-008,3,9.684265e-001,2.673503e-001,,,,,,,,,,,,,,32,5,4.000000e+000,4.079437e-002,0.000000e+000,0,,0,
1578679685.791,,0.000000e+000,7.006487e+001,2.189519e-005,8.693510e-008,3,9.649164e-001,3.970512e-001,,,,,,,,,,,,,,32,5,4.000000e+000,8.514404e-002,0.000000e+000,0,,0,
1578679920.471,,0.000000e+000,7.507917e+001,2.090324e-005,4.388692e-008,3,9.641958e-001,2.099527e-001,,,,,,,,,,,,,,32,5,4.000000e+000,8.950043e-002,0.000000e+000,0,,0,
1578680156.242,,0.000000e+000,8.008554e+001,2.009562e-005,5.725993e-008,3,9.628617e-001,2.849374e-001,,,,,,,,,,,,,,32,5,4.000000e+000,9.779358e-002,0.000000e+000,0,,0,
1578680393.652,,0.000000e+000,8.509804e+001,1.910059e-005,1.056711e-007,3,9.613447e-001,5.532349e-001,,,,,,,,,,,,,,32,5,4.000000e+000,1.232376e-001,0.000000e+000,0,,0,
1578680630.052,,0.000000e+000,9.010832e+001,1.809155e-005,9.853882e-008,3,9.582002e-001,5.446675e-001,,,,,,,,,,,,,,32,5,4.000000e+000,1.237793e-001,0.000000e+000,0,,0,
1578680868.203,,0.000000e+000,9.511562e+001,1.700099e-005,4.626748e-008,3,9.594725e-001,2.721458e-001,,,,,,,,,,,,,,32,5,4.000000e+000,1.572800e-001,0.000000e+000,0,,0,
1578681106.823,,0.000000e+000,1.001246e+002,1.574576e-005,3.784936e-008,3,9.590153e-001,2.403781e-001,,,,,,,,,,,,,,32,5,4.000000e+000,1.492996e-001,0.000000e+000,0,,0,
1578681346.593,,0.000000e+000,1.051371e+002,1.428828e-005,8.507129e-008,3,9.560989e-001,5.953923e-001,,,,,,,,,,,,,,32,5,4.000000e+000,1.623001e-001,0.000000e+000,0,,0,
1578681588.574,,0.000000e+000,1.101390e+002,1.312611e-005,1.349394e-007,3,9.522942e-001,1.028022e+000,,,,,,,,,,,,,,32,5,4.000000e+000,1.532974e-001,0.000000e+000,0,,0,
1578681939.314,,0.000000e+000,1.150069e+002,1.156134e-005,3.576909e-008,3,9.555149e-001,3.093853e-001,,,,,,,,,,,,,,32,5,4.000000e+000,3.889465e-002,0.000000e+000,0,,0,
1578682179.674,,0.000000e+000,1.201497e+002,1.062411e-005,8.856080e-008,3,9.424002e-001,8.335830e-001,,,,,,,,,,,,,,32,5,4.000000e+000,2.058029e-001,0.000000e+000,0,,0,
1578682532.145,,0.000000e+000,1.250049e+002,9.696568e-006,4.460685e-008,3,9.364525e-001,4.600272e-001,,,,,,,,,,,,,,32,5,4.000000e+000,3.969574e-002,0.000000e+000,0,,0,
1578682771.765,,0.000000e+000,1.301794e+002,9.592443e-006,6.649920e-008,3,9.395498e-001,6.932457e-001,,,,,,,,,,,,,,32,5,4.000000e+000,2.505951e-001,0.000000e+000,0,,0,
1578683009.866,,0.000000e+000,1.351967e+002,9.360675e-006,9.377660e-008,3,9.391150e-001,1.001814e+000,,,,,,,,,,,,,,32,5,4.000000e+000,2.229004e-001,0.000000e+000,0,,0,
1578683334.406,,0.000000e+000,1.400195e+002,9.066864e-006,1.058973e-008,3,9.449531e-001,1.167960e-001,,,,,,,,,,,,,,32,5,4.000000e+000,1.049042e-001,0.000000e+000,0,,0,
1578683571.416,,0.000000e+000,1.452216e+002,9.004681e-006,1.181041e-007,3,9.444548e-001,1.311586e+000,,,,,,,,,,,,,,32,5,4.000000e+000,2.390900e-001,0.000000e+000,0,,0,
1578683808.227,,0.000000e+000,1.502065e+002,8.879906e-006,1.121355e-007,3,9.392731e-001,1.262800e+000,,,,,,,,,,,,,,32,5,4.000000e+000,2.854919e-001,0.000000e+000,0,,0,
1578684043.647,,0.000000e+000,1.552227e+002,8.729667e-006,7.162132e-008,3,9.404429e-001,8.204359e-001,,,,,,,,,,,,,,32,5,4.000000e+000,3.025970e-001,0.000000e+000,0,,0,
1578684277.387,,0.000000e+000,1.602333e+002,8.625649e-006,1.019505e-007,3,9.426058e-001,1.181946e+000,,,,,,,,,,,,,,32,5,4.000000e+000,3.158112e-001,0.000000e+000,0,,0,
1578684510.938,,0.000000e+000,1.652451e+002,8.510454e-006,9.011634e-008,3,9.363332e-001,1.058890e+000,,,,,,,,,,,,,,32,5,4.000000e+000,3.247070e-001,0.000000e+000,0,,0,
1578684748.008,,0.000000e+000,1.702444e+002,8.428753e-006,4.825311e-008,3,9.398466e-001,5.724822e-001,,,,,,,,,,,,,,32,5,4.000000e+000,3.329926e-001,0.000000e+000,0,,0,
1578684984.508,,0.000000e+000,1.752459e+002,8.361136e-006,9.755985e-008,3,9.368300e-001,1.166825e+000,,,,,,,,,,,,,,32,5,4.000000e+000,3.409119e-001,0.000000e+000,0,,0,
1578685220.739,,0.000000e+000,1.802518e+002,8.249202e-006,7.253686e-008,3,9.403607e-001,8.793196e-001,,,,,,,,,,,,,,32,5,4.000000e+000,3.370972e-001,0.000000e+000,0,,0,
1578685456.809,,0.000000e+000,1.852572e+002,8.229538e-006,8.505342e-008,3,9.375501e-001,1.033514e+000,,,,,,,,,,,,,,32,5,4.000000e+000,3.545990e-001,0.000000e+000,0,,0,
1578685757.289,,0.000000e+000,1.900326e+002,8.077573e-006,7.288255e-008,3,9.392200e-001,9.022828e-001,,,,,,,,,,,,,,32,5,4.000000e+000,9.748840e-002,0.000000e+000,0,,0,
1578686098.590,,0.000000e+000,1.950003e+002,8.097770e-006,3.661547e-008,3,9.447061e-001,4.521673e-001,,,,,,,,,,,,,,32,5,4.000000e+000,1.919556e-002,0.000000e+000,0,,0,
1578686339.790,,0.000000e+000,2.002563e+002,8.031629e-006,4.650531e-008,3,9.337257e-001,5.790271e-001,,,,,,,,,,,,,,32,5,4.000000e+000,3.430023e-001,0.000000e+000,0,,0,
1578686640.671,,0.000000e+000,2.050328e+002,7.961357e-006,4.544146e-008,3,9.376127e-001,5.707753e-001,,,,,,,,,,,,,,32,5,4.000000e+000,9.840393e-002,0.000000e+000,0,,0,
1578686881.361,,0.000000e+000,2.102593e+002,7.892086e-006,8.411531e-008,3,9.376063e-001,1.065819e+000,,,,,,,,,,,,,,32,5,4.000000e+000,3.394012e-001,0.000000e+000,0,,0,
1578687120.901,,0.000000e+000,2.152605e+002,7.827785e-006,3.212358e-008,3,9.369979e-001,4.103789e-001,,,,,,,,,,,,,,32,5,4.000000e+000,3.627930e-001,0.000000e+000,0,,0,
1578687360.672,,0.000000e+000,2.202609e+002,7.781726e-006,8.893775e-008,3,9.383518e-001,1.142905e+000,,,,,,,,,,,,,,32,5,4.000000e+000,3.549957e-001,0.000000e+000,0,,0,
1578687601.342,,0.000000e+000,2.252565e+002,7.731695e-006,9.113523e-008,3,9.359838e-001,1.178723e+000,,,,,,,,,,,,,,32,5,4.000000e+000,3.621979e-001,0.000000e+000,0,,0,
1578687840.562,,0.000000e+000,2.302722e+002,1.191560e-005,9.550939e-006,2,7.473487e-001,8.015492e+001,,,,,,,,,,,,,,32,5,4.000000e+000,3.777924e-001,0.000000e+000,0,,0,
1578688219.253,,0.000000e+000,2.349936e+002,-9.198906e-006,3.767429e-005,3,8.153241e-001,4.095518e+002,,,,,,,,,,,,,,32,5,4.000000e+000,1.829529e-002,0.000000e+000,0,,0,
1578688462.383,,0.000000e+000,2.402549e+002,1.475573e-005,1.614881e-005,3,7.502406e-001,1.094409e+002,,,,,,,,,,,,,,32,5,4.000000e+000,3.625946e-001,0.000000e+000,0,,0,
1578688781.164,,0.000000e+000,2.450079e+002,7.533486e-006,4.943617e-008,3,9.405055e-001,6.562191e-001,,,,,,,,,,,,,,32,5,4.000000e+000,6.930542e-002,0.000000e+000,0,,0,
1578689023.014,,0.000000e+000,2.502640e+002,7.473426e-006,4.841317e-008,3,9.387743e-001,6.478043e-001,,,,,,,,,,,,,,32,5,4.000000e+000,3.717957e-001,0.000000e+000,0,,0,
1578689264.134,,0.000000e+000,2.552624e+002,7.439509e-006,1.719234e-008,3,9.404146e-001,2.310951e-001,,,,,,,,,,,,,,32,5,4.000000e+000,3.649902e-001,0.000000e+000,0,,0,
1578689507.285,,0.000000e+000,2.602704e+002,7.277082e-006,4.882843e-008,3,9.352288e-001,6.709892e-001,,,,,,,,,,,,,,32,5,4.000000e+000,4.012756e-001,0.000000e+000,0,,0,
1578689750.895,,0.000000e+000,2.652697e+002,7.230874e-006,1.074753e-007,3,9.355434e-001,1.486338e+000,,,,,,,,,,,,,,32,5,4.000000e+000,3.708801e-001,0.000000e+000,0,,0,
1578689993.925,,0.000000e+000,2.702587e+002,7.262720e-006,4.272662e-008,3,9.369814e-001,5.883006e-001,,,,,,,,,,,,,,32,5,4.000000e+000,3.613892e-001,0.000000e+000,0,,0,
1578690235.526,,0.000000e+000,2.752672e+002,7.258774e-006,4.530367e-008,3,9.387223e-001,6.241229e-001,,,,,,,,,,,,,,32,5,4.000000e+000,3.754883e-001,0.000000e+000,0,,0,
1578690502.406,,0.000000e+000,2.801415e+002,7.102415e-006,4.368351e-008,3,9.384507e-001,6.150516e-001,,,,,,,,,,,,,,32,5,4.000000e+000,2.726135e-001,0.000000e+000,0,,0,
1578690746.846,,0.000000e+000,2.852595e+002,7.114711e-006,5.812015e-008,3,9.390919e-001,8.169011e-001,,,,,,,,,,,,,,32,5,4.000000e+000,3.775024e-001,0.000000e+000,0,,0,
1578691016.807,,0.000000e+000,2.901265e+002,2.590002e-005,3.178775e-005,3,5.842131e-001,1.227325e+002,,,,,,,,,,,,,,32,5,4.000000e+000,2.513123e-001,0.000000e+000,0,,0,
1578691262.317,,0.000000e+000,2.952512e+002,1.312662e-005,1.373754e-005,3,7.534652e-001,1.046540e+002,,,,,,,,,,,,,,32,5,4.000000e+000,3.619080e-001,0.000000e+000,0,,0,
1578691506.957,,0.000000e+000,3.002585e+002,2.330994e-005,3.655965e-005,3,8.339311e-001,1.568414e+002,,,,,,,,,,,,,,32,5,4.000000e+000,3.895874e-001,0.000000e+000,0,,0,
1578696789.445,,0.000000e+000,1.000329e+001,2.430238e-004,4.122393e-008,3,9.963208e-001,1.696292e-002,,,,,,,,,,,,,,32,5,4.000000e+000,1.718044e-002,0.000000e+000,0,,0,
1578696985.465,,0.000000e+000,1.499318e+001,1.970538e-004,1.875429e-006,3,9.960576e-001,9.517344e-001,,,,,,,,,,,,,,32,5,4.000000e+000,3.720951e-002,0.000000e+000,0,,0,
1578697198.515,,0.000000e+000,2.000120e+001,1.210975e-004,1.071029e-006,3,9.944347e-001,8.844358e-001,,,,,,,,,,,,,,32,5,4.000000e+000,1.209068e-002,0.000000e+000,0,,0,
1578697409.526,,0.000000e+000,2.499395e+001,7.638302e-005,6.193031e-007,3,9.900018e-001,8.107862e-001,,,,,,,,,,,,,,32,5,4.000000e+000,5.399132e-002,0.000000e+000,0,,0,
1578697613.446,,0.000000e+000,3.000207e+001,7.007843e-005,4.219316e-005,3,8.122531e-001,6.020848e+001,,,,,,,,,,,,,,32,5,4.000000e+000,4.510880e-003,0.000000e+000,0,,0,
1578697898.556,,0.000000e+000,3.500085e+001,3.750566e-005,1.370196e-007,3,9.806938e-001,3.653304e-001,,,,,,,,,,,,,,32,5,4.000000e+000,8.869171e-003,0.000000e+000,0,,0,
1578698174.837,,0.000000e+000,4.000175e+001,3.115213e-005,7.802031e-008,3,9.767572e-001,2.504494e-001,,,,,,,,,,,,,,32,5,4.000000e+000,1.121902e-002,0.000000e+000,0,,0,
1578698519.297,,0.000000e+000,4.499978e+001,2.654571e-005,7.893770e-008,3,9.720491e-001,2.973652e-001,,,,,,,,,,,,,,32,5,4.000000e+000,4.600525e-003,0.000000e+000,0,,0,
1578698746.028,,0.000000e+000,5.002158e+001,2.367494e-005,9.129646e-008,3,9.684893e-001,3.856248e-001,,,,,,,,,,,,,,32,5,4.000000e+000,4.722977e-002,0.000000e+000,0,,0,
1578698965.258,,0.000000e+000,5.504076e+001,2.167823e-005,4.127396e-008,3,9.714254e-001,1.903936e-001,,,,,,,,,,,,,,32,5,4.000000e+000,6.455994e-002,0.000000e+000,0,,0,
1578699190.358,,0.000000e+000,6.005290e+001,2.048466e-005,1.519074e-007,3,9.668404e-001,7.415666e-001,,,,,,,,,,,,,,32,5,4.000000e+000,7.234955e-002,0.000000e+000,0,,0,
1578699418.979,,0.000000e+000,6.506099e+001,1.947417e-005,3.132535e-008,3,9.647970e-001,1.608559e-001,,,,,,,,,,,,,,32,5,4.000000e+000,7.458496e-002,0.000000e+000,0,,0,
1578699651.469,,0.000000e+000,7.006647e+001,1.854563e-005,5.567479e-008,3,9.672564e-001,3.002043e-001,,,,,,,,,,,,,,32,5,4.000000e+000,7.704926e-002,0.000000e+000,0,,0,
1578699885.909,,0.000000e+000,7.507734e+001,1.784825e-005,6.094060e-008,3,9.624804e-001,3.414374e-001,,,,,,,,,,,,,,32,5,4.000000e+000,1.032181e-001,0.000000e+000,0,,0,
1578700122.030,,0.000000e+000,8.008656e+001,1.708871e-005,7.258292e-008,3,9.636218e-001,4.247420e-001,,,,,,,,,,,,,,32,5,4.000000e+000,1.029663e-001,0.000000e+000,0,,0,
1578700357.800,,0.000000e+000,8.510004e+001,1.633203e-005,3.497659e-008,3,9.615370e-001,2.141595e-001,,,,,,,,,,,,,,32,5,4.000000e+000,1.089096e-001,0.000000e+000,0,,0,
1578700597.110,,0.000000e+000,9.010832e+001,1.552971e-005,4.897531e-008,3,9.597107e-001,3.153653e-001,,,,,,,,,,,,,,32,5,4.000000e+000,1.332703e-001,0.000000e+000,0,,0,
1578700835.251,,0.000000e+000,9.512435e+001,1.480323e-005,3.896365e-008,3,9.589564e-001,2.632105e-001,,,,,,,,,,,,,,32,5,4.000000e+000,1.468048e-001,0.000000e+000,0,,0,
1578701074.181,,0.000000e+000,1.001269e+002,1.384210e-005,2.812969e-008,3,9.591589e-001,2.032184e-001,,,,,,,,,,,,,,32,5,4.000000e+000,1.570053e-001,0.000000e+000,0,,0,
1578701313.691,,0.000000e+000,1.051375e+002,1.293572e-005,5.144386e-008,3,9.516506e-001,3.976885e-001,,,,,,,,,,,,,,32,5,4.000000e+000,1.664963e-001,0.000000e+000,0,,0,
1578701552.662,,0.000000e+000,1.101377e+002,1.202308e-005,4.249268e-008,3,9.558021e-001,3.534260e-001,,,,,,,,,,,,,,32,5,4.000000e+000,1.488037e-001,0.000000e+000,0,,0,
1578701853.092,,0.000000e+000,1.150371e+002,1.108228e-005,3.165320e-008,3,9.532521e-001,2.856199e-001,,,,,,,,,,,,,,32,5,4.000000e+000,7.310486e-002,0.000000e+000,0,,0,
1578702093.432,,0.000000e+000,1.201587e+002,1.022358e-005,2.980532e-008,3,9.438111e-001,2.915352e-001,,,,,,,,,,,,,,32,5,4.000000e+000,2.163010e-001,0.000000e+000,0,,0,
1578702331.353,,0.000000e+000,1.251731e+002,9.605379e-006,2.642359e-008,3,9.408848e-001,2.750916e-001,,,,,,,,,,,,,,32,5,4.000000e+000,2.444992e-001,0.000000e+000,0,,0,
1578702568.123,,0.000000e+000,1.301758e+002,9.326945e-006,4.281812e-008,3,9.448094e-001,4.590798e-001,,,,,,,,,,,,,,32,5,4.000000e+000,2.628937e-001,0.000000e+000,0,,0,
1578702805.643,,0.000000e+000,1.351804e+002,9.152978e-006,5.420699e-008,3,9.403083e-001,5.922334e-001,,,,,,,,,,,,,,32,5,4.000000e+000,2.424927e-001,0.000000e+000,0,,0,
1578703042.734,,0.000000e+000,1.401924e+002,-1.041819e-005,4.336082e-005,3,8.259335e-001,4.162029e+002,,,,,,,,,,,,,,32,5,4.000000e+000,2.313995e-001,0.000000e+000,0,,0,
1578703279.074,,0.000000e+000,1.451918e+002,8.784044e-006,4.512911e-008,3,9.416879e-001,5.137624e-001,,,,,,,,,,,,,,32,5,4.000000e+000,3.135986e-001,0.000000e+000,0,,0,
1578703516.264,,0.000000e+000,1.502065e+002,8.737896e-006,5.778350e-008,3,9.439992e-001,6.612976e-001,,,,,,,,,,,,,,32,5,4.000000e+000,2.537994e-001,0.000000e+000,0,,0,
1578703751.925,,0.000000e+000,1.552281e+002,8.646089e-006,4.037956e-008,3,9.435394e-001,4.670269e-001,,,,,,,,,,,,,,32,5,4.000000e+000,3.067932e-001,0.000000e+000,0,,0,
1578703985.455,,0.000000e+000,1.602453e+002,8.549799e-006,3.631589e-008,3,9.450411e-001,4.247572e-001,,,,,,,,,,,,,,32,5,4.000000e+000,3.157959e-001,0.000000e+000,0,,0,
1578704221.685,,0.000000e+000,1.652432e+002,8.453519e-006,6.304728e-008,3,9.390217e-001,7.458111e-001,,,,,,,,,,,,,,32,5,4.000000e+000,3.294067e-001,0.000000e+000,0,,0,
1578704458.586,,0.000000e+000,1.702374e+002,8.399486e-006,3.539639e-008,3,9.418381e-001,4.214115e-001,,,,,,,,,,,,,,32,5,4.000000e+000,3.181000e-001,0.000000e+000,0,,0,
1578704693.346,,0.000000e+000,1.752501e+002,8.351091e-006,6.125013e-008,3,9.410551e-001,7.334386e-001,,,,,,,,,,,,,,32,5,4.000000e+000,3.355865e-001,0.000000e+000,0,,0,
1578704931.226,,0.000000e+000,1.802441e+002,8.275679e-006,7.494181e-008,3,9.394987e-001,9.055669e-001,,,,,,,,,,,,,,32,5,4.000000e+000,3.258972e-001,0.000000e+000,0,,0,
1578705169.227,,0.000000e+000,1.852496e+002,8.216528e-006,5.089068e-008,3,9.381530e-001,6.193696e-001,,,,,,,,,,,,,,32,5,4.000000e+000,3.372040e-001,0.000000e+000,0,,0,
1578705406.237,,0.000000e+000,1.902560e+002,8.164009e-006,3.586807e-008,3,9.390436e-001,4.393438e-001,,,,,,,,,,,,,,32,5,4.000000e+000,3.361053e-001,0.000000e+000,0,,0,
1578705643.907,,0.000000e+000,1.952553e+002,8.089492e-006,3.409631e-008,3,9.414521e-001,4.214889e-001,,,,,,,,,,,,,,32,5,4.000000e+000,3.464966e-001,0.000000e+000,0,,0,
1578705882.538,,0.000000e+000,2.002604e+002,8.056132e-006,4.504347e-008,3,9.387089e-001,5.591203e-001,,,,,,,,,,,,,,32,5,4.000000e+000,3.497925e-001,0.000000e+000,0,,0,
1578706122.078,,0.000000e+000,2.052566e+002,2.645248e-005,4.122664e-005,3,8.489763e-001,1.558517e+002,,,,,,,,,,,,,,32,5,4.000000e+000,3.451996e-001,0.000000e+000,0,,0,
1578706362.078,,0.000000e+000,2.102608e+002,7.967593e-006,4.437142e-008,3,9.364039e-001,5.568987e-001,,,,,,,,,,,,,,32,5,4.000000e+000,3.540955e-001,0.000000e+000,0,,0,
1578706601.749,,0.000000e+000,2.152551e+002,7.926231e-006,3.226183e-008,3,9.368770e-001,4.070261e-001,,,,,,,,,,,,,,32,5,4.000000e+000,3.704987e-001,0.000000e+000,0,,0,
1578706842.069,,0.000000e+000,2.202585e+002,7.913249e-006,3.311744e-008,3,9.415591e-001,4.185062e-001,,,,,,,,,,,,,,32,5,4.000000e+000,3.549957e-001,0.000000e+000,0,,0,
1578707081.489,,0.000000e+000,2.252633e+002,7.891749e-006,4.825814e-008,3,9.454080e-001,6.115012e-001,,,,,,,,,,,,,,32,5,4.000000e+000,3.453064e-001,0.000000e+000,0,,0,
1578707322.260,,0.000000e+000,2.302626e+002,7.828440e-006,4.294976e-008,3,9.439796e-001,5.486375e-001,,,,,,,,,,,,,,32,5,4.000000e+000,3.602142e-001,0.000000e+000,0,,0,
1578707588.560,,0.000000e+000,2.351325e+002,7.819342e-006,4.277203e-008,3,9.452493e-001,5.470029e-001,,,,,,,,,,,,,,32,5,4.000000e+000,2.469940e-001,0.000000e+000,0,,0,
1578707830.630,,0.000000e+000,2.402673e+002,7.712375e-006,5.717923e-008,3,9.424966e-001,7.413958e-001,,,,,,,,,,,,,,32,5,4.000000e+000,3.529968e-001,0.000000e+000,0,,0,
1578708070.701,,0.000000e+000,2.452648e+002,7.621331e-006,5.183854e-008,3,9.397403e-001,6.801769e-001,,,,,,,,,,,,,,32,5,4.000000e+000,3.675079e-001,0.000000e+000,0,,0,
1578708313.091,,0.000000e+000,2.502619e+002,7.603891e-006,4.226630e-008,3,9.411200e-001,5.558510e-001,,,,,,,,,,,,,,32,5,4.000000e+000,3.511963e-001,0.000000e+000,0,,0,
1578708556.491,,0.000000e+000,2.552635e+002,7.566555e-006,3.240051e-008,3,9.409007e-001,4.282069e-001,,,,,,,,,,,,,,32,5,4.000000e+000,3.648987e-001,0.000000e+000,0,,0,
1578708873.082,,0.000000e+000,2.600164e+002,7.426825e-006,6.214027e-008,3,9.403864e-001,8.367004e-001,,,,,,,,,,,,,,32,5,4.000000e+000,5.560303e-002,0.000000e+000,0,,0,
1578709117.842,,0.000000e+000,2.652698e+002,7.409426e-006,2.250051e-008,3,9.392719e-001,3.036741e-001,,,,,,,,,,,,,,32,5,4.000000e+000,3.823853e-001,0.000000e+000,0,,0,
1578709360.902,,0.000000e+000,2.702623e+002,7.369916e-006,5.595790e-008,3,9.378785e-001,7.592747e-001,,,,,,,,,,,,,,32,5,4.000000e+000,3.733826e-001,0.000000e+000,0,,0,
1578709605.123,,0.000000e+000,2.752622e+002,7.407061e-006,4.608719e-008,3,9.422370e-001,6.222062e-001,,,,,,,,,,,,,,32,5,4.000000e+000,3.880005e-001,0.000000e+000,0,,0,
1578709847.273,,0.000000e+000,2.802649e+002,7.331018e-006,4.985686e-008,3,9.403034e-001,6.800810e-001,,,,,,,,,,,,,,32,5,4.000000e+000,3.508911e-001,0.000000e+000,0,,0,
1578710089.603,,0.000000e+000,2.852622e+002,7.332006e-006,5.876083e-008,3,9.419645e-001,8.014291e-001,,,,,,,,,,,,,,32,5,4.000000e+000,3.910217e-001,0.000000e+000,0,,0,
1578710332.724,,0.000000e+000,2.902592e+002,7.309131e-006,4.869965e-008,3,9.444540e-001,6.662850e-001,,,,,,,,,,,,,,32,5,4.000000e+000,3.773193e-001,0.000000e+000,0,,0,
1578710577.664,,0.000000e+000,2.952643e+002,7.148932e-006,4.562389e-008,3,9.357094e-001,6.381918e-001,,,,,,,,,,,,,,32,5,4.000000e+000,3.908997e-001,0.000000e+000,0,,0,
1578710823.105,,0.000000e+000,3.002495e+002,7.160177e-006,6.262071e-008,3,9.382014e-001,8.745693e-001,,,,,,,,,,,,,,32,5,4.000000e+000,3.744812e-001,0.000000e+000,0,,0,
1578711402.725,,0.000000e+000,2.999966e+002,1.835896e-005,9.687181e-008,3,9.675878e-001,5.276541e-001,,,,,,,,,,,,,,32,5,4.000000e+000,2.990723e-002,0.000000e+000,0,,0,
1578711889.646,,0.000000e+000,2.947339e+002,1.821819e-005,7.365758e-008,3,9.689258e-001,4.043078e-001,,,,,,,,,,,,,,32,5,4.000000e+000,2.019958e-001,0.000000e+000,0,,0,
1578712276.077,,0.000000e+000,2.896888e+002,1.808577e-005,4.168430e-008,3,9.715489e-001,2.304812e-001,,,,,,,,,,,,,,32,5,4.000000e+000,2.783813e-001,0.000000e+000,0,,0,
1578712647.137,,0.000000e+000,2.846932e+002,1.801520e-005,5.460642e-008,3,9.716725e-001,3.031130e-001,,,,,,,,,,,,,,32,5,4.000000e+000,1.611023e-001,0.000000e+000,0,,0,
1578713032.808,,0.000000e+000,2.797047e+002,1.790708e-005,5.968819e-008,3,9.699143e-001,3.333218e-001,,,,,,,,,,,,,,32,5,4.000000e+000,1.811829e-001,0.000000e+000,0,,0,
1578713429.488,,0.000000e+000,2.747151e+002,1.784775e-005,2.325446e-008,3,9.687411e-001,1.302935e-001,,,,,,,,,,,,,,32,5,4.000000e+000,1.744995e-001,0.000000e+000,0,,0,
1578713831.319,,0.000000e+000,2.697225e+002,1.778055e-005,5.093532e-008,3,9.683595e-001,2.864665e-001,,,,,,,,,,,,,,32,5,4.000000e+000,1.679993e-001,0.000000e+000,0,,0,
1578714244.679,,0.000000e+000,2.647379e+002,1.767099e-005,6.593947e-008,3,9.689859e-001,3.731510e-001,,,,,,,,,,,,,,32,5,4.000000e+000,1.730957e-001,0.000000e+000,0,,0,
1578714681.280,,0.000000e+000,2.597631e+002,1.744241e-005,3.609358e-008,3,9.704199e-001,2.069300e-001,,,,,,,,,,,,,,32,5,4.000000e+000,2.333069e-001,0.000000e+000,0,,0,
1578715110.091,,0.000000e+000,2.547504e+002,1.736715e-005,6.285837e-008,3,9.640686e-001,3.619383e-001,,,,,,,,,,,,,,32,5,4.000000e+000,1.923981e-001,0.000000e+000,0,,0,
1578715539.171,,0.000000e+000,2.497507e+002,1.726434e-005,5.954418e-008,3,9.718248e-001,3.448969e-001,,,,,,,,,,,,,,32,5,4.000000e+000,1.748047e-001,0.000000e+000,0,,0,
1578715971.622,,0.000000e+000,2.447634e+002,1.723446e-005,3.433284e-008,3,9.722802e-001,1.992104e-001,,,,,,,,,,,,,,32,5,4.000000e+000,1.681061e-001,0.000000e+000,0,,0,
1578716441.732,,0.000000e+000,2.398730e+002,1.711407e-005,1.974757e-008,3,9.732926e-001,1.153879e-001,,,,,,,,,,,,,,32,5,4.000000e+000,2.187042e-001,0.000000e+000,0,,0,
1578716909.173,,0.000000e+000,2.348429e+002,1.704937e-005,3.414259e-008,3,9.710150e-001,2.002571e-001,,,,,,,,,,,,,,32,5,4.000000e+000,2.463989e-001,0.000000e+000,0,,0,
1578717351.074,,0.000000e+000,2.297717e+002,1.706610e-005,5.625388e-008,3,9.697990e-001,3.296236e-001,,,,,,,,,,,,,,32,5,4.000000e+000,1.925049e-001,0.000000e+000,0,,0,
1578717790.674,,0.000000e+000,2.247750e+002,1.684865e-005,3.058499e-008,3,9.695957e-001,1.815278e-001,,,,,,,,,,,,,,32,5,4.000000e+000,1.676941e-001,0.000000e+000,0,,0,
1578718305.235,,0.000000e+000,2.199773e+002,1.673773e-005,4.096457e-008,3,9.670295e-001,2.447440e-001,,,,,,,,,,,,,,32,5,4.000000e+000,9.660339e-002,0.000000e+000,0,,0,
1578718755.606,,0.000000e+000,2.147853e+002,1.667576e-005,1.796237e-008,3,9.653188e-001,1.077154e-001,,,,,,,,,,,,,,32,5,4.000000e+000,1.997986e-001,0.000000e+000,0,,0,
1578719201.666,,0.000000e+000,2.097889e+002,1.651356e-005,2.055186e-008,3,9.691407e-001,1.244544e-001,,,,,,,,,,,,,,32,5,4.000000e+000,1.763000e-001,0.000000e+000,0,,0,
1578719650.587,,0.000000e+000,2.047933e+002,1.637441e-005,5.347646e-008,3,9.683087e-001,3.265855e-001,,,,,,,,,,,,,,32,5,4.000000e+000,1.613922e-001,0.000000e+000,0,,0,
1578720100.827,,0.000000e+000,1.998006e+002,1.629071e-005,4.714683e-008,3,9.627387e-001,2.894094e-001,,,,,,,,,,,,,,32,5,4.000000e+000,1.540985e-001,0.000000e+000,0,,0,
1578720556.658,,0.000000e+000,1.948073e+002,1.610395e-005,4.251478e-008,3,9.669006e-001,2.640023e-001,,,,,,,,,,,,,,32,5,4.000000e+000,1.660919e-001,0.000000e+000,0,,0,
1578721013.309,,0.000000e+000,1.898127e+002,1.594931e-005,2.930310e-008,3,9.624346e-001,1.837264e-001,,,,,,,,,,,,,,32,5,4.000000e+000,1.641998e-001,0.000000e+000,0,,0,
1578721578.670,,0.000000e+000,1.850128e+002,1.574356e-005,7.795194e-008,3,9.628543e-001,4.951354e-001,,,,,,,,,,,,,,32,5,4.000000e+000,2.899170e-002,0.000000e+000,0,,0,
1578722042.630,,0.000000e+000,1.798225e+002,1.552396e-005,3.643418e-008,3,9.648085e-001,2.346964e-001,,,,,,,,,,,,,,32,5,4.000000e+000,1.759949e-001,0.000000e+000,0,,0,
1578722532.211,,0.000000e+000,1.748968e+002,1.550183e-005,4.942617e-008,3,9.641973e-001,3.188409e-001,,,,,,,,,,,,,,32,5,4.000000e+000,1.776123e-001,0.000000e+000,0,,0,
1578722997.772,,0.000000e+000,1.698317e+002,1.506907e-005,3.355965e-008,3,9.651879e-001,2.227055e-001,,,,,,,,,,,,,,32,5,4.000000e+000,1.584015e-001,0.000000e+000,0,,0,
1578723464.942,,0.000000e+000,1.648395e+002,1.498586e-005,3.035401e-008,3,9.619644e-001,2.025511e-001,,,,,,,,,,,,,,32,5,4.000000e+000,1.638947e-001,0.000000e+000,0,,0,
1578723931.493,,0.000000e+000,1.598446e+002,1.467844e-005,5.810028e-008,3,9.615986e-001,3.958205e-001,,,,,,,,,,,,,,32,5,4.000000e+000,1.549988e-001,0.000000e+000,0,,0,
1578724398.694,,0.000000e+000,1.548507e+002,1.423377e-005,2.428816e-008,3,9.630872e-001,1.706376e-001,,,,,,,,,,,,,,32,5,4.000000e+000,1.632080e-001,0.000000e+000,0,,0,
1578724864.224,,0.000000e+000,1.498534e+002,1.385921e-005,2.791120e-008,3,9.621204e-001,2.013909e-001,,,,,,,,,,,,,,32,5,4.000000e+000,1.501007e-001,0.000000e+000,0,,0,
1578725372.275,,0.000000e+000,1.449565e+002,1.350604e-005,2.723942e-008,3,9.592882e-001,2.016832e-001,,,,,,,,,,,,,,32,5,4.000000e+000,1.266022e-001,0.000000e+000,0,,0,
1578725841.296,,0.000000e+000,1.398675e+002,1.313724e-005,5.092614e-008,3,9.537283e-001,3.876473e-001,,,,,,,,,,,,,,32,5,4.000000e+000,1.535034e-001,0.000000e+000,0,,0,
1578726411.276,,0.000000e+000,1.350146e+002,1.283399e-005,1.583178e-008,3,9.611801e-001,1.233583e-001,,,,,,,,,,,,,,32,5,4.000000e+000,2.610779e-002,0.000000e+000,0,,0,
1578726880.127,,0.000000e+000,1.298782e+002,1.209505e-005,7.239417e-008,3,9.537818e-001,5.985436e-001,,,,,,,,,,,,,,32,5,4.000000e+000,1.551971e-001,0.000000e+000,0,,0,
1578727348.848,,0.000000e+000,1.248845e+002,1.155913e-005,2.391089e-008,3,9.531299e-001,2.068572e-001,,,,,,,,,,,,,,32,5,4.000000e+000,1.472015e-001,0.000000e+000,0,,0,
1578727817.548,,0.000000e+000,1.198907e+002,1.079693e-005,3.281626e-008,3,9.539438e-001,3.039405e-001,,,,,,,,,,,,,,32,5,4.000000e+000,1.471024e-001,0.000000e+000,0,,0,
1578728283.489,,0.000000e+000,1.148979e+002,9.772239e-006,5.795181e-008,3,9.526045e-001,5.930249e-001,,,,,,,,,,,,,,32,5,4.000000e+000,1.409988e-001,0.000000e+000,0,,0,
1578728815.310,,0.000000e+000,1.100102e+002,9.064653e-006,4.991314e-008,3,9.522802e-001,5.506349e-001,,,,,,,,,,,,,,32,5,4.000000e+000,4.039764e-002,0.000000e+000,0,,0,
1578729276.660,,0.000000e+000,1.049181e+002,8.400528e-006,4.025684e-008,3,9.469237e-001,4.792180e-001,,,,,,,,,,,,,,32,5,4.000000e+000,1.327057e-001,0.000000e+000,0,,0,
1578729731.661,,0.000000e+000,9.992290e+001,7.921237e-006,7.181234e-008,3,9.509775e-001,9.065800e-001,,,,,,,,,,,,,,32,5,4.000000e+000,1.316071e-001,0.000000e+000,0,,0,
1578730184.002,,0.000000e+000,9.494189e+001,7.581885e-006,4.194204e-008,3,9.409243e-001,5.531875e-001,,,,,,,,,,,,,,32,5,4.000000e+000,1.427917e-001,0.000000e+000,0,,0,
1578730629.102,,0.000000e+000,8.994962e+001,7.605887e-006,2.765031e-008,3,9.409982e-001,3.635383e-001,,,,,,,,,,,,,,32,5,4.000000e+000,1.296539e-001,0.000000e+000,0,,0,
1578731065.473,,0.000000e+000,8.495838e+001,7.453123e-006,2.294246e-008,3,9.393247e-001,3.078234e-001,,,,,,,,,,,,,,32,5,4.000000e+000,1.257324e-001,0.000000e+000,0,,0,
1578731491.003,,0.000000e+000,7.997346e+001,7.231978e-006,3.226358e-008,3,9.295212e-001,4.461239e-001,,,,,,,,,,,,,,32,5,4.000000e+000,1.026840e-001,0.000000e+000,0,,0,
1578731901.644,,0.000000e+000,7.498180e+001,7.348266e-006,2.647377e-008,3,9.428779e-001,3.602724e-001,,,,,,,,,,,,,,32,5,4.000000e+000,1.075363e-001,0.000000e+000,0,,0,
1578732300.075,,0.000000e+000,6.999620e+001,7.301809e-006,1.340576e-008,3,9.399570e-001,1.835950e-001,,,,,,,,,,,,,,32,5,4.000000e+000,8.699036e-002,0.000000e+000,0,,0,
1578732688.715,,0.000000e+000,6.501024e+001,7.082376e-006,4.455981e-008,3,9.372622e-001,6.291647e-001,,,,,,,,,,,,,,32,5,4.000000e+000,7.093048e-002,0.000000e+000,0,,0,
1578733058.176,,0.000000e+000,6.001674e+001,7.023820e-006,5.542775e-008,3,9.274947e-001,7.891396e-001,,,,,,,,,,,,,,32,5,4.000000e+000,5.534744e-002,0.000000e+000,0,,0,
1578733417.266,,0.000000e+000,5.501548e+001,7.314111e-006,4.732566e-008,3,9.343184e-001,6.470460e-001,,,,,,,,,,,,,,32,5,4.000000e+000,4.343033e-002,0.000000e+000,0,,0,
1578733764.327,,0.000000e+000,5.002224e+001,7.167017e-006,4.693598e-008,3,9.299666e-001,6.548886e-001,,,,,,,,,,,,,,32,5,4.000000e+000,2.000046e-002,0.000000e+000,0,,0,
1578734077.587,,0.000000e+000,4.501520e+001,7.347016e-006,2.945207e-008,3,9.429824e-001,4.008713e-001,,,,,,,,,,,,,,32,5,4.000000e+000,1.382065e-002,0.000000e+000,0,,0,
1578734379.267,,0.000000e+000,4.000941e+001,7.337674e-006,5.603887e-008,3,9.391143e-001,7.637144e-001,,,,,,,,,,,,,,32,5,4.000000e+000,9.338379e-003,0.000000e+000,0,,0,
1578734664.648,,0.000000e+000,3.500602e+001,7.167224e-006,1.513141e-008,3,9.395863e-001,2.111195e-001,,,,,,,,,,,,,,32,5,4.000000e+000,1.033783e-002,0.000000e+000,0,,0,
1578734929.308,,0.000000e+000,2.999958e+001,7.373362e-006,5.108648e-008,3,9.375228e-001,6.928520e-001,,,,,,,,,,,,,,32,5,4.000000e+000,5.640030e-003,0.000000e+000,0,,0,
1578735184.209,,0.000000e+000,2.501065e+001,7.404725e-006,2.647819e-008,3,9.401029e-001,3.575851e-001,,,,,,,,,,,,,,32,5,4.000000e+000,3.767967e-002,0.000000e+000,0,,0,
1578735461.109,,0.000000e+000,1.999916e+001,7.424661e-006,2.541490e-008,3,9.452664e-001,3.423038e-001,,,,,,,,,,,,,,32,5,4.000000e+000,8.790970e-003,0.000000e+000,0,,0,
1578735721.659,,0.000000e+000,1.499959e+001,7.457243e-006,2.935498e-008,3,9.410480e-001,3.936439e-001,,,,,,,,,,,,,,32,5,4.000000e+000,5.780220e-003,0.000000e+000,0,,0,
1578735942.080,,0.000000e+000,1.000556e+001,7.617958e-006,5.121081e-008,3,9.367517e-001,6.722381e-001,,,,,,,,,,,,,,32,5,4.000000e+000,1.715088e-002,0.000000e+000,0,,0,
1578736062.540,,0.000000e+000,9.998137e+000,7.400534e-006,6.418865e-008,3,9.296376e-001,8.673516e-001,,,,,,,,,,,,,,32,5,4.000000e+000,6.327629e-003,0.000000e+000,0,,0,
1578736333.130,,0.000000e+000,1.499702e+001,7.463057e-006,4.174334e-008,3,9.385063e-001,5.593330e-001,,,,,,,,,,,,,,32,5,4.000000e+000,2.570152e-003,0.000000e+000,0,,0,
1578736533.330,,0.000000e+000,1.999714e+001,7.252012e-006,4.484064e-008,3,9.468070e-001,6.183200e-001,,,,,,,,,,,,,,32,5,4.000000e+000,2.087975e-002,0.000000e+000,0,,0,
1578736770.451,,0.000000e+000,2.500319e+001,7.214535e-006,4.080884e-008,3,9.446827e-001,5.656475e-001,,,,,,,,,,,,,,32,5,4.000000e+000,9.830475e-003,0.000000e+000,0,,0,
1578736977.511,,0.000000e+000,3.000195e+001,7.458200e-006,4.541975e-008,3,9.443119e-001,6.089907e-001,,,,,,,,,,,,,,32,5,4.000000e+000,4.508972e-003,0.000000e+000,0,,0,
1578737200.181,,0.000000e+000,3.500188e+001,7.358173e-006,5.592421e-008,3,9.360305e-001,7.600285e-001,,,,,,,,,,,,,,32,5,4.000000e+000,7.389069e-003,0.000000e+000,0,,0,
1578737438.212,,0.000000e+000,4.000455e+001,7.422025e-006,1.888009e-008,3,9.401503e-001,2.543792e-001,,,,,,,,,,,,,,32,5,4.000000e+000,9.349823e-003,0.000000e+000,0,,0,
1578737683.112,,0.000000e+000,4.500692e+001,7.361024e-006,7.533549e-008,3,9.394871e-001,1.023438e+000,,,,,,,,,,,,,,32,5,4.000000e+000,1.150894e-002,0.000000e+000,0,,0,
1578737907.662,,0.000000e+000,5.002408e+001,7.337190e-006,5.967043e-008,3,9.401681e-001,8.132601e-001,,,,,,,,,,,,,,32,5,4.000000e+000,3.610992e-002,0.000000e+000,0,,0,
1578738163.563,,0.000000e+000,5.501561e+001,7.093690e-006,5.072476e-008,3,9.433064e-001,7.150688e-001,,,,,,,,,,,,,,32,5,4.000000e+000,3.289795e-002,0.000000e+000,0,,0,
1578738390.043,,0.000000e+000,6.004905e+001,7.132209e-006,3.781367e-008,3,9.241601e-001,5.301818e-001,,,,,,,,,,,,,,32,5,4.000000e+000,7.081223e-002,0.000000e+000,0,,0,
1578738619.153,,0.000000e+000,6.506364e+001,7.080447e-006,5.525907e-008,3,9.379665e-001,7.804461e-001,,,,,,,,,,,,,,32,5,4.000000e+000,8.169556e-002,0.000000e+000,0,,0,
1578738851.244,,0.000000e+000,7.006850e+001,7.303901e-006,4.757289e-008,3,9.365710e-001,6.513354e-001,,,,,,,,,,,,,,32,5,4.000000e+000,7.905579e-002,0.000000e+000,0,,0,
1578739085.024,,0.000000e+000,7.508215e+001,7.100323e-006,2.976194e-008,3,9.417616e-001,4.191631e-001,,,,,,,,,,,,,,32,5,4.000000e+000,9.404755e-002,0.000000e+000,0,,0,
1578739323.384,,0.000000e+000,8.008606e+001,7.357456e-006,3.390637e-008,3,9.388198e-001,4.608437e-001,,,,,,,,,,,,,,32,5,4.000000e+000,1.029663e-001,0.000000e+000,0,,0,
1578739561.875,,0.000000e+000,8.509859e+001,7.463806e-006,5.605066e-008,3,9.387280e-001,7.509662e-001,,,,,,,,,,,,,,32,5,4.000000e+000,1.175156e-001,0.000000e+000,0,,0,
1578739798.825,,0.000000e+000,9.011784e+001,7.534340e-006,2.852634e-008,3,9.369790e-001,3.786176e-001,,,,,,,,,,,,,,32,5,4.000000e+000,1.269608e-001,0.000000e+000,0,,0,
1578740037.755,,0.000000e+000,9.511457e+001,7.444598e-006,2.424781e-008,3,9.377283e-001,3.257101e-001,,,,,,,,,,,,,,32,5,4.000000e+000,1.118240e-001,0.000000e+000,0,,0,
1578740278.276,,0.000000e+000,1.001303e+002,7.653627e-006,2.711786e-008,3,9.393889e-001,3.543139e-001,,,,,,,,,,,,,,32,5,4.000000e+000,1.647034e-001,0.000000e+000,0,,0,
1578740517.686,,0.000000e+000,1.051367e+002,8.215421e-006,6.212446e-008,3,9.485142e-001,7.561933e-001,,,,,,,,,,,,,,32,5,4.000000e+000,1.706009e-001,0.000000e+000,0,,0,
1578740757.416,,0.000000e+000,1.101332e+002,8.308316e-006,5.182618e-008,3,9.472264e-001,6.237869e-001,,,,,,,,,,,,,,32,5,4.000000e+000,1.623001e-001,0.000000e+000,0,,0,
1578740997.477,,0.000000e+000,1.151600e+002,8.939736e-006,1.892558e-008,3,9.453389e-001,2.117018e-001,,,,,,,,,,,,,,32,5,4.000000e+000,2.245026e-001,0.000000e+000,0,,0,
1578741235.527,,0.000000e+000,1.201640e+002,9.046000e-006,2.728737e-008,3,9.537418e-001,3.016512e-001,,,,,,,,,,,,,,32,5,4.000000e+000,2.322006e-001,0.000000e+000,0,,0,
1578741472.187,,0.000000e+000,1.251566e+002,9.462742e-006,1.035858e-008,3,9.426802e-001,1.094670e-001,,,,,,,,,,,,,,32,5,4.000000e+000,2.276001e-001,0.000000e+000,0,,0,
1578741707.698,,0.000000e+000,1.301794e+002,9.781145e-006,2.051276e-008,3,9.522656e-001,2.097174e-001,,,,,,,,,,,,,,32,5,4.000000e+000,2.384949e-001,0.000000e+000,0,,0,
1578741944.998,,0.000000e+000,1.351817e+002,9.766733e-006,4.093937e-008,3,9.570647e-001,4.191716e-001,,,,,,,,,,,,,,32,5,4.000000e+000,2.687988e-001,0.000000e+000,0,,0,
1578742182.548,,0.000000e+000,1.401896e+002,9.972000e-006,5.245944e-008,3,9.438128e-001,5.260674e-001,,,,,,,,,,,,,,32,5,4.000000e+000,2.382965e-001,0.000000e+000,0,,0,
1578742418.339,,0.000000e+000,1.452052e+002,9.993577e-006,4.486010e-008,3,9.544894e-001,4.488894e-001,,,,,,,,,,,,,,32,5,4.000000e+000,2.837982e-001,0.000000e+000,0,,0,
1578742654.279,,0.000000e+000,1.502224e+002,1.036233e-005,3.006108e-008,3,9.524612e-001,2.900996e-001,,,,,,,,,,,,,,32,5,4.000000e+000,3.173981e-001,0.000000e+000,0,,0,
1578742889.139,,0.000000e+000,1.552294e+002,1.013999e-005,4.918008e-008,3,9.520897e-001,4.850111e-001,,,,,,,,,,,,,,32,5,4.000000e+000,3.193970e-001,0.000000e+000,0,,0,
1578743124.250,,0.000000e+000,1.602360e+002,1.046233e-005,4.860417e-008,3,9.531711e-001,4.645637e-001,,,,,,,,,,,,,,32,5,4.000000e+000,3.202057e-001,0.000000e+000,0,,0,
1578743357.980,,0.000000e+000,1.652489e+002,1.027828e-005,3.014882e-008,3,9.468177e-001,2.933255e-001,,,,,,,,,,,,,,32,5,4.000000e+000,3.247070e-001,0.000000e+000,0,,0,
1578743594.460,,0.000000e+000,1.702369e+002,1.031388e-005,3.483541e-008,3,9.487689e-001,3.377528e-001,,,,,,,,,,,,,,32,5,4.000000e+000,3.230896e-001,0.000000e+000,0,,0,
1578743831.171,,0.000000e+000,1.752464e+002,1.039434e-005,5.528353e-008,3,9.554655e-001,5.318620e-001,,,,,,,,,,,,,,32,5,4.000000e+000,3.303986e-001,0.000000e+000,0,,0,
1578744066.271,,0.000000e+000,1.802601e+002,1.038245e-005,4.156312e-008,3,9.544770e-001,4.003209e-001,,,,,,,,,,,,,,32,5,4.000000e+000,3.480988e-001,0.000000e+000,0,,0,
1578744304.691,,0.000000e+000,1.852439e+002,1.047143e-005,5.970301e-008,3,9.503910e-001,5.701516e-001,,,,,,,,,,,,,,32,5,4.000000e+000,3.312988e-001,0.000000e+000,0,,0,
1578744542.532,,0.000000e+000,1.902517e+002,1.057002e-005,9.547524e-009,3,9.609059e-001,9.032643e-002,,,,,,,,,,,,,,32,5,4.000000e+000,3.361053e-001,0.000000e+000,0,,0,
1578744780.422,,0.000000e+000,1.952534e+002,1.053331e-005,4.091389e-008,3,9.516889e-001,3.884237e-001,,,,,,,,,,,,,,32,5,4.000000e+000,3.399963e-001,0.000000e+000,0,,0,
1578745018.632,,0.000000e+000,2.002604e+002,1.057567e-005,3.101273e-008,3,9.486818e-001,2.932459e-001,,,,,,,,,,,,,,32,5,4.000000e+000,3.564911e-001,0.000000e+000,0,,0,
1578745257.663,,0.000000e+000,2.052601e+002,1.063175e-005,2.812838e-008,3,9.480669e-001,2.645695e-001,,,,,,,,,,,,,,32,5,4.000000e+000,3.594055e-001,0.000000e+000,0,,0,
1578745499.493,,0.000000e+000,2.102608e+002,1.054933e-005,4.114684e-008,3,9.595509e-001,3.900422e-001,,,,,,,,,,,,,,32,5,4.000000e+000,3.762970e-001,0.000000e+000,0,,0,
1578745737.043,,0.000000e+000,2.152667e+002,1.053890e-005,1.010865e-008,3,9.570391e-001,9.591749e-002,,,,,,,,,,,,,,32,5,4.000000e+000,3.473969e-001,0.000000e+000,0,,0,
1578745976.884,,0.000000e+000,2.202617e+002,1.077731e-005,4.825474e-008,3,9.541275e-001,4.477439e-001,,,,,,,,,,,,,,32,5,4.000000e+000,3.629913e-001,0.000000e+000,0,,0,
1578746216.464,,0.000000e+000,2.252633e+002,1.079193e-005,3.995286e-008,3,9.607089e-001,3.702105e-001,,,,,,,,,,,,,,32,5,4.000000e+000,3.621979e-001,0.000000e+000,0,,0,
1578746457.604,,0.000000e+000,2.302626e+002,1.061163e-005,5.268334e-008,3,9.433901e-001,4.964678e-001,,,,,,,,,,,,,,32,5,4.000000e+000,3.690033e-001,0.000000e+000,0,,0,
1578746698.265,,0.000000e+000,2.352644e+002,1.050131e-005,6.692771e-008,3,9.562581e-001,6.373274e-001,,,,,,,,,,,,,,32,5,4.000000e+000,3.847046e-001,0.000000e+000,0,,0,
1578746963.685,,0.000000e+000,2.401357e+002,1.073271e-005,5.640580e-008,3,9.576006e-001,5.255506e-001,,,,,,,,,,,,,,32,5,4.000000e+000,2.382965e-001,0.000000e+000,0,,0,
1578747205.085,,0.000000e+000,2.452658e+002,1.052853e-005,3.133015e-008,3,9.606271e-001,2.975740e-001,,,,,,,,,,,,,,32,5,4.000000e+000,3.576050e-001,0.000000e+000,0,,0,
1578747445.626,,0.000000e+000,2.502753e+002,1.049916e-005,3.164223e-008,3,9.589937e-001,3.013788e-001,,,,,,,,,,,,,,32,5,4.000000e+000,3.719025e-001,0.000000e+000,0,,0,
1578747687.796,,0.000000e+000,2.552635e+002,1.047553e-005,2.396724e-008,3,9.586577e-001,2.287927e-001,,,,,,,,,,,,,,32,5,4.000000e+000,3.757019e-001,0.000000e+000,0,,0,
1578747928.816,,0.000000e+000,2.602682e+002,1.067055e-005,3.853899e-008,3,9.553779e-001,3.611717e-001,,,,,,,,,,,,,,32,5,4.000000e+000,3.901978e-001,0.000000e+000,0,,0,
1578748172.387,,0.000000e+000,2.652721e+002,1.063255e-005,2.606466e-008,3,9.557055e-001,2.451403e-001,,,,,,,,,,,,,,32,5,4.000000e+000,3.476868e-001,0.000000e+000,0,,0,
1578748489.947,,0.000000e+000,2.700119e+002,1.046347e-005,1.801491e-008,3,9.502684e-001,1.721696e-001,,,,,,,,,,,,,,32,5,4.000000e+000,7.208252e-002,0.000000e+000,0,,0,
1578748735.108,,0.000000e+000,2.752509e+002,1.045301e-005,2.924802e-008,3,9.597122e-001,2.798047e-001,,,,,,,,,,,,,,32,5,4.000000e+000,3.880920e-001,0.000000e+000,0,,0,
1578748978.768,,0.000000e+000,2.802610e+002,1.058725e-005,5.753887e-008,3,9.572780e-001,5.434734e-001,,,,,,,,,,,,,,32,5,4.000000e+000,3.768921e-001,0.000000e+000,0,,0,
1578749274.448,,0.000000e+000,2.850439e+002,1.035848e-005,3.407259e-008,3,9.557589e-001,3.289343e-001,,,,,,,,,,,,,,32,5,4.000000e+000,1.614990e-001,0.000000e+000,0,,0,
1578749519.809,,0.000000e+000,2.902550e+002,1.051964e-005,2.720926e-008,3,9.551439e-001,2.586519e-001,,,,,,,,,,,,,,32,5,4.000000e+000,3.773193e-001,0.000000e+000,0,,0,
1578749762.609,,0.000000e+000,2.952628e+002,1.033396e-005,8.006872e-008,3,9.583321e-001,7.748114e-001,,,,,,,,,,,,,,32,5,4.000000e+000,3.908997e-001,0.000000e+000,0,,0,
1578750006.029,,0.000000e+000,3.002556e+002,1.023712e-005,3.579230e-008,3,9.553446e-001,3.496326e-001,,,,,,,,,,,,,,32,5,4.000000e+000,3.594971e-001,0.000000e+000,0,,0,