File: data/Rock_mag/2020_IRM_data_files/Raw_data/MPMS-XL/data/BD7-7r_FC-ZFC-RTSIRM-10K.dc.dat
[Header]
TITLE,MPMS DC Measurement
BYAPP,MPMS Measurement,2.1,Summary
FILEOPENTIME, 1578331924.896000 1/6/2020, 11:32:04 AM

INFO, APPNAME, MPMS MultiVu Application, Revision 1.61,  Build 082

INFO, NAME, BD7-7r
INFO, WEIGHT, 1.000
INFO, AREA, 1.000
INFO, LENGTH, 1.000
INFO, SHAPE, 0
INFO, COMMENT,
INFO, SEQUENCE FILE: FC-ZFC LTSIRM and RTSIRM LTD 10K.seq


INFO, BACKGROUND DATA FILE:, None


STARTUPAXIS,X,4,LINEAR,AUTO,0.000000,0.000000
STARTUPAXIS,Y1,5,LINEAR,AUTO,0.000000,0.000000


STARTUPGROUP,Longitudinal
FIELDGROUP,Longitudinal,1,2,3,4,5,6,7,8,9,15,16,17,18,27,28
FIELDGROUP,Transverse,1,2,3,4,10,11,12,13,14,19,20,21,22,27,28

PLOT_APPEARANCE,ALL,HORZ_GRID_ON,VERT_GRID_ON,MARKERS_AND_LINES

[Data]
Time,Comment,Field (Oe),Temperature (K),Long Moment (emu),Long Scan Std Dev,Long Algorithm,Long Reg Fit,Long Percent Error (%),Trans Moment (emu),Trans Scan Std Dev,Trans Algorithm,Trans Reg Fit,Trans Percent Error (%),Long Moment [w/o ABS] (emu),Long Scan Std Dev [w/o ABS],Long Reg Fit [w/o ABS],Long Percent Error [w/o ABS] (%),Trans Moment [w/o ABS] (emu),Trans Scan Std Dev [w/o ABS],Trans Reg Fit [w/o ABS],Trans Percent Error [w/o ABS] (%),Points per Scan,Scans per Measurement,Scan Length (cm),Delta Temp (K),Rot Position (deg),Error,EC Comp. Running,Using ABS,
1578331924.896,,0.000000e+000,9.999552e+000,3.039503e-002,0.000000e+000,3,9.927777e-001,0.000000e+000,,,,,,,,,,,,,,32,1,4.000000e+000,2.715683e-002,0.000000e+000,0,,0,
1578332007.606,,0.000000e+000,1.551839e+001,2.952080e-002,0.000000e+000,3,9.925432e-001,0.000000e+000,,,,,,,,,,,,,,32,1,4.000000e+000,9.877892e-001,0.000000e+000,0,,0,
1578332080.236,,0.000000e+000,2.156472e+001,2.083886e-002,0.000000e+000,3,9.926189e-001,0.000000e+000,,,,,,,,,,,,,,32,1,4.000000e+000,1.007151e+000,0.000000e+000,0,,0,
1578332128.866,,0.000000e+000,2.557139e+001,1.689488e-002,0.000000e+000,3,9.923410e-001,0.000000e+000,,,,,,,,,,,,,,32,1,4.000000e+000,9.762402e-001,0.000000e+000,0,,0,
1578332188.726,,0.000000e+000,3.050145e+001,1.385811e-002,0.000000e+000,3,9.918736e-001,0.000000e+000,,,,,,,,,,,,,,32,1,4.000000e+000,9.412594e-001,0.000000e+000,0,,0,
1578332250.606,,0.000000e+000,3.559827e+001,1.186432e-002,0.000000e+000,3,9.917900e-001,0.000000e+000,,,,,,,,,,,,,,32,1,4.000000e+000,8.311501e-001,0.000000e+000,0,,0,
1578332312.777,,0.000000e+000,4.068591e+001,1.029651e-002,0.000000e+000,3,9.916605e-001,0.000000e+000,,,,,,,,,,,,,,32,1,4.000000e+000,9.684868e-001,0.000000e+000,0,,0,
1578332372.057,,0.000000e+000,4.556419e+001,9.004356e-003,0.000000e+000,3,9.908584e-001,0.000000e+000,,,,,,,,,,,,,,32,1,4.000000e+000,1.018688e+000,0.000000e+000,0,,0,
1578332432.167,,0.000000e+000,5.058157e+001,7.883294e-003,0.000000e+000,3,9.913650e-001,0.000000e+000,,,,,,,,,,,,,,32,1,4.000000e+000,9.263306e-001,0.000000e+000,0,,0,
1578332504.617,,0.000000e+000,5.664729e+001,6.785333e-003,0.000000e+000,3,9.916754e-001,0.000000e+000,,,,,,,,,,,,,,32,1,4.000000e+000,9.040871e-001,0.000000e+000,0,,0,
1578332552.687,,0.000000e+000,6.063139e+001,6.287033e-003,0.000000e+000,3,9.910752e-001,0.000000e+000,,,,,,,,,,,,,,32,1,4.000000e+000,9.506912e-001,0.000000e+000,0,,0,
1578332611.307,,0.000000e+000,6.552734e+001,5.846162e-003,0.000000e+000,3,9.906787e-001,0.000000e+000,,,,,,,,,,,,,,32,1,4.000000e+000,8.812103e-001,0.000000e+000,0,,0,
1578332672.887,,0.000000e+000,7.065128e+001,5.480827e-003,0.000000e+000,3,9.909386e-001,0.000000e+000,,,,,,,,,,,,,,32,1,4.000000e+000,1.038940e+000,0.000000e+000,0,,0,
1578332730.767,,0.000000e+000,7.552287e+001,5.180468e-003,0.000000e+000,3,9.910321e-001,0.000000e+000,,,,,,,,,,,,,,32,1,4.000000e+000,1.013031e+000,0.000000e+000,0,,0,
1578332790.487,,0.000000e+000,8.052257e+001,4.865794e-003,0.000000e+000,3,9.910503e-001,0.000000e+000,,,,,,,,,,,,,,32,1,4.000000e+000,9.198685e-001,0.000000e+000,0,,0,
1578332850.897,,0.000000e+000,8.555649e+001,4.521894e-003,0.000000e+000,3,9.912981e-001,0.000000e+000,,,,,,,,,,,,,,32,1,4.000000e+000,8.853912e-001,0.000000e+000,0,,0,
1578332909.567,,0.000000e+000,9.049028e+001,4.144671e-003,0.000000e+000,3,9.910021e-001,0.000000e+000,,,,,,,,,,,,,,32,1,4.000000e+000,9.750671e-001,0.000000e+000,0,,0,
1578332969.298,,0.000000e+000,9.549759e+001,3.707189e-003,0.000000e+000,3,9.912497e-001,0.000000e+000,,,,,,,,,,,,,,32,1,4.000000e+000,8.903961e-001,0.000000e+000,0,,0,
1578333030.918,,0.000000e+000,1.006551e+002,3.230867e-003,0.000000e+000,3,9.913103e-001,0.000000e+000,,,,,,,,,,,,,,32,1,4.000000e+000,1.004303e+000,0.000000e+000,0,,0,
1578333100.588,,0.000000e+000,1.064937e+002,2.670232e-003,0.000000e+000,3,9.913166e-001,0.000000e+000,,,,,,,,,,,,,,32,1,4.000000e+000,9.655991e-001,0.000000e+000,0,,0,
1578333149.428,,0.000000e+000,1.105185e+002,2.315451e-003,0.000000e+000,3,9.909564e-001,0.000000e+000,,,,,,,,,,,,,,32,1,4.000000e+000,8.888016e-001,0.000000e+000,0,,0,
1578333209.858,,0.000000e+000,1.156693e+002,1.930645e-003,0.000000e+000,3,9.913057e-001,0.000000e+000,,,,,,,,,,,,,,32,1,4.000000e+000,8.956070e-001,0.000000e+000,0,,0,
1578333268.008,,0.000000e+000,1.205230e+002,1.661535e-003,0.000000e+000,3,9.909120e-001,0.000000e+000,,,,,,,,,,,,,,32,1,4.000000e+000,8.382034e-001,0.000000e+000,0,,0,
1578333341.768,,0.000000e+000,1.266770e+002,1.431054e-003,0.000000e+000,3,9.914024e-001,0.000000e+000,,,,,,,,,,,,,,32,1,4.000000e+000,1.012100e+000,0.000000e+000,0,,0,
1578333388.598,,0.000000e+000,1.305681e+002,1.324023e-003,0.000000e+000,3,9.919062e-001,0.000000e+000,,,,,,,,,,,,,,32,1,4.000000e+000,8.480988e-001,0.000000e+000,0,,0,
1578333447.828,,0.000000e+000,1.354738e+002,1.220454e-003,0.000000e+000,3,9.914561e-001,0.000000e+000,,,,,,,,,,,,,,32,1,4.000000e+000,8.618011e-001,0.000000e+000,0,,0,
1578333507.958,,0.000000e+000,1.405728e+002,1.135230e-003,0.000000e+000,3,9.914871e-001,0.000000e+000,,,,,,,,,,,,,,32,1,4.000000e+000,1.007294e+000,0.000000e+000,0,,0,
1578333568.558,,0.000000e+000,1.455897e+002,1.065971e-003,0.000000e+000,3,9.924818e-001,0.000000e+000,,,,,,,,,,,,,,32,1,4.000000e+000,9.004059e-001,0.000000e+000,0,,0,
1578333626.858,,0.000000e+000,1.505119e+002,1.012172e-003,0.000000e+000,3,9.914644e-001,0.000000e+000,,,,,,,,,,,,,,32,1,4.000000e+000,8.912048e-001,0.000000e+000,0,,0,
1578333688.279,,0.000000e+000,1.555768e+002,9.634860e-004,0.000000e+000,3,9.915637e-001,0.000000e+000,,,,,,,,,,,,,,32,1,4.000000e+000,9.367065e-001,0.000000e+000,0,,0,
1578333748.449,,0.000000e+000,1.606588e+002,9.209900e-004,0.000000e+000,3,9.923785e-001,0.000000e+000,,,,,,,,,,,,,,32,1,4.000000e+000,9.248047e-001,0.000000e+000,0,,0,
1578333807.059,,0.000000e+000,1.655186e+002,8.860952e-004,0.000000e+000,3,9.920898e-001,0.000000e+000,,,,,,,,,,,,,,32,1,4.000000e+000,9.295959e-001,0.000000e+000,0,,0,
1578333867.219,,0.000000e+000,1.705137e+002,8.528124e-004,0.000000e+000,3,9.916226e-001,0.000000e+000,,,,,,,,,,,,,,32,1,4.000000e+000,9.122009e-001,0.000000e+000,0,,0,
1578333926.929,,0.000000e+000,1.754706e+002,8.235087e-004,0.000000e+000,3,9.920254e-001,0.000000e+000,,,,,,,,,,,,,,32,1,4.000000e+000,9.039001e-001,0.000000e+000,0,,0,
1578333986.949,,0.000000e+000,1.805068e+002,7.980993e-004,0.000000e+000,3,9.918870e-001,0.000000e+000,,,,,,,,,,,,,,32,1,4.000000e+000,9.802094e-001,0.000000e+000,0,,0,
1578334060.449,,0.000000e+000,1.866495e+002,7.685866e-004,0.000000e+000,3,9.915261e-001,0.000000e+000,,,,,,,,,,,,,,32,1,4.000000e+000,9.019012e-001,0.000000e+000,0,,0,
1578334107.189,,0.000000e+000,1.905836e+002,7.512624e-004,0.000000e+000,3,9.921658e-001,0.000000e+000,,,,,,,,,,,,,,32,1,4.000000e+000,8.948975e-001,0.000000e+000,0,,0,
1578334166.179,,0.000000e+000,1.955087e+002,7.325321e-004,0.000000e+000,3,9.920123e-001,0.000000e+000,,,,,,,,,,,,,,32,1,4.000000e+000,9.580078e-001,0.000000e+000,0,,0,
1578334226.979,,0.000000e+000,2.005633e+002,7.146375e-004,0.000000e+000,3,9.921226e-001,0.000000e+000,,,,,,,,,,,,,,32,1,4.000000e+000,1.038803e+000,0.000000e+000,0,,0,
1578334287.349,,0.000000e+000,2.055822e+002,6.979844e-004,0.000000e+000,3,9.925830e-001,0.000000e+000,,,,,,,,,,,,,,32,1,4.000000e+000,9.468994e-001,0.000000e+000,0,,0,
1578334346.639,,0.000000e+000,2.105276e+002,6.836482e-004,0.000000e+000,3,9.915689e-001,0.000000e+000,,,,,,,,,,,,,,32,1,4.000000e+000,9.319000e-001,0.000000e+000,0,,0,
1578334407.210,,0.000000e+000,2.156432e+002,6.700692e-004,0.000000e+000,3,9.921623e-001,0.000000e+000,,,,,,,,,,,,,,32,1,4.000000e+000,8.674011e-001,0.000000e+000,0,,0,
1578334466.990,,0.000000e+000,2.205816e+002,6.576405e-004,0.000000e+000,3,9.924884e-001,0.000000e+000,,,,,,,,,,,,,,32,1,4.000000e+000,9.058075e-001,0.000000e+000,0,,0,
1578334527.900,,0.000000e+000,2.256026e+002,6.458021e-004,0.000000e+000,3,9.922583e-001,0.000000e+000,,,,,,,,,,,,,,32,1,4.000000e+000,1.089386e+000,0.000000e+000,0,,0,
1578334587.140,,0.000000e+000,2.305609e+002,6.354333e-004,0.000000e+000,3,9.924888e-001,0.000000e+000,,,,,,,,,,,,,,32,1,4.000000e+000,1.012695e+000,0.000000e+000,0,,0,
1578334646.790,,0.000000e+000,2.356089e+002,6.259824e-004,0.000000e+000,3,9.925548e-001,0.000000e+000,,,,,,,,,,,,,,32,1,4.000000e+000,8.448029e-001,0.000000e+000,0,,0,
1578334706.010,,0.000000e+000,2.405182e+002,6.168392e-004,0.000000e+000,3,9.922689e-001,0.000000e+000,,,,,,,,,,,,,,32,1,4.000000e+000,8.984985e-001,0.000000e+000,0,,0,
1578334767.010,,0.000000e+000,2.455907e+002,6.082742e-004,0.000000e+000,3,9.923030e-001,0.000000e+000,,,,,,,,,,,,,,32,1,4.000000e+000,9.158020e-001,0.000000e+000,0,,0,
1578334827.130,,0.000000e+000,2.506110e+002,6.004654e-004,0.000000e+000,3,9.925744e-001,0.000000e+000,,,,,,,,,,,,,,32,1,4.000000e+000,8.180084e-001,0.000000e+000,0,,0,
1578334886.630,,0.000000e+000,2.556091e+002,5.932400e-004,0.000000e+000,3,9.924909e-001,0.000000e+000,,,,,,,,,,,,,,32,1,4.000000e+000,9.039001e-001,0.000000e+000,0,,0,
1578334945.850,,0.000000e+000,2.604753e+002,5.861294e-004,0.000000e+000,3,9.928139e-001,0.000000e+000,,,,,,,,,,,,,,32,1,4.000000e+000,9.152832e-001,0.000000e+000,0,,0,
1578335006.990,,0.000000e+000,2.655826e+002,5.802147e-004,0.000000e+000,3,9.926268e-001,0.000000e+000,,,,,,,,,,,,,,32,1,4.000000e+000,9.058838e-001,0.000000e+000,0,,0,
1578335066.700,,0.000000e+000,2.705922e+002,5.738149e-004,0.000000e+000,3,9.933034e-001,0.000000e+000,,,,,,,,,,,,,,32,1,4.000000e+000,8.937073e-001,0.000000e+000,0,,0,
1578335126.571,,0.000000e+000,2.755336e+002,5.679354e-004,0.000000e+000,3,9.934989e-001,0.000000e+000,,,,,,,,,,,,,,32,1,4.000000e+000,9.655762e-001,0.000000e+000,0,,0,
1578335185.441,,0.000000e+000,2.805101e+002,5.630205e-004,0.000000e+000,3,9.939953e-001,0.000000e+000,,,,,,,,,,,,,,32,1,4.000000e+000,9.111938e-001,0.000000e+000,0,,0,
1578335246.601,,0.000000e+000,2.856166e+002,5.579233e-004,0.000000e+000,3,9.937315e-001,0.000000e+000,,,,,,,,,,,,,,32,1,4.000000e+000,9.460144e-001,0.000000e+000,0,,0,
1578335305.961,,0.000000e+000,2.904991e+002,5.530543e-004,0.000000e+000,3,9.943044e-001,0.000000e+000,,,,,,,,,,,,,,32,1,4.000000e+000,9.238892e-001,0.000000e+000,0,,0,
1578335366.441,,0.000000e+000,2.956158e+002,5.479967e-004,0.000000e+000,3,9.948295e-001,0.000000e+000,,,,,,,,,,,,,,32,1,4.000000e+000,9.577942e-001,0.000000e+000,0,,0,
1578335699.651,,0.000000e+000,3.000265e+002,5.409501e-004,0.000000e+000,3,9.946411e-001,0.000000e+000,,,,,,,,,,,,,,32,1,4.000000e+000,0.000000e+000,0.000000e+000,0,,0,
1578341503.479,,0.000000e+000,9.999825e+000,3.255686e-002,0.000000e+000,3,9.931930e-001,0.000000e+000,,,,,,,,,,,,,,32,1,4.000000e+000,6.601143e-002,0.000000e+000,0,,0,
1578341585.120,,0.000000e+000,1.555182e+001,3.128113e-002,0.000000e+000,3,9.931308e-001,0.000000e+000,,,,,,,,,,,,,,32,1,4.000000e+000,9.121990e-001,0.000000e+000,0,,0,
1578341657.600,,0.000000e+000,2.159882e+001,2.309008e-002,0.000000e+000,3,9.927796e-001,0.000000e+000,,,,,,,,,,,,,,32,1,4.000000e+000,9.258099e-001,0.000000e+000,0,,0,
1578341706.490,,0.000000e+000,2.556771e+001,1.965262e-002,0.000000e+000,3,9.922367e-001,0.000000e+000,,,,,,,,,,,,,,32,1,4.000000e+000,9.853611e-001,0.000000e+000,0,,0,
1578341766.820,,0.000000e+000,3.049740e+001,1.705280e-002,0.000000e+000,3,9.921638e-001,0.000000e+000,,,,,,,,,,,,,,32,1,4.000000e+000,9.421997e-001,0.000000e+000,0,,0,
1578341827.550,,0.000000e+000,3.552640e+001,1.527371e-002,0.000000e+000,3,9.919564e-001,0.000000e+000,,,,,,,,,,,,,,32,1,4.000000e+000,9.904518e-001,0.000000e+000,0,,0,
1578341887.990,,0.000000e+000,4.053627e+001,1.371998e-002,0.000000e+000,3,9.915254e-001,0.000000e+000,,,,,,,,,,,,,,32,1,4.000000e+000,9.698792e-001,0.000000e+000,0,,0,
1578341950.060,,0.000000e+000,4.566609e+001,1.215156e-002,0.000000e+000,3,9.915227e-001,0.000000e+000,,,,,,,,,,,,,,32,1,4.000000e+000,9.542580e-001,0.000000e+000,0,,0,
1578342010.150,,0.000000e+000,5.054276e+001,1.047127e-002,0.000000e+000,3,9.914526e-001,0.000000e+000,,,,,,,,,,,,,,32,1,4.000000e+000,8.487091e-001,0.000000e+000,0,,0,
1578342069.230,,0.000000e+000,5.551305e+001,8.956991e-003,0.000000e+000,3,9.914955e-001,0.000000e+000,,,,,,,,,,,,,,32,1,4.000000e+000,9.990883e-001,0.000000e+000,0,,0,
1578342130.090,,0.000000e+000,6.063316e+001,7.965825e-003,0.000000e+000,3,9.914387e-001,0.000000e+000,,,,,,,,,,,,,,32,1,4.000000e+000,9.789314e-001,0.000000e+000,0,,0,
1578342202.460,,0.000000e+000,6.661552e+001,7.257274e-003,0.000000e+000,3,9.914078e-001,0.000000e+000,,,,,,,,,,,,,,32,1,4.000000e+000,9.667740e-001,0.000000e+000,0,,0,
1578342250.200,,0.000000e+000,7.060645e+001,6.927694e-003,0.000000e+000,3,9.908543e-001,0.000000e+000,,,,,,,,,,,,,,32,1,4.000000e+000,9.411850e-001,0.000000e+000,0,,0,
1578342308.281,,0.000000e+000,7.552539e+001,6.566100e-003,0.000000e+000,3,9.910175e-001,0.000000e+000,,,,,,,,,,,,,,32,1,4.000000e+000,8.392410e-001,0.000000e+000,0,,0,
1578342368.111,,0.000000e+000,8.050682e+001,6.207694e-003,0.000000e+000,3,9.912397e-001,0.000000e+000,,,,,,,,,,,,,,32,1,4.000000e+000,8.883820e-001,0.000000e+000,0,,0,
1578342428.771,,0.000000e+000,8.561057e+001,5.814143e-003,0.000000e+000,3,9.913118e-001,0.000000e+000,,,,,,,,,,,,,,32,1,4.000000e+000,9.935455e-001,0.000000e+000,0,,0,
1578342486.861,,0.000000e+000,9.047899e+001,5.377968e-003,0.000000e+000,3,9.913886e-001,0.000000e+000,,,,,,,,,,,,,,32,1,4.000000e+000,9.524841e-001,0.000000e+000,0,,0,
1578342547.111,,0.000000e+000,9.553494e+001,4.849561e-003,0.000000e+000,3,9.911996e-001,0.000000e+000,,,,,,,,,,,,,,32,1,4.000000e+000,9.790726e-001,0.000000e+000,0,,0,
1578342608.651,,0.000000e+000,1.005811e+002,4.255312e-003,0.000000e+000,3,9.913129e-001,0.000000e+000,,,,,,,,,,,,,,32,1,4.000000e+000,8.718948e-001,0.000000e+000,0,,0,
1578342666.081,,0.000000e+000,1.054727e+002,3.681998e-003,0.000000e+000,3,9.914219e-001,0.000000e+000,,,,,,,,,,,,,,32,1,4.000000e+000,9.162979e-001,0.000000e+000,0,,0,
1578342727.801,,0.000000e+000,1.106438e+002,3.094386e-003,0.000000e+000,3,9.914369e-001,0.000000e+000,,,,,,,,,,,,,,32,1,4.000000e+000,1.013199e+000,0.000000e+000,0,,0,
1578342800.361,,0.000000e+000,1.166890e+002,2.514925e-003,0.000000e+000,3,9.913276e-001,0.000000e+000,,,,,,,,,,,,,,32,1,4.000000e+000,9.951019e-001,0.000000e+000,0,,0,
1578342846.131,,0.000000e+000,1.205101e+002,2.247229e-003,0.000000e+000,3,9.913086e-001,0.000000e+000,,,,,,,,,,,,,,32,1,4.000000e+000,9.600983e-001,0.000000e+000,0,,0,
1578342905.451,,0.000000e+000,1.255065e+002,1.999839e-003,0.000000e+000,3,9.914878e-001,0.000000e+000,,,,,,,,,,,,,,32,1,4.000000e+000,9.602051e-001,0.000000e+000,0,,0,
1578342966.111,,0.000000e+000,1.306176e+002,1.824953e-003,0.000000e+000,3,9.919143e-001,0.000000e+000,,,,,,,,,,,,,,32,1,4.000000e+000,9.595032e-001,0.000000e+000,0,,0,
1578343025.302,,0.000000e+000,1.355367e+002,1.701978e-003,0.000000e+000,3,9.916525e-001,0.000000e+000,,,,,,,,,,,,,,32,1,4.000000e+000,9.745026e-001,0.000000e+000,0,,0,
1578343086.112,,0.000000e+000,1.405621e+002,1.607941e-003,0.000000e+000,3,9.915590e-001,0.000000e+000,,,,,,,,,,,,,,32,1,4.000000e+000,1.000092e+000,0.000000e+000,0,,0,
1578343146.672,,0.000000e+000,1.456836e+002,1.536570e-003,0.000000e+000,3,9.914502e-001,0.000000e+000,,,,,,,,,,,,,,32,1,4.000000e+000,9.239960e-001,0.000000e+000,0,,0,
1578343218.672,,0.000000e+000,1.516174e+002,1.468418e-003,0.000000e+000,3,9.910726e-001,0.000000e+000,,,,,,,,,,,,,,32,1,4.000000e+000,9.674072e-001,0.000000e+000,0,,0,
1578343265.582,,0.000000e+000,1.554945e+002,1.433035e-003,0.000000e+000,3,9.909991e-001,0.000000e+000,,,,,,,,,,,,,,32,1,4.000000e+000,9.485016e-001,0.000000e+000,0,,0,
1578343325.642,,0.000000e+000,1.605649e+002,1.393106e-003,0.000000e+000,3,9.913344e-001,0.000000e+000,,,,,,,,,,,,,,32,1,4.000000e+000,9.239044e-001,0.000000e+000,0,,0,
1578343384.632,,0.000000e+000,1.655091e+002,1.359747e-003,0.000000e+000,3,9.916632e-001,0.000000e+000,,,,,,,,,,,,,,32,1,4.000000e+000,9.199982e-001,0.000000e+000,0,,0,
1578343445.682,,0.000000e+000,1.705112e+002,1.329854e-003,0.000000e+000,3,9.913378e-001,0.000000e+000,,,,,,,,,,,,,,32,1,4.000000e+000,9.172058e-001,0.000000e+000,0,,0,
1578343506.062,,0.000000e+000,1.756337e+002,1.302956e-003,0.000000e+000,3,9.913395e-001,0.000000e+000,,,,,,,,,,,,,,32,1,4.000000e+000,9.161072e-001,0.000000e+000,0,,0,
1578343563.902,,0.000000e+000,1.805041e+002,1.281132e-003,0.000000e+000,3,9.912100e-001,0.000000e+000,,,,,,,,,,,,,,32,1,4.000000e+000,9.967957e-001,0.000000e+000,0,,0,
1578343624.382,,0.000000e+000,1.854980e+002,1.261053e-003,0.000000e+000,3,9.910602e-001,0.000000e+000,,,,,,,,,,,,,,32,1,4.000000e+000,8.856964e-001,0.000000e+000,0,,0,
1578343684.933,,0.000000e+000,1.905379e+002,1.242068e-003,0.000000e+000,3,9.912285e-001,0.000000e+000,,,,,,,,,,,,,,32,1,4.000000e+000,9.740906e-001,0.000000e+000,0,,0,
1578343744.763,,0.000000e+000,1.955891e+002,1.225688e-003,0.000000e+000,3,9.914480e-001,0.000000e+000,,,,,,,,,,,,,,32,1,4.000000e+000,9.651031e-001,0.000000e+000,0,,0,
1578343803.843,,0.000000e+000,2.005226e+002,1.211547e-003,0.000000e+000,3,9.918346e-001,0.000000e+000,,,,,,,,,,,,,,32,1,4.000000e+000,9.575043e-001,0.000000e+000,0,,0,
1578343864.913,,0.000000e+000,2.055435e+002,1.197672e-003,0.000000e+000,3,9.915875e-001,0.000000e+000,,,,,,,,,,,,,,32,1,4.000000e+000,1.024200e+000,0.000000e+000,0,,0,
1578343924.243,,0.000000e+000,2.105165e+002,1.185126e-003,0.000000e+000,3,9.918424e-001,0.000000e+000,,,,,,,,,,,,,,32,1,4.000000e+000,9.391022e-001,0.000000e+000,0,,0,
1578343984.043,,0.000000e+000,2.155696e+002,1.173603e-003,0.000000e+000,3,9.917225e-001,0.000000e+000,,,,,,,,,,,,,,32,1,4.000000e+000,8.589935e-001,0.000000e+000,0,,0,
1578344044.653,,0.000000e+000,2.205735e+002,1.162929e-003,0.000000e+000,3,9.913610e-001,0.000000e+000,,,,,,,,,,,,,,32,1,4.000000e+000,9.219971e-001,0.000000e+000,0,,0,
1578344104.423,,0.000000e+000,2.255645e+002,1.152248e-003,0.000000e+000,3,9.919022e-001,0.000000e+000,,,,,,,,,,,,,,32,1,4.000000e+000,1.013092e+000,0.000000e+000,0,,0,
1578344164.303,,0.000000e+000,2.305608e+002,1.142638e-003,0.000000e+000,3,9.918230e-001,0.000000e+000,,,,,,,,,,,,,,32,1,4.000000e+000,9.950104e-001,0.000000e+000,0,,0,
1578344225.313,,0.000000e+000,2.356366e+002,1.133325e-003,0.000000e+000,3,9.919348e-001,0.000000e+000,,,,,,,,,,,,,,32,1,4.000000e+000,9.184875e-001,0.000000e+000,0,,0,
1578344284.103,,0.000000e+000,2.405087e+002,1.124923e-003,0.000000e+000,3,9.921617e-001,0.000000e+000,,,,,,,,,,,,,,32,1,4.000000e+000,9.176025e-001,0.000000e+000,0,,0,
1578344344.163,,0.000000e+000,2.455607e+002,1.116577e-003,0.000000e+000,3,9.920672e-001,0.000000e+000,,,,,,,,,,,,,,32,1,4.000000e+000,8.359985e-001,0.000000e+000,0,,0,
1578344403.854,,0.000000e+000,2.505750e+002,1.108396e-003,0.000000e+000,3,9.923298e-001,0.000000e+000,,,,,,,,,,,,,,32,1,4.000000e+000,9.108887e-001,0.000000e+000,0,,0,
1578344464.034,,0.000000e+000,2.555231e+002,1.101202e-003,0.000000e+000,3,9.920776e-001,0.000000e+000,,,,,,,,,,,,,,32,1,4.000000e+000,9.031982e-001,0.000000e+000,0,,0,
1578344523.594,,0.000000e+000,2.604921e+002,1.094111e-003,0.000000e+000,3,9.926771e-001,0.000000e+000,,,,,,,,,,,,,,32,1,4.000000e+000,9.711914e-001,0.000000e+000,0,,0,
1578344584.644,,0.000000e+000,2.655710e+002,1.086419e-003,0.000000e+000,3,9.929273e-001,0.000000e+000,,,,,,,,,,,,,,32,1,4.000000e+000,9.058838e-001,0.000000e+000,0,,0,
1578344643.604,,0.000000e+000,2.705198e+002,1.079656e-003,0.000000e+000,3,9.929121e-001,0.000000e+000,,,,,,,,,,,,,,32,1,4.000000e+000,8.932800e-001,0.000000e+000,0,,0,
1578344704.544,,0.000000e+000,2.755336e+002,1.072711e-003,0.000000e+000,3,9.931129e-001,0.000000e+000,,,,,,,,,,,,,,32,1,4.000000e+000,9.655762e-001,0.000000e+000,0,,0,
1578344763.894,,0.000000e+000,2.805493e+002,1.066314e-003,0.000000e+000,3,9.931880e-001,0.000000e+000,,,,,,,,,,,,,,32,1,4.000000e+000,9.635925e-001,0.000000e+000,0,,0,
1578344823.694,,0.000000e+000,2.855759e+002,1.060257e-003,0.000000e+000,3,9.935092e-001,0.000000e+000,,,,,,,,,,,,,,32,1,4.000000e+000,8.646240e-001,0.000000e+000,0,,0,
1578344883.964,,0.000000e+000,2.905831e+002,1.054246e-003,0.000000e+000,3,9.932669e-001,0.000000e+000,,,,,,,,,,,,,,32,1,4.000000e+000,9.523926e-001,0.000000e+000,0,,0,
1578344944.414,,0.000000e+000,2.956158e+002,1.047200e-003,0.000000e+000,3,9.943601e-001,0.000000e+000,,,,,,,,,,,,,,32,1,4.000000e+000,9.577942e-001,0.000000e+000,0,,0,
1578345277.665,,0.000000e+000,3.000339e+002,1.036758e-003,0.000000e+000,3,9.935616e-001,0.000000e+000,,,,,,,,,,,,,,32,1,4.000000e+000,1.492310e-002,0.000000e+000,0,,0,
1578345845.506,,0.000000e+000,2.999966e+002,1.055214e-002,0.000000e+000,3,9.922314e-001,0.000000e+000,,,,,,,,,,,,,,32,1,4.000000e+000,0.000000e+000,0.000000e+000,0,,0,
1578346121.976,,0.000000e+000,2.946967e+002,1.049616e-002,0.000000e+000,3,9.923889e-001,0.000000e+000,,,,,,,,,,,,,,32,1,4.000000e+000,5.912170e-001,0.000000e+000,0,,0,
1578346201.566,,0.000000e+000,2.893839e+002,1.044449e-002,0.000000e+000,3,9.920829e-001,0.000000e+000,,,,,,,,,,,,,,32,1,4.000000e+000,9.997864e-001,0.000000e+000,0,,0,
1578346260.486,,0.000000e+000,2.843122e+002,1.038543e-002,0.000000e+000,3,9.914357e-001,0.000000e+000,,,,,,,,,,,,,,32,1,4.000000e+000,1.097595e+000,0.000000e+000,0,,0,
1578346314.686,,0.000000e+000,2.794150e+002,1.031491e-002,0.000000e+000,3,9.913372e-001,0.000000e+000,,,,,,,,,,,,,,32,1,4.000000e+000,1.123322e+000,0.000000e+000,0,,0,
1578346371.796,,0.000000e+000,2.742487e+002,1.023821e-002,0.000000e+000,3,9.912770e-001,0.000000e+000,,,,,,,,,,,,,,32,1,4.000000e+000,1.229584e+000,0.000000e+000,0,,0,
1578346428.496,,0.000000e+000,2.693549e+002,1.016617e-002,0.000000e+000,3,9.910951e-001,0.000000e+000,,,,,,,,,,,,,,32,1,4.000000e+000,1.196198e+000,0.000000e+000,0,,0,
1578346488.936,,0.000000e+000,2.642486e+002,1.008663e-002,0.000000e+000,3,9.911972e-001,0.000000e+000,,,,,,,,,,,,,,32,1,4.000000e+000,1.114807e+000,0.000000e+000,0,,0,
1578346551.027,,0.000000e+000,2.593970e+002,1.000437e-002,0.000000e+000,3,9.908120e-001,0.000000e+000,,,,,,,,,,,,,,32,1,4.000000e+000,1.040924e+000,0.000000e+000,0,,0,
1578346616.147,,0.000000e+000,2.543513e+002,9.922072e-003,0.000000e+000,3,9.905248e-001,0.000000e+000,,,,,,,,,,,,,,32,1,4.000000e+000,1.097702e+000,0.000000e+000,0,,0,
1578346681.987,,0.000000e+000,2.494159e+002,9.843878e-003,0.000000e+000,3,9.901061e-001,0.000000e+000,,,,,,,,,,,,,,32,1,4.000000e+000,1.056595e+000,0.000000e+000,0,,0,
1578346750.327,,0.000000e+000,2.443773e+002,9.756159e-003,0.000000e+000,3,9.903454e-001,0.000000e+000,,,,,,,,,,,,,,32,1,4.000000e+000,1.054901e+000,0.000000e+000,0,,0,
1578346815.977,,0.000000e+000,2.394573e+002,9.669666e-003,0.000000e+000,3,9.906976e-001,0.000000e+000,,,,,,,,,,,,,,32,1,4.000000e+000,1.033005e+000,0.000000e+000,0,,0,
1578346880.077,,0.000000e+000,2.344442e+002,9.578248e-003,0.000000e+000,3,9.907485e-001,0.000000e+000,,,,,,,,,,,,,,32,1,4.000000e+000,1.064102e+000,0.000000e+000,0,,0,
1578346942.357,,0.000000e+000,2.293737e+002,9.478775e-003,0.000000e+000,3,9.906242e-001,0.000000e+000,,,,,,,,,,,,,,32,1,4.000000e+000,1.011307e+000,0.000000e+000,0,,0,
1578347004.397,,0.000000e+000,2.243972e+002,9.375635e-003,0.000000e+000,3,9.902505e-001,0.000000e+000,,,,,,,,,,,,,,32,1,4.000000e+000,1.203705e+000,0.000000e+000,0,,0,
1578347064.607,,0.000000e+000,2.193751e+002,9.269681e-003,0.000000e+000,3,9.898838e-001,0.000000e+000,,,,,,,,,,,,,,32,1,4.000000e+000,1.040298e+000,0.000000e+000,0,,0,
1578347125.747,,0.000000e+000,2.143998e+002,9.155609e-003,0.000000e+000,3,9.894057e-001,0.000000e+000,,,,,,,,,,,,,,32,1,4.000000e+000,1.033890e+000,0.000000e+000,0,,0,
1578347186.397,,0.000000e+000,2.094097e+002,9.033988e-003,0.000000e+000,3,9.900535e-001,0.000000e+000,,,,,,,,,,,,,,32,1,4.000000e+000,1.112701e+000,0.000000e+000,0,,0,
1578347247.457,,0.000000e+000,2.043530e+002,8.906046e-003,0.000000e+000,3,9.897908e-001,0.000000e+000,,,,,,,,,,,,,,32,1,4.000000e+000,1.145798e+000,0.000000e+000,0,,0,
1578347309.238,,0.000000e+000,1.993030e+002,8.764910e-003,0.000000e+000,3,9.897060e-001,0.000000e+000,,,,,,,,,,,,,,32,1,4.000000e+000,1.159805e+000,0.000000e+000,0,,0,
1578347368.478,,0.000000e+000,1.943773e+002,8.615535e-003,0.000000e+000,3,9.895136e-001,0.000000e+000,,,,,,,,,,,,,,32,1,4.000000e+000,1.138397e+000,0.000000e+000,0,,0,
1578347428.118,,0.000000e+000,1.893535e+002,8.462168e-003,0.000000e+000,3,9.891569e-001,0.000000e+000,,,,,,,,,,,,,,32,1,4.000000e+000,1.065796e+000,0.000000e+000,0,,0,
1578347487.718,,0.000000e+000,1.843828e+002,8.294477e-003,0.000000e+000,3,9.888982e-001,0.000000e+000,,,,,,,,,,,,,,32,1,4.000000e+000,9.851990e-001,0.000000e+000,0,,0,
1578347547.648,,0.000000e+000,1.793810e+002,8.108674e-003,0.000000e+000,3,9.891478e-001,0.000000e+000,,,,,,,,,,,,,,32,1,4.000000e+000,9.963074e-001,0.000000e+000,0,,0,
1578347609.358,,0.000000e+000,1.742288e+002,7.907518e-003,0.000000e+000,3,9.893335e-001,0.000000e+000,,,,,,,,,,,,,,32,1,4.000000e+000,1.193008e+000,0.000000e+000,0,,0,
1578347679.498,,0.000000e+000,1.682950e+002,7.715263e-003,0.000000e+000,3,9.893807e-001,0.000000e+000,,,,,,,,,,,,,,32,1,4.000000e+000,8.563080e-001,0.000000e+000,0,,0,
1578347726.428,,0.000000e+000,1.644353e+002,7.473953e-003,0.000000e+000,3,9.890544e-001,0.000000e+000,,,,,,,,,,,,,,32,1,4.000000e+000,1.011688e+000,0.000000e+000,0,,0,
1578347788.148,,0.000000e+000,1.592186e+002,7.121284e-003,0.000000e+000,3,9.906103e-001,0.000000e+000,,,,,,,,,,,,,,32,1,4.000000e+000,1.024399e+000,0.000000e+000,0,,0,
1578347844.958,,0.000000e+000,1.544681e+002,6.935791e-003,0.000000e+000,3,9.888045e-001,0.000000e+000,,,,,,,,,,,,,,32,1,4.000000e+000,1.037399e+000,0.000000e+000,0,,0,
1578347903.928,,0.000000e+000,1.494493e+002,6.629958e-003,0.000000e+000,3,9.884864e-001,0.000000e+000,,,,,,,,,,,,,,32,1,4.000000e+000,1.052994e+000,0.000000e+000,0,,0,
1578347963.888,,0.000000e+000,1.443406e+002,6.275995e-003,0.000000e+000,3,9.885522e-001,0.000000e+000,,,,,,,,,,,,,,32,1,4.000000e+000,1.271103e+000,0.000000e+000,0,,0,
1578348021.229,,0.000000e+000,1.393803e+002,5.899387e-003,0.000000e+000,3,9.888150e-001,0.000000e+000,,,,,,,,,,,,,,32,1,4.000000e+000,9.741058e-001,0.000000e+000,0,,0,
1578348078.449,,0.000000e+000,1.344549e+002,5.473680e-003,0.000000e+000,3,9.887190e-001,0.000000e+000,,,,,,,,,,,,,,32,1,4.000000e+000,1.086594e+000,0.000000e+000,0,,0,
1578348137.749,,0.000000e+000,1.293354e+002,4.971566e-003,0.000000e+000,3,9.885474e-001,0.000000e+000,,,,,,,,,,,,,,32,1,4.000000e+000,1.216888e+000,0.000000e+000,0,,0,
1578348194.779,,0.000000e+000,1.244341e+002,4.435305e-003,0.000000e+000,3,9.885783e-001,0.000000e+000,,,,,,,,,,,,,,32,1,4.000000e+000,1.108200e+000,0.000000e+000,0,,0,
1578348252.649,,0.000000e+000,1.193635e+002,3.843613e-003,0.000000e+000,3,9.884654e-001,0.000000e+000,,,,,,,,,,,,,,32,1,4.000000e+000,1.110199e+000,0.000000e+000,0,,0,
1578348309.429,,0.000000e+000,1.143018e+002,3.252586e-003,0.000000e+000,3,9.882933e-001,0.000000e+000,,,,,,,,,,,,,,32,1,4.000000e+000,1.136299e+000,0.000000e+000,0,,0,
1578348380.189,,0.000000e+000,1.081303e+002,2.723930e-003,0.000000e+000,3,9.897395e-001,0.000000e+000,,,,,,,,,,,,,,32,1,4.000000e+000,1.032700e+000,0.000000e+000,0,,0,
1578348420.929,,0.000000e+000,1.043861e+002,2.343039e-003,0.000000e+000,3,9.741663e-001,0.000000e+000,,,,,,,,,,,,,,32,1,4.000000e+000,1.185699e+000,0.000000e+000,0,,0,
1578348474.769,,0.000000e+000,9.941537e+001,1.876494e-003,0.000000e+000,3,9.888451e-001,0.000000e+000,,,,,,,,,,,,,,32,1,4.000000e+000,1.131020e+000,0.000000e+000,0,,0,
1578348528.999,,0.000000e+000,9.437267e+001,1.580129e-003,0.000000e+000,3,9.886186e-001,0.000000e+000,,,,,,,,,,,,,,32,1,4.000000e+000,1.199043e+000,0.000000e+000,0,,0,
1578348594.809,,0.000000e+000,8.805898e+001,1.355344e-003,0.000000e+000,3,9.902430e-001,0.000000e+000,,,,,,,,,,,,,,32,1,4.000000e+000,1.028114e+000,0.000000e+000,0,,0,
1578348633.229,,0.000000e+000,8.440747e+001,1.194121e-003,0.000000e+000,3,9.897132e-001,0.000000e+000,,,,,,,,,,,,,,32,1,4.000000e+000,1.183525e+000,0.000000e+000,0,,0,
1578348684.000,,0.000000e+000,7.938248e+001,1.082624e-003,0.000000e+000,3,9.903544e-001,0.000000e+000,,,,,,,,,,,,,,32,1,4.000000e+000,1.206108e+000,0.000000e+000,0,,0,
1578348735.370,,0.000000e+000,7.427306e+001,1.010931e-003,0.000000e+000,3,9.908494e-001,0.000000e+000,,,,,,,,,,,,,,32,1,4.000000e+000,1.239586e+000,0.000000e+000,0,,0,
1578348787.360,,0.000000e+000,6.926291e+001,9.677759e-004,0.000000e+000,3,9.908007e-001,0.000000e+000,,,,,,,,,,,,,,32,1,4.000000e+000,1.288292e+000,0.000000e+000,0,,0,
1578348832.520,,0.000000e+000,6.437163e+001,9.416103e-004,0.000000e+000,3,9.915664e-001,0.000000e+000,,,,,,,,,,,,,,32,1,4.000000e+000,1.249184e+000,0.000000e+000,0,,0,
1578348879.570,,0.000000e+000,5.931606e+001,9.272882e-004,0.000000e+000,3,9.916658e-001,0.000000e+000,,,,,,,,,,,,,,32,1,4.000000e+000,1.362610e+000,0.000000e+000,0,,0,
1578348928.480,,0.000000e+000,5.431928e+001,9.216958e-004,0.000000e+000,3,9.915807e-001,0.000000e+000,,,,,,,,,,,,,,32,1,4.000000e+000,1.178219e+000,0.000000e+000,0,,0,
1578348978.800,,0.000000e+000,4.938036e+001,9.217188e-004,0.000000e+000,3,9.918877e-001,0.000000e+000,,,,,,,,,,,,,,32,1,4.000000e+000,1.226910e+000,0.000000e+000,0,,0,
1578349029.310,,0.000000e+000,4.438766e+001,9.244037e-004,0.000000e+000,3,9.918756e-001,0.000000e+000,,,,,,,,,,,,,,32,1,4.000000e+000,1.174080e+000,0.000000e+000,0,,0,
1578349078.740,,0.000000e+000,3.937904e+001,9.287922e-004,0.000000e+000,3,9.916989e-001,0.000000e+000,,,,,,,,,,,,,,32,1,4.000000e+000,1.172562e+000,0.000000e+000,0,,0,
1578349126.170,,0.000000e+000,3.429623e+001,9.344349e-004,0.000000e+000,3,9.915846e-001,0.000000e+000,,,,,,,,,,,,,,32,1,4.000000e+000,1.157330e+000,0.000000e+000,0,,0,
1578349170.330,,0.000000e+000,2.931416e+001,9.401095e-004,0.000000e+000,3,9.916284e-001,0.000000e+000,,,,,,,,,,,,,,32,1,4.000000e+000,1.280519e+000,0.000000e+000,0,,0,
1578349213.500,,0.000000e+000,2.396601e+001,9.467466e-004,0.000000e+000,3,9.918965e-001,0.000000e+000,,,,,,,,,,,,,,32,1,4.000000e+000,1.589649e+000,0.000000e+000,0,,0,
1578349271.570,,0.000000e+000,1.953677e+001,9.512253e-004,0.000000e+000,3,9.918398e-001,0.000000e+000,,,,,,,,,,,,,,32,1,4.000000e+000,8.498516e-001,0.000000e+000,0,,0,
1578349328.960,,0.000000e+000,1.406744e+001,9.547234e-004,0.000000e+000,3,9.917538e-001,0.000000e+000,,,,,,,,,,,,,,32,1,4.000000e+000,1.797421e+000,0.000000e+000,0,,0,
1578350169.312,,0.000000e+000,1.000977e+001,9.560166e-004,0.000000e+000,3,9.918025e-001,0.000000e+000,,,,,,,,,,,,,,32,1,4.000000e+000,7.100105e-003,0.000000e+000,0,,0,
1578350240.282,,0.000000e+000,1.003754e+001,9.559632e-004,0.000000e+000,3,9.916115e-001,0.000000e+000,,,,,,,,,,,,,,32,1,4.000000e+000,4.759789e-003,0.000000e+000,0,,0,
1578350320.852,,0.000000e+000,1.555721e+001,9.539998e-004,0.000000e+000,3,9.919219e-001,0.000000e+000,,,,,,,,,,,,,,32,1,4.000000e+000,9.086714e-001,0.000000e+000,0,,0,
1578350381.272,,0.000000e+000,2.054920e+001,9.502081e-004,0.000000e+000,3,9.914214e-001,0.000000e+000,,,,,,,,,,,,,,32,1,4.000000e+000,1.004539e+000,0.000000e+000,0,,0,
1578350442.082,,0.000000e+000,2.560036e+001,9.448529e-004,0.000000e+000,3,9.915549e-001,0.000000e+000,,,,,,,,,,,,,,32,1,4.000000e+000,8.971500e-001,0.000000e+000,0,,0,
1578350501.802,,0.000000e+000,3.051431e+001,9.387637e-004,0.000000e+000,3,9.913555e-001,0.000000e+000,,,,,,,,,,,,,,32,1,4.000000e+000,8.583488e-001,0.000000e+000,0,,0,
1578350562.752,,0.000000e+000,3.551022e+001,9.321853e-004,0.000000e+000,3,9.913633e-001,0.000000e+000,,,,,,,,,,,,,,32,1,4.000000e+000,8.335915e-001,0.000000e+000,0,,0,
1578350624.312,,0.000000e+000,4.060329e+001,9.274216e-004,0.000000e+000,3,9.914780e-001,0.000000e+000,,,,,,,,,,,,,,32,1,4.000000e+000,9.688721e-001,0.000000e+000,0,,0,
1578350684.532,,0.000000e+000,4.547474e+001,9.231198e-004,0.000000e+000,3,9.913489e-001,0.000000e+000,,,,,,,,,,,,,,32,1,4.000000e+000,8.674469e-001,0.000000e+000,0,,0,
1578350745.832,,0.000000e+000,5.064262e+001,9.203870e-004,0.000000e+000,3,9.916661e-001,0.000000e+000,,,,,,,,,,,,,,32,1,4.000000e+000,9.368401e-001,0.000000e+000,0,,0,
1578350804.902,,0.000000e+000,5.558937e+001,9.220489e-004,0.000000e+000,3,9.916234e-001,0.000000e+000,,,,,,,,,,,,,,32,1,4.000000e+000,9.988594e-001,0.000000e+000,0,,0,
1578350865.443,,0.000000e+000,6.052509e+001,9.300181e-004,0.000000e+000,3,9.913214e-001,0.000000e+000,,,,,,,,,,,,,,32,1,4.000000e+000,9.539299e-001,0.000000e+000,0,,0,
1578350925.153,,0.000000e+000,6.555116e+001,9.478673e-004,0.000000e+000,3,9.911001e-001,0.000000e+000,,,,,,,,,,,,,,32,1,4.000000e+000,9.501801e-001,0.000000e+000,0,,0,
1578350986.193,,0.000000e+000,7.066505e+001,9.787632e-004,0.000000e+000,3,9.910638e-001,0.000000e+000,,,,,,,,,,,,,,32,1,4.000000e+000,9.405136e-001,0.000000e+000,0,,0,
1578351043.693,,0.000000e+000,7.549958e+001,1.025954e-003,0.000000e+000,3,9.911517e-001,0.000000e+000,,,,,,,,,,,,,,32,1,4.000000e+000,9.939423e-001,0.000000e+000,0,,0,
1578351103.063,,0.000000e+000,8.049782e+001,1.098325e-003,0.000000e+000,3,9.908150e-001,0.000000e+000,,,,,,,,,,,,,,32,1,4.000000e+000,9.063950e-001,0.000000e+000,0,,0,
1578351163.303,,0.000000e+000,8.552322e+001,1.204507e-003,0.000000e+000,3,9.911810e-001,0.000000e+000,,,,,,,,,,,,,,32,1,4.000000e+000,8.876648e-001,0.000000e+000,0,,0,
1578351223.433,,0.000000e+000,9.054607e+001,1.347154e-003,0.000000e+000,3,9.910638e-001,0.000000e+000,,,,,,,,,,,,,,32,1,4.000000e+000,9.345322e-001,0.000000e+000,0,,0,
1578351282.183,,0.000000e+000,9.551020e+001,1.522436e-003,0.000000e+000,3,9.908345e-001,0.000000e+000,,,,,,,,,,,,,,32,1,4.000000e+000,9.574738e-001,0.000000e+000,0,,0,
1578351344.353,,0.000000e+000,1.006357e+002,1.734957e-003,0.000000e+000,3,9.908834e-001,0.000000e+000,,,,,,,,,,,,,,32,1,4.000000e+000,1.011703e+000,0.000000e+000,0,,0,
1578351403.183,,0.000000e+000,1.056130e+002,1.965889e-003,0.000000e+000,3,9.907362e-001,0.000000e+000,,,,,,,,,,,,,,32,1,4.000000e+000,9.225998e-001,0.000000e+000,0,,0,
1578351462.123,,0.000000e+000,1.105574e+002,2.213561e-003,0.000000e+000,3,9.906467e-001,0.000000e+000,,,,,,,,,,,,,,32,1,4.000000e+000,9.755936e-001,0.000000e+000,0,,0,
1578351521.733,,0.000000e+000,1.155100e+002,2.465534e-003,0.000000e+000,3,9.905555e-001,0.000000e+000,,,,,,,,,,,,,,32,1,4.000000e+000,1.006203e+000,0.000000e+000,0,,0,
1578351580.884,,0.000000e+000,1.205150e+002,2.692927e-003,0.000000e+000,3,9.907296e-001,0.000000e+000,,,,,,,,,,,,,,32,1,4.000000e+000,8.327942e-001,0.000000e+000,0,,0,
1578351641.724,,0.000000e+000,1.256093e+002,2.890587e-003,0.000000e+000,3,9.909725e-001,0.000000e+000,,,,,,,,,,,,,,32,1,4.000000e+000,9.043045e-001,0.000000e+000,0,,0,
1578351701.564,,0.000000e+000,1.306419e+002,3.050321e-003,0.000000e+000,3,9.908715e-001,0.000000e+000,,,,,,,,,,,,,,32,1,4.000000e+000,8.614044e-001,0.000000e+000,0,,0,
1578351760.434,,0.000000e+000,1.355036e+002,3.178380e-003,0.000000e+000,3,9.909766e-001,0.000000e+000,,,,,,,,,,,,,,32,1,4.000000e+000,9.214020e-001,0.000000e+000,0,,0,
1578351821.004,,0.000000e+000,1.405441e+002,3.285114e-003,0.000000e+000,3,9.911318e-001,0.000000e+000,,,,,,,,,,,,,,32,1,4.000000e+000,8.519897e-001,0.000000e+000,0,,0,
1578351882.494,,0.000000e+000,1.456794e+002,3.375123e-003,0.000000e+000,3,9.908593e-001,0.000000e+000,,,,,,,,,,,,,,32,1,4.000000e+000,7.511902e-001,0.000000e+000,0,,0,
1578351941.844,,0.000000e+000,1.505877e+002,3.450354e-003,0.000000e+000,3,9.905809e-001,0.000000e+000,,,,,,,,,,,,,,32,1,4.000000e+000,9.636993e-001,0.000000e+000,0,,0,
1578352001.154,,0.000000e+000,1.555578e+002,3.515560e-003,0.000000e+000,3,9.901176e-001,0.000000e+000,,,,,,,,,,,,,,32,1,4.000000e+000,9.490967e-001,0.000000e+000,0,,0,
1578352061.354,,0.000000e+000,1.606387e+002,3.570482e-003,0.000000e+000,3,9.909002e-001,0.000000e+000,,,,,,,,,,,,,,32,1,4.000000e+000,9.380035e-001,0.000000e+000,0,,0,
1578352119.704,,0.000000e+000,1.654973e+002,3.619371e-003,0.000000e+000,3,9.909993e-001,0.000000e+000,,,,,,,,,,,,,,32,1,4.000000e+000,9.340973e-001,0.000000e+000,0,,0,
1578352179.834,,0.000000e+000,1.704962e+002,3.662550e-003,0.000000e+000,3,9.910685e-001,0.000000e+000,,,,,,,,,,,,,,32,1,4.000000e+000,9.169006e-001,0.000000e+000,0,,0,
1578352241.244,,0.000000e+000,1.755760e+002,3.700205e-003,0.000000e+000,3,9.905123e-001,0.000000e+000,,,,,,,,,,,,,,32,1,4.000000e+000,9.890900e-001,0.000000e+000,0,,0,
1578352300.325,,0.000000e+000,1.805789e+002,3.731630e-003,0.000000e+000,3,9.905789e-001,0.000000e+000,,,,,,,,,,,,,,32,1,4.000000e+000,9.810028e-001,0.000000e+000,0,,0,
1578352359.925,,0.000000e+000,1.855211e+002,3.761921e-003,0.000000e+000,3,9.907064e-001,0.000000e+000,,,,,,,,,,,,,,32,1,4.000000e+000,8.159943e-001,0.000000e+000,0,,0,
1578352420.685,,0.000000e+000,1.905658e+002,3.786740e-003,0.000000e+000,3,9.907604e-001,0.000000e+000,,,,,,,,,,,,,,32,1,4.000000e+000,1.054108e+000,0.000000e+000,0,,0,
1578352479.445,,0.000000e+000,1.954863e+002,3.808488e-003,0.000000e+000,3,9.912340e-001,0.000000e+000,,,,,,,,,,,,,,32,1,4.000000e+000,9.642944e-001,0.000000e+000,0,,0,
1578352539.515,,0.000000e+000,2.005427e+002,3.828573e-003,0.000000e+000,3,9.911253e-001,0.000000e+000,,,,,,,,,,,,,,32,1,4.000000e+000,8.632050e-001,0.000000e+000,0,,0,
1578352600.605,,0.000000e+000,2.056035e+002,3.845291e-003,0.000000e+000,3,9.911287e-001,0.000000e+000,,,,,,,,,,,,,,32,1,4.000000e+000,1.031799e+000,0.000000e+000,0,,0,
1578352659.385,,0.000000e+000,2.105018e+002,3.858609e-003,0.000000e+000,3,9.911453e-001,0.000000e+000,,,,,,,,,,,,,,32,1,4.000000e+000,9.537964e-001,0.000000e+000,0,,0,
1578352720.405,,0.000000e+000,2.155079e+002,3.872531e-003,0.000000e+000,3,9.907894e-001,0.000000e+000,,,,,,,,,,,,,,32,1,4.000000e+000,9.358063e-001,0.000000e+000,0,,0,
1578352780.315,,0.000000e+000,2.206020e+002,3.884087e-003,0.000000e+000,3,9.907856e-001,0.000000e+000,,,,,,,,,,,,,,32,1,4.000000e+000,1.011200e+000,0.000000e+000,0,,0,
1578352838.935,,0.000000e+000,2.255094e+002,3.891562e-003,0.000000e+000,3,9.913245e-001,0.000000e+000,,,,,,,,,,,,,,32,1,4.000000e+000,9.197998e-001,0.000000e+000,0,,0,
1578352899.625,,0.000000e+000,2.304991e+002,3.899699e-003,0.000000e+000,3,9.914050e-001,0.000000e+000,,,,,,,,,,,,,,32,1,4.000000e+000,9.241028e-001,0.000000e+000,0,,0,
1578352960.905,,0.000000e+000,2.356689e+002,3.906705e-003,0.000000e+000,3,9.914876e-001,0.000000e+000,,,,,,,,,,,,,,32,1,4.000000e+000,1.001404e+000,0.000000e+000,0,,0,
1578353018.786,,0.000000e+000,2.404992e+002,3.910401e-003,0.000000e+000,3,9.914812e-001,0.000000e+000,,,,,,,,,,,,,,32,1,4.000000e+000,9.365997e-001,0.000000e+000,0,,0,
1578353079.416,,0.000000e+000,2.455360e+002,3.913053e-003,0.000000e+000,3,9.914963e-001,0.000000e+000,,,,,,,,,,,,,,32,1,4.000000e+000,9.850922e-001,0.000000e+000,0,,0,
1578353140.256,,0.000000e+000,2.505905e+002,3.920378e-003,0.000000e+000,3,9.913670e-001,0.000000e+000,,,,,,,,,,,,,,32,1,4.000000e+000,9.835052e-001,0.000000e+000,0,,0,
1578353199.766,,0.000000e+000,2.555930e+002,3.918315e-003,0.000000e+000,3,9.917492e-001,0.000000e+000,,,,,,,,,,,,,,32,1,4.000000e+000,9.144897e-001,0.000000e+000,0,,0,
1578353258.956,,0.000000e+000,2.605255e+002,3.917636e-003,0.000000e+000,3,9.919980e-001,0.000000e+000,,,,,,,,,,,,,,32,1,4.000000e+000,9.044800e-001,0.000000e+000,0,,0,
1578353319.936,,0.000000e+000,2.655535e+002,3.918196e-003,0.000000e+000,3,9.923180e-001,0.000000e+000,,,,,,,,,,,,,,32,1,4.000000e+000,8.940735e-001,0.000000e+000,0,,0,
1578353379.266,,0.000000e+000,2.705320e+002,3.914630e-003,0.000000e+000,3,9.925479e-001,0.000000e+000,,,,,,,,,,,,,,32,1,4.000000e+000,9.656982e-001,0.000000e+000,0,,0,
1578353439.776,,0.000000e+000,2.755523e+002,3.910051e-003,0.000000e+000,3,9.926745e-001,0.000000e+000,,,,,,,,,,,,,,32,1,4.000000e+000,8.779907e-001,0.000000e+000,0,,0,
1578353499.706,,0.000000e+000,2.806013e+002,3.905658e-003,0.000000e+000,3,9.926430e-001,0.000000e+000,,,,,,,,,,,,,,32,1,4.000000e+000,9.379272e-001,0.000000e+000,0,,0,
1578353558.726,,0.000000e+000,2.855287e+002,3.900490e-003,0.000000e+000,3,9.926426e-001,0.000000e+000,,,,,,,,,,,,,,32,1,4.000000e+000,9.589233e-001,0.000000e+000,0,,0,
1578353619.066,,0.000000e+000,2.905272e+002,3.891680e-003,0.000000e+000,3,9.929873e-001,0.000000e+000,,,,,,,,,,,,,,32,1,4.000000e+000,1.007996e+000,0.000000e+000,0,,0,
1578353680.596,,0.000000e+000,2.956594e+002,3.871642e-003,0.000000e+000,3,9.865468e-001,0.000000e+000,,,,,,,,,,,,,,32,1,4.000000e+000,9.580994e-001,0.000000e+000,0,,0,
1578353975.707,,0.000000e+000,3.000265e+002,3.872497e-003,0.000000e+000,3,9.931774e-001,0.000000e+000,,,,,,,,,,,,,,32,1,4.000000e+000,0.000000e+000,0.000000e+000,0,,0,