File: data/Rock_mag/2020_IRM_data_files/Raw_data/MPMS-XL/data/bg_rockmag_FC-ZFC-RTSIRM-10K.dc.dc.dat
[Header]
TITLE,MPMS DC Measurement
BYAPP,MPMS Measurement,2.1,Summary
FILEOPENTIME, 1578764083.179000 1/11/2020, 11:34:43 AM

INFO, APPNAME, MPMS MultiVu Application, Revision 1.61,  Build 082

INFO, NAME, bg_rockmag
INFO, WEIGHT, 1.000
INFO, AREA, 1.000
INFO, LENGTH, 1.000
INFO, SHAPE, 0
INFO, COMMENT,
INFO, SEQUENCE FILE: FC-ZFC LTSIRM and RTSIRM LTD 10K.seq


INFO, BACKGROUND DATA FILE:, None


STARTUPAXIS,X,4,LINEAR,AUTO,0.000000,0.000000
STARTUPAXIS,Y1,5,LINEAR,AUTO,0.000000,0.000000


STARTUPGROUP,Longitudinal
FIELDGROUP,Longitudinal,1,2,3,4,5,6,7,8,9,15,16,17,18,27,28
FIELDGROUP,Transverse,1,2,3,4,10,11,12,13,14,19,20,21,22,27,28

PLOT_APPEARANCE,ALL,HORZ_GRID_ON,VERT_GRID_ON,MARKERS_AND_LINES

[Data]
Time,Comment,Field (Oe),Temperature (K),Long Moment (emu),Long Scan Std Dev,Long Algorithm,Long Reg Fit,Long Percent Error (%),Trans Moment (emu),Trans Scan Std Dev,Trans Algorithm,Trans Reg Fit,Trans Percent Error (%),Long Moment [w/o ABS] (emu),Long Scan Std Dev [w/o ABS],Long Reg Fit [w/o ABS],Long Percent Error [w/o ABS] (%),Trans Moment [w/o ABS] (emu),Trans Scan Std Dev [w/o ABS],Trans Reg Fit [w/o ABS],Trans Percent Error [w/o ABS] (%),Points per Scan,Scans per Measurement,Scan Length (cm),Delta Temp (K),Rot Position (deg),Error,EC Comp. Running,Using ABS,
1578764083.179,,0.000000e+000,9.975760e+000,4.160922e-003,0.000000e+000,3,9.759156e-001,0.000000e+000,,,,,,,,,,,,,,32,1,4.000000e+000,5.337715e-003,0.000000e+000,0,,0,
1578764164.629,,0.000000e+000,1.559760e+001,4.140564e-003,0.000000e+000,3,9.755974e-001,0.000000e+000,,,,,,,,,,,,,,32,1,4.000000e+000,9.111099e-001,0.000000e+000,0,,0,
1578764224.379,,0.000000e+000,2.055867e+001,3.982852e-003,0.000000e+000,3,9.755079e-001,0.000000e+000,,,,,,,,,,,,,,32,1,4.000000e+000,9.349594e-001,0.000000e+000,0,,0,
1578764286.559,,0.000000e+000,2.566235e+001,3.811654e-003,0.000000e+000,3,9.754910e-001,0.000000e+000,,,,,,,,,,,,,,32,1,4.000000e+000,8.967209e-001,0.000000e+000,0,,0,
1578764345.469,,0.000000e+000,3.054672e+001,3.660858e-003,0.000000e+000,3,9.754682e-001,0.000000e+000,,,,,,,,,,,,,,32,1,4.000000e+000,9.390392e-001,0.000000e+000,0,,0,
1578764405.480,,0.000000e+000,3.545885e+001,3.512417e-003,0.000000e+000,3,9.751584e-001,0.000000e+000,,,,,,,,,,,,,,32,1,4.000000e+000,9.115906e-001,0.000000e+000,0,,0,
1578764467.660,,0.000000e+000,4.058803e+001,3.373207e-003,0.000000e+000,3,9.756112e-001,0.000000e+000,,,,,,,,,,,,,,32,1,4.000000e+000,9.759102e-001,0.000000e+000,0,,0,
1578764527.400,,0.000000e+000,4.549895e+001,3.268827e-003,0.000000e+000,3,9.750906e-001,0.000000e+000,,,,,,,,,,,,,,32,1,4.000000e+000,9.527473e-001,0.000000e+000,0,,0,
1578764587.970,,0.000000e+000,5.048402e+001,3.187339e-003,0.000000e+000,3,9.751313e-001,0.000000e+000,,,,,,,,,,,,,,32,1,4.000000e+000,9.259911e-001,0.000000e+000,0,,0,
1578764648.640,,0.000000e+000,5.556205e+001,3.123684e-003,0.000000e+000,3,9.755329e-001,0.000000e+000,,,,,,,,,,,,,,32,1,4.000000e+000,1.018082e+000,0.000000e+000,0,,0,
1578764707.690,,0.000000e+000,6.054809e+001,3.074044e-003,0.000000e+000,3,9.752564e-001,0.000000e+000,,,,,,,,,,,,,,32,1,4.000000e+000,8.921089e-001,0.000000e+000,0,,0,
1578764767.940,,0.000000e+000,6.552964e+001,3.025769e-003,0.000000e+000,3,9.754862e-001,0.000000e+000,,,,,,,,,,,,,,32,1,4.000000e+000,9.604034e-001,0.000000e+000,0,,0,
1578764829.010,,0.000000e+000,7.056752e+001,2.984197e-003,0.000000e+000,3,9.757408e-001,0.000000e+000,,,,,,,,,,,,,,32,1,4.000000e+000,9.566956e-001,0.000000e+000,0,,0,
1578764888.130,,0.000000e+000,7.556573e+001,2.946564e-003,0.000000e+000,3,9.748758e-001,0.000000e+000,,,,,,,,,,,,,,32,1,4.000000e+000,1.007080e+000,0.000000e+000,0,,0,
1578764947.120,,0.000000e+000,8.052420e+001,2.909053e-003,0.000000e+000,3,9.750253e-001,0.000000e+000,,,,,,,,,,,,,,32,1,4.000000e+000,9.848633e-001,0.000000e+000,0,,0,
1578765008.030,,0.000000e+000,8.565549e+001,2.870389e-003,0.000000e+000,3,9.758604e-001,0.000000e+000,,,,,,,,,,,,,,32,1,4.000000e+000,9.973755e-001,0.000000e+000,0,,0,
1578765066.110,,0.000000e+000,9.052698e+001,2.836322e-003,0.000000e+000,3,9.753894e-001,0.000000e+000,,,,,,,,,,,,,,32,1,4.000000e+000,9.597626e-001,0.000000e+000,0,,0,
1578765126.001,,0.000000e+000,9.549606e+001,2.801825e-003,0.000000e+000,3,9.752889e-001,0.000000e+000,,,,,,,,,,,,,,32,1,4.000000e+000,9.431381e-001,0.000000e+000,0,,0,
1578765186.261,,0.000000e+000,1.004616e+002,2.767693e-003,0.000000e+000,3,9.754184e-001,0.000000e+000,,,,,,,,,,,,,,32,1,4.000000e+000,8.470001e-001,0.000000e+000,0,,0,
1578765246.371,,0.000000e+000,1.055652e+002,2.734032e-003,0.000000e+000,3,9.754712e-001,0.000000e+000,,,,,,,,,,,,,,32,1,4.000000e+000,1.026596e+000,0.000000e+000,0,,0,
1578765305.491,,0.000000e+000,1.104847e+002,2.698903e-003,0.000000e+000,3,9.754156e-001,0.000000e+000,,,,,,,,,,,,,,32,1,4.000000e+000,9.381943e-001,0.000000e+000,0,,0,
1578765366.821,,0.000000e+000,1.155860e+002,2.758467e-003,0.000000e+000,3,9.713827e-001,0.000000e+000,,,,,,,,,,,,,,32,1,4.000000e+000,9.926987e-001,0.000000e+000,0,,0,
1578765424.521,,0.000000e+000,1.205257e+002,2.632041e-003,0.000000e+000,3,9.752812e-001,0.000000e+000,,,,,,,,,,,,,,32,1,4.000000e+000,8.754044e-001,0.000000e+000,0,,0,
1578765484.541,,0.000000e+000,1.255034e+002,2.595889e-003,0.000000e+000,3,9.754981e-001,0.000000e+000,,,,,,,,,,,,,,32,1,4.000000e+000,8.857956e-001,0.000000e+000,0,,0,
1578765545.781,,0.000000e+000,1.305618e+002,2.559818e-003,0.000000e+000,3,9.758375e-001,0.000000e+000,,,,,,,,,,,,,,32,1,4.000000e+000,7.742920e-001,0.000000e+000,0,,0,
1578765603.981,,0.000000e+000,1.354376e+002,2.526689e-003,0.000000e+000,3,9.757165e-001,0.000000e+000,,,,,,,,,,,,,,32,1,4.000000e+000,8.679962e-001,0.000000e+000,0,,0,
1578765664.061,,0.000000e+000,1.405300e+002,2.490446e-003,0.000000e+000,3,9.758837e-001,0.000000e+000,,,,,,,,,,,,,,32,1,4.000000e+000,8.518066e-001,0.000000e+000,0,,0,
1578765725.131,,0.000000e+000,1.455894e+002,2.452934e-003,0.000000e+000,3,9.760283e-001,0.000000e+000,,,,,,,,,,,,,,32,1,4.000000e+000,7.803040e-001,0.000000e+000,0,,0,
1578765785.561,,0.000000e+000,1.506474e+002,2.415062e-003,0.000000e+000,3,9.759447e-001,0.000000e+000,,,,,,,,,,,,,,32,1,4.000000e+000,9.245911e-001,0.000000e+000,0,,0,
1578765843.832,,0.000000e+000,1.554879e+002,2.378544e-003,0.000000e+000,3,9.758021e-001,0.000000e+000,,,,,,,,,,,,,,32,1,4.000000e+000,8.515015e-001,0.000000e+000,0,,0,
1578765904.912,,0.000000e+000,1.605360e+002,2.338580e-003,0.000000e+000,3,9.760833e-001,0.000000e+000,,,,,,,,,,,,,,32,1,4.000000e+000,9.369965e-001,0.000000e+000,0,,0,
1578765963.772,,0.000000e+000,1.655230e+002,2.298128e-003,0.000000e+000,3,9.760557e-001,0.000000e+000,,,,,,,,,,,,,,32,1,4.000000e+000,8.353119e-001,0.000000e+000,0,,0,
1578766023.362,,0.000000e+000,1.704788e+002,2.276268e-003,0.000000e+000,3,9.384769e-001,0.000000e+000,,,,,,,,,,,,,,32,1,4.000000e+000,9.217987e-001,0.000000e+000,0,,0,
1578766084.182,,0.000000e+000,1.756021e+002,2.213867e-003,0.000000e+000,3,9.760929e-001,0.000000e+000,,,,,,,,,,,,,,32,1,4.000000e+000,9.157104e-001,0.000000e+000,0,,0,
1578766145.112,,0.000000e+000,1.806398e+002,2.169407e-003,0.000000e+000,3,9.762884e-001,0.000000e+000,,,,,,,,,,,,,,32,1,4.000000e+000,9.815979e-001,0.000000e+000,0,,0,
1578766202.822,,0.000000e+000,1.854601e+002,2.125100e-003,0.000000e+000,3,9.761734e-001,0.000000e+000,,,,,,,,,,,,,,32,1,4.000000e+000,8.912048e-001,0.000000e+000,0,,0,
1578766264.382,,0.000000e+000,1.905901e+002,2.079205e-003,0.000000e+000,3,9.762656e-001,0.000000e+000,,,,,,,,,,,,,,32,1,4.000000e+000,9.684906e-001,0.000000e+000,0,,0,
1578766324.472,,0.000000e+000,1.956374e+002,2.032069e-003,0.000000e+000,3,9.762399e-001,0.000000e+000,,,,,,,,,,,,,,32,1,4.000000e+000,9.591980e-001,0.000000e+000,0,,0,
1578766382.922,,0.000000e+000,2.004890e+002,1.984280e-003,0.000000e+000,3,9.765798e-001,0.000000e+000,,,,,,,,,,,,,,32,1,4.000000e+000,9.570923e-001,0.000000e+000,0,,0,
1578766444.232,,0.000000e+000,2.056281e+002,1.934454e-003,0.000000e+000,3,9.762189e-001,0.000000e+000,,,,,,,,,,,,,,32,1,4.000000e+000,9.544067e-001,0.000000e+000,0,,0,
1578766502.862,,0.000000e+000,2.104908e+002,1.886096e-003,0.000000e+000,3,9.767988e-001,0.000000e+000,,,,,,,,,,,,,,32,1,4.000000e+000,9.463043e-001,0.000000e+000,0,,0,
1578766563.583,,0.000000e+000,2.155270e+002,1.835928e-003,0.000000e+000,3,9.767342e-001,0.000000e+000,,,,,,,,,,,,,,32,1,4.000000e+000,8.509064e-001,0.000000e+000,0,,0,
1578766624.493,,0.000000e+000,2.206664e+002,1.785968e-003,0.000000e+000,3,9.764015e-001,0.000000e+000,,,,,,,,,,,,,,32,1,4.000000e+000,8.661041e-001,0.000000e+000,0,,0,
1578766683.033,,0.000000e+000,2.255307e+002,1.736796e-003,0.000000e+000,3,9.765645e-001,0.000000e+000,,,,,,,,,,,,,,32,1,4.000000e+000,1.012787e+000,0.000000e+000,0,,0,
1578766743.643,,0.000000e+000,2.305653e+002,1.685911e-003,0.000000e+000,3,9.766158e-001,0.000000e+000,,,,,,,,,,,,,,32,1,4.000000e+000,1.074295e+000,0.000000e+000,0,,0,
1578766804.593,,0.000000e+000,2.356045e+002,1.635094e-003,0.000000e+000,3,9.769263e-001,0.000000e+000,,,,,,,,,,,,,,32,1,4.000000e+000,9.275055e-001,0.000000e+000,0,,0,
1578766875.103,,0.000000e+000,2.415165e+002,1.576568e-003,0.000000e+000,3,9.767401e-001,0.000000e+000,,,,,,,,,,,,,,32,1,4.000000e+000,1.002090e+000,0.000000e+000,0,,0,
1578766922.463,,0.000000e+000,2.454911e+002,1.536829e-003,0.000000e+000,3,9.771910e-001,0.000000e+000,,,,,,,,,,,,,,32,1,4.000000e+000,9.151001e-001,0.000000e+000,0,,0,
1578766983.613,,0.000000e+000,2.506163e+002,1.486099e-003,0.000000e+000,3,9.771680e-001,0.000000e+000,,,,,,,,,,,,,,32,1,4.000000e+000,9.111938e-001,0.000000e+000,0,,0,
1578767042.733,,0.000000e+000,2.555447e+002,1.437198e-003,0.000000e+000,3,9.770133e-001,0.000000e+000,,,,,,,,,,,,,,32,1,4.000000e+000,9.894867e-001,0.000000e+000,0,,0,
1578767103.843,,0.000000e+000,2.605869e+002,1.387323e-003,0.000000e+000,3,9.772618e-001,0.000000e+000,,,,,,,,,,,,,,32,1,4.000000e+000,8.937988e-001,0.000000e+000,0,,0,
1578767163.983,,0.000000e+000,2.655769e+002,1.337322e-003,0.000000e+000,3,9.776011e-001,0.000000e+000,,,,,,,,,,,,,,32,1,4.000000e+000,9.871826e-001,0.000000e+000,0,,0,
1578767222.393,,0.000000e+000,2.705200e+002,1.290517e-003,0.000000e+000,3,9.772086e-001,0.000000e+000,,,,,,,,,,,,,,32,1,4.000000e+000,9.898071e-001,0.000000e+000,0,,0,
1578767282.754,,0.000000e+000,2.754457e+002,1.241649e-003,0.000000e+000,3,9.777272e-001,0.000000e+000,,,,,,,,,,,,,,32,1,4.000000e+000,8.898926e-001,0.000000e+000,0,,0,
1578767342.934,,0.000000e+000,2.805884e+002,1.193283e-003,0.000000e+000,3,9.779730e-001,0.000000e+000,,,,,,,,,,,,,,32,1,4.000000e+000,9.898987e-001,0.000000e+000,0,,0,
1578767403.804,,0.000000e+000,2.856235e+002,1.145025e-003,0.000000e+000,3,9.778267e-001,0.000000e+000,,,,,,,,,,,,,,32,1,4.000000e+000,1.040588e+000,0.000000e+000,0,,0,
1578767462.164,,0.000000e+000,2.904778e+002,1.100221e-003,0.000000e+000,3,9.781013e-001,0.000000e+000,,,,,,,,,,,,,,32,1,4.000000e+000,7.697144e-001,0.000000e+000,0,,0,
1578767523.224,,0.000000e+000,2.955868e+002,1.053501e-003,0.000000e+000,3,9.784911e-001,0.000000e+000,,,,,,,,,,,,,,32,1,4.000000e+000,9.576111e-001,0.000000e+000,0,,0,
1578767856.634,,0.000000e+000,3.000265e+002,1.174033e-003,0.000000e+000,3,8.573937e-001,0.000000e+000,,,,,,,,,,,,,,32,1,4.000000e+000,0.000000e+000,0.000000e+000,0,,0,
1578772916.891,,0.000000e+000,1.000396e+001,2.664583e-003,0.000000e+000,3,9.751540e-001,0.000000e+000,,,,,,,,,,,,,,32,1,4.000000e+000,1.897240e-002,0.000000e+000,0,,0,
1578772998.572,,0.000000e+000,1.553950e+001,2.641470e-003,0.000000e+000,3,9.755780e-001,0.000000e+000,,,,,,,,,,,,,,32,1,4.000000e+000,8.367395e-001,0.000000e+000,0,,0,
1578773058.132,,0.000000e+000,2.046173e+001,2.541952e-003,0.000000e+000,3,9.757626e-001,0.000000e+000,,,,,,,,,,,,,,32,1,4.000000e+000,9.177704e-001,0.000000e+000,0,,0,
1578773120.682,,0.000000e+000,2.563581e+001,2.457768e-003,0.000000e+000,3,9.762206e-001,0.000000e+000,,,,,,,,,,,,,,32,1,4.000000e+000,8.967896e-001,0.000000e+000,0,,0,
1578773181.302,,0.000000e+000,3.064117e+001,2.394683e-003,0.000000e+000,3,9.756225e-001,0.000000e+000,,,,,,,,,,,,,,32,1,4.000000e+000,1.021311e+000,0.000000e+000,0,,0,
1578773241.232,,0.000000e+000,3.550953e+001,2.339868e-003,0.000000e+000,3,9.756833e-001,0.000000e+000,,,,,,,,,,,,,,32,1,4.000000e+000,9.093399e-001,0.000000e+000,0,,0,
1578773302.752,,0.000000e+000,4.063786e+001,2.286847e-003,0.000000e+000,3,9.759451e-001,0.000000e+000,,,,,,,,,,,,,,32,1,4.000000e+000,9.703217e-001,0.000000e+000,0,,0,
1578773363.442,,0.000000e+000,4.558542e+001,2.242590e-003,0.000000e+000,3,9.754824e-001,0.000000e+000,,,,,,,,,,,,,,32,1,4.000000e+000,1.024242e+000,0.000000e+000,0,,0,
1578773423.262,,0.000000e+000,5.056237e+001,2.201532e-003,0.000000e+000,3,9.757217e-001,0.000000e+000,,,,,,,,,,,,,,32,1,4.000000e+000,9.993210e-001,0.000000e+000,0,,0,
1578773483.642,,0.000000e+000,5.558465e+001,2.162148e-003,0.000000e+000,3,9.758942e-001,0.000000e+000,,,,,,,,,,,,,,32,1,4.000000e+000,9.075584e-001,0.000000e+000,0,,0,
1578773542.632,,0.000000e+000,6.057299e+001,2.128982e-003,0.000000e+000,3,9.757373e-001,0.000000e+000,,,,,,,,,,,,,,32,1,4.000000e+000,9.912491e-001,0.000000e+000,0,,0,
1578773602.732,,0.000000e+000,6.554976e+001,2.098030e-003,0.000000e+000,3,9.756252e-001,0.000000e+000,,,,,,,,,,,,,,32,1,4.000000e+000,8.691635e-001,0.000000e+000,0,,0,
1578773663.592,,0.000000e+000,7.063940e+001,2.066776e-003,0.000000e+000,3,9.757246e-001,0.000000e+000,,,,,,,,,,,,,,32,1,4.000000e+000,9.502106e-001,0.000000e+000,0,,0,
1578773722.873,,0.000000e+000,7.558487e+001,2.043318e-003,0.000000e+000,3,9.754220e-001,0.000000e+000,,,,,,,,,,,,,,32,1,4.000000e+000,1.095764e+000,0.000000e+000,0,,0,
1578773780.823,,0.000000e+000,8.046021e+001,2.183065e-003,0.000000e+000,3,9.382150e-001,0.000000e+000,,,,,,,,,,,,,,32,1,4.000000e+000,9.134216e-001,0.000000e+000,0,,0,
1578773841.993,,0.000000e+000,8.558559e+001,1.991977e-003,0.000000e+000,3,9.760002e-001,0.000000e+000,,,,,,,,,,,,,,32,1,4.000000e+000,9.206619e-001,0.000000e+000,0,,0,
1578773901.003,,0.000000e+000,9.051251e+001,1.970877e-003,0.000000e+000,3,9.756323e-001,0.000000e+000,,,,,,,,,,,,,,32,1,4.000000e+000,9.435120e-001,0.000000e+000,0,,0,
1578773960.073,,0.000000e+000,9.543413e+001,1.949403e-003,0.000000e+000,3,9.752954e-001,0.000000e+000,,,,,,,,,,,,,,32,1,4.000000e+000,8.542099e-001,0.000000e+000,0,,0,
1578774020.543,,0.000000e+000,1.004618e+002,1.926890e-003,0.000000e+000,3,9.755927e-001,0.000000e+000,,,,,,,,,,,,,,32,1,4.000000e+000,8.932037e-001,0.000000e+000,0,,0,
1578774080.783,,0.000000e+000,1.055711e+002,1.906704e-003,0.000000e+000,3,9.758162e-001,0.000000e+000,,,,,,,,,,,,,,32,1,4.000000e+000,9.303970e-001,0.000000e+000,0,,0,
1578774140.283,,0.000000e+000,1.105345e+002,1.886499e-003,0.000000e+000,3,9.755189e-001,0.000000e+000,,,,,,,,,,,,,,32,1,4.000000e+000,9.388962e-001,0.000000e+000,0,,0,
1578774201.123,,0.000000e+000,1.156402e+002,1.865891e-003,0.000000e+000,3,9.760577e-001,0.000000e+000,,,,,,,,,,,,,,32,1,4.000000e+000,9.837036e-001,0.000000e+000,0,,0,
1578774260.503,,0.000000e+000,1.205821e+002,1.847723e-003,0.000000e+000,3,9.754844e-001,0.000000e+000,,,,,,,,,,,,,,32,1,4.000000e+000,1.051407e+000,0.000000e+000,0,,0,
1578774319.723,,0.000000e+000,1.255520e+002,1.828053e-003,0.000000e+000,3,9.760606e-001,0.000000e+000,,,,,,,,,,,,,,32,1,4.000000e+000,8.693008e-001,0.000000e+000,0,,0,
1578774379.543,,0.000000e+000,1.305408e+002,1.807630e-003,0.000000e+000,3,9.763340e-001,0.000000e+000,,,,,,,,,,,,,,32,1,4.000000e+000,9.523010e-001,0.000000e+000,0,,0,
1578774438.864,,0.000000e+000,1.355366e+002,1.789761e-003,0.000000e+000,3,9.761051e-001,0.000000e+000,,,,,,,,,,,,,,32,1,4.000000e+000,9.611969e-001,0.000000e+000,0,,0,
1578774499.764,,0.000000e+000,1.405905e+002,1.770436e-003,0.000000e+000,3,9.761546e-001,0.000000e+000,,,,,,,,,,,,,,32,1,4.000000e+000,1.042694e+000,0.000000e+000,0,,0,
1578774558.804,,0.000000e+000,1.455933e+002,1.751071e-003,0.000000e+000,3,9.765813e-001,0.000000e+000,,,,,,,,,,,,,,32,1,4.000000e+000,8.629913e-001,0.000000e+000,0,,0,
1578774619.964,,0.000000e+000,1.506635e+002,1.731994e-003,0.000000e+000,3,9.763684e-001,0.000000e+000,,,,,,,,,,,,,,32,1,4.000000e+000,9.885101e-001,0.000000e+000,0,,0,
1578774678.064,,0.000000e+000,1.554605e+002,1.714220e-003,0.000000e+000,3,9.762620e-001,0.000000e+000,,,,,,,,,,,,,,32,1,4.000000e+000,8.470001e-001,0.000000e+000,0,,0,
1578774740.404,,0.000000e+000,1.606389e+002,1.693283e-003,0.000000e+000,3,9.767654e-001,0.000000e+000,,,,,,,,,,,,,,32,1,4.000000e+000,1.018494e+000,0.000000e+000,0,,0,
1578774799.444,,0.000000e+000,1.655825e+002,1.674168e-003,0.000000e+000,3,9.765441e-001,0.000000e+000,,,,,,,,,,,,,,32,1,4.000000e+000,1.010406e+000,0.000000e+000,0,,0,
1578774858.884,,0.000000e+000,1.705812e+002,1.655746e-003,0.000000e+000,3,9.761435e-001,0.000000e+000,,,,,,,,,,,,,,32,1,4.000000e+000,9.976044e-001,0.000000e+000,0,,0,
1578774918.014,,0.000000e+000,1.755335e+002,1.634759e-003,0.000000e+000,3,9.766087e-001,0.000000e+000,,,,,,,,,,,,,,32,1,4.000000e+000,8.203888e-001,0.000000e+000,0,,0,
1578774978.224,,0.000000e+000,1.805262e+002,1.614697e-003,0.000000e+000,3,9.765283e-001,0.000000e+000,,,,,,,,,,,,,,32,1,4.000000e+000,9.859009e-001,0.000000e+000,0,,0,
1578775038.554,,0.000000e+000,1.855652e+002,1.593850e-003,0.000000e+000,3,9.765133e-001,0.000000e+000,,,,,,,,,,,,,,32,1,4.000000e+000,9.737091e-001,0.000000e+000,0,,0,
1578775099.854,,0.000000e+000,1.906452e+002,1.573470e-003,0.000000e+000,3,9.763933e-001,0.000000e+000,,,,,,,,,,,,,,32,1,4.000000e+000,9.812927e-001,0.000000e+000,0,,0,
1578775158.365,,0.000000e+000,1.955280e+002,1.552091e-003,0.000000e+000,3,9.765416e-001,0.000000e+000,,,,,,,,,,,,,,32,1,4.000000e+000,9.710999e-001,0.000000e+000,0,,0,
1578775218.025,,0.000000e+000,2.005833e+002,1.530791e-003,0.000000e+000,3,9.767430e-001,0.000000e+000,,,,,,,,,,,,,,32,1,4.000000e+000,8.905029e-001,0.000000e+000,0,,0,
1578775278.895,,0.000000e+000,2.055572e+002,1.509303e-003,0.000000e+000,3,9.765233e-001,0.000000e+000,,,,,,,,,,,,,,32,1,4.000000e+000,8.547974e-001,0.000000e+000,0,,0,
1578775338.625,,0.000000e+000,2.106202e+002,1.487128e-003,0.000000e+000,3,9.766865e-001,0.000000e+000,,,,,,,,,,,,,,32,1,4.000000e+000,9.547882e-001,0.000000e+000,0,,0,
1578775398.025,,0.000000e+000,2.155428e+002,1.465164e-003,0.000000e+000,3,9.768658e-001,0.000000e+000,,,,,,,,,,,,,,32,1,4.000000e+000,9.438934e-001,0.000000e+000,0,,0,
1578775458.255,,0.000000e+000,2.205210e+002,1.443306e-003,0.000000e+000,3,9.768959e-001,0.000000e+000,,,,,,,,,,,,,,32,1,4.000000e+000,9.295959e-001,0.000000e+000,0,,0,
1578775518.585,,0.000000e+000,2.256191e+002,1.420239e-003,0.000000e+000,3,9.768133e-001,0.000000e+000,,,,,,,,,,,,,,32,1,4.000000e+000,9.207001e-001,0.000000e+000,0,,0,
1578775577.335,,0.000000e+000,2.305430e+002,1.396926e-003,0.000000e+000,3,9.772036e-001,0.000000e+000,,,,,,,,,,,,,,32,1,4.000000e+000,9.244995e-001,0.000000e+000,0,,0,
1578775637.835,,0.000000e+000,2.355035e+002,1.373592e-003,0.000000e+000,3,9.769917e-001,0.000000e+000,,,,,,,,,,,,,,32,1,4.000000e+000,9.265900e-001,0.000000e+000,0,,0,
1578775697.285,,0.000000e+000,2.404993e+002,1.349598e-003,0.000000e+000,3,9.771557e-001,0.000000e+000,,,,,,,,,,,,,,32,1,4.000000e+000,9.940033e-001,0.000000e+000,0,,0,
1578775758.255,,0.000000e+000,2.456156e+002,1.323675e-003,0.000000e+000,3,9.776185e-001,0.000000e+000,,,,,,,,,,,,,,32,1,4.000000e+000,9.259949e-001,0.000000e+000,0,,0,
1578775817.675,,0.000000e+000,2.505905e+002,1.298694e-003,0.000000e+000,3,9.774128e-001,0.000000e+000,,,,,,,,,,,,,,32,1,4.000000e+000,9.006958e-001,0.000000e+000,0,,0,
1578775877.126,,0.000000e+000,2.554694e+002,1.272770e-003,0.000000e+000,3,9.771212e-001,0.000000e+000,,,,,,,,,,,,,,32,1,4.000000e+000,9.029083e-001,0.000000e+000,0,,0,
1578775937.506,,0.000000e+000,2.605589e+002,1.245206e-003,0.000000e+000,3,9.776374e-001,0.000000e+000,,,,,,,,,,,,,,32,1,4.000000e+000,8.823853e-001,0.000000e+000,0,,0,
1578775999.676,,0.000000e+000,2.656176e+002,1.216052e-003,0.000000e+000,3,9.775301e-001,0.000000e+000,,,,,,,,,,,,,,32,1,4.000000e+000,9.758911e-001,0.000000e+000,0,,0,
1578776056.736,,0.000000e+000,2.704958e+002,1.188844e-003,0.000000e+000,3,9.775720e-001,0.000000e+000,,,,,,,,,,,,,,32,1,4.000000e+000,9.655151e-001,0.000000e+000,0,,0,
1578776116.226,,0.000000e+000,2.754835e+002,1.159539e-003,0.000000e+000,3,9.781496e-001,0.000000e+000,,,,,,,,,,,,,,32,1,4.000000e+000,9.653015e-001,0.000000e+000,0,,0,
1578776177.176,,0.000000e+000,2.805231e+002,1.128924e-003,0.000000e+000,3,9.778047e-001,0.000000e+000,,,,,,,,,,,,,,32,1,4.000000e+000,8.851929e-001,0.000000e+000,0,,0,
1578776237.716,,0.000000e+000,2.855625e+002,1.097503e-003,0.000000e+000,3,9.779314e-001,0.000000e+000,,,,,,,,,,,,,,32,1,4.000000e+000,9.456177e-001,0.000000e+000,0,,0,
1578776297.976,,0.000000e+000,2.906041e+002,1.065938e-003,0.000000e+000,3,9.781551e-001,0.000000e+000,,,,,,,,,,,,,,32,1,4.000000e+000,9.385986e-001,0.000000e+000,0,,0,
1578776358.006,,0.000000e+000,2.955650e+002,1.032926e-003,0.000000e+000,3,9.785830e-001,0.000000e+000,,,,,,,,,,,,,,32,1,4.000000e+000,9.719849e-001,0.000000e+000,0,,0,
1578776693.067,,0.000000e+000,3.000265e+002,9.834867e-004,0.000000e+000,3,9.785675e-001,0.000000e+000,,,,,,,,,,,,,,32,1,4.000000e+000,0.000000e+000,0.000000e+000,0,,0,
1578777244.647,,0.000000e+000,3.000041e+002,1.026916e-003,0.000000e+000,3,9.780345e-001,0.000000e+000,,,,,,,,,,,,,,32,1,4.000000e+000,1.489258e-002,0.000000e+000,0,,0,
1578777502.598,,0.000000e+000,2.946246e+002,1.049757e-003,0.000000e+000,3,9.776466e-001,0.000000e+000,,,,,,,,,,,,,,32,1,4.000000e+000,6.197205e-001,0.000000e+000,0,,0,
1578777582.888,,0.000000e+000,2.893214e+002,1.075176e-003,0.000000e+000,3,9.771297e-001,0.000000e+000,,,,,,,,,,,,,,32,1,4.000000e+000,9.854736e-001,0.000000e+000,0,,0,
1578777645.238,,0.000000e+000,2.843792e+002,1.095409e-003,0.000000e+000,3,9.767624e-001,0.000000e+000,,,,,,,,,,,,,,32,1,4.000000e+000,1.125000e+000,0.000000e+000,0,,0,
1578777705.118,,0.000000e+000,2.794472e+002,1.113450e-003,0.000000e+000,3,9.766908e-001,0.000000e+000,,,,,,,,,,,,,,32,1,4.000000e+000,1.084900e+000,0.000000e+000,0,,0,
1578777767.128,,0.000000e+000,2.742794e+002,1.130997e-003,0.000000e+000,3,9.769555e-001,0.000000e+000,,,,,,,,,,,,,,32,1,4.000000e+000,1.093201e+000,0.000000e+000,0,,0,
1578777828.838,,0.000000e+000,2.693846e+002,1.147219e-003,0.000000e+000,3,9.762680e-001,0.000000e+000,,,,,,,,,,,,,,32,1,4.000000e+000,1.112701e+000,0.000000e+000,0,,0,
1578777889.988,,0.000000e+000,2.643636e+002,1.161830e-003,0.000000e+000,3,9.763349e-001,0.000000e+000,,,,,,,,,,,,,,32,1,4.000000e+000,1.115814e+000,0.000000e+000,0,,0,
1578777953.648,,0.000000e+000,2.593309e+002,1.175999e-003,0.000000e+000,3,9.761467e-001,0.000000e+000,,,,,,,,,,,,,,32,1,4.000000e+000,1.173218e+000,0.000000e+000,0,,0,
1578778017.709,,0.000000e+000,2.542821e+002,1.189604e-003,0.000000e+000,3,9.758710e-001,0.000000e+000,,,,,,,,,,,,,,32,1,4.000000e+000,1.150406e+000,0.000000e+000,0,,0,
1578778080.379,,0.000000e+000,2.493390e+002,1.201287e-003,0.000000e+000,3,9.761706e-001,0.000000e+000,,,,,,,,,,,,,,32,1,4.000000e+000,1.086807e+000,0.000000e+000,0,,0,
1578778144.769,,0.000000e+000,2.444416e+002,1.212647e-003,0.000000e+000,3,9.761013e-001,0.000000e+000,,,,,,,,,,,,,,32,1,4.000000e+000,1.085098e+000,0.000000e+000,0,,0,
1578778210.669,,0.000000e+000,2.393772e+002,1.224381e-003,0.000000e+000,3,9.759245e-001,0.000000e+000,,,,,,,,,,,,,,32,1,4.000000e+000,1.231201e+000,0.000000e+000,0,,0,
1578778272.959,,0.000000e+000,2.343805e+002,1.234339e-003,0.000000e+000,3,9.760975e-001,0.000000e+000,,,,,,,,,,,,,,32,1,4.000000e+000,1.063599e+000,0.000000e+000,0,,0,
1578778335.389,,0.000000e+000,2.293521e+002,1.244588e-003,0.000000e+000,3,9.761515e-001,0.000000e+000,,,,,,,,,,,,,,32,1,4.000000e+000,1.159286e+000,0.000000e+000,0,,0,
1578778395.279,,0.000000e+000,2.243805e+002,1.254143e-003,0.000000e+000,3,9.758061e-001,0.000000e+000,,,,,,,,,,,,,,32,1,4.000000e+000,1.153305e+000,0.000000e+000,0,,0,
1578778455.449,,0.000000e+000,2.194512e+002,1.328739e-003,0.000000e+000,3,9.367810e-001,0.000000e+000,,,,,,,,,,,,,,32,1,4.000000e+000,1.097107e+000,0.000000e+000,0,,0,
1578778517.569,,0.000000e+000,2.143542e+002,1.270829e-003,0.000000e+000,3,9.760003e-001,0.000000e+000,,,,,,,,,,,,,,32,1,4.000000e+000,1.171295e+000,0.000000e+000,0,,0,
1578778578.199,,0.000000e+000,2.093585e+002,1.279222e-003,0.000000e+000,3,9.754556e-001,0.000000e+000,,,,,,,,,,,,,,32,1,4.000000e+000,1.112198e+000,0.000000e+000,0,,0,
1578778639.189,,0.000000e+000,2.042866e+002,1.286887e-003,0.000000e+000,3,9.757676e-001,0.000000e+000,,,,,,,,,,,,,,32,1,4.000000e+000,1.096298e+000,0.000000e+000,0,,0,
1578778699.050,,0.000000e+000,1.993494e+002,1.293287e-003,0.000000e+000,3,9.755594e-001,0.000000e+000,,,,,,,,,,,,,,32,1,4.000000e+000,1.040405e+000,0.000000e+000,0,,0,
1578778760.060,,0.000000e+000,1.943073e+002,1.300283e-003,0.000000e+000,3,9.756953e-001,0.000000e+000,,,,,,,,,,,,,,32,1,4.000000e+000,1.112198e+000,0.000000e+000,0,,0,
1578778818.720,,0.000000e+000,1.894142e+002,1.305921e-003,0.000000e+000,3,9.755659e-001,0.000000e+000,,,,,,,,,,,,,,32,1,4.000000e+000,1.127014e+000,0.000000e+000,0,,0,
1578778880.640,,0.000000e+000,1.842825e+002,1.265122e-003,0.000000e+000,3,9.603421e-001,0.000000e+000,,,,,,,,,,,,,,32,1,4.000000e+000,1.185699e+000,0.000000e+000,0,,0,
1578778939.560,,0.000000e+000,1.793761e+002,1.316259e-003,0.000000e+000,3,9.757319e-001,0.000000e+000,,,,,,,,,,,,,,32,1,4.000000e+000,1.215210e+000,0.000000e+000,0,,0,
1578778999.350,,0.000000e+000,1.743378e+002,1.322440e-003,0.000000e+000,3,9.756307e-001,0.000000e+000,,,,,,,,,,,,,,32,1,4.000000e+000,1.204803e+000,0.000000e+000,0,,0,
1578779058.270,,0.000000e+000,1.694043e+002,1.326329e-003,0.000000e+000,3,9.756156e-001,0.000000e+000,,,,,,,,,,,,,,32,1,4.000000e+000,1.068695e+000,0.000000e+000,0,,0,
1578779118.080,,0.000000e+000,1.643985e+002,1.330380e-003,0.000000e+000,3,9.758531e-001,0.000000e+000,,,,,,,,,,,,,,32,1,4.000000e+000,1.151001e+000,0.000000e+000,0,,0,
1578779177.650,,0.000000e+000,1.594168e+002,1.302199e-003,0.000000e+000,3,9.504344e-001,0.000000e+000,,,,,,,,,,,,,,32,1,4.000000e+000,1.070801e+000,0.000000e+000,0,,0,
1578779237.240,,0.000000e+000,1.544099e+002,1.338105e-003,0.000000e+000,3,9.756410e-001,0.000000e+000,,,,,,,,,,,,,,32,1,4.000000e+000,1.086609e+000,0.000000e+000,0,,0,
1578779297.300,,0.000000e+000,1.493258e+002,1.341624e-003,0.000000e+000,3,9.755346e-001,0.000000e+000,,,,,,,,,,,,,,32,1,4.000000e+000,1.094589e+000,0.000000e+000,0,,0,
1578779355.000,,0.000000e+000,1.443828e+002,1.342962e-003,0.000000e+000,3,9.759414e-001,0.000000e+000,,,,,,,,,,,,,,32,1,4.000000e+000,1.171997e+000,0.000000e+000,0,,0,
1578779413.321,,0.000000e+000,1.393864e+002,1.346333e-003,0.000000e+000,3,9.756765e-001,0.000000e+000,,,,,,,,,,,,,,32,1,4.000000e+000,1.192703e+000,0.000000e+000,0,,0,
1578779472.231,,0.000000e+000,1.342881e+002,1.347680e-003,0.000000e+000,3,9.757944e-001,0.000000e+000,,,,,,,,,,,,,,32,1,4.000000e+000,1.100296e+000,0.000000e+000,0,,0,
1578779529.201,,0.000000e+000,1.293755e+002,1.348557e-003,0.000000e+000,3,9.757985e-001,0.000000e+000,,,,,,,,,,,,,,32,1,4.000000e+000,1.033295e+000,0.000000e+000,0,,0,
1578779587.351,,0.000000e+000,1.243865e+002,1.349796e-003,0.000000e+000,3,9.753330e-001,0.000000e+000,,,,,,,,,,,,,,32,1,4.000000e+000,1.141098e+000,0.000000e+000,0,,0,
1578779645.311,,0.000000e+000,1.193662e+002,1.351081e-003,0.000000e+000,3,9.752324e-001,0.000000e+000,,,,,,,,,,,,,,32,1,4.000000e+000,1.136200e+000,0.000000e+000,0,,0,
1578779703.161,,0.000000e+000,1.142831e+002,1.351113e-003,0.000000e+000,3,9.754726e-001,0.000000e+000,,,,,,,,,,,,,,32,1,4.000000e+000,1.246605e+000,0.000000e+000,0,,0,
1578779758.481,,0.000000e+000,1.093118e+002,1.351437e-003,0.000000e+000,3,9.756001e-001,0.000000e+000,,,,,,,,,,,,,,32,1,4.000000e+000,1.087799e+000,0.000000e+000,0,,0,
1578779813.411,,0.000000e+000,1.043694e+002,1.348505e-003,0.000000e+000,3,9.753882e-001,0.000000e+000,,,,,,,,,,,,,,32,1,4.000000e+000,1.115601e+000,0.000000e+000,0,,0,
1578779867.711,,0.000000e+000,9.936262e+001,1.348110e-003,0.000000e+000,3,9.754331e-001,0.000000e+000,,,,,,,,,,,,,,32,1,4.000000e+000,1.160233e+000,0.000000e+000,0,,0,
1578779921.211,,0.000000e+000,9.438274e+001,1.346154e-003,0.000000e+000,3,9.755478e-001,0.000000e+000,,,,,,,,,,,,,,32,1,4.000000e+000,1.151024e+000,0.000000e+000,0,,0,
1578779973.731,,0.000000e+000,8.941429e+001,1.344437e-003,0.000000e+000,3,9.754311e-001,0.000000e+000,,,,,,,,,,,,,,32,1,4.000000e+000,1.157936e+000,0.000000e+000,0,,0,
1578780026.621,,0.000000e+000,8.432636e+001,1.343166e-003,0.000000e+000,3,9.754387e-001,0.000000e+000,,,,,,,,,,,,,,32,1,4.000000e+000,1.294312e+000,0.000000e+000,0,,0,
1578780077.641,,0.000000e+000,7.935471e+001,1.341949e-003,0.000000e+000,3,9.757199e-001,0.000000e+000,,,,,,,,,,,,,,32,1,4.000000e+000,1.220566e+000,0.000000e+000,0,,0,
1578780127.762,,0.000000e+000,7.425951e+001,1.340422e-003,0.000000e+000,3,9.753241e-001,0.000000e+000,,,,,,,,,,,,,,32,1,4.000000e+000,1.230194e+000,0.000000e+000,0,,0,
1578780178.332,,0.000000e+000,6.931853e+001,1.338643e-003,0.000000e+000,3,9.754880e-001,0.000000e+000,,,,,,,,,,,,,,32,1,4.000000e+000,1.286148e+000,0.000000e+000,0,,0,
1578780226.112,,0.000000e+000,6.425525e+001,1.336845e-003,0.000000e+000,3,9.759603e-001,0.000000e+000,,,,,,,,,,,,,,32,1,4.000000e+000,1.361488e+000,0.000000e+000,0,,0,
1578780272.182,,0.000000e+000,5.919991e+001,1.334932e-003,0.000000e+000,3,9.760817e-001,0.000000e+000,,,,,,,,,,,,,,32,1,4.000000e+000,1.159821e+000,0.000000e+000,0,,0,
1578780318.912,,0.000000e+000,5.437572e+001,1.333189e-003,0.000000e+000,3,9.761262e-001,0.000000e+000,,,,,,,,,,,,,,32,1,4.000000e+000,1.222919e+000,0.000000e+000,0,,0,
1578780368.772,,0.000000e+000,4.929972e+001,1.331580e-003,0.000000e+000,3,9.752089e-001,0.000000e+000,,,,,,,,,,,,,,32,1,4.000000e+000,1.237442e+000,0.000000e+000,0,,0,
1578780418.422,,0.000000e+000,4.434389e+001,1.330195e-003,0.000000e+000,3,9.759344e-001,0.000000e+000,,,,,,,,,,,,,,32,1,4.000000e+000,1.189960e+000,0.000000e+000,0,,0,
1578780467.592,,0.000000e+000,3.931097e+001,1.328570e-003,0.000000e+000,3,9.762412e-001,0.000000e+000,,,,,,,,,,,,,,32,1,4.000000e+000,1.170830e+000,0.000000e+000,0,,0,
1578780515.522,,0.000000e+000,3.428120e+001,1.327367e-003,0.000000e+000,3,9.763247e-001,0.000000e+000,,,,,,,,,,,,,,32,1,4.000000e+000,1.246151e+000,0.000000e+000,0,,0,
1578780558.982,,0.000000e+000,2.933722e+001,1.326902e-003,0.000000e+000,3,9.764428e-001,0.000000e+000,,,,,,,,,,,,,,32,1,4.000000e+000,1.241131e+000,0.000000e+000,0,,0,
1578780601.472,,0.000000e+000,2.410067e+001,1.326159e-003,0.000000e+000,3,9.762141e-001,0.000000e+000,,,,,,,,,,,,,,32,1,4.000000e+000,1.475328e+000,0.000000e+000,0,,0,
1578780661.142,,0.000000e+000,1.953426e+001,1.326499e-003,0.000000e+000,3,9.763945e-001,0.000000e+000,,,,,,,,,,,,,,32,1,4.000000e+000,9.075012e-001,0.000000e+000,0,,0,
1578780715.792,,0.000000e+000,1.397663e+001,1.326648e-003,0.000000e+000,3,9.763965e-001,0.000000e+000,,,,,,,,,,,,,,32,1,4.000000e+000,1.659989e+000,0.000000e+000,0,,0,
1578781560.994,,0.000000e+000,1.001179e+001,1.327164e-003,0.000000e+000,3,9.765338e-001,0.000000e+000,,,,,,,,,,,,,,32,1,4.000000e+000,2.360344e-003,0.000000e+000,0,,0,
1578781630.754,,0.000000e+000,1.004890e+001,1.327167e-003,0.000000e+000,3,9.765646e-001,0.000000e+000,,,,,,,,,,,,,,32,1,4.000000e+000,1.410007e-002,0.000000e+000,0,,0,
1578781710.264,,0.000000e+000,1.550868e+001,1.326694e-003,0.000000e+000,3,9.765546e-001,0.000000e+000,,,,,,,,,,,,,,32,1,4.000000e+000,9.128399e-001,0.000000e+000,0,,0,
1578781771.294,,0.000000e+000,2.057940e+001,1.326192e-003,0.000000e+000,3,9.765310e-001,0.000000e+000,,,,,,,,,,,,,,32,1,4.000000e+000,1.011860e+000,0.000000e+000,0,,0,
1578781832.164,,0.000000e+000,2.559283e+001,1.325720e-003,0.000000e+000,3,9.768233e-001,0.000000e+000,,,,,,,,,,,,,,32,1,4.000000e+000,9.845200e-001,0.000000e+000,0,,0,
1578781891.994,,0.000000e+000,3.050490e+001,1.326335e-003,0.000000e+000,3,9.765596e-001,0.000000e+000,,,,,,,,,,,,,,32,1,4.000000e+000,9.391212e-001,0.000000e+000,0,,0,
1578781952.614,,0.000000e+000,3.554441e+001,1.327257e-003,0.000000e+000,3,9.764459e-001,0.000000e+000,,,,,,,,,,,,,,32,1,4.000000e+000,8.395691e-001,0.000000e+000,0,,0,
1578782013.184,,0.000000e+000,4.048754e+001,1.328599e-003,0.000000e+000,3,9.762581e-001,0.000000e+000,,,,,,,,,,,,,,32,1,4.000000e+000,9.697380e-001,0.000000e+000,0,,0,
1578782073.764,,0.000000e+000,4.548018e+001,1.330176e-003,0.000000e+000,3,9.762560e-001,0.000000e+000,,,,,,,,,,,,,,32,1,4.000000e+000,9.520493e-001,0.000000e+000,0,,0,
1578782135.794,,0.000000e+000,5.056113e+001,1.331816e-003,0.000000e+000,3,9.762762e-001,0.000000e+000,,,,,,,,,,,,,,32,1,4.000000e+000,8.464279e-001,0.000000e+000,0,,0,
1578782195.344,,0.000000e+000,5.557787e+001,1.333395e-003,0.000000e+000,3,9.763339e-001,0.000000e+000,,,,,,,,,,,,,,32,1,4.000000e+000,8.966522e-001,0.000000e+000,0,,0,
1578782255.185,,0.000000e+000,6.057921e+001,1.335497e-003,0.000000e+000,3,9.763645e-001,0.000000e+000,,,,,,,,,,,,,,32,1,4.000000e+000,9.851799e-001,0.000000e+000,0,,0,
1578782314.295,,0.000000e+000,6.550984e+001,1.337557e-003,0.000000e+000,3,9.762194e-001,0.000000e+000,,,,,,,,,,,,,,32,1,4.000000e+000,9.562912e-001,0.000000e+000,0,,0,
1578782374.745,,0.000000e+000,7.058032e+001,1.339277e-003,0.000000e+000,3,9.759247e-001,0.000000e+000,,,,,,,,,,,,,,32,1,4.000000e+000,8.604660e-001,0.000000e+000,0,,0,
1578782434.435,,0.000000e+000,7.554027e+001,1.341228e-003,0.000000e+000,3,9.761185e-001,0.000000e+000,,,,,,,,,,,,,,32,1,4.000000e+000,1.015770e+000,0.000000e+000,0,,0,
1578782494.075,,0.000000e+000,8.054327e+001,1.344217e-003,0.000000e+000,3,9.756894e-001,0.000000e+000,,,,,,,,,,,,,,32,1,4.000000e+000,9.046936e-001,0.000000e+000,0,,0,
1578782554.395,,0.000000e+000,8.558490e+001,1.345071e-003,0.000000e+000,3,9.757802e-001,0.000000e+000,,,,,,,,,,,,,,32,1,4.000000e+000,1.068298e+000,0.000000e+000,0,,0,
1578782613.405,,0.000000e+000,9.057347e+001,1.346360e-003,0.000000e+000,3,9.757965e-001,0.000000e+000,,,,,,,,,,,,,,32,1,4.000000e+000,9.766464e-001,0.000000e+000,0,,0,
1578782672.565,,0.000000e+000,9.555256e+001,1.347566e-003,0.000000e+000,3,9.761158e-001,0.000000e+000,,,,,,,,,,,,,,32,1,4.000000e+000,9.793854e-001,0.000000e+000,0,,0,
1578782733.785,,0.000000e+000,1.005984e+002,1.348526e-003,0.000000e+000,3,9.756199e-001,0.000000e+000,,,,,,,,,,,,,,32,1,4.000000e+000,8.296967e-001,0.000000e+000,0,,0,
1578782792.245,,0.000000e+000,1.054473e+002,1.348943e-003,0.000000e+000,3,9.757003e-001,0.000000e+000,,,,,,,,,,,,,,32,1,4.000000e+000,8.406982e-001,0.000000e+000,0,,0,
1578782852.355,,0.000000e+000,1.105299e+002,1.349286e-003,0.000000e+000,3,9.753952e-001,0.000000e+000,,,,,,,,,,,,,,32,1,4.000000e+000,9.116058e-001,0.000000e+000,0,,0,
1578782912.745,,0.000000e+000,1.156005e+002,1.348984e-003,0.000000e+000,3,9.755479e-001,0.000000e+000,,,,,,,,,,,,,,32,1,4.000000e+000,8.945999e-001,0.000000e+000,0,,0,
1578782971.526,,0.000000e+000,1.205816e+002,1.348646e-003,0.000000e+000,3,9.753712e-001,0.000000e+000,,,,,,,,,,,,,,32,1,4.000000e+000,9.239044e-001,0.000000e+000,0,,0,
1578783031.906,,0.000000e+000,1.256011e+002,1.347453e-003,0.000000e+000,3,9.759646e-001,0.000000e+000,,,,,,,,,,,,,,32,1,4.000000e+000,1.001495e+000,0.000000e+000,0,,0,
1578783091.716,,0.000000e+000,1.306269e+002,1.346227e-003,0.000000e+000,3,9.758744e-001,0.000000e+000,,,,,,,,,,,,,,32,1,4.000000e+000,9.780121e-001,0.000000e+000,0,,0,
1578783151.416,,0.000000e+000,1.355468e+002,1.345245e-003,0.000000e+000,3,9.758546e-001,0.000000e+000,,,,,,,,,,,,,,32,1,4.000000e+000,1.046997e+000,0.000000e+000,0,,0,
1578783211.746,,0.000000e+000,1.406640e+002,1.343322e-003,0.000000e+000,3,9.759821e-001,0.000000e+000,,,,,,,,,,,,,,32,1,4.000000e+000,8.955994e-001,0.000000e+000,0,,0,
1578783271.476,,0.000000e+000,1.456122e+002,1.340649e-003,0.000000e+000,3,9.760539e-001,0.000000e+000,,,,,,,,,,,,,,32,1,4.000000e+000,9.307098e-001,0.000000e+000,0,,0,
1578783331.026,,0.000000e+000,1.505641e+002,1.337171e-003,0.000000e+000,3,9.762555e-001,0.000000e+000,,,,,,,,,,,,,,32,1,4.000000e+000,1.043106e+000,0.000000e+000,0,,0,
1578783390.876,,0.000000e+000,1.555428e+002,1.334757e-003,0.000000e+000,3,9.764305e-001,0.000000e+000,,,,,,,,,,,,,,32,1,4.000000e+000,8.519897e-001,0.000000e+000,0,,0,
1578783451.966,,0.000000e+000,1.605919e+002,1.331124e-003,0.000000e+000,3,9.763103e-001,0.000000e+000,,,,,,,,,,,,,,32,1,4.000000e+000,9.330902e-001,0.000000e+000,0,,0,
1578783510.676,,0.000000e+000,1.655849e+002,1.326902e-003,0.000000e+000,3,9.763507e-001,0.000000e+000,,,,,,,,,,,,,,32,1,4.000000e+000,1.015198e+000,0.000000e+000,0,,0,
1578783571.246,,0.000000e+000,1.705837e+002,1.322315e-003,0.000000e+000,3,9.764992e-001,0.000000e+000,,,,,,,,,,,,,,32,1,4.000000e+000,1.012711e+000,0.000000e+000,0,,0,
1578783630.786,,0.000000e+000,1.755704e+002,1.317494e-003,0.000000e+000,3,9.761863e-001,0.000000e+000,,,,,,,,,,,,,,32,1,4.000000e+000,8.942871e-001,0.000000e+000,0,,0,
1578783689.297,,0.000000e+000,1.804873e+002,1.311708e-003,0.000000e+000,3,9.764588e-001,0.000000e+000,,,,,,,,,,,,,,32,1,4.000000e+000,8.970032e-001,0.000000e+000,0,,0,
1578783750.157,,0.000000e+000,1.855154e+002,1.306436e-003,0.000000e+000,3,9.760016e-001,0.000000e+000,,,,,,,,,,,,,,32,1,4.000000e+000,8.858032e-001,0.000000e+000,0,,0,
1578783809.977,,0.000000e+000,1.906082e+002,1.300990e-003,0.000000e+000,3,9.761183e-001,0.000000e+000,,,,,,,,,,,,,,32,1,4.000000e+000,8.828125e-001,0.000000e+000,0,,0,
1578783869.747,,0.000000e+000,1.955280e+002,1.293918e-003,0.000000e+000,3,9.761590e-001,0.000000e+000,,,,,,,,,,,,,,32,1,4.000000e+000,9.581909e-001,0.000000e+000,0,,0,
1578783930.287,,0.000000e+000,2.005361e+002,1.286721e-003,0.000000e+000,3,9.764558e-001,0.000000e+000,,,,,,,,,,,,,,32,1,4.000000e+000,9.440002e-001,0.000000e+000,0,,0,
1578783990.657,,0.000000e+000,2.055963e+002,1.279586e-003,0.000000e+000,3,9.763943e-001,0.000000e+000,,,,,,,,,,,,,,32,1,4.000000e+000,9.468994e-001,0.000000e+000,0,,0,
1578784051.277,,0.000000e+000,2.105760e+002,1.271345e-003,0.000000e+000,3,9.766351e-001,0.000000e+000,,,,,,,,,,,,,,32,1,4.000000e+000,1.028488e+000,0.000000e+000,0,,0,
1578784110.227,,0.000000e+000,2.155855e+002,1.262954e-003,0.000000e+000,3,9.769028e-001,0.000000e+000,,,,,,,,,,,,,,32,1,4.000000e+000,1.029404e+000,0.000000e+000,0,,0,
1578784169.937,,0.000000e+000,2.205532e+002,1.254750e-003,0.000000e+000,3,9.766798e-001,0.000000e+000,,,,,,,,,,,,,,32,1,4.000000e+000,8.490143e-001,0.000000e+000,0,,0,
1578784230.387,,0.000000e+000,2.255855e+002,1.245520e-003,0.000000e+000,3,9.769299e-001,0.000000e+000,,,,,,,,,,,,,,32,1,4.000000e+000,1.004898e+000,0.000000e+000,0,,0,
1578784290.487,,0.000000e+000,2.306135e+002,1.235553e-003,0.000000e+000,3,9.763744e-001,0.000000e+000,,,,,,,,,,,,,,32,1,4.000000e+000,9.250031e-001,0.000000e+000,0,,0,
1578784351.557,,0.000000e+000,2.357057e+002,1.225099e-003,0.000000e+000,3,9.769773e-001,0.000000e+000,,,,,,,,,,,,,,32,1,4.000000e+000,1.001694e+000,0.000000e+000,0,,0,
1578784409.458,,0.000000e+000,2.405759e+002,1.214904e-003,0.000000e+000,3,9.769804e-001,0.000000e+000,,,,,,,,,,,,,,32,1,4.000000e+000,1.013702e+000,0.000000e+000,0,,0,
1578784468.728,,0.000000e+000,2.454564e+002,1.203589e-003,0.000000e+000,3,9.772819e-001,0.000000e+000,,,,,,,,,,,,,,32,1,4.000000e+000,9.048920e-001,0.000000e+000,0,,0,
1578784530.178,,0.000000e+000,2.506320e+002,1.190378e-003,0.000000e+000,3,9.777580e-001,0.000000e+000,,,,,,,,,,,,,,32,1,4.000000e+000,1.004486e+000,0.000000e+000,0,,0,
1578784589.248,,0.000000e+000,2.554640e+002,1.178240e-003,0.000000e+000,3,9.771913e-001,0.000000e+000,,,,,,,,,,,,,,32,1,4.000000e+000,9.136047e-001,0.000000e+000,0,,0,
1578784650.558,,0.000000e+000,2.606372e+002,1.163844e-003,0.000000e+000,3,9.777840e-001,0.000000e+000,,,,,,,,,,,,,,32,1,4.000000e+000,9.052124e-001,0.000000e+000,0,,0,
1578784711.088,,0.000000e+000,2.655883e+002,1.149422e-003,0.000000e+000,3,9.775938e-001,0.000000e+000,,,,,,,,,,,,,,32,1,4.000000e+000,8.942871e-001,0.000000e+000,0,,0,
1578784769.518,,0.000000e+000,2.705743e+002,1.134704e-003,0.000000e+000,3,9.777750e-001,0.000000e+000,,,,,,,,,,,,,,32,1,4.000000e+000,9.780884e-001,0.000000e+000,0,,0,
1578784830.308,,0.000000e+000,2.756526e+002,1.118495e-003,0.000000e+000,3,9.778402e-001,0.000000e+000,,,,,,,,,,,,,,32,1,4.000000e+000,8.787231e-001,0.000000e+000,0,,0,
1578784888.618,,0.000000e+000,2.805166e+002,1.101499e-003,0.000000e+000,3,9.776642e-001,0.000000e+000,,,,,,,,,,,,,,32,1,4.000000e+000,8.721924e-001,0.000000e+000,0,,0,
1578784948.108,,0.000000e+000,2.855286e+002,1.084101e-003,0.000000e+000,3,9.778782e-001,0.000000e+000,,,,,,,,,,,,,,32,1,4.000000e+000,8.778992e-001,0.000000e+000,0,,0,
1578785010.218,,0.000000e+000,2.906742e+002,1.064084e-003,0.000000e+000,3,9.781432e-001,0.000000e+000,,,,,,,,,,,,,,32,1,4.000000e+000,9.670105e-001,0.000000e+000,0,,0,
1578785069.458,,0.000000e+000,2.955141e+002,1.043493e-003,0.000000e+000,3,9.778447e-001,0.000000e+000,,,,,,,,,,,,,,32,1,4.000000e+000,8.701782e-001,0.000000e+000,0,,0,
1578785402.919,,0.000000e+000,3.000190e+002,1.012990e-003,0.000000e+000,3,9.788106e-001,0.000000e+000,,,,,,,,,,,,,,32,1,4.000000e+000,1.498413e-002,0.000000e+000,0,,0,