File: data/Rock_mag/2020_IRM_data_files/Raw_data/MPMS_5S/data/AX20-1r_RTSIRM-10K.dc.dc.dat
[Header]
TITLE,MPMS DC Measurement
BYAPP,MPMS Measurement,2.1,Summary
FILEOPENTIME, 1578513513.917000 1/8/2020, 1:58:33 PM

INFO, APPNAME, MPMS MultiVu Application, Revision 1.61,  Build 082

INFO, NAME, AX20-1r
INFO, WEIGHT, 1.000
INFO, AREA, 1.000
INFO, LENGTH, 1.000
INFO, SHAPE, 0
INFO, COMMENT,
INFO, SEQUENCE FILE: RTSIRM LTD 10K.seq


INFO, BACKGROUND DATA FILE:, None


STARTUPAXIS,X,4,LINEAR,AUTO,0.000000,0.000000
STARTUPAXIS,Y1,5,LINEAR,AUTO,0.000000,0.000000


STARTUPGROUP,Longitudinal
FIELDGROUP,Longitudinal,1,2,3,4,5,6,7,8,9,15,16,17,18,27,28
FIELDGROUP,Transverse,1,2,3,4,10,11,12,13,14,19,20,21,22,27,28

PLOT_APPEARANCE,ALL,HORZ_GRID_ON,VERT_GRID_ON,MARKERS_AND_LINES

[Data]
Time,Comment,Field (Oe),Temperature (K),Long Moment (emu),Long Scan Std Dev,Long Algorithm,Long Reg Fit,Long Percent Error (%),Trans Moment (emu),Trans Scan Std Dev,Trans Algorithm,Trans Reg Fit,Trans Percent Error (%),Long Moment [w/o ABS] (emu),Long Scan Std Dev [w/o ABS],Long Reg Fit [w/o ABS],Long Percent Error [w/o ABS] (%),Trans Moment [w/o ABS] (emu),Trans Scan Std Dev [w/o ABS],Trans Reg Fit [w/o ABS],Trans Percent Error [w/o ABS] (%),Points per Scan,Scans per Measurement,Scan Length (cm),Delta Temp (K),Rot Position (deg),Error,EC Comp. Running,Using ABS,
1578513513.917,,0.000000e+000,2.999927e+002,5.188099e-004,0.000000e+000,3,9.883903e-001,0.000000e+000,,,,,,,,,,,,,,32,1,4.000000e+000,0.000000e+000,0.000000e+000,0,,0,
1578513716.737,,0.000000e+000,2.966566e+002,5.177073e-004,0.000000e+000,3,9.878976e-001,0.000000e+000,,,,,,,,,,,,,,32,1,4.000000e+000,5.476990e-001,0.000000e+000,0,,0,
1578513772.397,,0.000000e+000,2.935339e+002,5.162978e-004,0.000000e+000,3,9.877421e-001,0.000000e+000,,,,,,,,,,,,,,32,1,4.000000e+000,7.832031e-001,0.000000e+000,0,,0,
1578513822.357,,0.000000e+000,2.905839e+002,5.145969e-004,0.000000e+000,3,9.876577e-001,0.000000e+000,,,,,,,,,,,,,,32,1,4.000000e+000,7.023010e-001,0.000000e+000,0,,0,
1578513872.387,,0.000000e+000,2.875983e+002,5.126412e-004,0.000000e+000,3,9.877165e-001,0.000000e+000,,,,,,,,,,,,,,32,1,4.000000e+000,7.738953e-001,0.000000e+000,0,,0,
1578513925.868,,0.000000e+000,2.846424e+002,5.107875e-004,0.000000e+000,3,9.876270e-001,0.000000e+000,,,,,,,,,,,,,,32,1,4.000000e+000,7.932129e-001,0.000000e+000,0,,0,
1578513984.978,,0.000000e+000,2.816687e+002,5.089874e-004,0.000000e+000,3,9.877265e-001,0.000000e+000,,,,,,,,,,,,,,32,1,4.000000e+000,6.677856e-001,0.000000e+000,0,,0,
1578514049.098,,0.000000e+000,2.787101e+002,5.071164e-004,0.000000e+000,3,9.876248e-001,0.000000e+000,,,,,,,,,,,,,,32,1,4.000000e+000,5.826111e-001,0.000000e+000,0,,0,
1578514117.878,,0.000000e+000,2.757338e+002,5.050489e-004,0.000000e+000,3,9.876477e-001,0.000000e+000,,,,,,,,,,,,,,32,1,4.000000e+000,6.258850e-001,0.000000e+000,0,,0,
1578514185.828,,0.000000e+000,2.727042e+002,5.029035e-004,0.000000e+000,3,9.876826e-001,0.000000e+000,,,,,,,,,,,,,,32,1,4.000000e+000,5.997009e-001,0.000000e+000,0,,0,
1578514249.318,,0.000000e+000,2.697581e+002,5.010182e-004,0.000000e+000,3,9.876100e-001,0.000000e+000,,,,,,,,,,,,,,32,1,4.000000e+000,5.529175e-001,0.000000e+000,0,,0,
1578514313.118,,0.000000e+000,2.666912e+002,4.991200e-004,0.000000e+000,3,9.875429e-001,0.000000e+000,,,,,,,,,,,,,,32,1,4.000000e+000,6.343079e-001,0.000000e+000,0,,0,
1578514373.658,,0.000000e+000,2.637415e+002,4.971722e-004,0.000000e+000,3,9.874328e-001,0.000000e+000,,,,,,,,,,,,,,32,1,4.000000e+000,6.703796e-001,0.000000e+000,0,,0,
1578514435.228,,0.000000e+000,2.607833e+002,4.950360e-004,0.000000e+000,3,9.874328e-001,0.000000e+000,,,,,,,,,,,,,,32,1,4.000000e+000,6.943054e-001,0.000000e+000,0,,0,
1578514495.718,,0.000000e+000,2.578015e+002,4.929235e-004,0.000000e+000,3,9.875762e-001,0.000000e+000,,,,,,,,,,,,,,32,1,4.000000e+000,6.184998e-001,0.000000e+000,0,,0,
1578514556.858,,0.000000e+000,2.547820e+002,4.906888e-004,0.000000e+000,3,9.876156e-001,0.000000e+000,,,,,,,,,,,,,,32,1,4.000000e+000,7.082977e-001,0.000000e+000,0,,0,
1578514617.969,,0.000000e+000,2.517766e+002,4.885924e-004,0.000000e+000,3,9.875654e-001,0.000000e+000,,,,,,,,,,,,,,32,1,4.000000e+000,6.343994e-001,0.000000e+000,0,,0,
1578514679.319,,0.000000e+000,2.487603e+002,4.864331e-004,0.000000e+000,3,9.874736e-001,0.000000e+000,,,,,,,,,,,,,,32,1,4.000000e+000,6.454926e-001,0.000000e+000,0,,0,
1578514739.459,,0.000000e+000,2.457984e+002,4.842675e-004,0.000000e+000,3,9.875403e-001,0.000000e+000,,,,,,,,,,,,,,32,1,4.000000e+000,6.289978e-001,0.000000e+000,0,,0,
1578514798.789,,0.000000e+000,2.428598e+002,4.820030e-004,0.000000e+000,3,9.875888e-001,0.000000e+000,,,,,,,,,,,,,,32,1,4.000000e+000,6.474915e-001,0.000000e+000,0,,0,
1578514860.709,,0.000000e+000,2.398153e+002,4.794356e-004,0.000000e+000,3,9.876581e-001,0.000000e+000,,,,,,,,,,,,,,32,1,4.000000e+000,7.057037e-001,0.000000e+000,0,,0,
1578514920.219,,0.000000e+000,2.368275e+002,4.772679e-004,0.000000e+000,3,9.877332e-001,0.000000e+000,,,,,,,,,,,,,,32,1,4.000000e+000,6.623077e-001,0.000000e+000,0,,0,
1578514979.969,,0.000000e+000,2.339071e+002,4.750851e-004,0.000000e+000,3,9.875804e-001,0.000000e+000,,,,,,,,,,,,,,32,1,4.000000e+000,6.287994e-001,0.000000e+000,0,,0,
1578515042.349,,0.000000e+000,2.308480e+002,4.726079e-004,0.000000e+000,3,9.875533e-001,0.000000e+000,,,,,,,,,,,,,,32,1,4.000000e+000,6.424103e-001,0.000000e+000,0,,0,
1578515102.019,,0.000000e+000,2.278817e+002,4.701003e-004,0.000000e+000,3,9.876703e-001,0.000000e+000,,,,,,,,,,,,,,32,1,4.000000e+000,5.723877e-001,0.000000e+000,0,,0,
1578515162.739,,0.000000e+000,2.248843e+002,4.676105e-004,0.000000e+000,3,9.876869e-001,0.000000e+000,,,,,,,,,,,,,,32,1,4.000000e+000,6.374054e-001,0.000000e+000,0,,0,
1578515224.139,,0.000000e+000,2.218578e+002,4.651464e-004,0.000000e+000,3,9.876174e-001,0.000000e+000,,,,,,,,,,,,,,32,1,4.000000e+000,6.623077e-001,0.000000e+000,0,,0,
1578515283.729,,0.000000e+000,2.189188e+002,4.626417e-004,0.000000e+000,3,9.875886e-001,0.000000e+000,,,,,,,,,,,,,,32,1,4.000000e+000,6.509857e-001,0.000000e+000,0,,0,
1578515343.080,,0.000000e+000,2.159593e+002,4.601862e-004,0.000000e+000,3,9.875343e-001,0.000000e+000,,,,,,,,,,,,,,32,1,4.000000e+000,6.528015e-001,0.000000e+000,0,,0,
1578515404.200,,0.000000e+000,2.128799e+002,4.574333e-004,0.000000e+000,3,9.874336e-001,0.000000e+000,,,,,,,,,,,,,,32,1,4.000000e+000,6.660919e-001,0.000000e+000,0,,0,
1578515463.770,,0.000000e+000,2.099612e+002,4.546880e-004,0.000000e+000,3,9.875253e-001,0.000000e+000,,,,,,,,,,,,,,32,1,4.000000e+000,6.661072e-001,0.000000e+000,0,,0,
1578515525.120,,0.000000e+000,2.069282e+002,4.518451e-004,0.000000e+000,3,9.875306e-001,0.000000e+000,,,,,,,,,,,,,,32,1,4.000000e+000,7.259979e-001,0.000000e+000,0,,0,
1578515585.380,,0.000000e+000,2.039582e+002,4.490327e-004,0.000000e+000,3,9.876379e-001,0.000000e+000,,,,,,,,,,,,,,32,1,4.000000e+000,6.566925e-001,0.000000e+000,0,,0,
1578515645.420,,0.000000e+000,2.009361e+002,4.461336e-004,0.000000e+000,3,9.875328e-001,0.000000e+000,,,,,,,,,,,,,,32,1,4.000000e+000,6.137085e-001,0.000000e+000,0,,0,
1578515704.940,,0.000000e+000,1.979769e+002,4.430681e-004,0.000000e+000,3,9.874024e-001,0.000000e+000,,,,,,,,,,,,,,32,1,4.000000e+000,6.177063e-001,0.000000e+000,0,,0,
1578515765.280,,0.000000e+000,1.950078e+002,4.397685e-004,0.000000e+000,3,9.874423e-001,0.000000e+000,,,,,,,,,,,,,,32,1,4.000000e+000,5.987091e-001,0.000000e+000,0,,0,
1578515826.220,,0.000000e+000,1.919790e+002,4.363849e-004,0.000000e+000,3,9.874831e-001,0.000000e+000,,,,,,,,,,,,,,32,1,4.000000e+000,6.694031e-001,0.000000e+000,0,,0,
1578515885.430,,0.000000e+000,1.890301e+002,4.329894e-004,0.000000e+000,3,9.874730e-001,0.000000e+000,,,,,,,,,,,,,,32,1,4.000000e+000,6.737976e-001,0.000000e+000,0,,0,
1578515946.290,,0.000000e+000,1.860197e+002,4.294957e-004,0.000000e+000,3,9.874752e-001,0.000000e+000,,,,,,,,,,,,,,32,1,4.000000e+000,5.481873e-001,0.000000e+000,0,,0,
1578516006.900,,0.000000e+000,1.830175e+002,4.258481e-004,0.000000e+000,3,9.873155e-001,0.000000e+000,,,,,,,,,,,,,,32,1,4.000000e+000,5.892944e-001,0.000000e+000,0,,0,
1578516067.071,,0.000000e+000,1.800506e+002,4.220951e-004,0.000000e+000,3,9.874284e-001,0.000000e+000,,,,,,,,,,,,,,32,1,4.000000e+000,7.023926e-001,0.000000e+000,0,,0,
1578516127.311,,0.000000e+000,1.770822e+002,4.180510e-004,0.000000e+000,3,9.873659e-001,0.000000e+000,,,,,,,,,,,,,,32,1,4.000000e+000,5.991058e-001,0.000000e+000,0,,0,
1578516187.461,,0.000000e+000,1.740430e+002,4.139016e-004,0.000000e+000,3,9.875669e-001,0.000000e+000,,,,,,,,,,,,,,32,1,4.000000e+000,6.091003e-001,0.000000e+000,0,,0,
1578516246.801,,0.000000e+000,1.710910e+002,4.097075e-004,0.000000e+000,3,9.875996e-001,0.000000e+000,,,,,,,,,,,,,,32,1,4.000000e+000,6.054993e-001,0.000000e+000,0,,0,
1578516307.241,,0.000000e+000,1.680918e+002,4.052392e-004,0.000000e+000,3,9.873036e-001,0.000000e+000,,,,,,,,,,,,,,32,1,4.000000e+000,6.651917e-001,0.000000e+000,0,,0,
1578516367.531,,0.000000e+000,1.650878e+002,4.005064e-004,0.000000e+000,3,9.873753e-001,0.000000e+000,,,,,,,,,,,,,,32,1,4.000000e+000,6.069031e-001,0.000000e+000,0,,0,
1578516426.481,,0.000000e+000,1.621234e+002,3.957063e-004,0.000000e+000,3,9.873947e-001,0.000000e+000,,,,,,,,,,,,,,32,1,4.000000e+000,6.222992e-001,0.000000e+000,0,,0,
1578516486.531,,0.000000e+000,1.591145e+002,3.905820e-004,0.000000e+000,3,9.876122e-001,0.000000e+000,,,,,,,,,,,,,,32,1,4.000000e+000,5.639038e-001,0.000000e+000,0,,0,
1578516546.051,,0.000000e+000,1.561425e+002,3.851102e-004,0.000000e+000,3,9.877162e-001,0.000000e+000,,,,,,,,,,,,,,32,1,4.000000e+000,6.195068e-001,0.000000e+000,0,,0,
1578516604.881,,0.000000e+000,1.531993e+002,3.796200e-004,0.000000e+000,3,9.876705e-001,0.000000e+000,,,,,,,,,,,,,,32,1,4.000000e+000,5.626984e-001,0.000000e+000,0,,0,
1578516665.551,,0.000000e+000,1.501609e+002,3.733551e-004,0.000000e+000,3,9.873459e-001,0.000000e+000,,,,,,,,,,,,,,32,1,4.000000e+000,5.694885e-001,0.000000e+000,0,,0,
1578516725.631,,0.000000e+000,1.471842e+002,3.670585e-004,0.000000e+000,3,9.874585e-001,0.000000e+000,,,,,,,,,,,,,,32,1,4.000000e+000,6.336060e-001,0.000000e+000,0,,0,
1578516784.582,,0.000000e+000,1.441795e+002,3.587822e-004,0.000000e+000,3,9.874458e-001,0.000000e+000,,,,,,,,,,,,,,32,1,4.000000e+000,5.811920e-001,0.000000e+000,0,,0,
1578516844.772,,0.000000e+000,1.411869e+002,3.520353e-004,0.000000e+000,3,9.875799e-001,0.000000e+000,,,,,,,,,,,,,,32,1,4.000000e+000,5.829926e-001,0.000000e+000,0,,0,
1578516904.572,,0.000000e+000,1.381919e+002,3.445471e-004,0.000000e+000,3,9.877309e-001,0.000000e+000,,,,,,,,,,,,,,32,1,4.000000e+000,6.457977e-001,0.000000e+000,0,,0,
1578516963.862,,0.000000e+000,1.352198e+002,3.365662e-004,0.000000e+000,3,9.877478e-001,0.000000e+000,,,,,,,,,,,,,,32,1,4.000000e+000,5.845947e-001,0.000000e+000,0,,0,
1578517023.272,,0.000000e+000,1.322461e+002,3.279680e-004,0.000000e+000,3,9.877173e-001,0.000000e+000,,,,,,,,,,,,,,32,1,4.000000e+000,5.941925e-001,0.000000e+000,0,,0,
1578517084.112,,0.000000e+000,1.291883e+002,3.182839e-004,0.000000e+000,3,9.876173e-001,0.000000e+000,,,,,,,,,,,,,,32,1,4.000000e+000,5.933990e-001,0.000000e+000,0,,0,
1578517141.552,,0.000000e+000,1.263239e+002,3.084436e-004,0.000000e+000,3,9.872462e-001,0.000000e+000,,,,,,,,,,,,,,32,1,4.000000e+000,5.380020e-001,0.000000e+000,0,,0,
1578517202.432,,0.000000e+000,1.232284e+002,2.976219e-004,0.000000e+000,3,9.875699e-001,0.000000e+000,,,,,,,,,,,,,,32,1,4.000000e+000,6.195984e-001,0.000000e+000,0,,0,
1578517261.542,,0.000000e+000,1.202527e+002,2.862625e-004,0.000000e+000,3,9.877633e-001,0.000000e+000,,,,,,,,,,,,,,32,1,4.000000e+000,6.162949e-001,0.000000e+000,0,,0,
1578517319.312,,0.000000e+000,1.172797e+002,2.747427e-004,0.000000e+000,3,9.880128e-001,0.000000e+000,,,,,,,,,,,,,,32,1,4.000000e+000,6.329956e-001,0.000000e+000,0,,0,
1578517378.322,,0.000000e+000,1.142684e+002,2.629635e-004,0.000000e+000,3,9.880939e-001,0.000000e+000,,,,,,,,,,,,,,32,1,4.000000e+000,6.343994e-001,0.000000e+000,0,,0,
1578517449.433,,0.000000e+000,1.105946e+002,2.510186e-004,0.000000e+000,3,9.881168e-001,0.000000e+000,,,,,,,,,,,,,,32,1,4.000000e+000,5.995026e-001,0.000000e+000,0,,0,
1578517494.513,,0.000000e+000,1.082939e+002,2.427395e-004,0.000000e+000,3,9.878715e-001,0.000000e+000,,,,,,,,,,,,,,32,1,4.000000e+000,6.525040e-001,0.000000e+000,0,,0,
1578517553.493,,0.000000e+000,1.053351e+002,2.323026e-004,0.000000e+000,3,9.881210e-001,0.000000e+000,,,,,,,,,,,,,,32,1,4.000000e+000,6.316986e-001,0.000000e+000,0,,0,
1578517611.093,,0.000000e+000,1.022878e+002,2.234459e-004,0.000000e+000,3,9.880666e-001,0.000000e+000,,,,,,,,,,,,,,32,1,4.000000e+000,7.342987e-001,0.000000e+000,0,,0,
1578517667.253,,0.000000e+000,9.937082e+001,2.158244e-004,0.000000e+000,3,9.885700e-001,0.000000e+000,,,,,,,,,,,,,,32,1,4.000000e+000,6.197128e-001,0.000000e+000,0,,0,
1578517724.883,,0.000000e+000,9.632079e+001,2.086926e-004,0.000000e+000,3,9.882125e-001,0.000000e+000,,,,,,,,,,,,,,32,1,4.000000e+000,6.327744e-001,0.000000e+000,0,,0,
1578517781.513,,0.000000e+000,9.332119e+001,2.026992e-004,0.000000e+000,3,9.887294e-001,0.000000e+000,,,,,,,,,,,,,,32,1,4.000000e+000,5.622559e-001,0.000000e+000,0,,0,
1578517837.573,,0.000000e+000,9.029677e+001,1.976202e-004,0.000000e+000,3,9.881681e-001,0.000000e+000,,,,,,,,,,,,,,32,1,4.000000e+000,6.597900e-001,0.000000e+000,0,,0,
1578517893.133,,0.000000e+000,8.736324e+001,1.934074e-004,0.000000e+000,3,9.885511e-001,0.000000e+000,,,,,,,,,,,,,,32,1,4.000000e+000,5.518036e-001,0.000000e+000,0,,0,
1578517947.913,,0.000000e+000,8.440172e+001,1.898205e-004,0.000000e+000,3,9.888926e-001,0.000000e+000,,,,,,,,,,,,,,32,1,4.000000e+000,6.136627e-001,0.000000e+000,0,,0,
1578518003.823,,0.000000e+000,8.136682e+001,1.867689e-004,0.000000e+000,3,9.883959e-001,0.000000e+000,,,,,,,,,,,,,,32,1,4.000000e+000,7.040405e-001,0.000000e+000,0,,0,
1578518057.583,,0.000000e+000,7.834230e+001,1.844034e-004,0.000000e+000,3,9.887562e-001,0.000000e+000,,,,,,,,,,,,,,32,1,4.000000e+000,7.191086e-001,0.000000e+000,0,,0,
1578518109.873,,0.000000e+000,7.545245e+001,1.826211e-004,0.000000e+000,3,9.890966e-001,0.000000e+000,,,,,,,,,,,,,,32,1,4.000000e+000,5.997238e-001,0.000000e+000,0,,0,
1578518164.924,,0.000000e+000,7.234014e+001,1.530881e-004,0.000000e+000,3,3.628688e-001,0.000000e+000,,,,,,,,,,,,,,32,1,4.000000e+000,6.936798e-001,0.000000e+000,0,,0,
1578518216.444,,0.000000e+000,6.941466e+001,1.799670e-004,0.000000e+000,3,9.891977e-001,0.000000e+000,,,,,,,,,,,,,,32,1,4.000000e+000,6.998520e-001,0.000000e+000,0,,0,
1578518267.724,,0.000000e+000,6.644241e+001,1.789603e-004,0.000000e+000,3,9.888700e-001,0.000000e+000,,,,,,,,,,,,,,32,1,4.000000e+000,6.500397e-001,0.000000e+000,0,,0,
1578518319.264,,0.000000e+000,6.342580e+001,1.783239e-004,0.000000e+000,3,9.891163e-001,0.000000e+000,,,,,,,,,,,,,,32,1,4.000000e+000,6.863098e-001,0.000000e+000,0,,0,
1578518369.124,,0.000000e+000,6.046281e+001,1.779407e-004,0.000000e+000,3,9.889885e-001,0.000000e+000,,,,,,,,,,,,,,32,1,4.000000e+000,6.798706e-001,0.000000e+000,0,,0,
1578518419.424,,0.000000e+000,5.746646e+001,1.774441e-004,0.000000e+000,3,9.893582e-001,0.000000e+000,,,,,,,,,,,,,,32,1,4.000000e+000,7.044907e-001,0.000000e+000,0,,0,
1578518469.104,,0.000000e+000,5.440715e+001,1.773814e-004,0.000000e+000,3,9.892735e-001,0.000000e+000,,,,,,,,,,,,,,32,1,4.000000e+000,6.485825e-001,0.000000e+000,0,,0,
1578518517.694,,0.000000e+000,5.144593e+001,1.773687e-004,0.000000e+000,3,9.893620e-001,0.000000e+000,,,,,,,,,,,,,,32,1,4.000000e+000,7.131195e-001,0.000000e+000,0,,0,
1578518565.534,,0.000000e+000,4.845620e+001,1.774568e-004,0.000000e+000,3,9.887374e-001,0.000000e+000,,,,,,,,,,,,,,32,1,4.000000e+000,6.637497e-001,0.000000e+000,0,,0,
1578518613.674,,0.000000e+000,4.551744e+001,1.775404e-004,0.000000e+000,3,9.890282e-001,0.000000e+000,,,,,,,,,,,,,,32,1,4.000000e+000,6.464615e-001,0.000000e+000,0,,0,
1578518665.014,,0.000000e+000,4.255527e+001,1.778056e-004,0.000000e+000,3,9.890507e-001,0.000000e+000,,,,,,,,,,,,,,32,1,4.000000e+000,5.831184e-001,0.000000e+000,0,,0,
1578518721.894,,0.000000e+000,3.946173e+001,1.779878e-004,0.000000e+000,3,9.888961e-001,0.000000e+000,,,,,,,,,,,,,,32,1,4.000000e+000,6.444397e-001,0.000000e+000,0,,0,
1578518775.794,,0.000000e+000,3.660600e+001,1.782608e-004,0.000000e+000,3,9.888948e-001,0.000000e+000,,,,,,,,,,,,,,32,1,4.000000e+000,5.718803e-001,0.000000e+000,0,,0,
1578518831.694,,0.000000e+000,3.356430e+001,1.785825e-004,0.000000e+000,3,9.891298e-001,0.000000e+000,,,,,,,,,,,,,,32,1,4.000000e+000,6.306992e-001,0.000000e+000,0,,0,
1578518887.365,,0.000000e+000,3.058192e+001,1.786864e-004,0.000000e+000,3,9.885539e-001,0.000000e+000,,,,,,,,,,,,,,32,1,4.000000e+000,6.504612e-001,0.000000e+000,0,,0,
1578518942.025,,0.000000e+000,2.755893e+001,1.789633e-004,0.000000e+000,3,9.887514e-001,0.000000e+000,,,,,,,,,,,,,,32,1,4.000000e+000,6.254196e-001,0.000000e+000,0,,0,
1578518997.555,,0.000000e+000,2.451425e+001,1.791987e-004,0.000000e+000,3,9.888099e-001,0.000000e+000,,,,,,,,,,,,,,32,1,4.000000e+000,6.922989e-001,0.000000e+000,0,,0,
1578519061.605,,0.000000e+000,2.155252e+001,1.792971e-004,0.000000e+000,3,9.889234e-001,0.000000e+000,,,,,,,,,,,,,,32,1,4.000000e+000,7.559795e-001,0.000000e+000,0,,0,
1578519118.135,,0.000000e+000,1.843903e+001,1.793881e-004,0.000000e+000,3,9.887200e-001,0.000000e+000,,,,,,,,,,,,,,32,1,4.000000e+000,8.324699e-001,0.000000e+000,0,,0,
1578519173.135,,0.000000e+000,1.512689e+001,2.676671e-004,0.000000e+000,3,6.319234e-001,0.000000e+000,,,,,,,,,,,,,,32,1,4.000000e+000,1.338551e+000,0.000000e+000,0,,0,
1578519230.345,,0.000000e+000,1.265956e+001,1.796187e-004,0.000000e+000,3,9.886841e-001,0.000000e+000,,,,,,,,,,,,,,32,1,4.000000e+000,5.119305e-001,0.000000e+000,0,,0,
1578519689.366,,0.000000e+000,1.002958e+001,1.793834e-004,0.000000e+000,3,9.886445e-001,0.000000e+000,,,,,,,,,,,,,,32,1,4.000000e+000,3.469467e-003,0.000000e+000,0,,0,
1578520375.167,,0.000000e+000,9.998055e+000,1.793465e-004,0.000000e+000,3,9.890442e-001,0.000000e+000,,,,,,,,,,,,,,32,1,4.000000e+000,9.088516e-003,0.000000e+000,0,,0,
1578520455.357,,0.000000e+000,1.333597e+001,1.793922e-004,0.000000e+000,3,9.889835e-001,0.000000e+000,,,,,,,,,,,,,,32,1,4.000000e+000,5.222702e-001,0.000000e+000,0,,0,
1578520514.677,,0.000000e+000,1.629110e+001,1.794071e-004,0.000000e+000,3,9.890359e-001,0.000000e+000,,,,,,,,,,,,,,32,1,4.000000e+000,5.649796e-001,0.000000e+000,0,,0,
1578520574.957,,0.000000e+000,1.931337e+001,1.793094e-004,0.000000e+000,3,9.889513e-001,0.000000e+000,,,,,,,,,,,,,,32,1,4.000000e+000,5.911503e-001,0.000000e+000,0,,0,
1578520635.597,,0.000000e+000,2.234394e+001,1.791398e-004,0.000000e+000,3,9.882414e-001,0.000000e+000,,,,,,,,,,,,,,32,1,4.000000e+000,5.277901e-001,0.000000e+000,0,,0,
1578520695.407,,0.000000e+000,2.530048e+001,1.790981e-004,0.000000e+000,3,9.888144e-001,0.000000e+000,,,,,,,,,,,,,,32,1,4.000000e+000,6.043015e-001,0.000000e+000,0,,0,
1578520754.967,,0.000000e+000,2.823803e+001,1.789344e-004,0.000000e+000,3,9.886215e-001,0.000000e+000,,,,,,,,,,,,,,32,1,4.000000e+000,5.412502e-001,0.000000e+000,0,,0,
1578520815.757,,0.000000e+000,3.125651e+001,1.786385e-004,0.000000e+000,3,9.885272e-001,0.000000e+000,,,,,,,,,,,,,,32,1,4.000000e+000,5.939407e-001,0.000000e+000,0,,0,
1578520875.637,,0.000000e+000,3.427797e+001,1.783928e-004,0.000000e+000,3,9.886914e-001,0.000000e+000,,,,,,,,,,,,,,32,1,4.000000e+000,5.609207e-001,0.000000e+000,0,,0,
1578520934.997,,0.000000e+000,3.722982e+001,1.782545e-004,0.000000e+000,3,9.888750e-001,0.000000e+000,,,,,,,,,,,,,,32,1,4.000000e+000,5.610580e-001,0.000000e+000,0,,0,
1578520994.207,,0.000000e+000,4.017157e+001,1.779010e-004,0.000000e+000,3,9.890904e-001,0.000000e+000,,,,,,,,,,,,,,32,1,4.000000e+000,5.463181e-001,0.000000e+000,0,,0,
1578521056.178,,0.000000e+000,4.324669e+001,1.776747e-004,0.000000e+000,3,9.886862e-001,0.000000e+000,,,,,,,,,,,,,,32,1,4.000000e+000,6.172714e-001,0.000000e+000,0,,0,
1578521115.698,,0.000000e+000,4.623608e+001,1.773243e-004,0.000000e+000,3,9.889418e-001,0.000000e+000,,,,,,,,,,,,,,32,1,4.000000e+000,6.051674e-001,0.000000e+000,0,,0,
1578521174.128,,0.000000e+000,4.915368e+001,1.773164e-004,0.000000e+000,3,9.890968e-001,0.000000e+000,,,,,,,,,,,,,,32,1,4.000000e+000,5.411797e-001,0.000000e+000,0,,0,
1578521234.858,,0.000000e+000,5.217291e+001,1.772348e-004,0.000000e+000,3,9.891213e-001,0.000000e+000,,,,,,,,,,,,,,32,1,4.000000e+000,5.740318e-001,0.000000e+000,0,,0,
1578521294.218,,0.000000e+000,5.517290e+001,1.772742e-004,0.000000e+000,3,9.892250e-001,0.000000e+000,,,,,,,,,,,,,,32,1,4.000000e+000,5.724525e-001,0.000000e+000,0,,0,
1578521354.508,,0.000000e+000,5.819793e+001,1.772495e-004,0.000000e+000,3,9.889665e-001,0.000000e+000,,,,,,,,,,,,,,32,1,4.000000e+000,5.035782e-001,0.000000e+000,0,,0,
1578521413.698,,0.000000e+000,6.114851e+001,1.774015e-004,0.000000e+000,3,9.892238e-001,0.000000e+000,,,,,,,,,,,,,,32,1,4.000000e+000,5.503235e-001,0.000000e+000,0,,0,
1578521473.428,,0.000000e+000,6.412033e+001,1.775799e-004,0.000000e+000,3,9.889908e-001,0.000000e+000,,,,,,,,,,,,,,32,1,4.000000e+000,5.059204e-001,0.000000e+000,0,,0,
1578521532.678,,0.000000e+000,6.711915e+001,1.780404e-004,0.000000e+000,3,9.888582e-001,0.000000e+000,,,,,,,,,,,,,,32,1,4.000000e+000,5.114594e-001,0.000000e+000,0,,0,
1578521592.818,,0.000000e+000,7.010999e+001,1.786612e-004,0.000000e+000,3,9.887913e-001,0.000000e+000,,,,,,,,,,,,,,32,1,4.000000e+000,5.055161e-001,0.000000e+000,0,,0,
1578521652.488,,0.000000e+000,7.309026e+001,1.792788e-004,0.000000e+000,3,9.891140e-001,0.000000e+000,,,,,,,,,,,,,,32,1,4.000000e+000,6.063004e-001,0.000000e+000,0,,0,
1578521711.898,,0.000000e+000,7.608006e+001,2.991568e-004,0.000000e+000,3,6.053370e-001,0.000000e+000,,,,,,,,,,,,,,32,1,4.000000e+000,6.005478e-001,0.000000e+000,0,,0,
1578521771.829,,0.000000e+000,7.911261e+001,1.814194e-004,0.000000e+000,3,9.889373e-001,0.000000e+000,,,,,,,,,,,,,,32,1,4.000000e+000,5.182343e-001,0.000000e+000,0,,0,
1578521832.279,,0.000000e+000,8.211906e+001,1.828645e-004,0.000000e+000,3,9.891661e-001,0.000000e+000,,,,,,,,,,,,,,32,1,4.000000e+000,5.303650e-001,0.000000e+000,0,,0,
1578521889.619,,0.000000e+000,8.502046e+001,1.845077e-004,0.000000e+000,3,9.891785e-001,0.000000e+000,,,,,,,,,,,,,,32,1,4.000000e+000,5.346146e-001,0.000000e+000,0,,0,
1578521951.439,,0.000000e+000,8.810880e+001,1.866700e-004,0.000000e+000,3,9.888111e-001,0.000000e+000,,,,,,,,,,,,,,32,1,4.000000e+000,5.123367e-001,0.000000e+000,0,,0,
1578522009.999,,0.000000e+000,9.101683e+001,1.890167e-004,0.000000e+000,3,9.887639e-001,0.000000e+000,,,,,,,,,,,,,,32,1,4.000000e+000,5.432663e-001,0.000000e+000,0,,0,
1578522070.069,,0.000000e+000,9.406534e+001,1.919836e-004,0.000000e+000,3,9.891113e-001,0.000000e+000,,,,,,,,,,,,,,32,1,4.000000e+000,5.242004e-001,0.000000e+000,0,,0,
1578522130.229,,0.000000e+000,9.703033e+001,1.949798e-004,0.000000e+000,3,9.890783e-001,0.000000e+000,,,,,,,,,,,,,,32,1,4.000000e+000,5.673904e-001,0.000000e+000,0,,0,
1578522189.409,,0.000000e+000,1.000132e+002,1.984668e-004,0.000000e+000,3,9.888583e-001,0.000000e+000,,,,,,,,,,,,,,32,1,4.000000e+000,5.779877e-001,0.000000e+000,0,,0,
1578522248.919,,0.000000e+000,1.030098e+002,2.022318e-004,0.000000e+000,3,9.890200e-001,0.000000e+000,,,,,,,,,,,,,,32,1,4.000000e+000,6.054001e-001,0.000000e+000,0,,0,
1578522307.969,,0.000000e+000,1.059995e+002,2.063673e-004,0.000000e+000,3,9.888374e-001,0.000000e+000,,,,,,,,,,,,,,32,1,4.000000e+000,5.284042e-001,0.000000e+000,0,,0,
1578522368.289,,0.000000e+000,1.089360e+002,2.107283e-004,0.000000e+000,3,9.887089e-001,0.000000e+000,,,,,,,,,,,,,,32,1,4.000000e+000,5.086975e-001,0.000000e+000,0,,0,
1578522428.149,,0.000000e+000,1.119455e+002,2.150653e-004,0.000000e+000,3,9.885247e-001,0.000000e+000,,,,,,,,,,,,,,32,1,4.000000e+000,5.721970e-001,0.000000e+000,0,,0,
1578522487.020,,0.000000e+000,1.149565e+002,2.194791e-004,0.000000e+000,3,9.886382e-001,0.000000e+000,,,,,,,,,,,,,,32,1,4.000000e+000,5.409012e-001,0.000000e+000,0,,0,
1578522548.280,,0.000000e+000,1.179948e+002,2.239846e-004,0.000000e+000,3,9.885013e-001,0.000000e+000,,,,,,,,,,,,,,32,1,4.000000e+000,5.684967e-001,0.000000e+000,0,,0,
1578522606.800,,0.000000e+000,1.208872e+002,2.282581e-004,0.000000e+000,3,9.886149e-001,0.000000e+000,,,,,,,,,,,,,,32,1,4.000000e+000,5.115967e-001,0.000000e+000,0,,0,
1578522666.490,,0.000000e+000,1.239118e+002,2.323436e-004,0.000000e+000,3,9.887171e-001,0.000000e+000,,,,,,,,,,,,,,32,1,4.000000e+000,5.231018e-001,0.000000e+000,0,,0,
1578522727.270,,0.000000e+000,1.269511e+002,2.360655e-004,0.000000e+000,3,9.884793e-001,0.000000e+000,,,,,,,,,,,,,,32,1,4.000000e+000,5.625992e-001,0.000000e+000,0,,0,
1578522786.220,,0.000000e+000,1.298792e+002,2.392221e-004,0.000000e+000,3,9.882301e-001,0.000000e+000,,,,,,,,,,,,,,32,1,4.000000e+000,5.059967e-001,0.000000e+000,0,,0,
1578522845.350,,0.000000e+000,1.328763e+002,2.419343e-004,0.000000e+000,3,9.881792e-001,0.000000e+000,,,,,,,,,,,,,,32,1,4.000000e+000,5.899963e-001,0.000000e+000,0,,0,
1578522905.980,,0.000000e+000,1.359532e+002,2.445230e-004,0.000000e+000,3,9.885635e-001,0.000000e+000,,,,,,,,,,,,,,32,1,4.000000e+000,5.699005e-001,0.000000e+000,0,,0,
1578522964.130,,0.000000e+000,1.388469e+002,2.466941e-004,0.000000e+000,3,9.884908e-001,0.000000e+000,,,,,,,,,,,,,,32,1,4.000000e+000,5.281982e-001,0.000000e+000,0,,0,
1578523025.340,,0.000000e+000,1.419032e+002,2.487546e-004,0.000000e+000,3,9.883342e-001,0.000000e+000,,,,,,,,,,,,,,32,1,4.000000e+000,5.689087e-001,0.000000e+000,0,,0,
1578523084.610,,0.000000e+000,1.448749e+002,2.505092e-004,0.000000e+000,3,9.885328e-001,0.000000e+000,,,,,,,,,,,,,,32,1,4.000000e+000,5.749969e-001,0.000000e+000,0,,0,
1578523142.970,,0.000000e+000,1.478084e+002,2.522350e-004,0.000000e+000,3,9.884523e-001,0.000000e+000,,,,,,,,,,,,,,32,1,4.000000e+000,5.487976e-001,0.000000e+000,0,,0,
1578523202.681,,0.000000e+000,1.508053e+002,2.536046e-004,0.000000e+000,3,9.885301e-001,0.000000e+000,,,,,,,,,,,,,,32,1,4.000000e+000,5.065002e-001,0.000000e+000,0,,0,
1578523263.841,,0.000000e+000,1.538354e+002,2.549591e-004,0.000000e+000,3,9.884973e-001,0.000000e+000,,,,,,,,,,,,,,32,1,4.000000e+000,5.202942e-001,0.000000e+000,0,,0,
1578523324.911,,0.000000e+000,1.566741e+002,2.561219e-004,0.000000e+000,3,9.883649e-001,0.000000e+000,,,,,,,,,,,,,,32,1,4.000000e+000,2.662964e-001,0.000000e+000,0,,0,
1578523393.101,,0.000000e+000,1.598355e+002,2.574986e-004,0.000000e+000,3,9.880500e-001,0.000000e+000,,,,,,,,,,,,,,32,1,4.000000e+000,4.817047e-001,0.000000e+000,0,,0,
1578523452.971,,0.000000e+000,1.628049e+002,2.585230e-004,0.000000e+000,3,9.882989e-001,0.000000e+000,,,,,,,,,,,,,,32,1,4.000000e+000,5.372925e-001,0.000000e+000,0,,0,
1578523511.471,,0.000000e+000,1.658734e+002,2.594911e-004,0.000000e+000,3,9.885060e-001,0.000000e+000,,,,,,,,,,,,,,32,1,4.000000e+000,5.654907e-001,0.000000e+000,0,,0,
1578523565.911,,0.000000e+000,1.687636e+002,2.603046e-004,0.000000e+000,3,9.885899e-001,0.000000e+000,,,,,,,,,,,,,,32,1,4.000000e+000,5.973969e-001,0.000000e+000,0,,0,
1578523623.221,,0.000000e+000,1.717892e+002,2.611047e-004,0.000000e+000,3,9.885771e-001,0.000000e+000,,,,,,,,,,,,,,32,1,4.000000e+000,6.399078e-001,0.000000e+000,0,,0,
1578523680.411,,0.000000e+000,1.746889e+002,2.618105e-004,0.000000e+000,3,9.884923e-001,0.000000e+000,,,,,,,,,,,,,,32,1,4.000000e+000,5.090942e-001,0.000000e+000,0,,0,
1578523740.611,,0.000000e+000,1.777440e+002,2.626113e-004,0.000000e+000,3,9.887429e-001,0.000000e+000,,,,,,,,,,,,,,32,1,4.000000e+000,5.000000e-001,0.000000e+000,0,,0,
1578523802.511,,0.000000e+000,1.807299e+002,2.632573e-004,0.000000e+000,3,9.885650e-001,0.000000e+000,,,,,,,,,,,,,,32,1,4.000000e+000,4.889069e-001,0.000000e+000,0,,0,
1578523862.431,,0.000000e+000,1.836823e+002,2.638999e-004,0.000000e+000,3,9.888281e-001,0.000000e+000,,,,,,,,,,,,,,32,1,4.000000e+000,5.581970e-001,0.000000e+000,0,,0,
1578523921.432,,0.000000e+000,1.867187e+002,2.593427e-004,0.000000e+000,3,9.310499e-001,0.000000e+000,,,,,,,,,,,,,,32,1,4.000000e+000,5.126038e-001,0.000000e+000,0,,0,
1578523979.572,,0.000000e+000,1.901757e+002,2.649354e-004,0.000000e+000,3,9.889681e-001,0.000000e+000,,,,,,,,,,,,,,32,1,4.000000e+000,6.616974e-001,0.000000e+000,0,,0,
1578524026.572,,0.000000e+000,1.927275e+002,2.654216e-004,0.000000e+000,3,9.888009e-001,0.000000e+000,,,,,,,,,,,,,,32,1,4.000000e+000,4.888000e-001,0.000000e+000,0,,0,
1578524089.532,,0.000000e+000,1.957015e+002,2.659108e-004,0.000000e+000,3,9.887319e-001,0.000000e+000,,,,,,,,,,,,,,32,1,4.000000e+000,5.045013e-001,0.000000e+000,0,,0,
1578524154.272,,0.000000e+000,1.986444e+002,2.663389e-004,0.000000e+000,3,9.886329e-001,0.000000e+000,,,,,,,,,,,,,,32,1,4.000000e+000,5.031891e-001,0.000000e+000,0,,0,
1578524217.502,,0.000000e+000,2.016449e+002,2.667158e-004,0.000000e+000,3,9.889259e-001,0.000000e+000,,,,,,,,,,,,,,32,1,4.000000e+000,4.898987e-001,0.000000e+000,0,,0,
1578524279.242,,0.000000e+000,2.046589e+002,2.670659e-004,0.000000e+000,3,9.889402e-001,0.000000e+000,,,,,,,,,,,,,,32,1,4.000000e+000,4.929962e-001,0.000000e+000,0,,0,
1578524339.362,,0.000000e+000,2.076008e+002,2.672993e-004,0.000000e+000,3,9.890926e-001,0.000000e+000,,,,,,,,,,,,,,32,1,4.000000e+000,5.451050e-001,0.000000e+000,0,,0,
1578524400.642,,0.000000e+000,2.106132e+002,2.676122e-004,0.000000e+000,3,9.889655e-001,0.000000e+000,,,,,,,,,,,,,,32,1,4.000000e+000,4.214020e-001,0.000000e+000,0,,0,
1578524469.232,,0.000000e+000,2.136073e+002,2.677828e-004,0.000000e+000,3,9.891396e-001,0.000000e+000,,,,,,,,,,,,,,32,1,4.000000e+000,5.787964e-001,0.000000e+000,0,,0,
1578524528.722,,0.000000e+000,2.166479e+002,2.680047e-004,0.000000e+000,3,9.892159e-001,0.000000e+000,,,,,,,,,,,,,,32,1,4.000000e+000,5.487061e-001,0.000000e+000,0,,0,
1578524584.472,,0.000000e+000,2.195751e+002,2.681202e-004,0.000000e+000,3,9.892632e-001,0.000000e+000,,,,,,,,,,,,,,32,1,4.000000e+000,5.088043e-001,0.000000e+000,0,,0,
1578524641.183,,0.000000e+000,2.225721e+002,1.538567e-004,0.000000e+000,3,5.109518e-001,0.000000e+000,,,,,,,,,,,,,,32,1,4.000000e+000,5.521088e-001,0.000000e+000,0,,0,
1578524700.233,,0.000000e+000,2.255972e+002,2.682531e-004,0.000000e+000,3,9.893799e-001,0.000000e+000,,,,,,,,,,,,,,32,1,4.000000e+000,5.826111e-001,0.000000e+000,0,,0,
1578524758.143,,0.000000e+000,2.285692e+002,2.860984e-004,0.000000e+000,3,8.213034e-001,0.000000e+000,,,,,,,,,,,,,,32,1,4.000000e+000,4.851990e-001,0.000000e+000,0,,0,
1578524816.323,,0.000000e+000,2.315272e+002,2.686070e-004,0.000000e+000,3,9.894052e-001,0.000000e+000,,,,,,,,,,,,,,32,1,4.000000e+000,5.763092e-001,0.000000e+000,0,,0,
1578524876.223,,0.000000e+000,2.345016e+002,2.685863e-004,0.000000e+000,3,9.893204e-001,0.000000e+000,,,,,,,,,,,,,,32,1,4.000000e+000,5.281982e-001,0.000000e+000,0,,0,
1578524935.993,,0.000000e+000,2.375822e+002,2.686411e-004,0.000000e+000,3,9.893677e-001,0.000000e+000,,,,,,,,,,,,,,32,1,4.000000e+000,5.679932e-001,0.000000e+000,0,,0,
1578524995.033,,0.000000e+000,2.405316e+002,2.686664e-004,0.000000e+000,3,9.895202e-001,0.000000e+000,,,,,,,,,,,,,,32,1,4.000000e+000,5.580902e-001,0.000000e+000,0,,0,
1578525055.333,,0.000000e+000,2.435091e+002,2.687137e-004,0.000000e+000,3,9.894853e-001,0.000000e+000,,,,,,,,,,,,,,32,1,4.000000e+000,5.991974e-001,0.000000e+000,0,,0,
1578525114.913,,0.000000e+000,2.465093e+002,2.687243e-004,0.000000e+000,3,9.891716e-001,0.000000e+000,,,,,,,,,,,,,,32,1,4.000000e+000,5.438080e-001,0.000000e+000,0,,0,
1578525174.913,,0.000000e+000,2.495172e+002,2.687442e-004,0.000000e+000,3,9.894933e-001,0.000000e+000,,,,,,,,,,,,,,32,1,4.000000e+000,5.764923e-001,0.000000e+000,0,,0,
1578525234.093,,0.000000e+000,2.524643e+002,2.685889e-004,0.000000e+000,3,9.896898e-001,0.000000e+000,,,,,,,,,,,,,,32,1,4.000000e+000,5.161896e-001,0.000000e+000,0,,0,
1578525295.193,,0.000000e+000,2.554633e+002,2.684053e-004,0.000000e+000,3,9.893907e-001,0.000000e+000,,,,,,,,,,,,,,32,1,4.000000e+000,5.583954e-001,0.000000e+000,0,,0,
1578525355.074,,0.000000e+000,2.585796e+002,2.683975e-004,0.000000e+000,3,9.892806e-001,0.000000e+000,,,,,,,,,,,,,,32,1,4.000000e+000,7.015991e-001,0.000000e+000,0,,0,
1578525409.444,,0.000000e+000,2.613781e+002,2.682508e-004,0.000000e+000,3,9.893399e-001,0.000000e+000,,,,,,,,,,,,,,32,1,4.000000e+000,4.549866e-001,0.000000e+000,0,,0,
1578525468.884,,0.000000e+000,2.644033e+002,2.680891e-004,0.000000e+000,3,9.892629e-001,0.000000e+000,,,,,,,,,,,,,,32,1,4.000000e+000,5.289001e-001,0.000000e+000,0,,0,
1578525533.484,,0.000000e+000,2.674385e+002,2.679403e-004,0.000000e+000,3,9.896144e-001,0.000000e+000,,,,,,,,,,,,,,32,1,4.000000e+000,4.999084e-001,0.000000e+000,0,,0,
1578525594.054,,0.000000e+000,2.704158e+002,2.676254e-004,0.000000e+000,3,9.897552e-001,0.000000e+000,,,,,,,,,,,,,,32,1,4.000000e+000,5.449829e-001,0.000000e+000,0,,0,
1578525655.274,,0.000000e+000,2.734393e+002,2.673516e-004,0.000000e+000,3,9.895408e-001,0.000000e+000,,,,,,,,,,,,,,32,1,4.000000e+000,5.585022e-001,0.000000e+000,0,,0,
1578525713.924,,0.000000e+000,2.764183e+002,2.672573e-004,0.000000e+000,3,9.896509e-001,0.000000e+000,,,,,,,,,,,,,,32,1,4.000000e+000,5.606079e-001,0.000000e+000,0,,0,
1578525772.054,,0.000000e+000,2.793817e+002,2.670288e-004,0.000000e+000,3,9.896621e-001,0.000000e+000,,,,,,,,,,,,,,32,1,4.000000e+000,5.036011e-001,0.000000e+000,0,,0,
1578525833.014,,0.000000e+000,2.823561e+002,2.666915e-004,0.000000e+000,3,9.897637e-001,0.000000e+000,,,,,,,,,,,,,,32,1,4.000000e+000,5.394897e-001,0.000000e+000,0,,0,
1578525892.364,,0.000000e+000,2.853826e+002,2.663400e-004,0.000000e+000,3,9.898016e-001,0.000000e+000,,,,,,,,,,,,,,32,1,4.000000e+000,5.890808e-001,0.000000e+000,0,,0,
1578525951.904,,0.000000e+000,2.883365e+002,2.660282e-004,0.000000e+000,3,9.897757e-001,0.000000e+000,,,,,,,,,,,,,,32,1,4.000000e+000,5.523071e-001,0.000000e+000,0,,0,
1578526012.034,,0.000000e+000,2.913391e+002,2.656852e-004,0.000000e+000,3,9.894314e-001,0.000000e+000,,,,,,,,,,,,,,32,1,4.000000e+000,4.495239e-001,0.000000e+000,0,,0,
1578526071.595,,0.000000e+000,2.943322e+002,2.653852e-004,0.000000e+000,3,9.895442e-001,0.000000e+000,,,,,,,,,,,,,,32,1,4.000000e+000,5.777893e-001,0.000000e+000,0,,0,
1578526131.835,,0.000000e+000,2.973268e+002,2.649270e-004,0.000000e+000,3,9.900416e-001,0.000000e+000,,,,,,,,,,,,,,32,1,4.000000e+000,4.446106e-001,0.000000e+000,0,,0,
1578526426.665,,0.000000e+000,2.999722e+002,2.642238e-004,0.000000e+000,3,9.900100e-001,0.000000e+000,,,,,,,,,,,,,,32,1,4.000000e+000,1.370239e-002,0.000000e+000,0,,0,