File: data/Rock_mag/2020_IRM_data_files/Raw_data/MPMS_5S/data/AX3-2r-ni_FC-ZFC-RTSIRM-10K.dc.dat
[Header]
TITLE,MPMS DC Measurement
BYAPP,MPMS Measurement,2.1,Summary
FILEOPENTIME, 1578331103.232000 1/6/2020, 11:18:23 AM

INFO, APPNAME, MPMS MultiVu Application, Revision 1.61,  Build 082

INFO, NAME, AX3-2r-ni
INFO, WEIGHT, 1.000
INFO, AREA, 1.000
INFO, LENGTH, 1.000
INFO, SHAPE, 0
INFO, COMMENT,
INFO, SEQUENCE FILE: FC-ZFC LTSIRM and RTSIRM LTD 10K.seq


INFO, BACKGROUND DATA FILE:, None


STARTUPAXIS,X,4,LINEAR,AUTO,0.000000,0.000000
STARTUPAXIS,Y1,5,LINEAR,AUTO,0.000000,0.000000


STARTUPGROUP,Longitudinal
FIELDGROUP,Longitudinal,1,2,3,4,5,6,7,8,9,15,16,17,18,27,28
FIELDGROUP,Transverse,1,2,3,4,10,11,12,13,14,19,20,21,22,27,28

PLOT_APPEARANCE,ALL,HORZ_GRID_ON,VERT_GRID_ON,MARKERS_AND_LINES

[Data]
Time,Comment,Field (Oe),Temperature (K),Long Moment (emu),Long Scan Std Dev,Long Algorithm,Long Reg Fit,Long Percent Error (%),Trans Moment (emu),Trans Scan Std Dev,Trans Algorithm,Trans Reg Fit,Trans Percent Error (%),Long Moment [w/o ABS] (emu),Long Scan Std Dev [w/o ABS],Long Reg Fit [w/o ABS],Long Percent Error [w/o ABS] (%),Trans Moment [w/o ABS] (emu),Trans Scan Std Dev [w/o ABS],Trans Reg Fit [w/o ABS],Trans Percent Error [w/o ABS] (%),Points per Scan,Scans per Measurement,Scan Length (cm),Delta Temp (K),Rot Position (deg),Error,EC Comp. Running,Using ABS,
1578331103.232,,0.000000e+000,9.993249e+000,1.474989e-005,0.000000e+000,3,9.668795e-001,0.000000e+000,,,,,,,,,,,,,,32,1,4.000000e+000,5.270004e-003,0.000000e+000,0,,0,
1578331186.222,,0.000000e+000,1.561626e+001,1.218291e-005,0.000000e+000,3,9.645798e-001,0.000000e+000,,,,,,,,,,,,,,32,1,4.000000e+000,9.512701e-001,0.000000e+000,0,,0,
1578331245.702,,0.000000e+000,2.050278e+001,1.030070e-005,0.000000e+000,3,9.655507e-001,0.000000e+000,,,,,,,,,,,,,,32,1,4.000000e+000,9.741707e-001,0.000000e+000,0,,0,
1578331307.922,,0.000000e+000,2.565661e+001,9.063959e-006,0.000000e+000,3,9.664163e-001,0.000000e+000,,,,,,,,,,,,,,32,1,4.000000e+000,9.102993e-001,0.000000e+000,0,,0,
1578331367.402,,0.000000e+000,3.053091e+001,8.542494e-006,0.000000e+000,3,9.620886e-001,0.000000e+000,,,,,,,,,,,,,,32,1,4.000000e+000,9.528103e-001,0.000000e+000,0,,0,
1578331428.982,,0.000000e+000,3.552697e+001,8.055051e-006,0.000000e+000,3,9.550351e-001,0.000000e+000,,,,,,,,,,,,,,32,1,4.000000e+000,9.349899e-001,0.000000e+000,0,,0,
1578331515.402,,0.000000e+000,4.273252e+001,7.520535e-006,0.000000e+000,3,9.590811e-001,0.000000e+000,,,,,,,,,,,,,,32,1,4.000000e+000,9.916000e-001,0.000000e+000,0,,0,
1578331549.932,,0.000000e+000,4.562766e+001,7.437523e-006,0.000000e+000,3,9.621105e-001,0.000000e+000,,,,,,,,,,,,,,32,1,4.000000e+000,9.248505e-001,0.000000e+000,0,,0,
1578331609.182,,0.000000e+000,5.050727e+001,7.320641e-006,0.000000e+000,3,9.619468e-001,0.000000e+000,,,,,,,,,,,,,,32,1,4.000000e+000,8.971214e-001,0.000000e+000,0,,0,
1578331670.892,,0.000000e+000,5.550976e+001,6.952641e-006,0.000000e+000,3,9.716215e-001,0.000000e+000,,,,,,,,,,,,,,32,1,4.000000e+000,8.685799e-001,0.000000e+000,0,,0,
1578331728.882,,0.000000e+000,6.043548e+001,7.040277e-006,0.000000e+000,3,9.504508e-001,0.000000e+000,,,,,,,,,,,,,,32,1,4.000000e+000,8.644218e-001,0.000000e+000,0,,0,
1578331789.953,,0.000000e+000,6.560880e+001,6.946589e-006,0.000000e+000,3,9.589490e-001,0.000000e+000,,,,,,,,,,,,,,32,1,4.000000e+000,9.085999e-001,0.000000e+000,0,,0,
1578331862.373,,0.000000e+000,7.158711e+001,6.621216e-006,0.000000e+000,3,9.486678e-001,0.000000e+000,,,,,,,,,,,,,,32,1,4.000000e+000,9.683990e-001,0.000000e+000,0,,0,
1578331908.373,,0.000000e+000,7.547298e+001,6.619443e-006,0.000000e+000,3,9.584083e-001,0.000000e+000,,,,,,,,,,,,,,32,1,4.000000e+000,8.096848e-001,0.000000e+000,0,,0,
1578331968.223,,0.000000e+000,8.055750e+001,6.453181e-006,0.000000e+000,3,9.600269e-001,0.000000e+000,,,,,,,,,,,,,,32,1,4.000000e+000,9.107208e-001,0.000000e+000,0,,0,
1578332028.973,,0.000000e+000,8.561544e+001,6.274807e-006,0.000000e+000,3,9.560061e-001,0.000000e+000,,,,,,,,,,,,,,32,1,4.000000e+000,9.903259e-001,0.000000e+000,0,,0,
1578332086.493,,0.000000e+000,9.044061e+001,5.973892e-006,0.000000e+000,3,9.584826e-001,0.000000e+000,,,,,,,,,,,,,,32,1,4.000000e+000,8.760147e-001,0.000000e+000,0,,0,
1578332148.833,,0.000000e+000,9.563927e+001,5.520870e-006,0.000000e+000,3,9.539666e-001,0.000000e+000,,,,,,,,,,,,,,32,1,4.000000e+000,8.653183e-001,0.000000e+000,0,,0,
1578332208.153,,0.000000e+000,1.006413e+002,4.804192e-006,0.000000e+000,3,9.498221e-001,0.000000e+000,,,,,,,,,,,,,,32,1,4.000000e+000,9.187012e-001,0.000000e+000,0,,0,
1578332266.603,,0.000000e+000,1.054977e+002,4.404237e-006,0.000000e+000,3,9.509475e-001,0.000000e+000,,,,,,,,,,,,,,32,1,4.000000e+000,9.826965e-001,0.000000e+000,0,,0,
1578332325.853,,0.000000e+000,1.104891e+002,4.162482e-006,0.000000e+000,3,9.469006e-001,0.000000e+000,,,,,,,,,,,,,,32,1,4.000000e+000,8.440018e-001,0.000000e+000,0,,0,
1578332400.813,,0.000000e+000,1.166981e+002,3.884186e-006,0.000000e+000,3,9.477406e-001,0.000000e+000,,,,,,,,,,,,,,32,1,4.000000e+000,8.427963e-001,0.000000e+000,0,,0,
1578332445.873,,0.000000e+000,1.204786e+002,3.865901e-006,0.000000e+000,3,9.460779e-001,0.000000e+000,,,,,,,,,,,,,,32,1,4.000000e+000,8.748016e-001,0.000000e+000,0,,0,
1578332508.354,,0.000000e+000,1.255647e+002,3.604582e-006,0.000000e+000,3,9.463081e-001,0.000000e+000,,,,,,,,,,,,,,32,1,4.000000e+000,9.962997e-001,0.000000e+000,0,,0,
1578332571.584,,0.000000e+000,1.303362e+002,3.487566e-006,0.000000e+000,3,9.478745e-001,0.000000e+000,,,,,,,,,,,,,,32,1,4.000000e+000,5.629120e-001,0.000000e+000,0,,0,
1578332642.724,,0.000000e+000,1.355202e+002,3.408963e-006,0.000000e+000,3,9.351713e-001,0.000000e+000,,,,,,,,,,,,,,32,1,4.000000e+000,9.281006e-001,0.000000e+000,0,,0,
1578332700.114,,0.000000e+000,1.406289e+002,3.349910e-006,0.000000e+000,3,9.472625e-001,0.000000e+000,,,,,,,,,,,,,,32,1,4.000000e+000,1.066696e+000,0.000000e+000,0,,0,
1578332780.604,,0.000000e+000,1.479810e+002,3.143108e-006,0.000000e+000,3,9.286190e-001,0.000000e+000,,,,,,,,,,,,,,32,1,4.000000e+000,9.313049e-001,0.000000e+000,0,,0,
1578332809.324,,0.000000e+000,1.506182e+002,3.146934e-006,0.000000e+000,3,9.194819e-001,0.000000e+000,,,,,,,,,,,,,,32,1,4.000000e+000,9.196014e-001,0.000000e+000,0,,0,
1578332863.854,,0.000000e+000,1.554892e+002,3.124436e-006,0.000000e+000,3,9.355227e-001,0.000000e+000,,,,,,,,,,,,,,32,1,4.000000e+000,8.768005e-001,0.000000e+000,0,,0,
1578332936.224,,0.000000e+000,1.619189e+002,3.053050e-006,0.000000e+000,3,9.317218e-001,0.000000e+000,,,,,,,,,,,,,,32,1,4.000000e+000,7.303009e-001,0.000000e+000,0,,0,
1578332978.814,,0.000000e+000,1.654939e+002,3.065647e-006,0.000000e+000,3,9.224437e-001,0.000000e+000,,,,,,,,,,,,,,32,1,4.000000e+000,8.600006e-001,0.000000e+000,0,,0,
1578333037.774,,0.000000e+000,1.704572e+002,3.061230e-006,0.000000e+000,3,9.318081e-001,0.000000e+000,,,,,,,,,,,,,,32,1,4.000000e+000,8.372955e-001,0.000000e+000,0,,0,
1578333102.694,,0.000000e+000,1.755051e+002,3.011234e-006,0.000000e+000,3,9.433339e-001,0.000000e+000,,,,,,,,,,,,,,32,1,4.000000e+000,8.785095e-001,0.000000e+000,0,,0,
1578333156.574,,0.000000e+000,1.806541e+002,2.938023e-006,0.000000e+000,3,9.299489e-001,0.000000e+000,,,,,,,,,,,,,,32,1,4.000000e+000,1.004791e+000,0.000000e+000,0,,0,
1578333221.165,,0.000000e+000,1.854612e+002,2.873058e-006,0.000000e+000,3,9.324379e-001,0.000000e+000,,,,,,,,,,,,,,32,1,4.000000e+000,7.461090e-001,0.000000e+000,0,,0,
1578333288.375,,0.000000e+000,1.904893e+002,2.853911e-006,0.000000e+000,3,9.240696e-001,0.000000e+000,,,,,,,,,,,,,,32,1,4.000000e+000,8.764954e-001,0.000000e+000,0,,0,
1578333350.865,,0.000000e+000,1.954943e+002,2.861605e-006,0.000000e+000,3,9.454981e-001,0.000000e+000,,,,,,,,,,,,,,32,1,4.000000e+000,9.629974e-001,0.000000e+000,0,,0,
1578333405.735,,0.000000e+000,2.004945e+002,2.740020e-006,0.000000e+000,3,9.064673e-001,0.000000e+000,,,,,,,,,,,,,,32,1,4.000000e+000,8.126984e-001,0.000000e+000,0,,0,
1578333466.655,,0.000000e+000,2.055443e+002,2.809941e-006,0.000000e+000,3,9.294873e-001,0.000000e+000,,,,,,,,,,,,,,32,1,4.000000e+000,8.554077e-001,0.000000e+000,0,,0,
1578333525.375,,0.000000e+000,2.107228e+002,2.784167e-006,0.000000e+000,3,9.329399e-001,0.000000e+000,,,,,,,,,,,,,,32,1,4.000000e+000,9.972076e-001,0.000000e+000,0,,0,
1578333583.745,,0.000000e+000,2.154630e+002,2.690277e-006,0.000000e+000,3,9.392876e-001,0.000000e+000,,,,,,,,,,,,,,32,1,4.000000e+000,8.908081e-001,0.000000e+000,0,,0,
1578333645.385,,0.000000e+000,2.205314e+002,2.571986e-006,0.000000e+000,3,9.070480e-001,0.000000e+000,,,,,,,,,,,,,,32,1,4.000000e+000,9.704895e-001,0.000000e+000,0,,0,
1578333703.795,,0.000000e+000,2.255354e+002,2.619411e-006,0.000000e+000,3,8.949192e-001,0.000000e+000,,,,,,,,,,,,,,32,1,4.000000e+000,1.061493e+000,0.000000e+000,0,,0,
1578333763.885,,0.000000e+000,2.305238e+002,2.612956e-006,0.000000e+000,3,9.432319e-001,0.000000e+000,,,,,,,,,,,,,,32,1,4.000000e+000,8.718872e-001,0.000000e+000,0,,0,
1578333825.035,,0.000000e+000,2.356000e+002,2.539927e-006,0.000000e+000,3,8.998524e-001,0.000000e+000,,,,,,,,,,,,,,32,1,4.000000e+000,8.003998e-001,0.000000e+000,0,,0,
1578333884.716,,0.000000e+000,2.405744e+002,2.509025e-006,0.000000e+000,3,9.237162e-001,0.000000e+000,,,,,,,,,,,,,,32,1,4.000000e+000,8.796997e-001,0.000000e+000,0,,0,
1578333932.866,,0.000000e+000,2.456889e+002,2.486853e-006,0.000000e+000,3,9.226729e-001,0.000000e+000,,,,,,,,,,,,,,32,1,4.000000e+000,1.221497e+000,0.000000e+000,0,,0,
1578333999.936,,0.000000e+000,2.515533e+002,2.414078e-006,0.000000e+000,3,9.046729e-001,0.000000e+000,,,,,,,,,,,,,,32,1,4.000000e+000,9.127045e-001,0.000000e+000,0,,0,
1578334050.986,,0.000000e+000,2.554299e+002,2.408513e-006,0.000000e+000,3,9.224582e-001,0.000000e+000,,,,,,,,,,,,,,32,1,4.000000e+000,7.796021e-001,0.000000e+000,0,,0,
1578334117.316,,0.000000e+000,2.605070e+002,2.394235e-006,0.000000e+000,3,9.323990e-001,0.000000e+000,,,,,,,,,,,,,,32,1,4.000000e+000,7.831116e-001,0.000000e+000,0,,0,
1578334181.116,,0.000000e+000,2.655814e+002,2.354646e-006,0.000000e+000,3,9.221994e-001,0.000000e+000,,,,,,,,,,,,,,32,1,4.000000e+000,8.273926e-001,0.000000e+000,0,,0,
1578334267.016,,0.000000e+000,2.725052e+002,2.261386e-006,0.000000e+000,3,9.042660e-001,0.000000e+000,,,,,,,,,,,,,,32,1,4.000000e+000,9.534912e-001,0.000000e+000,0,,0,
1578334302.966,,0.000000e+000,2.755579e+002,2.367264e-006,0.000000e+000,3,9.086363e-001,0.000000e+000,,,,,,,,,,,,,,32,1,4.000000e+000,8.634949e-001,0.000000e+000,0,,0,
1578334376.496,,0.000000e+000,2.816454e+002,2.306003e-006,0.000000e+000,3,9.286763e-001,0.000000e+000,,,,,,,,,,,,,,32,1,4.000000e+000,1.025299e+000,0.000000e+000,0,,0,
1578334422.436,,0.000000e+000,2.854628e+002,2.163681e-006,0.000000e+000,3,9.097607e-001,0.000000e+000,,,,,,,,,,,,,,32,1,4.000000e+000,8.965149e-001,0.000000e+000,0,,0,
1578334482.356,,0.000000e+000,2.904821e+002,2.282417e-006,0.000000e+000,3,9.277012e-001,0.000000e+000,,,,,,,,,,,,,,32,1,4.000000e+000,9.057922e-001,0.000000e+000,0,,0,
1578334552.486,,0.000000e+000,2.954201e+002,2.197033e-006,0.000000e+000,3,9.083676e-001,0.000000e+000,,,,,,,,,,,,,,32,1,4.000000e+000,7.810059e-001,0.000000e+000,0,,0,
1578334929.107,,0.000000e+000,3.000132e+002,2.187316e-006,0.000000e+000,3,9.141821e-001,0.000000e+000,,,,,,,,,,,,,,32,1,4.000000e+000,4.110718e-002,0.000000e+000,0,,0,
1578339934.704,,0.000000e+000,9.996411e+000,1.183141e-005,0.000000e+000,3,9.703110e-001,0.000000e+000,,,,,,,,,,,,,,32,1,4.000000e+000,6.853104e-003,0.000000e+000,0,,0,
1578340017.274,,0.000000e+000,1.552329e+001,9.744079e-006,0.000000e+000,3,9.630120e-001,0.000000e+000,,,,,,,,,,,,,,32,1,4.000000e+000,9.544296e-001,0.000000e+000,0,,0,
1578340077.314,,0.000000e+000,2.060714e+001,8.485717e-006,0.000000e+000,3,9.622689e-001,0.000000e+000,,,,,,,,,,,,,,32,1,4.000000e+000,8.944912e-001,0.000000e+000,0,,0,
1578340137.824,,0.000000e+000,2.551690e+001,7.683841e-006,0.000000e+000,3,9.508051e-001,0.000000e+000,,,,,,,,,,,,,,32,1,4.000000e+000,8.422890e-001,0.000000e+000,0,,0,
1578340198.164,,0.000000e+000,3.048044e+001,7.305442e-006,0.000000e+000,3,9.600706e-001,0.000000e+000,,,,,,,,,,,,,,32,1,4.000000e+000,8.819599e-001,0.000000e+000,0,,0,
1578340259.564,,0.000000e+000,3.550955e+001,7.091033e-006,0.000000e+000,3,9.518372e-001,0.000000e+000,,,,,,,,,,,,,,32,1,4.000000e+000,9.361916e-001,0.000000e+000,0,,0,
1578340320.185,,0.000000e+000,4.050240e+001,6.875028e-006,0.000000e+000,3,9.670939e-001,0.000000e+000,,,,,,,,,,,,,,32,1,4.000000e+000,8.263016e-001,0.000000e+000,0,,0,
1578340381.295,,0.000000e+000,4.556475e+001,6.809081e-006,0.000000e+000,3,9.595871e-001,0.000000e+000,,,,,,,,,,,,,,32,1,4.000000e+000,1.020599e+000,0.000000e+000,0,,0,
1578340440.685,,0.000000e+000,5.052740e+001,6.615828e-006,0.000000e+000,3,9.507055e-001,0.000000e+000,,,,,,,,,,,,,,32,1,4.000000e+000,8.084183e-001,0.000000e+000,0,,0,
1578340502.135,,0.000000e+000,5.560911e+001,6.653439e-006,0.000000e+000,3,9.532871e-001,0.000000e+000,,,,,,,,,,,,,,32,1,4.000000e+000,9.596214e-001,0.000000e+000,0,,0,
1578340561.025,,0.000000e+000,6.053083e+001,6.521070e-006,0.000000e+000,3,9.569127e-001,0.000000e+000,,,,,,,,,,,,,,32,1,4.000000e+000,9.229584e-001,0.000000e+000,0,,0,
1578340621.035,,0.000000e+000,6.549399e+001,6.452334e-006,0.000000e+000,3,9.591948e-001,0.000000e+000,,,,,,,,,,,,,,32,1,4.000000e+000,8.899307e-001,0.000000e+000,0,,0,
1578340682.505,,0.000000e+000,7.066824e+001,6.340253e-006,0.000000e+000,3,9.615093e-001,0.000000e+000,,,,,,,,,,,,,,32,1,4.000000e+000,1.024780e+000,0.000000e+000,0,,0,
1578340740.735,,0.000000e+000,7.554491e+001,6.150317e-006,0.000000e+000,3,9.493256e-001,0.000000e+000,,,,,,,,,,,,,,32,1,4.000000e+000,1.007507e+000,0.000000e+000,0,,0,
1578340801.285,,0.000000e+000,8.066511e+001,6.035003e-006,0.000000e+000,3,9.591793e-001,0.000000e+000,,,,,,,,,,,,,,32,1,4.000000e+000,9.807281e-001,0.000000e+000,0,,0,
1578340860.645,,0.000000e+000,8.560989e+001,5.895810e-006,0.000000e+000,3,9.623118e-001,0.000000e+000,,,,,,,,,,,,,,32,1,4.000000e+000,9.663696e-001,0.000000e+000,0,,0,
1578340920.755,,0.000000e+000,9.062054e+001,5.679713e-006,0.000000e+000,3,9.457782e-001,0.000000e+000,,,,,,,,,,,,,,32,1,4.000000e+000,9.397507e-001,0.000000e+000,0,,0,
1578340979.415,,0.000000e+000,9.551281e+001,5.369493e-006,0.000000e+000,3,9.453897e-001,0.000000e+000,,,,,,,,,,,,,,32,1,4.000000e+000,9.994049e-001,0.000000e+000,0,,0,
1578341040.116,,0.000000e+000,1.005468e+002,4.546626e-006,0.000000e+000,3,9.543445e-001,0.000000e+000,,,,,,,,,,,,,,32,1,4.000000e+000,9.052963e-001,0.000000e+000,0,,0,
1578341099.706,,0.000000e+000,1.055625e+002,4.298220e-006,0.000000e+000,3,9.419772e-001,0.000000e+000,,,,,,,,,,,,,,32,1,4.000000e+000,1.003204e+000,0.000000e+000,0,,0,
1578341159.586,,0.000000e+000,1.104964e+002,4.037087e-006,0.000000e+000,3,9.355955e-001,0.000000e+000,,,,,,,,,,,,,,32,1,4.000000e+000,9.077988e-001,0.000000e+000,0,,0,
1578341220.696,,0.000000e+000,1.156188e+002,3.870371e-006,0.000000e+000,3,9.505255e-001,0.000000e+000,,,,,,,,,,,,,,32,1,4.000000e+000,1.043701e+000,0.000000e+000,0,,0,
1578341282.156,,0.000000e+000,1.204911e+002,3.647740e-006,0.000000e+000,3,9.340416e-001,0.000000e+000,,,,,,,,,,,,,,32,1,4.000000e+000,8.833008e-001,0.000000e+000,0,,0,
1578341347.846,,0.000000e+000,1.254422e+002,3.427512e-006,0.000000e+000,3,9.364514e-001,0.000000e+000,,,,,,,,,,,,,,32,1,4.000000e+000,7.784958e-001,0.000000e+000,0,,0,
1578341404.886,,0.000000e+000,1.311356e+002,3.509748e-006,0.000000e+000,3,9.330669e-001,0.000000e+000,,,,,,,,,,,,,,32,1,4.000000e+000,9.676056e-001,0.000000e+000,0,,0,
1578341454.476,,0.000000e+000,1.354149e+002,3.305833e-006,0.000000e+000,3,9.372566e-001,0.000000e+000,,,,,,,,,,,,,,32,1,4.000000e+000,7.696991e-001,0.000000e+000,0,,0,
1578341521.356,,0.000000e+000,1.406546e+002,3.267159e-006,0.000000e+000,3,9.554951e-001,0.000000e+000,,,,,,,,,,,,,,32,1,4.000000e+000,1.129196e+000,0.000000e+000,0,,0,
1578341580.666,,0.000000e+000,1.454711e+002,3.212851e-006,0.000000e+000,3,9.208930e-001,0.000000e+000,,,,,,,,,,,,,,32,1,4.000000e+000,8.818054e-001,0.000000e+000,0,,0,
1578341641.746,,0.000000e+000,1.505472e+002,3.134283e-006,0.000000e+000,3,9.422505e-001,0.000000e+000,,,,,,,,,,,,,,32,1,4.000000e+000,9.833984e-001,0.000000e+000,0,,0,
1578341689.716,,0.000000e+000,1.557046e+002,3.093659e-006,0.000000e+000,3,9.375865e-001,0.000000e+000,,,,,,,,,,,,,,32,1,4.000000e+000,1.197708e+000,0.000000e+000,0,,0,
1578341743.287,,0.000000e+000,1.605180e+002,3.068415e-006,0.000000e+000,3,9.320385e-001,0.000000e+000,,,,,,,,,,,,,,32,1,4.000000e+000,9.125977e-001,0.000000e+000,0,,0,
1578341807.457,,0.000000e+000,1.655412e+002,3.027664e-006,0.000000e+000,3,9.418207e-001,0.000000e+000,,,,,,,,,,,,,,32,1,4.000000e+000,9.620972e-001,0.000000e+000,0,,0,
1578341871.707,,0.000000e+000,1.704468e+002,3.014666e-006,0.000000e+000,3,9.223250e-001,0.000000e+000,,,,,,,,,,,,,,32,1,4.000000e+000,8.661957e-001,0.000000e+000,0,,0,
1578341935.797,,0.000000e+000,1.755181e+002,2.937550e-006,0.000000e+000,3,9.319282e-001,0.000000e+000,,,,,,,,,,,,,,32,1,4.000000e+000,7.907104e-001,0.000000e+000,0,,0,
1578342007.967,,0.000000e+000,1.804398e+002,2.930353e-006,0.000000e+000,3,9.275244e-001,0.000000e+000,,,,,,,,,,,,,,32,1,4.000000e+000,7.890015e-001,0.000000e+000,0,,0,
1578342069.957,,0.000000e+000,1.855797e+002,2.914250e-006,0.000000e+000,3,9.417197e-001,0.000000e+000,,,,,,,,,,,,,,32,1,4.000000e+000,9.632874e-001,0.000000e+000,0,,0,
1578342127.517,,0.000000e+000,1.910122e+002,2.826897e-006,0.000000e+000,3,9.324110e-001,0.000000e+000,,,,,,,,,,,,,,32,1,4.000000e+000,9.492950e-001,0.000000e+000,0,,0,
1578342181.267,,0.000000e+000,1.956369e+002,2.822412e-006,0.000000e+000,3,9.413002e-001,0.000000e+000,,,,,,,,,,,,,,32,1,4.000000e+000,1.074097e+000,0.000000e+000,0,,0,
1578342237.777,,0.000000e+000,2.005986e+002,2.770817e-006,0.000000e+000,3,9.111485e-001,0.000000e+000,,,,,,,,,,,,,,32,1,4.000000e+000,9.404907e-001,0.000000e+000,0,,0,
1578342294.967,,0.000000e+000,2.056446e+002,2.683142e-006,0.000000e+000,3,9.367071e-001,0.000000e+000,,,,,,,,,,,,,,32,1,4.000000e+000,9.109039e-001,0.000000e+000,0,,0,
1578342353.067,,0.000000e+000,2.104894e+002,2.807515e-006,0.000000e+000,3,9.400082e-001,0.000000e+000,,,,,,,,,,,,,,32,1,4.000000e+000,8.354034e-001,0.000000e+000,0,,0,
1578342413.427,,0.000000e+000,2.154962e+002,2.802828e-006,0.000000e+000,3,9.284537e-001,0.000000e+000,,,,,,,,,,,,,,32,1,4.000000e+000,8.106995e-001,0.000000e+000,0,,0,
1578342474.768,,0.000000e+000,2.206230e+002,2.688024e-006,0.000000e+000,3,9.336713e-001,0.000000e+000,,,,,,,,,,,,,,32,1,4.000000e+000,9.854126e-001,0.000000e+000,0,,0,
1578342532.098,,0.000000e+000,2.254799e+002,2.745971e-006,0.000000e+000,3,9.230824e-001,0.000000e+000,,,,,,,,,,,,,,32,1,4.000000e+000,9.209137e-001,0.000000e+000,0,,0,
1578342587.208,,0.000000e+000,2.307523e+002,2.640672e-006,0.000000e+000,3,9.376624e-001,0.000000e+000,,,,,,,,,,,,,,32,1,4.000000e+000,1.159912e+000,0.000000e+000,0,,0,
1578342641.418,,0.000000e+000,2.356125e+002,2.612200e-006,0.000000e+000,3,9.323202e-001,0.000000e+000,,,,,,,,,,,,,,32,1,4.000000e+000,9.379120e-001,0.000000e+000,0,,0,
1578342702.828,,0.000000e+000,2.404389e+002,2.618576e-006,0.000000e+000,3,9.346339e-001,0.000000e+000,,,,,,,,,,,,,,32,1,4.000000e+000,7.940979e-001,0.000000e+000,0,,0,
1578342769.078,,0.000000e+000,2.455155e+002,2.577299e-006,0.000000e+000,3,8.994368e-001,0.000000e+000,,,,,,,,,,,,,,32,1,4.000000e+000,8.218994e-001,0.000000e+000,0,,0,
1578342832.998,,0.000000e+000,2.505793e+002,2.528887e-006,0.000000e+000,3,9.119140e-001,0.000000e+000,,,,,,,,,,,,,,32,1,4.000000e+000,7.572937e-001,0.000000e+000,0,,0,
1578342893.438,,0.000000e+000,2.555215e+002,2.622850e-006,0.000000e+000,3,9.342918e-001,0.000000e+000,,,,,,,,,,,,,,32,1,4.000000e+000,8.668976e-001,0.000000e+000,0,,0,
1578342955.378,,0.000000e+000,2.606026e+002,2.567231e-006,0.000000e+000,3,9.263304e-001,0.000000e+000,,,,,,,,,,,,,,32,1,4.000000e+000,9.343872e-001,0.000000e+000,0,,0,
1578343017.368,,0.000000e+000,2.654136e+002,2.465221e-006,0.000000e+000,3,9.246174e-001,0.000000e+000,,,,,,,,,,,,,,32,1,4.000000e+000,6.380005e-001,0.000000e+000,0,,0,
1578343089.458,,0.000000e+000,2.705528e+002,2.494613e-006,0.000000e+000,3,8.923984e-001,0.000000e+000,,,,,,,,,,,,,,32,1,4.000000e+000,9.711914e-001,0.000000e+000,0,,0,
1578343147.918,,0.000000e+000,2.755298e+002,2.401411e-006,0.000000e+000,3,9.099372e-001,0.000000e+000,,,,,,,,,,,,,,32,1,4.000000e+000,1.011108e+000,0.000000e+000,0,,0,
1578343205.299,,0.000000e+000,2.807721e+002,2.392799e-006,0.000000e+000,3,9.036643e-001,0.000000e+000,,,,,,,,,,,,,,32,1,4.000000e+000,9.827881e-001,0.000000e+000,0,,0,
1578343256.619,,0.000000e+000,2.855182e+002,2.470499e-006,0.000000e+000,3,9.051389e-001,0.000000e+000,,,,,,,,,,,,,,32,1,4.000000e+000,1.007507e+000,0.000000e+000,0,,0,
1578343314.009,,0.000000e+000,2.908534e+002,2.358570e-006,0.000000e+000,3,9.175270e-001,0.000000e+000,,,,,,,,,,,,,,32,1,4.000000e+000,1.292206e+000,0.000000e+000,0,,0,
1578343372.439,,0.000000e+000,2.955860e+002,2.409798e-006,0.000000e+000,3,9.430138e-001,0.000000e+000,,,,,,,,,,,,,,32,1,4.000000e+000,9.542236e-001,0.000000e+000,0,,0,
1578343741.129,,0.000000e+000,3.000406e+002,2.260645e-006,0.000000e+000,3,9.073417e-001,0.000000e+000,,,,,,,,,,,,,,32,1,4.000000e+000,1.367188e-002,0.000000e+000,0,,0,
1578344285.520,,0.000000e+000,3.000064e+002,4.318149e-006,0.000000e+000,3,9.396618e-001,0.000000e+000,,,,,,,,,,,,,,32,1,4.000000e+000,2.740479e-002,0.000000e+000,0,,0,
1578344482.540,,0.000000e+000,2.944115e+002,4.117935e-006,0.000000e+000,3,9.459845e-001,0.000000e+000,,,,,,,,,,,,,,32,1,4.000000e+000,9.459839e-001,0.000000e+000,0,,0,
1578344545.140,,0.000000e+000,2.893455e+002,4.224331e-006,0.000000e+000,3,9.574260e-001,0.000000e+000,,,,,,,,,,,,,,32,1,4.000000e+000,1.138397e+000,0.000000e+000,0,,0,
1578344599.991,,0.000000e+000,2.843508e+002,4.205461e-006,0.000000e+000,3,9.550568e-001,0.000000e+000,,,,,,,,,,,,,,32,1,4.000000e+000,1.229706e+000,0.000000e+000,0,,0,
1578344653.311,,0.000000e+000,2.793766e+002,4.200660e-006,0.000000e+000,3,9.492615e-001,0.000000e+000,,,,,,,,,,,,,,32,1,4.000000e+000,1.007202e+000,0.000000e+000,0,,0,
1578344707.051,,0.000000e+000,2.743259e+002,4.215156e-006,0.000000e+000,3,9.414274e-001,0.000000e+000,,,,,,,,,,,,,,32,1,4.000000e+000,1.125092e+000,0.000000e+000,0,,0,
1578344762.791,,0.000000e+000,2.692991e+002,4.130628e-006,0.000000e+000,3,9.488822e-001,0.000000e+000,,,,,,,,,,,,,,32,1,4.000000e+000,1.101715e+000,0.000000e+000,0,,0,
1578344819.331,,0.000000e+000,2.643990e+002,4.172329e-006,0.000000e+000,3,9.459227e-001,0.000000e+000,,,,,,,,,,,,,,32,1,4.000000e+000,1.057800e+000,0.000000e+000,0,,0,
1578344882.251,,0.000000e+000,2.592293e+002,4.149370e-006,0.000000e+000,3,9.563006e-001,0.000000e+000,,,,,,,,,,,,,,32,1,4.000000e+000,1.132507e+000,0.000000e+000,0,,0,
1578344945.331,,0.000000e+000,2.543481e+002,4.208750e-006,0.000000e+000,3,9.597170e-001,0.000000e+000,,,,,,,,,,,,,,32,1,4.000000e+000,1.153992e+000,0.000000e+000,0,,0,
1578345011.011,,0.000000e+000,2.495177e+002,4.192819e-006,0.000000e+000,3,9.467404e-001,0.000000e+000,,,,,,,,,,,,,,32,1,4.000000e+000,8.511047e-001,0.000000e+000,0,,0,
1578345079.681,,0.000000e+000,2.443728e+002,4.117635e-006,0.000000e+000,3,9.414403e-001,0.000000e+000,,,,,,,,,,,,,,32,1,4.000000e+000,1.023804e+000,0.000000e+000,0,,0,
1578345146.521,,0.000000e+000,2.395137e+002,4.187876e-006,0.000000e+000,3,9.484801e-001,0.000000e+000,,,,,,,,,,,,,,32,1,4.000000e+000,9.216003e-001,0.000000e+000,0,,0,
1578345215.841,,0.000000e+000,2.343946e+002,4.165364e-006,0.000000e+000,3,9.371226e-001,0.000000e+000,,,,,,,,,,,,,,32,1,4.000000e+000,1.063400e+000,0.000000e+000,0,,0,
1578345281.101,,0.000000e+000,2.294872e+002,4.227181e-006,0.000000e+000,3,9.627210e-001,0.000000e+000,,,,,,,,,,,,,,32,1,4.000000e+000,9.707947e-001,0.000000e+000,0,,0,
1578345346.552,,0.000000e+000,2.244389e+002,4.122533e-006,0.000000e+000,3,9.421787e-001,0.000000e+000,,,,,,,,,,,,,,32,1,4.000000e+000,9.850006e-001,0.000000e+000,0,,0,
1578345410.352,,0.000000e+000,2.194263e+002,4.126233e-006,0.000000e+000,3,9.526654e-001,0.000000e+000,,,,,,,,,,,,,,32,1,4.000000e+000,1.015991e+000,0.000000e+000,0,,0,
1578345472.152,,0.000000e+000,2.145164e+002,4.142758e-006,0.000000e+000,3,9.401485e-001,0.000000e+000,,,,,,,,,,,,,,32,1,4.000000e+000,9.357147e-001,0.000000e+000,0,,0,
1578345535.762,,0.000000e+000,2.094088e+002,4.071665e-006,0.000000e+000,3,9.332224e-001,0.000000e+000,,,,,,,,,,,,,,32,1,4.000000e+000,1.160797e+000,0.000000e+000,0,,0,
1578345597.952,,0.000000e+000,2.044676e+002,4.105883e-006,0.000000e+000,3,9.466270e-001,0.000000e+000,,,,,,,,,,,,,,32,1,4.000000e+000,9.600983e-001,0.000000e+000,0,,0,
1578345660.222,,0.000000e+000,1.994234e+002,4.059019e-006,0.000000e+000,3,9.556651e-001,0.000000e+000,,,,,,,,,,,,,,32,1,4.000000e+000,1.088806e+000,0.000000e+000,0,,0,
1578345722.542,,0.000000e+000,1.943875e+002,4.033149e-006,0.000000e+000,3,9.377675e-001,0.000000e+000,,,,,,,,,,,,,,32,1,4.000000e+000,9.895020e-001,0.000000e+000,0,,0,
1578345783.922,,0.000000e+000,1.894222e+002,4.017385e-006,0.000000e+000,3,9.535747e-001,0.000000e+000,,,,,,,,,,,,,,32,1,4.000000e+000,9.998016e-001,0.000000e+000,0,,0,
1578345844.722,,0.000000e+000,1.844564e+002,4.008274e-006,0.000000e+000,3,9.449226e-001,0.000000e+000,,,,,,,,,,,,,,32,1,4.000000e+000,9.705963e-001,0.000000e+000,0,,0,
1578345905.092,,0.000000e+000,1.794298e+002,3.997041e-006,0.000000e+000,3,9.536900e-001,0.000000e+000,,,,,,,,,,,,,,32,1,4.000000e+000,1.092300e+000,0.000000e+000,0,,0,
1578345967.012,,0.000000e+000,1.743490e+002,3.944271e-006,0.000000e+000,3,9.633909e-001,0.000000e+000,,,,,,,,,,,,,,32,1,4.000000e+000,9.971008e-001,0.000000e+000,0,,0,
1578346026.323,,0.000000e+000,1.694807e+002,3.885270e-006,0.000000e+000,3,9.557093e-001,0.000000e+000,,,,,,,,,,,,,,32,1,4.000000e+000,9.998932e-001,0.000000e+000,0,,0,
1578346087.393,,0.000000e+000,1.643341e+002,3.909866e-006,0.000000e+000,3,9.284168e-001,0.000000e+000,,,,,,,,,,,,,,32,1,4.000000e+000,1.125595e+000,0.000000e+000,0,,0,
1578346146.933,,0.000000e+000,1.594275e+002,3.734012e-006,0.000000e+000,3,9.472978e-001,0.000000e+000,,,,,,,,,,,,,,32,1,4.000000e+000,1.125000e+000,0.000000e+000,0,,0,
1578346207.613,,0.000000e+000,1.543841e+002,3.779528e-006,0.000000e+000,3,9.441537e-001,0.000000e+000,,,,,,,,,,,,,,32,1,4.000000e+000,1.132797e+000,0.000000e+000,0,,0,
1578346266.773,,0.000000e+000,1.493798e+002,3.674671e-006,0.000000e+000,3,9.480965e-001,0.000000e+000,,,,,,,,,,,,,,32,1,4.000000e+000,1.063400e+000,0.000000e+000,0,,0,
1578346326.573,,0.000000e+000,1.443576e+002,3.615817e-006,0.000000e+000,3,9.481657e-001,0.000000e+000,,,,,,,,,,,,,,32,1,4.000000e+000,1.078995e+000,0.000000e+000,0,,0,
1578346385.373,,0.000000e+000,1.394148e+002,3.539607e-006,0.000000e+000,3,9.501503e-001,0.000000e+000,,,,,,,,,,,,,,32,1,4.000000e+000,9.871979e-001,0.000000e+000,0,,0,
1578346444.963,,0.000000e+000,1.344271e+002,3.487219e-006,0.000000e+000,3,9.337597e-001,0.000000e+000,,,,,,,,,,,,,,32,1,4.000000e+000,9.904022e-001,0.000000e+000,0,,0,
1578346504.523,,0.000000e+000,1.293519e+002,3.371279e-006,0.000000e+000,3,9.402080e-001,0.000000e+000,,,,,,,,,,,,,,32,1,4.000000e+000,1.020203e+000,0.000000e+000,0,,0,
1578346562.383,,0.000000e+000,1.244734e+002,3.357027e-006,0.000000e+000,3,9.495723e-001,0.000000e+000,,,,,,,,,,,,,,32,1,4.000000e+000,1.046097e+000,0.000000e+000,0,,0,
1578346620.883,,0.000000e+000,1.194624e+002,3.221460e-006,0.000000e+000,3,9.348600e-001,0.000000e+000,,,,,,,,,,,,,,32,1,4.000000e+000,1.059303e+000,0.000000e+000,0,,0,
1578346678.833,,0.000000e+000,1.144618e+002,3.108078e-006,0.000000e+000,3,9.373918e-001,0.000000e+000,,,,,,,,,,,,,,32,1,4.000000e+000,9.687958e-001,0.000000e+000,0,,0,
1578346736.764,,0.000000e+000,1.093344e+002,3.054135e-006,0.000000e+000,3,9.428449e-001,0.000000e+000,,,,,,,,,,,,,,32,1,4.000000e+000,1.072495e+000,0.000000e+000,0,,0,
1578346792.544,,0.000000e+000,1.044294e+002,3.022874e-006,0.000000e+000,3,9.356833e-001,0.000000e+000,,,,,,,,,,,,,,32,1,4.000000e+000,1.141296e+000,0.000000e+000,0,,0,
1578346848.634,,0.000000e+000,9.942012e+001,2.990455e-006,0.000000e+000,3,9.407809e-001,0.000000e+000,,,,,,,,,,,,,,32,1,4.000000e+000,1.044556e+000,0.000000e+000,0,,0,
1578346905.344,,0.000000e+000,9.432027e+001,2.824291e-006,0.000000e+000,3,9.200583e-001,0.000000e+000,,,,,,,,,,,,,,32,1,4.000000e+000,1.132065e+000,0.000000e+000,0,,0,
1578346958.874,,0.000000e+000,8.939029e+001,2.805166e-006,0.000000e+000,3,9.114074e-001,0.000000e+000,,,,,,,,,,,,,,32,1,4.000000e+000,9.436951e-001,0.000000e+000,0,,0,
1578347012.664,,0.000000e+000,8.440196e+001,2.758228e-006,0.000000e+000,3,9.281958e-001,0.000000e+000,,,,,,,,,,,,,,32,1,4.000000e+000,1.098656e+000,0.000000e+000,0,,0,
1578347064.654,,0.000000e+000,7.933464e+001,2.748862e-006,0.000000e+000,3,9.086850e-001,0.000000e+000,,,,,,,,,,,,,,32,1,4.000000e+000,1.036377e+000,0.000000e+000,0,,0,
1578347116.384,,0.000000e+000,7.430089e+001,2.784491e-006,0.000000e+000,3,9.255507e-001,0.000000e+000,,,,,,,,,,,,,,32,1,4.000000e+000,1.100349e+000,0.000000e+000,0,,0,
1578347166.934,,0.000000e+000,6.936719e+001,2.773615e-006,0.000000e+000,3,9.347061e-001,0.000000e+000,,,,,,,,,,,,,,32,1,4.000000e+000,1.130379e+000,0.000000e+000,0,,0,
1578347215.114,,0.000000e+000,6.440240e+001,2.795317e-006,0.000000e+000,3,9.276090e-001,0.000000e+000,,,,,,,,,,,,,,32,1,4.000000e+000,1.180328e+000,0.000000e+000,0,,0,
1578347264.294,,0.000000e+000,5.923054e+001,2.799089e-006,0.000000e+000,3,9.348986e-001,0.000000e+000,,,,,,,,,,,,,,32,1,4.000000e+000,1.217300e+000,0.000000e+000,0,,0,
1578347310.814,,0.000000e+000,5.433867e+001,2.765038e-006,0.000000e+000,3,9.312373e-001,0.000000e+000,,,,,,,,,,,,,,32,1,4.000000e+000,1.292427e+000,0.000000e+000,0,,0,
1578347355.924,,0.000000e+000,4.937986e+001,2.788106e-006,0.000000e+000,3,9.139427e-001,0.000000e+000,,,,,,,,,,,,,,32,1,4.000000e+000,1.209579e+000,0.000000e+000,0,,0,
1578347403.974,,0.000000e+000,4.415862e+001,2.793750e-006,0.000000e+000,3,9.319388e-001,0.000000e+000,,,,,,,,,,,,,,32,1,4.000000e+000,1.440590e+000,0.000000e+000,0,,0,
1578347444.764,,0.000000e+000,3.923738e+001,2.852977e-006,0.000000e+000,3,9.192387e-001,0.000000e+000,,,,,,,,,,,,,,32,1,4.000000e+000,1.355209e+000,0.000000e+000,0,,0,
1578347487.465,,0.000000e+000,3.435263e+001,2.808464e-006,0.000000e+000,3,9.224201e-001,0.000000e+000,,,,,,,,,,,,,,32,1,4.000000e+000,1.291702e+000,0.000000e+000,0,,0,
1578347533.485,,0.000000e+000,2.931934e+001,2.746630e-006,0.000000e+000,3,9.296984e-001,0.000000e+000,,,,,,,,,,,,,,32,1,4.000000e+000,1.293650e+000,0.000000e+000,0,,0,
1578347582.445,,0.000000e+000,2.423966e+001,2.805661e-006,0.000000e+000,3,9.272669e-001,0.000000e+000,,,,,,,,,,,,,,32,1,4.000000e+000,1.292200e+000,0.000000e+000,0,,0,
1578347647.305,,0.000000e+000,1.879596e+001,2.873685e-006,0.000000e+000,3,9.293725e-001,0.000000e+000,,,,,,,,,,,,,,32,1,4.000000e+000,1.135201e+000,0.000000e+000,0,,0,
1578347688.825,,0.000000e+000,1.399615e+001,2.867150e-006,0.000000e+000,3,9.419995e-001,0.000000e+000,,,,,,,,,,,,,,32,1,4.000000e+000,3.552904e-001,0.000000e+000,0,,0,
1578348551.206,,0.000000e+000,1.003471e+001,2.671260e-006,0.000000e+000,3,9.473724e-001,0.000000e+000,,,,,,,,,,,,,,32,1,4.000000e+000,5.029678e-003,0.000000e+000,0,,0,
1578349476.047,,0.000000e+000,9.996687e+000,2.784306e-006,0.000000e+000,3,9.419243e-001,0.000000e+000,,,,,,,,,,,,,,32,1,4.000000e+000,7.405281e-003,0.000000e+000,0,,0,
1578349556.777,,0.000000e+000,1.552269e+001,2.812202e-006,0.000000e+000,3,9.357108e-001,0.000000e+000,,,,,,,,,,,,,,32,1,4.000000e+000,9.484406e-001,0.000000e+000,0,,0,
1578349617.358,,0.000000e+000,2.050760e+001,2.818936e-006,0.000000e+000,3,9.417913e-001,0.000000e+000,,,,,,,,,,,,,,32,1,4.000000e+000,8.942013e-001,0.000000e+000,0,,0,
1578349690.988,,0.000000e+000,2.653974e+001,2.798949e-006,0.000000e+000,3,9.271568e-001,0.000000e+000,,,,,,,,,,,,,,32,1,4.000000e+000,9.022408e-001,0.000000e+000,0,,0,
1578349738.768,,0.000000e+000,3.051002e+001,2.767718e-006,0.000000e+000,3,9.234506e-001,0.000000e+000,,,,,,,,,,,,,,32,1,4.000000e+000,9.531612e-001,0.000000e+000,0,,0,
1578349800.748,,0.000000e+000,3.558501e+001,2.669727e-006,0.000000e+000,3,9.348976e-001,0.000000e+000,,,,,,,,,,,,,,32,1,4.000000e+000,1.089092e+000,0.000000e+000,0,,0,
1578349860.808,,0.000000e+000,4.050665e+001,2.864354e-006,0.000000e+000,3,9.414833e-001,0.000000e+000,,,,,,,,,,,,,,32,1,4.000000e+000,9.812126e-001,0.000000e+000,0,,0,
1578349920.298,,0.000000e+000,4.547160e+001,2.760907e-006,0.000000e+000,3,9.161983e-001,0.000000e+000,,,,,,,,,,,,,,32,1,4.000000e+000,8.374901e-001,0.000000e+000,0,,0,
1578349981.368,,0.000000e+000,5.048248e+001,2.949908e-006,0.000000e+000,3,9.227487e-001,0.000000e+000,,,,,,,,,,,,,,32,1,4.000000e+000,8.982582e-001,0.000000e+000,0,,0,
1578350041.788,,0.000000e+000,5.553059e+001,2.748118e-006,0.000000e+000,3,9.277269e-001,0.000000e+000,,,,,,,,,,,,,,32,1,4.000000e+000,9.523125e-001,0.000000e+000,0,,0,
1578350101.818,,0.000000e+000,6.056794e+001,2.722000e-006,0.000000e+000,3,9.403014e-001,0.000000e+000,,,,,,,,,,,,,,32,1,4.000000e+000,1.019218e+000,0.000000e+000,0,,0,
1578350160.698,,0.000000e+000,6.549133e+001,2.715137e-006,0.000000e+000,3,9.219007e-001,0.000000e+000,,,,,,,,,,,,,,32,1,4.000000e+000,8.794479e-001,0.000000e+000,0,,0,
1578350221.088,,0.000000e+000,7.052876e+001,2.678380e-006,0.000000e+000,3,9.417424e-001,0.000000e+000,,,,,,,,,,,,,,32,1,4.000000e+000,9.415131e-001,0.000000e+000,0,,0,
1578350280.398,,0.000000e+000,7.553288e+001,2.776837e-006,0.000000e+000,3,9.235851e-001,0.000000e+000,,,,,,,,,,,,,,32,1,4.000000e+000,8.518600e-001,0.000000e+000,0,,0,
1578350340.389,,0.000000e+000,8.053033e+001,2.687759e-006,0.000000e+000,3,9.248635e-001,0.000000e+000,,,,,,,,,,,,,,32,1,4.000000e+000,8.792877e-001,0.000000e+000,0,,0,
1578350401.019,,0.000000e+000,8.556972e+001,2.828609e-006,0.000000e+000,3,9.217781e-001,0.000000e+000,,,,,,,,,,,,,,32,1,4.000000e+000,9.460297e-001,0.000000e+000,0,,0,
1578350460.359,,0.000000e+000,9.059128e+001,2.702040e-006,0.000000e+000,3,9.007583e-001,0.000000e+000,,,,,,,,,,,,,,32,1,4.000000e+000,8.812180e-001,0.000000e+000,0,,0,
1578350519.349,,0.000000e+000,9.559679e+001,2.829715e-006,0.000000e+000,3,9.286395e-001,0.000000e+000,,,,,,,,,,,,,,32,1,4.000000e+000,9.448700e-001,0.000000e+000,0,,0,
1578350580.559,,0.000000e+000,1.006310e+002,2.640001e-006,0.000000e+000,3,9.258183e-001,0.000000e+000,,,,,,,,,,,,,,32,1,4.000000e+000,9.155960e-001,0.000000e+000,0,,0,
1578350638.379,,0.000000e+000,1.055329e+002,2.879664e-006,0.000000e+000,3,9.274892e-001,0.000000e+000,,,,,,,,,,,,,,32,1,4.000000e+000,8.798981e-001,0.000000e+000,0,,0,
1578350698.959,,0.000000e+000,1.105072e+002,2.907083e-006,0.000000e+000,3,9.288594e-001,0.000000e+000,,,,,,,,,,,,,,32,1,4.000000e+000,9.644012e-001,0.000000e+000,0,,0,
1578350761.459,,0.000000e+000,1.155201e+002,2.907966e-006,0.000000e+000,3,9.285907e-001,0.000000e+000,,,,,,,,,,,,,,32,1,4.000000e+000,8.997040e-001,0.000000e+000,0,,0,
1578350822.079,,0.000000e+000,1.205521e+002,2.898775e-006,0.000000e+000,3,9.347209e-001,0.000000e+000,,,,,,,,,,,,,,32,1,4.000000e+000,1.021805e+000,0.000000e+000,0,,0,
1578350881.059,,0.000000e+000,1.255987e+002,3.012329e-006,0.000000e+000,3,9.427239e-001,0.000000e+000,,,,,,,,,,,,,,32,1,4.000000e+000,1.064499e+000,0.000000e+000,0,,0,
1578350939.909,,0.000000e+000,1.307317e+002,3.108956e-006,0.000000e+000,3,9.410062e-001,0.000000e+000,,,,,,,,,,,,,,32,1,4.000000e+000,9.665985e-001,0.000000e+000,0,,0,
1578350999.249,,0.000000e+000,1.353966e+002,3.010559e-006,0.000000e+000,3,9.257547e-001,0.000000e+000,,,,,,,,,,,,,,32,1,4.000000e+000,7.537994e-001,0.000000e+000,0,,0,
1578351065.000,,0.000000e+000,1.405153e+002,3.069943e-006,0.000000e+000,3,9.227049e-001,0.000000e+000,,,,,,,,,,,,,,32,1,4.000000e+000,8.058014e-001,0.000000e+000,0,,0,
1578351127.540,,0.000000e+000,1.456349e+002,3.122249e-006,0.000000e+000,3,9.321228e-001,0.000000e+000,,,,,,,,,,,,,,32,1,4.000000e+000,1.041092e+000,0.000000e+000,0,,0,
1578351182.600,,0.000000e+000,1.505343e+002,3.187045e-006,0.000000e+000,3,9.390157e-001,0.000000e+000,,,,,,,,,,,,,,32,1,4.000000e+000,9.962006e-001,0.000000e+000,0,,0,
1578351239.400,,0.000000e+000,1.555549e+002,3.159279e-006,0.000000e+000,3,9.277399e-001,0.000000e+000,,,,,,,,,,,,,,32,1,4.000000e+000,9.259033e-001,0.000000e+000,0,,0,
1578351298.450,,0.000000e+000,1.606800e+002,3.269838e-006,0.000000e+000,3,9.566947e-001,0.000000e+000,,,,,,,,,,,,,,32,1,4.000000e+000,8.701935e-001,0.000000e+000,0,,0,
1578351350.270,,0.000000e+000,1.655710e+002,3.151789e-006,0.000000e+000,3,9.320763e-001,0.000000e+000,,,,,,,,,,,,,,32,1,4.000000e+000,1.122894e+000,0.000000e+000,0,,0,
1578351411.830,,0.000000e+000,1.704280e+002,3.121793e-006,0.000000e+000,3,9.234508e-001,0.000000e+000,,,,,,,,,,,,,,32,1,4.000000e+000,8.122101e-001,0.000000e+000,0,,0,
1578351476.290,,0.000000e+000,1.755135e+002,3.157528e-006,0.000000e+000,3,9.377310e-001,0.000000e+000,,,,,,,,,,,,,,32,1,4.000000e+000,7.467041e-001,0.000000e+000,0,,0,
1578351536.990,,0.000000e+000,1.805491e+002,3.184395e-006,0.000000e+000,3,9.369949e-001,0.000000e+000,,,,,,,,,,,,,,32,1,4.000000e+000,8.596039e-001,0.000000e+000,0,,0,
1578351596.980,,0.000000e+000,1.855181e+002,3.256918e-006,0.000000e+000,3,9.438655e-001,0.000000e+000,,,,,,,,,,,,,,32,1,4.000000e+000,8.987122e-001,0.000000e+000,0,,0,
1578351658.020,,0.000000e+000,1.905853e+002,3.197705e-006,0.000000e+000,3,9.396272e-001,0.000000e+000,,,,,,,,,,,,,,32,1,4.000000e+000,8.619080e-001,0.000000e+000,0,,0,
1578351715.600,,0.000000e+000,1.956151e+002,3.061281e-006,0.000000e+000,3,9.333233e-001,0.000000e+000,,,,,,,,,,,,,,32,1,4.000000e+000,1.084702e+000,0.000000e+000,0,,0,
1578351773.921,,0.000000e+000,2.007352e+002,3.216248e-006,0.000000e+000,3,9.271795e-001,0.000000e+000,,,,,,,,,,,,,,32,1,4.000000e+000,1.248001e+000,0.000000e+000,0,,0,
1578351832.771,,0.000000e+000,2.056022e+002,3.216988e-006,0.000000e+000,3,9.458660e-001,0.000000e+000,,,,,,,,,,,,,,32,1,4.000000e+000,9.712067e-001,0.000000e+000,0,,0,
1578351895.291,,0.000000e+000,2.104960e+002,3.252950e-006,0.000000e+000,3,9.231389e-001,0.000000e+000,,,,,,,,,,,,,,32,1,4.000000e+000,9.375000e-001,0.000000e+000,0,,0,
1578351957.721,,0.000000e+000,2.155370e+002,3.027003e-006,0.000000e+000,3,9.251567e-001,0.000000e+000,,,,,,,,,,,,,,32,1,4.000000e+000,1.012100e+000,0.000000e+000,0,,0,
1578352015.891,,0.000000e+000,2.204787e+002,2.928706e-006,0.000000e+000,3,9.231181e-001,0.000000e+000,,,,,,,,,,,,,,32,1,4.000000e+000,9.349060e-001,0.000000e+000,0,,0,
1578352076.731,,0.000000e+000,2.254836e+002,3.207889e-006,0.000000e+000,3,9.290419e-001,0.000000e+000,,,,,,,,,,,,,,32,1,4.000000e+000,9.429932e-001,0.000000e+000,0,,0,
1578352136.061,,0.000000e+000,2.305743e+002,3.224945e-006,0.000000e+000,3,9.022230e-001,0.000000e+000,,,,,,,,,,,,,,32,1,4.000000e+000,1.018997e+000,0.000000e+000,0,,0,
1578352189.361,,0.000000e+000,2.358798e+002,3.127511e-006,0.000000e+000,3,9.098441e-001,0.000000e+000,,,,,,,,,,,,,,32,1,4.000000e+000,1.021408e+000,0.000000e+000,0,,0,
1578352242.331,,0.000000e+000,2.404729e+002,3.081317e-006,0.000000e+000,3,9.308754e-001,0.000000e+000,,,,,,,,,,,,,,32,1,4.000000e+000,8.958130e-001,0.000000e+000,0,,0,
1578352306.691,,0.000000e+000,2.454626e+002,3.146860e-006,0.000000e+000,3,9.379449e-001,0.000000e+000,,,,,,,,,,,,,,32,1,4.000000e+000,8.744965e-001,0.000000e+000,0,,0,
1578352371.011,,0.000000e+000,2.504872e+002,3.083839e-006,0.000000e+000,3,9.396981e-001,0.000000e+000,,,,,,,,,,,,,,32,1,4.000000e+000,8.858032e-001,0.000000e+000,0,,0,
1578352433.801,,0.000000e+000,2.554687e+002,3.134457e-006,0.000000e+000,3,9.417768e-001,0.000000e+000,,,,,,,,,,,,,,32,1,4.000000e+000,9.337921e-001,0.000000e+000,0,,0,
1578352496.022,,0.000000e+000,2.604971e+002,3.156868e-006,0.000000e+000,3,9.349334e-001,0.000000e+000,,,,,,,,,,,,,,32,1,4.000000e+000,8.834229e-001,0.000000e+000,0,,0,
1578352557.922,,0.000000e+000,2.655973e+002,3.085564e-006,0.000000e+000,3,9.319693e-001,0.000000e+000,,,,,,,,,,,,,,32,1,4.000000e+000,9.428101e-001,0.000000e+000,0,,0,
1578352617.362,,0.000000e+000,2.706183e+002,3.155789e-006,0.000000e+000,3,9.397232e-001,0.000000e+000,,,,,,,,,,,,,,32,1,4.000000e+000,9.498901e-001,0.000000e+000,0,,0,
1578352672.532,,0.000000e+000,2.755240e+002,3.150879e-006,0.000000e+000,3,9.236572e-001,0.000000e+000,,,,,,,,,,,,,,32,1,4.000000e+000,9.996948e-001,0.000000e+000,0,,0,
1578352731.042,,0.000000e+000,2.805590e+002,3.100837e-006,0.000000e+000,3,9.445485e-001,0.000000e+000,,,,,,,,,,,,,,32,1,4.000000e+000,9.339905e-001,0.000000e+000,0,,0,
1578352791.132,,0.000000e+000,2.854810e+002,3.065933e-006,0.000000e+000,3,9.302536e-001,0.000000e+000,,,,,,,,,,,,,,32,1,4.000000e+000,7.369080e-001,0.000000e+000,0,,0,
1578352851.592,,0.000000e+000,2.904757e+002,3.035977e-006,0.000000e+000,3,9.442188e-001,0.000000e+000,,,,,,,,,,,,,,32,1,4.000000e+000,8.930054e-001,0.000000e+000,0,,0,
1578352914.202,,0.000000e+000,2.955596e+002,3.084061e-006,0.000000e+000,3,9.500972e-001,0.000000e+000,,,,,,,,,,,,,,32,1,4.000000e+000,1.033600e+000,0.000000e+000,0,,0,
1578353263.643,,0.000000e+000,3.000338e+002,2.992569e-006,0.000000e+000,3,9.347609e-001,0.000000e+000,,,,,,,,,,,,,,32,1,4.000000e+000,0.000000e+000,0.000000e+000,0,,0,