File: data/Rock_mag/2020_IRM_data_files/Raw_data/MPMS_5S/data/AX6-1r_FC-ZFC-RTSIRM-10K.dc.dat
[Header]
TITLE,MPMS DC Measurement
BYAPP,MPMS Measurement,2.1,Summary
FILEOPENTIME, 1578414095.188000 1/7/2020, 10:21:35 AM

INFO, APPNAME, MPMS MultiVu Application, Revision 1.61,  Build 082

INFO, NAME, AX6-1r
INFO, WEIGHT, 1.000
INFO, AREA, 1.000
INFO, LENGTH, 1.000
INFO, SHAPE, 0
INFO, COMMENT,
INFO, SEQUENCE FILE: FC-ZFC LTSIRM and RTSIRM LTD 10K.seq


INFO, BACKGROUND DATA FILE:, None


STARTUPAXIS,X,4,LINEAR,AUTO,0.000000,0.000000
STARTUPAXIS,Y1,5,LINEAR,AUTO,0.000000,0.000000


STARTUPGROUP,Longitudinal
FIELDGROUP,Longitudinal,1,2,3,4,5,6,7,8,9,15,16,17,18,27,28
FIELDGROUP,Transverse,1,2,3,4,10,11,12,13,14,19,20,21,22,27,28

PLOT_APPEARANCE,ALL,HORZ_GRID_ON,VERT_GRID_ON,MARKERS_AND_LINES

[Data]
Time,Comment,Field (Oe),Temperature (K),Long Moment (emu),Long Scan Std Dev,Long Algorithm,Long Reg Fit,Long Percent Error (%),Trans Moment (emu),Trans Scan Std Dev,Trans Algorithm,Trans Reg Fit,Trans Percent Error (%),Long Moment [w/o ABS] (emu),Long Scan Std Dev [w/o ABS],Long Reg Fit [w/o ABS],Long Percent Error [w/o ABS] (%),Trans Moment [w/o ABS] (emu),Trans Scan Std Dev [w/o ABS],Trans Reg Fit [w/o ABS],Trans Percent Error [w/o ABS] (%),Points per Scan,Scans per Measurement,Scan Length (cm),Delta Temp (K),Rot Position (deg),Error,EC Comp. Running,Using ABS,
1578414095.168,,0.000000e+000,1.000066e+001,3.474514e-004,0.000000e+000,3,9.859271e-001,0.000000e+000,,,,,,,,,,,,,,32,1,4.000000e+000,1.324272e-002,0.000000e+000,0,,0,
1578414176.998,,0.000000e+000,1.556891e+001,2.915231e-004,0.000000e+000,3,9.850227e-001,0.000000e+000,,,,,,,,,,,,,,32,1,4.000000e+000,8.766994e-001,0.000000e+000,0,,0,
1578414236.638,,0.000000e+000,2.049107e+001,2.503315e-004,0.000000e+000,3,9.848711e-001,0.000000e+000,,,,,,,,,,,,,,32,1,4.000000e+000,9.730892e-001,0.000000e+000,0,,0,
1578414298.708,,0.000000e+000,2.556531e+001,2.245859e-004,0.000000e+000,3,9.849578e-001,0.000000e+000,,,,,,,,,,,,,,32,1,4.000000e+000,9.197807e-001,0.000000e+000,0,,0,
1578414359.268,,0.000000e+000,3.059377e+001,2.069133e-004,0.000000e+000,3,9.851652e-001,0.000000e+000,,,,,,,,,,,,,,32,1,4.000000e+000,9.548912e-001,0.000000e+000,0,,0,
1578414419.978,,0.000000e+000,3.555423e+001,1.927625e-004,0.000000e+000,3,9.847797e-001,0.000000e+000,,,,,,,,,,,,,,32,1,4.000000e+000,8.510399e-001,0.000000e+000,0,,0,
1578414494.348,,0.000000e+000,4.172152e+001,1.785653e-004,0.000000e+000,3,9.854117e-001,0.000000e+000,,,,,,,,,,,,,,32,1,4.000000e+000,9.708405e-001,0.000000e+000,0,,0,
1578414540.198,,0.000000e+000,4.548954e+001,1.714355e-004,0.000000e+000,3,9.854604e-001,0.000000e+000,,,,,,,,,,,,,,32,1,4.000000e+000,8.381195e-001,0.000000e+000,0,,0,
1578414600.539,,0.000000e+000,5.049542e+001,1.639044e-004,0.000000e+000,3,9.852444e-001,0.000000e+000,,,,,,,,,,,,,,32,1,4.000000e+000,9.046516e-001,0.000000e+000,0,,0,
1578414662.129,,0.000000e+000,5.557760e+001,1.573301e-004,0.000000e+000,3,9.850131e-001,0.000000e+000,,,,,,,,,,,,,,32,1,4.000000e+000,1.032322e+000,0.000000e+000,0,,0,
1578414721.219,,0.000000e+000,6.057100e+001,1.521503e-004,0.000000e+000,3,9.853306e-001,0.000000e+000,,,,,,,,,,,,,,32,1,4.000000e+000,8.653107e-001,0.000000e+000,0,,0,
1578414781.199,,0.000000e+000,6.557993e+001,1.472497e-004,0.000000e+000,3,9.855225e-001,0.000000e+000,,,,,,,,,,,,,,32,1,4.000000e+000,8.843536e-001,0.000000e+000,0,,0,
1578414840.699,,0.000000e+000,7.053929e+001,1.427898e-004,0.000000e+000,3,9.852663e-001,0.000000e+000,,,,,,,,,,,,,,32,1,4.000000e+000,9.477768e-001,0.000000e+000,0,,0,
1578414900.139,,0.000000e+000,7.550005e+001,1.385804e-004,0.000000e+000,3,9.851635e-001,0.000000e+000,,,,,,,,,,,,,,32,1,4.000000e+000,9.279099e-001,0.000000e+000,0,,0,
1578414959.969,,0.000000e+000,8.053528e+001,1.343729e-004,0.000000e+000,3,9.853806e-001,0.000000e+000,,,,,,,,,,,,,,32,1,4.000000e+000,9.044418e-001,0.000000e+000,0,,0,
1578415020.369,,0.000000e+000,8.555847e+001,1.302264e-004,0.000000e+000,3,9.849815e-001,0.000000e+000,,,,,,,,,,,,,,32,1,4.000000e+000,8.635483e-001,0.000000e+000,0,,0,
1578415079.879,,0.000000e+000,9.055994e+001,1.259929e-004,0.000000e+000,3,9.851331e-001,0.000000e+000,,,,,,,,,,,,,,32,1,4.000000e+000,8.854599e-001,0.000000e+000,0,,0,
1578415142.199,,0.000000e+000,9.555054e+001,1.215440e-004,0.000000e+000,3,9.847633e-001,0.000000e+000,,,,,,,,,,,,,,32,1,4.000000e+000,7.675018e-001,0.000000e+000,0,,0,
1578415206.169,,0.000000e+000,1.005346e+002,1.168350e-004,0.000000e+000,3,9.848033e-001,0.000000e+000,,,,,,,,,,,,,,32,1,4.000000e+000,7.929993e-001,0.000000e+000,0,,0,
1578415262.289,,0.000000e+000,1.055753e+002,1.119989e-004,0.000000e+000,3,9.855005e-001,0.000000e+000,,,,,,,,,,,,,,32,1,4.000000e+000,9.646988e-001,0.000000e+000,0,,0,
1578415318.320,,0.000000e+000,1.106189e+002,1.062578e-004,0.000000e+000,3,9.843450e-001,0.000000e+000,,,,,,,,,,,,,,32,1,4.000000e+000,1.047699e+000,0.000000e+000,0,,0,
1578415377.780,,0.000000e+000,1.156817e+002,9.962338e-005,0.000000e+000,3,9.849328e-001,0.000000e+000,,,,,,,,,,,,,,32,1,4.000000e+000,9.020996e-001,0.000000e+000,0,,0,
1578415437.570,,0.000000e+000,1.204934e+002,9.320654e-005,0.000000e+000,3,9.858050e-001,0.000000e+000,,,,,,,,,,,,,,32,1,4.000000e+000,9.375992e-001,0.000000e+000,0,,0,
1578415496.700,,0.000000e+000,1.254582e+002,8.860684e-005,0.000000e+000,3,9.858216e-001,0.000000e+000,,,,,,,,,,,,,,32,1,4.000000e+000,8.372040e-001,0.000000e+000,0,,0,
1578415560.950,,0.000000e+000,1.305708e+002,8.556715e-005,0.000000e+000,3,9.849494e-001,0.000000e+000,,,,,,,,,,,,,,32,1,4.000000e+000,9.837952e-001,0.000000e+000,0,,0,
1578415620.660,,0.000000e+000,1.354993e+002,8.277039e-005,0.000000e+000,3,9.852261e-001,0.000000e+000,,,,,,,,,,,,,,32,1,4.000000e+000,9.172974e-001,0.000000e+000,0,,0,
1578415683.150,,0.000000e+000,1.405301e+002,8.045072e-005,0.000000e+000,3,9.848366e-001,0.000000e+000,,,,,,,,,,,,,,32,1,4.000000e+000,1.025803e+000,0.000000e+000,0,,0,
1578415756.390,,0.000000e+000,1.468839e+002,7.799855e-005,0.000000e+000,3,9.856025e-001,0.000000e+000,,,,,,,,,,,,,,32,1,4.000000e+000,1.188400e+000,0.000000e+000,0,,0,
1578415796.880,,0.000000e+000,1.504984e+002,7.653952e-005,0.000000e+000,3,9.855718e-001,0.000000e+000,,,,,,,,,,,,,,32,1,4.000000e+000,9.116974e-001,0.000000e+000,0,,0,
1578415849.090,,0.000000e+000,1.555584e+002,7.468795e-005,0.000000e+000,3,9.852931e-001,0.000000e+000,,,,,,,,,,,,,,32,1,4.000000e+000,9.604950e-001,0.000000e+000,0,,0,
1578415906.590,,0.000000e+000,1.606024e+002,7.257926e-005,0.000000e+000,3,9.846211e-001,0.000000e+000,,,,,,,,,,,,,,32,1,4.000000e+000,8.030090e-001,0.000000e+000,0,,0,
1578415969.910,,0.000000e+000,1.654803e+002,7.061294e-005,0.000000e+000,3,9.851375e-001,0.000000e+000,,,,,,,,,,,,,,32,1,4.000000e+000,8.793945e-001,0.000000e+000,0,,0,
1578416034.341,,0.000000e+000,1.704175e+002,6.885824e-005,0.000000e+000,3,9.863710e-001,0.000000e+000,,,,,,,,,,,,,,32,1,4.000000e+000,7.250061e-001,0.000000e+000,0,,0,
1578416104.601,,0.000000e+000,1.755183e+002,6.699564e-005,0.000000e+000,3,9.861887e-001,0.000000e+000,,,,,,,,,,,,,,32,1,4.000000e+000,9.137115e-001,0.000000e+000,0,,0,
1578416165.901,,0.000000e+000,1.805909e+002,6.551044e-005,0.000000e+000,3,9.864394e-001,0.000000e+000,,,,,,,,,,,,,,32,1,4.000000e+000,8.600922e-001,0.000000e+000,0,,0,
1578416224.781,,0.000000e+000,1.855699e+002,6.392842e-005,0.000000e+000,3,9.867759e-001,0.000000e+000,,,,,,,,,,,,,,32,1,4.000000e+000,9.925995e-001,0.000000e+000,0,,0,
1578416282.931,,0.000000e+000,1.907311e+002,6.242979e-005,0.000000e+000,3,9.871988e-001,0.000000e+000,,,,,,,,,,,,,,32,1,4.000000e+000,9.879913e-001,0.000000e+000,0,,0,
1578416337.331,,0.000000e+000,1.955381e+002,6.110976e-005,0.000000e+000,3,9.868758e-001,0.000000e+000,,,,,,,,,,,,,,32,1,4.000000e+000,9.634094e-001,0.000000e+000,0,,0,
1578416394.391,,0.000000e+000,2.005121e+002,5.982005e-005,0.000000e+000,3,9.867522e-001,0.000000e+000,,,,,,,,,,,,,,32,1,4.000000e+000,9.396057e-001,0.000000e+000,0,,0,
1578416455.041,,0.000000e+000,2.056387e+002,5.858716e-005,0.000000e+000,3,9.861177e-001,0.000000e+000,,,,,,,,,,,,,,32,1,4.000000e+000,9.958038e-001,0.000000e+000,0,,0,
1578416513.091,,0.000000e+000,2.105473e+002,5.737022e-005,0.000000e+000,3,9.866865e-001,0.000000e+000,,,,,,,,,,,,,,32,1,4.000000e+000,1.052795e+000,0.000000e+000,0,,0,
1578416573.001,,0.000000e+000,2.155337e+002,5.628976e-005,0.000000e+000,3,9.874989e-001,0.000000e+000,,,,,,,,,,,,,,32,1,4.000000e+000,1.045609e+000,0.000000e+000,0,,0,
1578416629.241,,0.000000e+000,2.206295e+002,5.514172e-005,0.000000e+000,3,9.872271e-001,0.000000e+000,,,,,,,,,,,,,,32,1,4.000000e+000,7.460938e-001,0.000000e+000,0,,0,
1578416693.371,,0.000000e+000,2.254872e+002,5.409640e-005,0.000000e+000,3,9.857224e-001,0.000000e+000,,,,,,,,,,,,,,32,1,4.000000e+000,8.915100e-001,0.000000e+000,0,,0,
1578416752.872,,0.000000e+000,2.305585e+002,5.322061e-005,0.000000e+000,3,9.860579e-001,0.000000e+000,,,,,,,,,,,,,,32,1,4.000000e+000,8.489990e-001,0.000000e+000,0,,0,
1578416815.422,,0.000000e+000,2.354912e+002,5.210795e-005,0.000000e+000,3,9.861616e-001,0.000000e+000,,,,,,,,,,,,,,32,1,4.000000e+000,9.531097e-001,0.000000e+000,0,,0,
1578416877.322,,0.000000e+000,2.406768e+002,5.112874e-005,0.000000e+000,3,9.859152e-001,0.000000e+000,,,,,,,,,,,,,,32,1,4.000000e+000,1.286896e+000,0.000000e+000,0,,0,
1578416937.232,,0.000000e+000,2.456975e+002,5.029072e-005,0.000000e+000,3,9.868137e-001,0.000000e+000,,,,,,,,,,,,,,32,1,4.000000e+000,1.115402e+000,0.000000e+000,0,,0,
1578416995.822,,0.000000e+000,2.504917e+002,4.918323e-005,0.000000e+000,3,9.868706e-001,0.000000e+000,,,,,,,,,,,,,,32,1,4.000000e+000,8.214111e-001,0.000000e+000,0,,0,
1578417059.962,,0.000000e+000,2.556229e+002,4.838474e-005,0.000000e+000,3,9.874090e-001,0.000000e+000,,,,,,,,,,,,,,32,1,4.000000e+000,9.542999e-001,0.000000e+000,0,,0,
1578417116.302,,0.000000e+000,2.605224e+002,4.752499e-005,0.000000e+000,3,9.864867e-001,0.000000e+000,,,,,,,,,,,,,,32,1,4.000000e+000,9.940186e-001,0.000000e+000,0,,0,
1578417176.342,,0.000000e+000,2.655083e+002,4.678647e-005,0.000000e+000,3,9.869502e-001,0.000000e+000,,,,,,,,,,,,,,32,1,4.000000e+000,9.525757e-001,0.000000e+000,0,,0,
1578417236.232,,0.000000e+000,2.704762e+002,4.589889e-005,0.000000e+000,3,9.874274e-001,0.000000e+000,,,,,,,,,,,,,,32,1,4.000000e+000,8.616028e-001,0.000000e+000,0,,0,
1578417290.772,,0.000000e+000,2.755408e+002,4.511471e-005,0.000000e+000,3,9.865189e-001,0.000000e+000,,,,,,,,,,,,,,32,1,4.000000e+000,8.974915e-001,0.000000e+000,0,,0,
1578417353.262,,0.000000e+000,2.804763e+002,4.429966e-005,0.000000e+000,3,9.878170e-001,0.000000e+000,,,,,,,,,,,,,,32,1,4.000000e+000,9.096985e-001,0.000000e+000,0,,0,
1578417413.702,,0.000000e+000,2.856040e+002,4.346974e-005,0.000000e+000,3,9.881368e-001,0.000000e+000,,,,,,,,,,,,,,32,1,4.000000e+000,8.359985e-001,0.000000e+000,0,,0,
1578417473.043,,0.000000e+000,2.905459e+002,4.281638e-005,0.000000e+000,3,9.884472e-001,0.000000e+000,,,,,,,,,,,,,,32,1,4.000000e+000,9.318237e-001,0.000000e+000,0,,0,
1578417533.633,,0.000000e+000,2.955262e+002,4.216906e-005,0.000000e+000,3,9.880024e-001,0.000000e+000,,,,,,,,,,,,,,32,1,4.000000e+000,8.875122e-001,0.000000e+000,0,,0,
1578417912.603,,0.000000e+000,3.000201e+002,4.062167e-005,0.000000e+000,3,9.874647e-001,0.000000e+000,,,,,,,,,,,,,,32,1,4.000000e+000,2.740479e-002,0.000000e+000,0,,0,
1578422865.950,,0.000000e+000,9.999777e+000,2.887982e-004,0.000000e+000,3,9.859391e-001,0.000000e+000,,,,,,,,,,,,,,32,1,4.000000e+000,1.990604e-002,0.000000e+000,0,,0,
1578422948.790,,0.000000e+000,1.559886e+001,2.364456e-004,0.000000e+000,3,9.853439e-001,0.000000e+000,,,,,,,,,,,,,,32,1,4.000000e+000,9.542904e-001,0.000000e+000,0,,0,
1578423008.270,,0.000000e+000,2.052261e+001,2.023179e-004,0.000000e+000,3,9.851782e-001,0.000000e+000,,,,,,,,,,,,,,32,1,4.000000e+000,8.947411e-001,0.000000e+000,0,,0,
1578423083.670,,0.000000e+000,2.673075e+001,1.793142e-004,0.000000e+000,3,9.856508e-001,0.000000e+000,,,,,,,,,,,,,,32,1,4.000000e+000,9.821091e-001,0.000000e+000,0,,0,
1578423129.350,,0.000000e+000,3.051157e+001,1.693214e-004,0.000000e+000,3,9.852210e-001,0.000000e+000,,,,,,,,,,,,,,32,1,4.000000e+000,9.532490e-001,0.000000e+000,0,,0,
1578423191.651,,0.000000e+000,3.561810e+001,1.574257e-004,0.000000e+000,3,9.854014e-001,0.000000e+000,,,,,,,,,,,,,,32,1,4.000000e+000,8.559418e-001,0.000000e+000,0,,0,
1578423251.421,,0.000000e+000,4.050406e+001,1.470922e-004,0.000000e+000,3,9.855554e-001,0.000000e+000,,,,,,,,,,,,,,32,1,4.000000e+000,9.837112e-001,0.000000e+000,0,,0,
1578423311.961,,0.000000e+000,4.555473e+001,1.384680e-004,0.000000e+000,3,9.856468e-001,0.000000e+000,,,,,,,,,,,,,,32,1,4.000000e+000,1.000568e+000,0.000000e+000,0,,0,
1578423372.251,,0.000000e+000,5.055880e+001,1.319045e-004,0.000000e+000,3,9.858454e-001,0.000000e+000,,,,,,,,,,,,,,32,1,4.000000e+000,8.829422e-001,0.000000e+000,0,,0,
1578423432.551,,0.000000e+000,5.556681e+001,1.267110e-004,0.000000e+000,3,9.858950e-001,0.000000e+000,,,,,,,,,,,,,,32,1,4.000000e+000,8.750191e-001,0.000000e+000,0,,0,
1578423492.861,,0.000000e+000,6.052006e+001,1.219457e-004,0.000000e+000,3,9.851567e-001,0.000000e+000,,,,,,,,,,,,,,32,1,4.000000e+000,7.744713e-001,0.000000e+000,0,,0,
1578423552.241,,0.000000e+000,6.552386e+001,1.178644e-004,0.000000e+000,3,9.851863e-001,0.000000e+000,,,,,,,,,,,,,,32,1,4.000000e+000,9.753647e-001,0.000000e+000,0,,0,
1578423625.241,,0.000000e+000,7.165797e+001,1.134521e-004,0.000000e+000,3,9.860782e-001,0.000000e+000,,,,,,,,,,,,,,32,1,4.000000e+000,9.486084e-001,0.000000e+000,0,,0,
1578423670.811,,0.000000e+000,7.549745e+001,1.107582e-004,0.000000e+000,3,9.863098e-001,0.000000e+000,,,,,,,,,,,,,,32,1,4.000000e+000,9.227295e-001,0.000000e+000,0,,0,
1578423730.981,,0.000000e+000,8.051893e+001,1.075923e-004,0.000000e+000,3,9.861284e-001,0.000000e+000,,,,,,,,,,,,,,32,1,4.000000e+000,9.098816e-001,0.000000e+000,0,,0,
1578423842.651,,0.000000e+000,8.978251e+001,1.017678e-004,0.000000e+000,3,9.859694e-001,0.000000e+000,,,,,,,,,,,,,,32,1,4.000000e+000,9.326630e-001,0.000000e+000,0,,0,
1578423856.161,,0.000000e+000,9.091167e+001,1.011121e-004,0.000000e+000,3,9.852539e-001,0.000000e+000,,,,,,,,,,,,,,32,1,4.000000e+000,1.008728e+000,0.000000e+000,0,,0,
1578423912.562,,0.000000e+000,9.549426e+001,9.836748e-005,0.000000e+000,3,9.855610e-001,0.000000e+000,,,,,,,,,,,,,,32,1,4.000000e+000,7.238998e-001,0.000000e+000,0,,0,
1578423984.442,,0.000000e+000,1.016843e+002,9.437498e-005,0.000000e+000,3,9.860275e-001,0.000000e+000,,,,,,,,,,,,,,32,1,4.000000e+000,9.881973e-001,0.000000e+000,0,,0,
1578424029.812,,0.000000e+000,1.054978e+002,9.160150e-005,0.000000e+000,3,9.858990e-001,0.000000e+000,,,,,,,,,,,,,,32,1,4.000000e+000,9.955978e-001,0.000000e+000,0,,0,
1578424090.632,,0.000000e+000,1.104983e+002,8.749253e-005,0.000000e+000,3,9.851896e-001,0.000000e+000,,,,,,,,,,,,,,32,1,4.000000e+000,9.395981e-001,0.000000e+000,0,,0,
1578424156.922,,0.000000e+000,1.154967e+002,8.280133e-005,0.000000e+000,3,9.859388e-001,0.000000e+000,,,,,,,,,,,,,,32,1,4.000000e+000,8.224945e-001,0.000000e+000,0,,0,
1578424217.282,,0.000000e+000,1.205582e+002,7.829982e-005,0.000000e+000,3,9.857770e-001,0.000000e+000,,,,,,,,,,,,,,32,1,4.000000e+000,9.843979e-001,0.000000e+000,0,,0,
1578424275.812,,0.000000e+000,1.255939e+002,7.451079e-005,0.000000e+000,3,9.856748e-001,0.000000e+000,,,,,,,,,,,,,,32,1,4.000000e+000,9.923019e-001,0.000000e+000,0,,0,
1578424334.652,,0.000000e+000,1.309592e+002,7.197841e-005,0.000000e+000,3,9.853378e-001,0.000000e+000,,,,,,,,,,,,,,32,1,4.000000e+000,9.945068e-001,0.000000e+000,0,,0,
1578424391.422,,0.000000e+000,1.355753e+002,6.987841e-005,0.000000e+000,3,9.861193e-001,0.000000e+000,,,,,,,,,,,,,,32,1,4.000000e+000,9.235992e-001,0.000000e+000,0,,0,
1578424450.812,,0.000000e+000,1.406114e+002,6.808023e-005,0.000000e+000,3,9.862633e-001,0.000000e+000,,,,,,,,,,,,,,32,1,4.000000e+000,8.746033e-001,0.000000e+000,0,,0,
1578424509.272,,0.000000e+000,1.456165e+002,6.647498e-005,0.000000e+000,3,9.857087e-001,0.000000e+000,,,,,,,,,,,,,,32,1,4.000000e+000,9.924927e-001,0.000000e+000,0,,0,
1578424566.912,,0.000000e+000,1.505470e+002,6.490960e-005,0.000000e+000,3,9.850372e-001,0.000000e+000,,,,,,,,,,,,,,32,1,4.000000e+000,9.187012e-001,0.000000e+000,0,,0,
1578424625.883,,0.000000e+000,1.554888e+002,6.356529e-005,0.000000e+000,3,9.851903e-001,0.000000e+000,,,,,,,,,,,,,,32,1,4.000000e+000,7.662964e-001,0.000000e+000,0,,0,
1578424686.903,,0.000000e+000,1.605914e+002,6.194703e-005,0.000000e+000,3,9.849322e-001,0.000000e+000,,,,,,,,,,,,,,32,1,4.000000e+000,8.250122e-001,0.000000e+000,0,,0,
1578424746.943,,0.000000e+000,1.655723e+002,6.054420e-005,0.000000e+000,3,9.860315e-001,0.000000e+000,,,,,,,,,,,,,,32,1,4.000000e+000,8.999023e-001,0.000000e+000,0,,0,
1578424806.763,,0.000000e+000,1.705443e+002,5.920164e-005,0.000000e+000,3,9.863480e-001,0.000000e+000,,,,,,,,,,,,,,32,1,4.000000e+000,8.880005e-001,0.000000e+000,0,,0,
1578424865.973,,0.000000e+000,1.755690e+002,5.779594e-005,0.000000e+000,3,9.857953e-001,0.000000e+000,,,,,,,,,,,,,,32,1,4.000000e+000,9.714966e-001,0.000000e+000,0,,0,
1578424925.753,,0.000000e+000,1.805468e+002,5.665981e-005,0.000000e+000,3,9.859276e-001,0.000000e+000,,,,,,,,,,,,,,32,1,4.000000e+000,8.735962e-001,0.000000e+000,0,,0,
1578424985.123,,0.000000e+000,1.854764e+002,5.554365e-005,0.000000e+000,3,9.865467e-001,0.000000e+000,,,,,,,,,,,,,,32,1,4.000000e+000,9.424896e-001,0.000000e+000,0,,0,
1578425044.443,,0.000000e+000,1.904504e+002,5.448253e-005,0.000000e+000,3,9.866579e-001,0.000000e+000,,,,,,,,,,,,,,32,1,4.000000e+000,8.917084e-001,0.000000e+000,0,,0,
1578425105.983,,0.000000e+000,1.954530e+002,5.352747e-005,0.000000e+000,3,9.863739e-001,0.000000e+000,,,,,,,,,,,,,,32,1,4.000000e+000,8.804932e-001,0.000000e+000,0,,0,
1578425168.643,,0.000000e+000,2.005842e+002,5.263824e-005,0.000000e+000,3,9.875302e-001,0.000000e+000,,,,,,,,,,,,,,32,1,4.000000e+000,8.999023e-001,0.000000e+000,0,,0,
1578425230.073,,0.000000e+000,2.056418e+002,5.179408e-005,0.000000e+000,3,9.875171e-001,0.000000e+000,,,,,,,,,,,,,,32,1,4.000000e+000,1.038391e+000,0.000000e+000,0,,0,
1578425288.003,,0.000000e+000,2.105023e+002,5.114084e-005,0.000000e+000,3,9.880596e-001,0.000000e+000,,,,,,,,,,,,,,32,1,4.000000e+000,8.993073e-001,0.000000e+000,0,,0,
1578425347.844,,0.000000e+000,2.155101e+002,5.022949e-005,0.000000e+000,3,9.876922e-001,0.000000e+000,,,,,,,,,,,,,,32,1,4.000000e+000,9.983978e-001,0.000000e+000,0,,0,
1578425406.074,,0.000000e+000,2.206613e+002,4.956425e-005,0.000000e+000,3,9.872311e-001,0.000000e+000,,,,,,,,,,,,,,32,1,4.000000e+000,8.096924e-001,0.000000e+000,0,,0,
1578425464.124,,0.000000e+000,2.255166e+002,4.889284e-005,0.000000e+000,3,9.871080e-001,0.000000e+000,,,,,,,,,,,,,,32,1,4.000000e+000,8.769989e-001,0.000000e+000,0,,0,
1578425525.964,,0.000000e+000,2.304621e+002,4.833486e-005,0.000000e+000,3,9.875116e-001,0.000000e+000,,,,,,,,,,,,,,32,1,4.000000e+000,8.713989e-001,0.000000e+000,0,,0,
1578425586.114,,0.000000e+000,2.355961e+002,4.764504e-005,0.000000e+000,3,9.871470e-001,0.000000e+000,,,,,,,,,,,,,,32,1,4.000000e+000,8.407898e-001,0.000000e+000,0,,0,
1578425640.314,,0.000000e+000,2.407101e+002,4.719499e-005,0.000000e+000,3,9.875461e-001,0.000000e+000,,,,,,,,,,,,,,32,1,4.000000e+000,1.016296e+000,0.000000e+000,0,,0,
1578425704.544,,0.000000e+000,2.454494e+002,4.655123e-005,0.000000e+000,3,9.870342e-001,0.000000e+000,,,,,,,,,,,,,,32,1,4.000000e+000,8.479004e-001,0.000000e+000,0,,0,
1578425769.254,,0.000000e+000,2.505426e+002,4.602480e-005,0.000000e+000,3,9.849886e-001,0.000000e+000,,,,,,,,,,,,,,32,1,4.000000e+000,9.233093e-001,0.000000e+000,0,,0,
1578425830.254,,0.000000e+000,2.555793e+002,4.552411e-005,0.000000e+000,3,9.869178e-001,0.000000e+000,,,,,,,,,,,,,,32,1,4.000000e+000,8.865204e-001,0.000000e+000,0,,0,
1578425887.314,,0.000000e+000,2.604922e+002,4.505687e-005,0.000000e+000,3,9.868876e-001,0.000000e+000,,,,,,,,,,,,,,32,1,4.000000e+000,9.536743e-001,0.000000e+000,0,,0,
1578425948.664,,0.000000e+000,2.656706e+002,4.446737e-005,0.000000e+000,3,9.862189e-001,0.000000e+000,,,,,,,,,,,,,,32,1,4.000000e+000,9.223938e-001,0.000000e+000,0,,0,
1578426006.644,,0.000000e+000,2.705800e+002,4.399337e-005,0.000000e+000,3,9.867263e-001,0.000000e+000,,,,,,,,,,,,,,32,1,4.000000e+000,9.385986e-001,0.000000e+000,0,,0,
1578426065.245,,0.000000e+000,2.755406e+002,4.357158e-005,0.000000e+000,3,9.861589e-001,0.000000e+000,,,,,,,,,,,,,,32,1,4.000000e+000,7.612915e-001,0.000000e+000,0,,0,
1578426124.905,,0.000000e+000,2.805649e+002,4.309962e-005,0.000000e+000,3,9.882250e-001,0.000000e+000,,,,,,,,,,,,,,32,1,4.000000e+000,9.222107e-001,0.000000e+000,0,,0,
1578426184.005,,0.000000e+000,2.855735e+002,4.266908e-005,0.000000e+000,3,9.888185e-001,0.000000e+000,,,,,,,,,,,,,,32,1,4.000000e+000,9.462891e-001,0.000000e+000,0,,0,
1578426241.005,,0.000000e+000,2.904501e+002,4.221619e-005,0.000000e+000,3,9.877830e-001,0.000000e+000,,,,,,,,,,,,,,32,1,4.000000e+000,8.417969e-001,0.000000e+000,0,,0,
1578426296.735,,0.000000e+000,2.958649e+002,4.163033e-005,0.000000e+000,3,9.894569e-001,0.000000e+000,,,,,,,,,,,,,,32,1,4.000000e+000,1.115601e+000,0.000000e+000,0,,0,
1578426662.975,,0.000000e+000,3.000270e+002,4.075322e-005,0.000000e+000,3,9.875491e-001,0.000000e+000,,,,,,,,,,,,,,32,1,4.000000e+000,1.370239e-002,0.000000e+000,0,,0,
1578427207.826,,0.000000e+000,3.000132e+002,6.854064e-005,0.000000e+000,3,9.885457e-001,0.000000e+000,,,,,,,,,,,,,,32,1,4.000000e+000,1.370239e-002,0.000000e+000,0,,0,
1578427401.266,,0.000000e+000,2.944704e+002,6.835346e-005,0.000000e+000,3,9.878935e-001,0.000000e+000,,,,,,,,,,,,,,32,1,4.000000e+000,8.018188e-001,0.000000e+000,0,,0,
1578427465.167,,0.000000e+000,2.894086e+002,6.833093e-005,0.000000e+000,3,9.867014e-001,0.000000e+000,,,,,,,,,,,,,,32,1,4.000000e+000,1.037689e+000,0.000000e+000,0,,0,
1578427518.357,,0.000000e+000,2.844115e+002,6.842263e-005,0.000000e+000,3,9.874520e-001,0.000000e+000,,,,,,,,,,,,,,32,1,4.000000e+000,1.157227e+000,0.000000e+000,0,,0,
1578427572.367,,0.000000e+000,2.792835e+002,6.836276e-005,0.000000e+000,3,9.872488e-001,0.000000e+000,,,,,,,,,,,,,,32,1,4.000000e+000,1.264008e+000,0.000000e+000,0,,0,
1578427623.557,,0.000000e+000,2.742925e+002,6.838368e-005,0.000000e+000,3,9.872770e-001,0.000000e+000,,,,,,,,,,,,,,32,1,4.000000e+000,1.282288e+000,0.000000e+000,0,,0,
1578427679.237,,0.000000e+000,2.691380e+002,6.829255e-005,0.000000e+000,3,9.866782e-001,0.000000e+000,,,,,,,,,,,,,,32,1,4.000000e+000,1.402222e+000,0.000000e+000,0,,0,
1578427734.807,,0.000000e+000,2.643682e+002,6.826022e-005,0.000000e+000,3,9.872755e-001,0.000000e+000,,,,,,,,,,,,,,32,1,4.000000e+000,1.223389e+000,0.000000e+000,0,,0,
1578427796.297,,0.000000e+000,2.594232e+002,6.812145e-005,0.000000e+000,3,9.867516e-001,0.000000e+000,,,,,,,,,,,,,,32,1,4.000000e+000,1.144287e+000,0.000000e+000,0,,0,
1578427860.137,,0.000000e+000,2.543862e+002,6.806620e-005,0.000000e+000,3,9.878470e-001,0.000000e+000,,,,,,,,,,,,,,32,1,4.000000e+000,1.116211e+000,0.000000e+000,0,,0,
1578427928.097,,0.000000e+000,2.493485e+002,6.790290e-005,0.000000e+000,3,9.873844e-001,0.000000e+000,,,,,,,,,,,,,,32,1,4.000000e+000,9.138947e-001,0.000000e+000,0,,0,
1578428023.867,,0.000000e+000,2.424250e+002,6.770762e-005,0.000000e+000,3,9.869654e-001,0.000000e+000,,,,,,,,,,,,,,32,1,4.000000e+000,8.255920e-001,0.000000e+000,0,,0,
1578428065.897,,0.000000e+000,2.394887e+002,6.760022e-005,0.000000e+000,3,9.881987e-001,0.000000e+000,,,,,,,,,,,,,,32,1,4.000000e+000,9.716034e-001,0.000000e+000,0,,0,
1578428134.677,,0.000000e+000,2.344504e+002,6.741760e-005,0.000000e+000,3,9.873847e-001,0.000000e+000,,,,,,,,,,,,,,32,1,4.000000e+000,9.998932e-001,0.000000e+000,0,,0,
1578428201.808,,0.000000e+000,2.294415e+002,6.729636e-005,0.000000e+000,3,9.884369e-001,0.000000e+000,,,,,,,,,,,,,,32,1,4.000000e+000,1.016205e+000,0.000000e+000,0,,0,
1578428267.718,,0.000000e+000,2.243990e+002,6.707749e-005,0.000000e+000,3,9.876146e-001,0.000000e+000,,,,,,,,,,,,,,32,1,4.000000e+000,1.050308e+000,0.000000e+000,0,,0,
1578428332.278,,0.000000e+000,2.192767e+002,6.685047e-005,0.000000e+000,3,9.873031e-001,0.000000e+000,,,,,,,,,,,,,,32,1,4.000000e+000,9.797974e-001,0.000000e+000,0,,0,
1578428394.108,,0.000000e+000,2.143474e+002,6.670189e-005,0.000000e+000,3,9.877393e-001,0.000000e+000,,,,,,,,,,,,,,32,1,4.000000e+000,9.806061e-001,0.000000e+000,0,,0,
1578428457.688,,0.000000e+000,2.094117e+002,6.645360e-005,0.000000e+000,3,9.870549e-001,0.000000e+000,,,,,,,,,,,,,,32,1,4.000000e+000,1.066193e+000,0.000000e+000,0,,0,
1578428520.748,,0.000000e+000,2.043929e+002,6.613768e-005,0.000000e+000,3,9.864256e-001,0.000000e+000,,,,,,,,,,,,,,32,1,4.000000e+000,1.073303e+000,0.000000e+000,0,,0,
1578428581.838,,0.000000e+000,1.994489e+002,6.593728e-005,0.000000e+000,3,9.875971e-001,0.000000e+000,,,,,,,,,,,,,,32,1,4.000000e+000,1.003510e+000,0.000000e+000,0,,0,
1578428644.488,,0.000000e+000,1.943578e+002,6.566632e-005,0.000000e+000,3,9.873772e-001,0.000000e+000,,,,,,,,,,,,,,32,1,4.000000e+000,1.016312e+000,0.000000e+000,0,,0,
1578428703.828,,0.000000e+000,1.894633e+002,6.537602e-005,0.000000e+000,3,9.873549e-001,0.000000e+000,,,,,,,,,,,,,,32,1,4.000000e+000,1.041290e+000,0.000000e+000,0,,0,
1578428766.018,,0.000000e+000,1.843573e+002,6.505381e-005,0.000000e+000,3,9.871079e-001,0.000000e+000,,,,,,,,,,,,,,32,1,4.000000e+000,1.119904e+000,0.000000e+000,0,,0,
1578428827.288,,0.000000e+000,1.793632e+002,6.457912e-005,0.000000e+000,3,9.860349e-001,0.000000e+000,,,,,,,,,,,,,,32,1,4.000000e+000,1.031906e+000,0.000000e+000,0,,0,
1578428888.539,,0.000000e+000,1.743581e+002,6.427414e-005,0.000000e+000,3,9.879435e-001,0.000000e+000,,,,,,,,,,,,,,32,1,4.000000e+000,1.136002e+000,0.000000e+000,0,,0,
1578428947.009,,0.000000e+000,1.694604e+002,6.378998e-005,0.000000e+000,3,9.878588e-001,0.000000e+000,,,,,,,,,,,,,,32,1,4.000000e+000,1.057098e+000,0.000000e+000,0,,0,
1578429008.199,,0.000000e+000,1.644114e+002,6.329524e-005,0.000000e+000,3,9.858744e-001,0.000000e+000,,,,,,,,,,,,,,32,1,4.000000e+000,1.165207e+000,0.000000e+000,0,,0,
1578429068.559,,0.000000e+000,1.593965e+002,6.278299e-005,0.000000e+000,3,9.876703e-001,0.000000e+000,,,,,,,,,,,,,,32,1,4.000000e+000,1.070007e+000,0.000000e+000,0,,0,
1578429127.889,,0.000000e+000,1.544383e+002,6.215659e-005,0.000000e+000,3,9.874510e-001,0.000000e+000,,,,,,,,,,,,,,32,1,4.000000e+000,1.079208e+000,0.000000e+000,0,,0,
1578429188.509,,0.000000e+000,1.494085e+002,6.146021e-005,0.000000e+000,3,9.874802e-001,0.000000e+000,,,,,,,,,,,,,,32,1,4.000000e+000,1.089401e+000,0.000000e+000,0,,0,
1578429248.279,,0.000000e+000,1.443948e+002,6.068220e-005,0.000000e+000,3,9.878656e-001,0.000000e+000,,,,,,,,,,,,,,32,1,4.000000e+000,1.094406e+000,0.000000e+000,0,,0,
1578429308.549,,0.000000e+000,1.393470e+002,5.988040e-005,0.000000e+000,3,9.870642e-001,0.000000e+000,,,,,,,,,,,,,,32,1,4.000000e+000,1.027802e+000,0.000000e+000,0,,0,
1578429366.099,,0.000000e+000,1.344557e+002,5.892103e-005,0.000000e+000,3,9.864042e-001,0.000000e+000,,,,,,,,,,,,,,32,1,4.000000e+000,1.032089e+000,0.000000e+000,0,,0,
1578429425.279,,0.000000e+000,1.294740e+002,5.786786e-005,0.000000e+000,3,9.865869e-001,0.000000e+000,,,,,,,,,,,,,,32,1,4.000000e+000,1.050903e+000,0.000000e+000,0,,0,
1578429485.059,,0.000000e+000,1.244563e+002,5.640204e-005,0.000000e+000,3,9.854290e-001,0.000000e+000,,,,,,,,,,,,,,32,1,4.000000e+000,9.549026e-001,0.000000e+000,0,,0,
1578429544.639,,0.000000e+000,1.193300e+002,5.482087e-005,0.000000e+000,3,9.845408e-001,0.000000e+000,,,,,,,,,,,,,,32,1,4.000000e+000,1.183800e+000,0.000000e+000,0,,0,
1578429600.580,,0.000000e+000,1.144171e+002,5.338175e-005,0.000000e+000,3,9.858753e-001,0.000000e+000,,,,,,,,,,,,,,32,1,4.000000e+000,1.115303e+000,0.000000e+000,0,,0,
1578429657.910,,0.000000e+000,1.094538e+002,5.192371e-005,0.000000e+000,3,9.853068e-001,0.000000e+000,,,,,,,,,,,,,,32,1,4.000000e+000,1.078094e+000,0.000000e+000,0,,0,
1578429714.330,,0.000000e+000,1.044668e+002,5.083191e-005,0.000000e+000,3,9.868466e-001,0.000000e+000,,,,,,,,,,,,,,32,1,4.000000e+000,1.021599e+000,0.000000e+000,0,,0,
1578429770.860,,0.000000e+000,9.939293e+001,5.002972e-005,0.000000e+000,3,9.850084e-001,0.000000e+000,,,,,,,,,,,,,,32,1,4.000000e+000,1.087280e+000,0.000000e+000,0,,0,
1578429825.790,,0.000000e+000,9.436417e+001,4.940292e-005,0.000000e+000,3,9.854020e-001,0.000000e+000,,,,,,,,,,,,,,32,1,4.000000e+000,1.049545e+000,0.000000e+000,0,,0,
1578429880.190,,0.000000e+000,8.934949e+001,4.897068e-005,0.000000e+000,3,9.861493e-001,0.000000e+000,,,,,,,,,,,,,,32,1,4.000000e+000,1.210892e+000,0.000000e+000,0,,0,
1578429933.590,,0.000000e+000,8.434845e+001,4.860772e-005,0.000000e+000,3,9.861886e-001,0.000000e+000,,,,,,,,,,,,,,32,1,4.000000e+000,1.133125e+000,0.000000e+000,0,,0,
1578429985.920,,0.000000e+000,7.932257e+001,4.825731e-005,0.000000e+000,3,9.843579e-001,0.000000e+000,,,,,,,,,,,,,,32,1,4.000000e+000,1.193436e+000,0.000000e+000,0,,0,
1578430038.250,,0.000000e+000,7.423572e+001,4.805951e-005,0.000000e+000,3,9.857403e-001,0.000000e+000,,,,,,,,,,,,,,32,1,4.000000e+000,1.116699e+000,0.000000e+000,0,,0,
1578430087.790,,0.000000e+000,6.934441e+001,4.800644e-005,0.000000e+000,3,9.854913e-001,0.000000e+000,,,,,,,,,,,,,,32,1,4.000000e+000,1.273407e+000,0.000000e+000,0,,0,
1578430137.010,,0.000000e+000,6.421358e+001,4.802129e-005,0.000000e+000,3,9.859026e-001,0.000000e+000,,,,,,,,,,,,,,32,1,4.000000e+000,1.202496e+000,0.000000e+000,0,,0,
1578430184.590,,0.000000e+000,5.928791e+001,4.787555e-005,0.000000e+000,3,9.848349e-001,0.000000e+000,,,,,,,,,,,,,,32,1,4.000000e+000,1.363621e+000,0.000000e+000,0,,0,
1578430231.900,,0.000000e+000,5.432063e+001,4.784757e-005,0.000000e+000,3,9.871022e-001,0.000000e+000,,,,,,,,,,,,,,32,1,4.000000e+000,1.183220e+000,0.000000e+000,0,,0,
1578430276.610,,0.000000e+000,4.933955e+001,4.789156e-005,0.000000e+000,3,9.866753e-001,0.000000e+000,,,,,,,,,,,,,,32,1,4.000000e+000,1.255180e+000,0.000000e+000,0,,0,
1578430326.111,,0.000000e+000,4.401066e+001,4.781524e-005,0.000000e+000,3,9.869636e-001,0.000000e+000,,,,,,,,,,,,,,32,1,4.000000e+000,1.305958e+000,0.000000e+000,0,,0,
1578430365.361,,0.000000e+000,3.917985e+001,4.789387e-005,0.000000e+000,3,9.870441e-001,0.000000e+000,,,,,,,,,,,,,,32,1,4.000000e+000,1.264042e+000,0.000000e+000,0,,0,
1578430408.451,,0.000000e+000,3.422113e+001,4.788052e-005,0.000000e+000,3,9.860197e-001,0.000000e+000,,,,,,,,,,,,,,32,1,4.000000e+000,1.208900e+000,0.000000e+000,0,,0,
1578430452.961,,0.000000e+000,2.933028e+001,4.790465e-005,0.000000e+000,3,9.861438e-001,0.000000e+000,,,,,,,,,,,,,,32,1,4.000000e+000,1.301739e+000,0.000000e+000,0,,0,
1578430502.331,,0.000000e+000,2.418269e+001,4.797915e-005,0.000000e+000,3,9.873686e-001,0.000000e+000,,,,,,,,,,,,,,32,1,4.000000e+000,1.385012e+000,0.000000e+000,0,,0,
1578430566.931,,0.000000e+000,1.884597e+001,4.823810e-005,0.000000e+000,3,9.868134e-001,0.000000e+000,,,,,,,,,,,,,,32,1,4.000000e+000,1.318892e+000,0.000000e+000,0,,0,
1578430609.411,,0.000000e+000,1.460859e+001,4.799709e-005,0.000000e+000,3,9.853565e-001,0.000000e+000,,,,,,,,,,,,,,32,1,4.000000e+000,3.038979e-002,0.000000e+000,0,,0,
1578431470.812,,0.000000e+000,1.003414e+001,4.810283e-005,0.000000e+000,3,9.860975e-001,0.000000e+000,,,,,,,,,,,,,,32,1,4.000000e+000,4.469872e-003,0.000000e+000,0,,0,
1578432488.864,,0.000000e+000,9.997902e+000,4.818726e-005,0.000000e+000,3,9.861466e-001,0.000000e+000,,,,,,,,,,,,,,32,1,4.000000e+000,7.197380e-003,0.000000e+000,0,,0,
1578432570.404,,0.000000e+000,1.554321e+001,4.785925e-005,0.000000e+000,3,9.863589e-001,0.000000e+000,,,,,,,,,,,,,,32,1,4.000000e+000,1.035610e+000,0.000000e+000,0,,0,
1578432630.374,,0.000000e+000,2.053574e+001,4.797297e-005,0.000000e+000,3,9.860546e-001,0.000000e+000,,,,,,,,,,,,,,32,1,4.000000e+000,9.757290e-001,0.000000e+000,0,,0,
1578432692.404,,0.000000e+000,2.561536e+001,4.793801e-005,0.000000e+000,3,9.854969e-001,0.000000e+000,,,,,,,,,,,,,,32,1,4.000000e+000,9.164715e-001,0.000000e+000,0,,0,
1578432752.814,,0.000000e+000,3.057436e+001,4.814726e-005,0.000000e+000,3,9.854099e-001,0.000000e+000,,,,,,,,,,,,,,32,1,4.000000e+000,9.553185e-001,0.000000e+000,0,,0,
1578432812.434,,0.000000e+000,3.553420e+001,4.786089e-005,0.000000e+000,3,9.853094e-001,0.000000e+000,,,,,,,,,,,,,,32,1,4.000000e+000,8.511810e-001,0.000000e+000,0,,0,
1578432874.704,,0.000000e+000,4.053922e+001,4.777803e-005,0.000000e+000,3,9.842833e-001,0.000000e+000,,,,,,,,,,,,,,32,1,4.000000e+000,8.999519e-001,0.000000e+000,0,,0,
1578432934.694,,0.000000e+000,4.555721e+001,4.786532e-005,0.000000e+000,3,9.867604e-001,0.000000e+000,,,,,,,,,,,,,,32,1,4.000000e+000,1.002289e+000,0.000000e+000,0,,0,
1578432993.964,,0.000000e+000,5.051984e+001,4.776765e-005,0.000000e+000,3,9.860589e-001,0.000000e+000,,,,,,,,,,,,,,32,1,4.000000e+000,9.729767e-001,0.000000e+000,0,,0,
1578433053.884,,0.000000e+000,5.548374e+001,4.783083e-005,0.000000e+000,3,9.860903e-001,0.000000e+000,,,,,,,,,,,,,,32,1,4.000000e+000,8.773003e-001,0.000000e+000,0,,0,
1578433114.264,,0.000000e+000,6.051414e+001,4.775139e-005,0.000000e+000,3,9.850116e-001,0.000000e+000,,,,,,,,,,,,,,32,1,4.000000e+000,9.336510e-001,0.000000e+000,0,,0,
1578433173.855,,0.000000e+000,6.549849e+001,4.786216e-005,0.000000e+000,3,9.858662e-001,0.000000e+000,,,,,,,,,,,,,,32,1,4.000000e+000,9.759216e-001,0.000000e+000,0,,0,
1578433234.035,,0.000000e+000,7.054536e+001,4.792733e-005,0.000000e+000,3,9.866817e-001,0.000000e+000,,,,,,,,,,,,,,32,1,4.000000e+000,8.324280e-001,0.000000e+000,0,,0,
1578433293.195,,0.000000e+000,7.545905e+001,4.803639e-005,0.000000e+000,3,9.861543e-001,0.000000e+000,,,,,,,,,,,,,,32,1,4.000000e+000,9.133301e-001,0.000000e+000,0,,0,
1578433353.595,,0.000000e+000,8.053566e+001,4.813770e-005,0.000000e+000,3,9.860039e-001,0.000000e+000,,,,,,,,,,,,,,32,1,4.000000e+000,9.738770e-001,0.000000e+000,0,,0,
1578433414.495,,0.000000e+000,8.565109e+001,4.810715e-005,0.000000e+000,3,9.856862e-001,0.000000e+000,,,,,,,,,,,,,,32,1,4.000000e+000,9.715881e-001,0.000000e+000,0,,0,
1578433472.105,,0.000000e+000,9.050478e+001,4.839047e-005,0.000000e+000,3,9.862614e-001,0.000000e+000,,,,,,,,,,,,,,32,1,4.000000e+000,9.470901e-001,0.000000e+000,0,,0,
1578433532.975,,0.000000e+000,9.552310e+001,4.853866e-005,0.000000e+000,3,9.856780e-001,0.000000e+000,,,,,,,,,,,,,,32,1,4.000000e+000,9.140701e-001,0.000000e+000,0,,0,
1578433593.365,,0.000000e+000,1.006116e+002,4.880600e-005,0.000000e+000,3,9.865794e-001,0.000000e+000,,,,,,,,,,,,,,32,1,4.000000e+000,8.591995e-001,0.000000e+000,0,,0,
1578433653.655,,0.000000e+000,1.056236e+002,4.928832e-005,0.000000e+000,3,9.856727e-001,0.000000e+000,,,,,,,,,,,,,,32,1,4.000000e+000,9.072037e-001,0.000000e+000,0,,0,
1578433711.195,,0.000000e+000,1.104858e+002,4.985844e-005,0.000000e+000,3,9.851181e-001,0.000000e+000,,,,,,,,,,,,,,32,1,4.000000e+000,9.076004e-001,0.000000e+000,0,,0,
1578433772.205,,0.000000e+000,1.156198e+002,5.036016e-005,0.000000e+000,3,9.854827e-001,0.000000e+000,,,,,,,,,,,,,,32,1,4.000000e+000,8.011017e-001,0.000000e+000,0,,0,
1578433831.325,,0.000000e+000,1.205661e+002,5.108559e-005,0.000000e+000,3,9.862027e-001,0.000000e+000,,,,,,,,,,,,,,32,1,4.000000e+000,8.676987e-001,0.000000e+000,0,,0,
1578433890.816,,0.000000e+000,1.255055e+002,5.160629e-005,0.000000e+000,3,9.857731e-001,0.000000e+000,,,,,,,,,,,,,,32,1,4.000000e+000,8.423004e-001,0.000000e+000,0,,0,
1578433952.426,,0.000000e+000,1.306604e+002,5.198878e-005,0.000000e+000,3,9.873859e-001,0.000000e+000,,,,,,,,,,,,,,32,1,4.000000e+000,8.143921e-001,0.000000e+000,0,,0,
1578434011.246,,0.000000e+000,1.354703e+002,5.243759e-005,0.000000e+000,3,9.862283e-001,0.000000e+000,,,,,,,,,,,,,,32,1,4.000000e+000,8.907928e-001,0.000000e+000,0,,0,
1578434070.046,,0.000000e+000,1.405158e+002,5.249120e-005,0.000000e+000,3,9.875148e-001,0.000000e+000,,,,,,,,,,,,,,32,1,4.000000e+000,9.636078e-001,0.000000e+000,0,,0,
1578434131.106,,0.000000e+000,1.455558e+002,5.267507e-005,0.000000e+000,3,9.854051e-001,0.000000e+000,,,,,,,,,,,,,,32,1,4.000000e+000,9.190979e-001,0.000000e+000,0,,0,
1578434190.726,,0.000000e+000,1.506115e+002,5.295964e-005,0.000000e+000,3,9.869458e-001,0.000000e+000,,,,,,,,,,,,,,32,1,4.000000e+000,8.676910e-001,0.000000e+000,0,,0,
1578434252.906,,0.000000e+000,1.554823e+002,5.302883e-005,0.000000e+000,3,9.861850e-001,0.000000e+000,,,,,,,,,,,,,,32,1,4.000000e+000,9.042969e-001,0.000000e+000,0,,0,
1578434316.866,,0.000000e+000,1.604771e+002,5.310425e-005,0.000000e+000,3,9.856890e-001,0.000000e+000,,,,,,,,,,,,,,32,1,4.000000e+000,7.283020e-001,0.000000e+000,0,,0,
1578434380.646,,0.000000e+000,1.654840e+002,5.319759e-005,0.000000e+000,3,9.858664e-001,0.000000e+000,,,,,,,,,,,,,,32,1,4.000000e+000,8.090973e-001,0.000000e+000,0,,0,
1578434438.996,,0.000000e+000,1.705051e+002,5.319816e-005,0.000000e+000,3,9.865579e-001,0.000000e+000,,,,,,,,,,,,,,32,1,4.000000e+000,9.248962e-001,0.000000e+000,0,,0,
1578434496.636,,0.000000e+000,1.756945e+002,5.327228e-005,0.000000e+000,3,9.863560e-001,0.000000e+000,,,,,,,,,,,,,,32,1,4.000000e+000,1.021194e+000,0.000000e+000,0,,0,
1578434551.336,,0.000000e+000,1.804818e+002,5.342002e-005,0.000000e+000,3,9.864255e-001,0.000000e+000,,,,,,,,,,,,,,32,1,4.000000e+000,9.101105e-001,0.000000e+000,0,,0,
1578434611.107,,0.000000e+000,1.855825e+002,5.333058e-005,0.000000e+000,3,9.864056e-001,0.000000e+000,,,,,,,,,,,,,,32,1,4.000000e+000,1.076309e+000,0.000000e+000,0,,0,
1578434669.057,,0.000000e+000,1.906346e+002,5.337663e-005,0.000000e+000,3,9.873824e-001,0.000000e+000,,,,,,,,,,,,,,32,1,4.000000e+000,8.363037e-001,0.000000e+000,0,,0,
1578434726.517,,0.000000e+000,1.955796e+002,5.341078e-005,0.000000e+000,3,9.871895e-001,0.000000e+000,,,,,,,,,,,,,,32,1,4.000000e+000,1.122696e+000,0.000000e+000,0,,0,
1578434777.967,,0.000000e+000,2.006476e+002,5.334042e-005,0.000000e+000,3,9.876822e-001,0.000000e+000,,,,,,,,,,,,,,32,1,4.000000e+000,9.120941e-001,0.000000e+000,0,,0,
1578434847.037,,0.000000e+000,2.054591e+002,5.322122e-005,0.000000e+000,3,9.884409e-001,0.000000e+000,,,,,,,,,,,,,,32,1,4.000000e+000,7.091980e-001,0.000000e+000,0,,0,
1578434912.697,,0.000000e+000,2.104576e+002,5.318922e-005,0.000000e+000,3,9.874495e-001,0.000000e+000,,,,,,,,,,,,,,32,1,4.000000e+000,8.733978e-001,0.000000e+000,0,,0,
1578434974.157,,0.000000e+000,2.155701e+002,5.312670e-005,0.000000e+000,3,9.876219e-001,0.000000e+000,,,,,,,,,,,,,,32,1,4.000000e+000,8.381042e-001,0.000000e+000,0,,0,
1578435033.977,,0.000000e+000,2.206160e+002,5.296447e-005,0.000000e+000,3,9.886612e-001,0.000000e+000,,,,,,,,,,,,,,32,1,4.000000e+000,9.994049e-001,0.000000e+000,0,,0,
1578435089.477,,0.000000e+000,2.255609e+002,5.281837e-005,0.000000e+000,3,9.881588e-001,0.000000e+000,,,,,,,,,,,,,,32,1,4.000000e+000,9.216003e-001,0.000000e+000,0,,0,
1578435148.577,,0.000000e+000,2.305742e+002,5.280319e-005,0.000000e+000,3,9.873886e-001,0.000000e+000,,,,,,,,,,,,,,32,1,4.000000e+000,9.725952e-001,0.000000e+000,0,,0,
1578435208.737,,0.000000e+000,2.355396e+002,5.262435e-005,0.000000e+000,3,9.865705e-001,0.000000e+000,,,,,,,,,,,,,,32,1,4.000000e+000,8.887939e-001,0.000000e+000,0,,0,
1578435265.497,,0.000000e+000,2.404771e+002,5.248510e-005,0.000000e+000,3,9.880437e-001,0.000000e+000,,,,,,,,,,,,,,32,1,4.000000e+000,8.874054e-001,0.000000e+000,0,,0,
1578435326.728,,0.000000e+000,2.456173e+002,5.232983e-005,0.000000e+000,3,9.873374e-001,0.000000e+000,,,,,,,,,,,,,,32,1,4.000000e+000,8.491974e-001,0.000000e+000,0,,0,
1578435385.578,,0.000000e+000,2.505150e+002,5.218756e-005,0.000000e+000,3,9.881122e-001,0.000000e+000,,,,,,,,,,,,,,32,1,4.000000e+000,9.785004e-001,0.000000e+000,0,,0,
1578435445.968,,0.000000e+000,2.555361e+002,5.206397e-005,0.000000e+000,3,9.877023e-001,0.000000e+000,,,,,,,,,,,,,,32,1,4.000000e+000,9.537048e-001,0.000000e+000,0,,0,
1578435506.448,,0.000000e+000,2.605573e+002,5.188904e-005,0.000000e+000,3,9.881226e-001,0.000000e+000,,,,,,,,,,,,,,32,1,4.000000e+000,8.436890e-001,0.000000e+000,0,,0,
1578435566.308,,0.000000e+000,2.656080e+002,5.168117e-005,0.000000e+000,3,9.895405e-001,0.000000e+000,,,,,,,,,,,,,,32,1,4.000000e+000,1.068512e+000,0.000000e+000,0,,0,
1578435622.398,,0.000000e+000,2.704651e+002,5.146743e-005,0.000000e+000,3,9.886575e-001,0.000000e+000,,,,,,,,,,,,,,32,1,4.000000e+000,7.525024e-001,0.000000e+000,0,,0,
1578435683.798,,0.000000e+000,2.754783e+002,5.129269e-005,0.000000e+000,3,9.890242e-001,0.000000e+000,,,,,,,,,,,,,,32,1,4.000000e+000,8.175964e-001,0.000000e+000,0,,0,
1578435741.778,,0.000000e+000,2.807899e+002,5.103053e-005,0.000000e+000,3,9.877614e-001,0.000000e+000,,,,,,,,,,,,,,32,1,4.000000e+000,9.710999e-001,0.000000e+000,0,,0,
1578435808.868,,0.000000e+000,2.854566e+002,5.091130e-005,0.000000e+000,3,9.880770e-001,0.000000e+000,,,,,,,,,,,,,,32,1,4.000000e+000,8.842163e-001,0.000000e+000,0,,0,
1578435872.978,,0.000000e+000,2.904629e+002,5.066358e-005,0.000000e+000,3,9.881045e-001,0.000000e+000,,,,,,,,,,,,,,32,1,4.000000e+000,8.930054e-001,0.000000e+000,0,,0,
1578435934.568,,0.000000e+000,2.955464e+002,5.035587e-005,0.000000e+000,3,9.883251e-001,0.000000e+000,,,,,,,,,,,,,,32,1,4.000000e+000,1.086487e+000,0.000000e+000,0,,0,
1578436313.869,,0.000000e+000,3.000064e+002,4.965303e-005,0.000000e+000,3,9.887075e-001,0.000000e+000,,,,,,,,,,,,,,32,1,4.000000e+000,2.740479e-002,0.000000e+000,0,,0,