File: data/Rock_mag/2020_IRM_data_files/Raw_data/MPMS_5S/data/MC7-4r_FC-ZFC-RTSIRM-10K.dc.dc.dat
[Header]
TITLE,MPMS DC Measurement
BYAPP,MPMS Measurement,2.1,Summary
FILEOPENTIME, 1578615527.358000 1/9/2020, 6:18:47 PM

INFO, APPNAME, MPMS MultiVu Application, Revision 1.61,  Build 082

INFO, NAME, MC7-4r
INFO, WEIGHT, 1.000
INFO, AREA, 1.000
INFO, LENGTH, 1.000
INFO, SHAPE, 0
INFO, COMMENT,
INFO, SEQUENCE FILE: FC-ZFC LTSIRM and RTSIRM LTD 10K.seq


INFO, BACKGROUND DATA FILE:, None


STARTUPAXIS,X,4,LINEAR,AUTO,0.000000,0.000000
STARTUPAXIS,Y1,5,LINEAR,AUTO,0.000000,0.000000


STARTUPGROUP,Longitudinal
FIELDGROUP,Longitudinal,1,2,3,4,5,6,7,8,9,15,16,17,18,27,28
FIELDGROUP,Transverse,1,2,3,4,10,11,12,13,14,19,20,21,22,27,28

PLOT_APPEARANCE,ALL,HORZ_GRID_ON,VERT_GRID_ON,MARKERS_AND_LINES

[Data]
Time,Comment,Field (Oe),Temperature (K),Long Moment (emu),Long Scan Std Dev,Long Algorithm,Long Reg Fit,Long Percent Error (%),Trans Moment (emu),Trans Scan Std Dev,Trans Algorithm,Trans Reg Fit,Trans Percent Error (%),Long Moment [w/o ABS] (emu),Long Scan Std Dev [w/o ABS],Long Reg Fit [w/o ABS],Long Percent Error [w/o ABS] (%),Trans Moment [w/o ABS] (emu),Trans Scan Std Dev [w/o ABS],Trans Reg Fit [w/o ABS],Trans Percent Error [w/o ABS] (%),Points per Scan,Scans per Measurement,Scan Length (cm),Delta Temp (K),Rot Position (deg),Error,EC Comp. Running,Using ABS,
1578615527.358,,0.000000e+000,9.998156e+000,8.076592e-004,0.000000e+000,3,9.810846e-001,0.000000e+000,,,,,,,,,,,,,,32,1,4.000000e+000,6.127357e-003,0.000000e+000,0,,0,
1578615607.898,,0.000000e+000,1.547779e+001,6.941971e-004,0.000000e+000,3,9.809032e-001,0.000000e+000,,,,,,,,,,,,,,32,1,4.000000e+000,9.539204e-001,0.000000e+000,0,,0,
1578615682.528,,0.000000e+000,2.164312e+001,5.719264e-004,0.000000e+000,3,9.807902e-001,0.000000e+000,,,,,,,,,,,,,,32,1,4.000000e+000,9.566517e-001,0.000000e+000,0,,0,
1578615731.308,,0.000000e+000,2.567071e+001,5.071859e-004,0.000000e+000,3,9.803701e-001,0.000000e+000,,,,,,,,,,,,,,32,1,4.000000e+000,9.168396e-001,0.000000e+000,0,,0,
1578615790.898,,0.000000e+000,3.058740e+001,4.392118e-004,0.000000e+000,3,9.794302e-001,0.000000e+000,,,,,,,,,,,,,,32,1,4.000000e+000,8.876991e-001,0.000000e+000,0,,0,
1578615850.618,,0.000000e+000,3.547122e+001,3.856202e-004,0.000000e+000,3,9.791062e-001,0.000000e+000,,,,,,,,,,,,,,32,1,4.000000e+000,9.414787e-001,0.000000e+000,0,,0,
1578615913.518,,0.000000e+000,4.062308e+001,3.536541e-004,0.000000e+000,3,9.786997e-001,0.000000e+000,,,,,,,,,,,,,,32,1,4.000000e+000,9.852104e-001,0.000000e+000,0,,0,
1578615972.558,,0.000000e+000,4.556464e+001,3.360933e-004,0.000000e+000,3,9.783116e-001,0.000000e+000,,,,,,,,,,,,,,32,1,4.000000e+000,9.273720e-001,0.000000e+000,0,,0,
1578616033.279,,0.000000e+000,5.060775e+001,3.244532e-004,0.000000e+000,3,9.781958e-001,0.000000e+000,,,,,,,,,,,,,,32,1,4.000000e+000,9.064713e-001,0.000000e+000,0,,0,
1578616105.909,,0.000000e+000,5.661414e+001,3.173917e-004,0.000000e+000,3,9.782392e-001,0.000000e+000,,,,,,,,,,,,,,32,1,4.000000e+000,9.681015e-001,0.000000e+000,0,,0,
1578616152.399,,0.000000e+000,6.049895e+001,3.136444e-004,0.000000e+000,3,9.775266e-001,0.000000e+000,,,,,,,,,,,,,,32,1,4.000000e+000,9.583397e-001,0.000000e+000,0,,0,
1578616212.839,,0.000000e+000,6.553893e+001,3.082746e-004,0.000000e+000,3,9.777514e-001,0.000000e+000,,,,,,,,,,,,,,32,1,4.000000e+000,8.924103e-001,0.000000e+000,0,,0,
1578616273.099,,0.000000e+000,7.062881e+001,3.029544e-004,0.000000e+000,3,9.778656e-001,0.000000e+000,,,,,,,,,,,,,,32,1,4.000000e+000,8.538513e-001,0.000000e+000,0,,0,
1578616332.179,,0.000000e+000,7.553842e+001,2.973737e-004,0.000000e+000,3,9.779857e-001,0.000000e+000,,,,,,,,,,,,,,32,1,4.000000e+000,9.236908e-001,0.000000e+000,0,,0,
1578616391.919,,0.000000e+000,8.053869e+001,2.916269e-004,0.000000e+000,3,9.777780e-001,0.000000e+000,,,,,,,,,,,,,,32,1,4.000000e+000,9.951630e-001,0.000000e+000,0,,0,
1578616452.269,,0.000000e+000,8.564348e+001,2.851810e-004,0.000000e+000,3,9.777498e-001,0.000000e+000,,,,,,,,,,,,,,32,1,4.000000e+000,9.649200e-001,0.000000e+000,0,,0,
1578616510.599,,0.000000e+000,9.049893e+001,2.781458e-004,0.000000e+000,3,9.779173e-001,0.000000e+000,,,,,,,,,,,,,,32,1,4.000000e+000,9.831238e-001,0.000000e+000,0,,0,
1578616571.579,,0.000000e+000,9.563794e+001,2.696248e-004,0.000000e+000,3,9.779894e-001,0.000000e+000,,,,,,,,,,,,,,32,1,4.000000e+000,8.679733e-001,0.000000e+000,0,,0,
1578616630.479,,0.000000e+000,1.005838e+002,2.596845e-004,0.000000e+000,3,9.781308e-001,0.000000e+000,,,,,,,,,,,,,,32,1,4.000000e+000,9.325027e-001,0.000000e+000,0,,0,
1578616689.289,,0.000000e+000,1.054619e+002,2.480068e-004,0.000000e+000,3,9.782545e-001,0.000000e+000,,,,,,,,,,,,,,32,1,4.000000e+000,9.045029e-001,0.000000e+000,0,,0,
1578616750.010,,0.000000e+000,1.105548e+002,2.353250e-004,0.000000e+000,3,9.784082e-001,0.000000e+000,,,,,,,,,,,,,,32,1,4.000000e+000,9.334030e-001,0.000000e+000,0,,0,
1578616811.130,,0.000000e+000,1.156301e+002,2.216519e-004,0.000000e+000,3,9.787115e-001,0.000000e+000,,,,,,,,,,,,,,32,1,4.000000e+000,9.745026e-001,0.000000e+000,0,,0,
1578616870.840,,0.000000e+000,1.205955e+002,2.096714e-004,0.000000e+000,3,9.790019e-001,0.000000e+000,,,,,,,,,,,,,,32,1,4.000000e+000,9.015045e-001,0.000000e+000,0,,0,
1578616931.130,,0.000000e+000,1.254583e+002,1.993371e-004,0.000000e+000,3,9.789026e-001,0.000000e+000,,,,,,,,,,,,,,32,1,4.000000e+000,8.642044e-001,0.000000e+000,0,,0,
1578616991.200,,0.000000e+000,1.306751e+002,1.912350e-004,0.000000e+000,3,9.795439e-001,0.000000e+000,,,,,,,,,,,,,,32,1,4.000000e+000,8.437958e-001,0.000000e+000,0,,0,
1578617049.670,,0.000000e+000,1.355573e+002,1.839668e-004,0.000000e+000,3,9.799275e-001,0.000000e+000,,,,,,,,,,,,,,32,1,4.000000e+000,1.023087e+000,0.000000e+000,0,,0,
1578617107.600,,0.000000e+000,1.405272e+002,1.770298e-004,0.000000e+000,3,9.798270e-001,0.000000e+000,,,,,,,,,,,,,,32,1,4.000000e+000,1.008804e+000,0.000000e+000,0,,0,
1578617180.570,,0.000000e+000,1.466737e+002,1.692890e-004,0.000000e+000,3,9.799626e-001,0.000000e+000,,,,,,,,,,,,,,32,1,4.000000e+000,8.780975e-001,0.000000e+000,0,,0,
1578617227.970,,0.000000e+000,1.505374e+002,1.651887e-004,0.000000e+000,3,9.792904e-001,0.000000e+000,,,,,,,,,,,,,,32,1,4.000000e+000,9.509888e-001,0.000000e+000,0,,0,
1578617287.410,,0.000000e+000,1.555753e+002,1.605227e-004,0.000000e+000,3,9.799091e-001,0.000000e+000,,,,,,,,,,,,,,32,1,4.000000e+000,8.154907e-001,0.000000e+000,0,,0,
1578617347.750,,0.000000e+000,1.605621e+002,1.562999e-004,0.000000e+000,3,9.800244e-001,0.000000e+000,,,,,,,,,,,,,,32,1,4.000000e+000,8.836060e-001,0.000000e+000,0,,0,
1578617407.410,,0.000000e+000,1.655605e+002,1.527526e-004,0.000000e+000,3,9.794425e-001,0.000000e+000,,,,,,,,,,,,,,32,1,4.000000e+000,8.998108e-001,0.000000e+000,0,,0,
1578617467.721,,0.000000e+000,1.705734e+002,1.498224e-004,0.000000e+000,3,9.805184e-001,0.000000e+000,,,,,,,,,,,,,,32,1,4.000000e+000,8.965912e-001,0.000000e+000,0,,0,
1578617527.791,,0.000000e+000,1.755380e+002,1.472189e-004,0.000000e+000,3,9.793459e-001,0.000000e+000,,,,,,,,,,,,,,32,1,4.000000e+000,8.831940e-001,0.000000e+000,0,,0,
1578617587.601,,0.000000e+000,1.805052e+002,1.449992e-004,0.000000e+000,3,9.790008e-001,0.000000e+000,,,,,,,,,,,,,,32,1,4.000000e+000,9.568024e-001,0.000000e+000,0,,0,
1578617648.041,,0.000000e+000,1.855992e+002,1.432182e-004,0.000000e+000,3,9.792539e-001,0.000000e+000,,,,,,,,,,,,,,32,1,4.000000e+000,8.946991e-001,0.000000e+000,0,,0,
1578617708.421,,0.000000e+000,1.906609e+002,1.414277e-004,0.000000e+000,3,9.792958e-001,0.000000e+000,,,,,,,,,,,,,,32,1,4.000000e+000,1.013306e+000,0.000000e+000,0,,0,
1578617767.751,,0.000000e+000,1.955656e+002,1.399966e-004,0.000000e+000,3,9.790578e-001,0.000000e+000,,,,,,,,,,,,,,32,1,4.000000e+000,1.029404e+000,0.000000e+000,0,,0,
1578617826.751,,0.000000e+000,2.005181e+002,1.387021e-004,0.000000e+000,3,9.791733e-001,0.000000e+000,,,,,,,,,,,,,,32,1,4.000000e+000,1.008804e+000,0.000000e+000,0,,0,
1578617887.301,,0.000000e+000,2.056112e+002,1.372563e-004,0.000000e+000,3,9.795439e-001,0.000000e+000,,,,,,,,,,,,,,32,1,4.000000e+000,9.288025e-001,0.000000e+000,0,,0,
1578617945.501,,0.000000e+000,2.104672e+002,1.363060e-004,0.000000e+000,3,9.792584e-001,0.000000e+000,,,,,,,,,,,,,,32,1,4.000000e+000,9.054108e-001,0.000000e+000,0,,0,
1578618006.861,,0.000000e+000,2.155570e+002,1.354715e-004,0.000000e+000,3,9.791267e-001,0.000000e+000,,,,,,,,,,,,,,32,1,4.000000e+000,9.853973e-001,0.000000e+000,0,,0,
1578618068.431,,0.000000e+000,2.206866e+002,1.343354e-004,0.000000e+000,3,9.791225e-001,0.000000e+000,,,,,,,,,,,,,,32,1,4.000000e+000,1.070496e+000,0.000000e+000,0,,0,
1578618126.341,,0.000000e+000,2.255498e+002,1.335441e-004,0.000000e+000,3,9.790946e-001,0.000000e+000,,,,,,,,,,,,,,32,1,4.000000e+000,8.993988e-001,0.000000e+000,0,,0,
1578618186.042,,0.000000e+000,2.304815e+002,1.326737e-004,0.000000e+000,3,9.788827e-001,0.000000e+000,,,,,,,,,,,,,,32,1,4.000000e+000,9.564972e-001,0.000000e+000,0,,0,
1578618247.772,,0.000000e+000,2.355437e+002,1.318626e-004,0.000000e+000,3,9.786186e-001,0.000000e+000,,,,,,,,,,,,,,32,1,4.000000e+000,8.970032e-001,0.000000e+000,0,,0,
1578618307.202,,0.000000e+000,2.405746e+002,1.310421e-004,0.000000e+000,3,9.788590e-001,0.000000e+000,,,,,,,,,,,,,,32,1,4.000000e+000,9.812012e-001,0.000000e+000,0,,0,
1578618366.952,,0.000000e+000,2.455999e+002,1.304791e-004,0.000000e+000,3,9.786052e-001,0.000000e+000,,,,,,,,,,,,,,32,1,4.000000e+000,9.729004e-001,0.000000e+000,0,,0,
1578618426.512,,0.000000e+000,2.505658e+002,1.296073e-004,0.000000e+000,3,9.790968e-001,0.000000e+000,,,,,,,,,,,,,,32,1,4.000000e+000,9.696045e-001,0.000000e+000,0,,0,
1578618486.432,,0.000000e+000,2.555601e+002,1.288315e-004,0.000000e+000,3,9.784342e-001,0.000000e+000,,,,,,,,,,,,,,32,1,4.000000e+000,8.863983e-001,0.000000e+000,0,,0,
1578618545.432,,0.000000e+000,2.605170e+002,1.281874e-004,0.000000e+000,3,9.788798e-001,0.000000e+000,,,,,,,,,,,,,,32,1,4.000000e+000,7.832031e-001,0.000000e+000,0,,0,
1578618607.182,,0.000000e+000,2.655446e+002,1.274139e-004,0.000000e+000,3,9.783773e-001,0.000000e+000,,,,,,,,,,,,,,32,1,4.000000e+000,7.749023e-001,0.000000e+000,0,,0,
1578618666.072,,0.000000e+000,2.705474e+002,1.266725e-004,0.000000e+000,3,9.788594e-001,0.000000e+000,,,,,,,,,,,,,,32,1,4.000000e+000,9.602966e-001,0.000000e+000,0,,0,
1578618725.812,,0.000000e+000,2.756149e+002,1.259988e-004,0.000000e+000,3,9.791865e-001,0.000000e+000,,,,,,,,,,,,,,32,1,4.000000e+000,9.547729e-001,0.000000e+000,0,,0,
1578618785.822,,0.000000e+000,2.806121e+002,1.251986e-004,0.000000e+000,3,9.787041e-001,0.000000e+000,,,,,,,,,,,,,,32,1,4.000000e+000,8.515015e-001,0.000000e+000,0,,0,
1578618846.222,,0.000000e+000,2.856103e+002,1.244813e-004,0.000000e+000,3,9.787673e-001,0.000000e+000,,,,,,,,,,,,,,32,1,4.000000e+000,9.465942e-001,0.000000e+000,0,,0,
1578618904.843,,0.000000e+000,2.905139e+002,1.237747e-004,0.000000e+000,3,9.790503e-001,0.000000e+000,,,,,,,,,,,,,,32,1,4.000000e+000,8.678284e-001,0.000000e+000,0,,0,
1578618965.893,,0.000000e+000,2.955793e+002,1.230271e-004,0.000000e+000,3,9.786189e-001,0.000000e+000,,,,,,,,,,,,,,32,1,4.000000e+000,9.143982e-001,0.000000e+000,0,,0,
1578619313.023,,0.000000e+000,3.000201e+002,1.221924e-004,0.000000e+000,3,9.787326e-001,0.000000e+000,,,,,,,,,,,,,,32,1,4.000000e+000,0.000000e+000,0.000000e+000,0,,0,
1578624248.800,,0.000000e+000,9.994304e+000,4.078368e-004,0.000000e+000,3,9.803881e-001,0.000000e+000,,,,,,,,,,,,,,32,1,4.000000e+000,7.905960e-003,0.000000e+000,0,,0,
1578624331.210,,0.000000e+000,1.554488e+001,3.444586e-004,0.000000e+000,3,9.805584e-001,0.000000e+000,,,,,,,,,,,,,,32,1,4.000000e+000,9.888191e-001,0.000000e+000,0,,0,
1578624390.490,,0.000000e+000,2.047228e+001,3.147596e-004,0.000000e+000,3,9.807734e-001,0.000000e+000,,,,,,,,,,,,,,32,1,4.000000e+000,8.977795e-001,0.000000e+000,0,,0,
1578624453.030,,0.000000e+000,2.558174e+001,3.021925e-004,0.000000e+000,3,9.802740e-001,0.000000e+000,,,,,,,,,,,,,,32,1,4.000000e+000,9.375801e-001,0.000000e+000,0,,0,
1578624515.660,,0.000000e+000,3.045193e+001,2.943642e-004,0.000000e+000,3,9.804743e-001,0.000000e+000,,,,,,,,,,,,,,32,1,4.000000e+000,8.755703e-001,0.000000e+000,0,,0,
1578624572.800,,0.000000e+000,3.557098e+001,2.861996e-004,0.000000e+000,3,9.807613e-001,0.000000e+000,,,,,,,,,,,,,,32,1,4.000000e+000,1.002949e+000,0.000000e+000,0,,0,
1578624635.161,,0.000000e+000,4.066589e+001,2.758150e-004,0.000000e+000,3,9.805446e-001,0.000000e+000,,,,,,,,,,,,,,32,1,4.000000e+000,9.779091e-001,0.000000e+000,0,,0,
1578624694.271,,0.000000e+000,4.556542e+001,2.682153e-004,0.000000e+000,3,9.806701e-001,0.000000e+000,,,,,,,,,,,,,,32,1,4.000000e+000,8.325615e-001,0.000000e+000,0,,0,
1578624755.121,,0.000000e+000,5.049136e+001,2.632177e-004,0.000000e+000,3,9.804647e-001,0.000000e+000,,,,,,,,,,,,,,32,1,4.000000e+000,8.926086e-001,0.000000e+000,0,,0,
1578624816.431,,0.000000e+000,5.561082e+001,2.590449e-004,0.000000e+000,3,9.802116e-001,0.000000e+000,,,,,,,,,,,,,,32,1,4.000000e+000,8.739586e-001,0.000000e+000,0,,0,
1578624874.751,,0.000000e+000,6.048081e+001,2.552364e-004,0.000000e+000,3,9.800553e-001,0.000000e+000,,,,,,,,,,,,,,32,1,4.000000e+000,9.605980e-001,0.000000e+000,0,,0,
1578624935.741,,0.000000e+000,6.557216e+001,2.513377e-004,0.000000e+000,3,9.802253e-001,0.000000e+000,,,,,,,,,,,,,,32,1,4.000000e+000,9.871445e-001,0.000000e+000,0,,0,
1578624995.801,,0.000000e+000,7.062292e+001,2.471122e-004,0.000000e+000,3,9.799509e-001,0.000000e+000,,,,,,,,,,,,,,32,1,4.000000e+000,8.747635e-001,0.000000e+000,0,,0,
1578625052.711,,0.000000e+000,7.544585e+001,2.429563e-004,0.000000e+000,3,9.802475e-001,0.000000e+000,,,,,,,,,,,,,,32,1,4.000000e+000,8.363800e-001,0.000000e+000,0,,0,
1578625113.211,,0.000000e+000,8.048234e+001,2.385981e-004,0.000000e+000,3,9.800637e-001,0.000000e+000,,,,,,,,,,,,,,32,1,4.000000e+000,9.129486e-001,0.000000e+000,0,,0,
1578625173.931,,0.000000e+000,8.557150e+001,2.340074e-004,0.000000e+000,3,9.797026e-001,0.000000e+000,,,,,,,,,,,,,,32,1,4.000000e+000,8.724594e-001,0.000000e+000,0,,0,
1578625233.471,,0.000000e+000,9.056282e+001,2.291107e-004,0.000000e+000,3,9.797512e-001,0.000000e+000,,,,,,,,,,,,,,32,1,4.000000e+000,9.820251e-001,0.000000e+000,0,,0,
1578625290.421,,0.000000e+000,9.549796e+001,2.234304e-004,0.000000e+000,3,9.796671e-001,0.000000e+000,,,,,,,,,,,,,,32,1,4.000000e+000,9.697113e-001,0.000000e+000,0,,0,
1578625351.552,,0.000000e+000,1.006014e+002,2.165259e-004,0.000000e+000,3,9.801451e-001,0.000000e+000,,,,,,,,,,,,,,32,1,4.000000e+000,9.151001e-001,0.000000e+000,0,,0,
1578625411.282,,0.000000e+000,1.054489e+002,2.090754e-004,0.000000e+000,3,9.798779e-001,0.000000e+000,,,,,,,,,,,,,,32,1,4.000000e+000,8.785019e-001,0.000000e+000,0,,0,
1578625471.362,,0.000000e+000,1.105105e+002,2.010468e-004,0.000000e+000,3,9.799286e-001,0.000000e+000,,,,,,,,,,,,,,32,1,4.000000e+000,9.008026e-001,0.000000e+000,0,,0,
1578625533.492,,0.000000e+000,1.156416e+002,1.923732e-004,0.000000e+000,3,9.798239e-001,0.000000e+000,,,,,,,,,,,,,,32,1,4.000000e+000,9.823990e-001,0.000000e+000,0,,0,
1578625590.952,,0.000000e+000,1.205704e+002,1.846380e-004,0.000000e+000,3,9.797114e-001,0.000000e+000,,,,,,,,,,,,,,32,1,4.000000e+000,9.011002e-001,0.000000e+000,0,,0,
1578625650.832,,0.000000e+000,1.255957e+002,1.777237e-004,0.000000e+000,3,9.795602e-001,0.000000e+000,,,,,,,,,,,,,,32,1,4.000000e+000,8.795013e-001,0.000000e+000,0,,0,
1578625710.672,,0.000000e+000,1.305319e+002,1.721392e-004,0.000000e+000,3,9.797189e-001,0.000000e+000,,,,,,,,,,,,,,32,1,4.000000e+000,1.002609e+000,0.000000e+000,0,,0,
1578625771.032,,0.000000e+000,1.355541e+002,1.673326e-004,0.000000e+000,3,9.791602e-001,0.000000e+000,,,,,,,,,,,,,,32,1,4.000000e+000,8.603973e-001,0.000000e+000,0,,0,
1578625830.782,,0.000000e+000,1.405692e+002,1.630677e-004,0.000000e+000,3,9.798247e-001,0.000000e+000,,,,,,,,,,,,,,32,1,4.000000e+000,9.022980e-001,0.000000e+000,0,,0,
1578625891.582,,0.000000e+000,1.455949e+002,1.590985e-004,0.000000e+000,3,9.791842e-001,0.000000e+000,,,,,,,,,,,,,,32,1,4.000000e+000,8.650970e-001,0.000000e+000,0,,0,
1578625950.292,,0.000000e+000,1.506281e+002,1.557565e-004,0.000000e+000,3,9.795204e-001,0.000000e+000,,,,,,,,,,,,,,32,1,4.000000e+000,1.003891e+000,0.000000e+000,0,,0,
1578626009.622,,0.000000e+000,1.555136e+002,1.528018e-004,0.000000e+000,3,9.795644e-001,0.000000e+000,,,,,,,,,,,,,,32,1,4.000000e+000,9.806976e-001,0.000000e+000,0,,0,
1578626070.063,,0.000000e+000,1.605511e+002,1.504892e-004,0.000000e+000,3,9.789310e-001,0.000000e+000,,,,,,,,,,,,,,32,1,4.000000e+000,8.908997e-001,0.000000e+000,0,,0,
1578626130.113,,0.000000e+000,1.655040e+002,1.485024e-004,0.000000e+000,3,9.788752e-001,0.000000e+000,,,,,,,,,,,,,,32,1,4.000000e+000,9.499969e-001,0.000000e+000,0,,0,
1578626189.553,,0.000000e+000,1.705797e+002,1.468034e-004,0.000000e+000,3,9.794617e-001,0.000000e+000,,,,,,,,,,,,,,32,1,4.000000e+000,9.340057e-001,0.000000e+000,0,,0,
1578626250.133,,0.000000e+000,1.756220e+002,1.451314e-004,0.000000e+000,3,9.797300e-001,0.000000e+000,,,,,,,,,,,,,,32,1,4.000000e+000,1.042404e+000,0.000000e+000,0,,0,
1578626309.493,,0.000000e+000,1.804655e+002,1.439590e-004,0.000000e+000,3,9.787478e-001,0.000000e+000,,,,,,,,,,,,,,32,1,4.000000e+000,8.496094e-001,0.000000e+000,0,,0,
1578626370.323,,0.000000e+000,1.855673e+002,1.427761e-004,0.000000e+000,3,9.790128e-001,0.000000e+000,,,,,,,,,,,,,,32,1,4.000000e+000,9.091034e-001,0.000000e+000,0,,0,
1578626430.613,,0.000000e+000,1.905879e+002,1.416135e-004,0.000000e+000,3,9.783331e-001,0.000000e+000,,,,,,,,,,,,,,32,1,4.000000e+000,8.567047e-001,0.000000e+000,0,,0,
1578626489.003,,0.000000e+000,1.955191e+002,1.406464e-004,0.000000e+000,3,9.786782e-001,0.000000e+000,,,,,,,,,,,,,,32,1,4.000000e+000,1.034393e+000,0.000000e+000,0,,0,
1578626548.563,,0.000000e+000,2.006216e+002,1.397784e-004,0.000000e+000,3,9.790838e-001,0.000000e+000,,,,,,,,,,,,,,32,1,4.000000e+000,8.598938e-001,0.000000e+000,0,,0,
1578626608.493,,0.000000e+000,2.055869e+002,1.388735e-004,0.000000e+000,3,9.789285e-001,0.000000e+000,,,,,,,,,,,,,,32,1,4.000000e+000,9.164124e-001,0.000000e+000,0,,0,
1578626669.133,,0.000000e+000,2.105821e+002,1.380401e-004,0.000000e+000,3,9.790032e-001,0.000000e+000,,,,,,,,,,,,,,32,1,4.000000e+000,9.062958e-001,0.000000e+000,0,,0,
1578626729.004,,0.000000e+000,2.155770e+002,1.373854e-004,0.000000e+000,3,9.787327e-001,0.000000e+000,,,,,,,,,,,,,,32,1,4.000000e+000,9.320984e-001,0.000000e+000,0,,0,
1578626788.404,,0.000000e+000,2.205911e+002,1.364732e-004,0.000000e+000,3,9.789135e-001,0.000000e+000,,,,,,,,,,,,,,32,1,4.000000e+000,8.936005e-001,0.000000e+000,0,,0,
1578626847.994,,0.000000e+000,2.255428e+002,1.356272e-004,0.000000e+000,3,9.782984e-001,0.000000e+000,,,,,,,,,,,,,,32,1,4.000000e+000,1.032013e+000,0.000000e+000,0,,0,
1578626908.054,,0.000000e+000,2.305432e+002,1.350541e-004,0.000000e+000,3,9.788662e-001,0.000000e+000,,,,,,,,,,,,,,32,1,4.000000e+000,8.952942e-001,0.000000e+000,0,,0,
1578626969.304,,0.000000e+000,2.355761e+002,1.343710e-004,0.000000e+000,3,9.779245e-001,0.000000e+000,,,,,,,,,,,,,,32,1,4.000000e+000,9.618988e-001,0.000000e+000,0,,0,
1578627028.654,,0.000000e+000,2.405786e+002,1.334996e-004,0.000000e+000,3,9.785193e-001,0.000000e+000,,,,,,,,,,,,,,32,1,4.000000e+000,8.713074e-001,0.000000e+000,0,,0,
1578627088.384,,0.000000e+000,2.455159e+002,1.330054e-004,0.000000e+000,3,9.786297e-001,0.000000e+000,,,,,,,,,,,,,,32,1,4.000000e+000,9.809875e-001,0.000000e+000,0,,0,
1578627149.644,,0.000000e+000,2.505795e+002,1.323654e-004,0.000000e+000,3,9.785976e-001,0.000000e+000,,,,,,,,,,,,,,32,1,4.000000e+000,8.681946e-001,0.000000e+000,0,,0,
1578627207.744,,0.000000e+000,2.555359e+002,1.316252e-004,0.000000e+000,3,9.783557e-001,0.000000e+000,,,,,,,,,,,,,,32,1,4.000000e+000,7.802887e-001,0.000000e+000,0,,0,
1578627267.874,,0.000000e+000,2.605776e+002,1.310217e-004,0.000000e+000,3,9.788696e-001,0.000000e+000,,,,,,,,,,,,,,32,1,4.000000e+000,9.644165e-001,0.000000e+000,0,,0,
1578627328.824,,0.000000e+000,2.656393e+002,1.302661e-004,0.000000e+000,3,9.780073e-001,0.000000e+000,,,,,,,,,,,,,,32,1,4.000000e+000,9.850159e-001,0.000000e+000,0,,0,
1578627388.034,,0.000000e+000,2.705420e+002,1.296338e-004,0.000000e+000,3,9.784163e-001,0.000000e+000,,,,,,,,,,,,,,32,1,4.000000e+000,1.036591e+000,0.000000e+000,0,,0,
1578627447.325,,0.000000e+000,2.755467e+002,1.290048e-004,0.000000e+000,3,9.785528e-001,0.000000e+000,,,,,,,,,,,,,,32,1,4.000000e+000,9.544067e-001,0.000000e+000,0,,0,
1578627508.535,,0.000000e+000,2.805707e+002,1.282500e-004,0.000000e+000,3,9.777717e-001,0.000000e+000,,,,,,,,,,,,,,32,1,4.000000e+000,8.630981e-001,0.000000e+000,0,,0,
1578627567.705,,0.000000e+000,2.855918e+002,1.275798e-004,0.000000e+000,3,9.784203e-001,0.000000e+000,,,,,,,,,,,,,,32,1,4.000000e+000,9.096069e-001,0.000000e+000,0,,0,
1578627626.275,,0.000000e+000,2.905521e+002,1.268758e-004,0.000000e+000,3,9.785193e-001,0.000000e+000,,,,,,,,,,,,,,32,1,4.000000e+000,8.170166e-001,0.000000e+000,0,,0,
1578627687.805,,0.000000e+000,2.954998e+002,1.263095e-004,0.000000e+000,3,9.775177e-001,0.000000e+000,,,,,,,,,,,,,,32,1,4.000000e+000,9.139099e-001,0.000000e+000,0,,0,
1578628044.065,,0.000000e+000,2.999996e+002,1.252916e-004,0.000000e+000,3,9.787688e-001,0.000000e+000,,,,,,,,,,,,,,32,1,4.000000e+000,4.110718e-002,0.000000e+000,0,,0,
1578628592.646,,0.000000e+000,2.999927e+002,2.975932e-004,0.000000e+000,3,9.790744e-001,0.000000e+000,,,,,,,,,,,,,,32,1,4.000000e+000,2.740479e-002,0.000000e+000,0,,0,
1578628806.796,,0.000000e+000,2.945953e+002,2.977907e-004,0.000000e+000,3,9.782943e-001,0.000000e+000,,,,,,,,,,,,,,32,1,4.000000e+000,7.895203e-001,0.000000e+000,0,,0,
1578628877.117,,0.000000e+000,2.894274e+002,2.972685e-004,0.000000e+000,3,9.780380e-001,0.000000e+000,,,,,,,,,,,,,,32,1,4.000000e+000,9.745178e-001,0.000000e+000,0,,0,
1578628938.037,,0.000000e+000,2.843748e+002,2.967147e-004,0.000000e+000,3,9.777216e-001,0.000000e+000,,,,,,,,,,,,,,32,1,4.000000e+000,1.059509e+000,0.000000e+000,0,,0,
1578628996.987,,0.000000e+000,2.794117e+002,2.960828e-004,0.000000e+000,3,9.776631e-001,0.000000e+000,,,,,,,,,,,,,,32,1,4.000000e+000,1.007507e+000,0.000000e+000,0,,0,
1578629056.147,,0.000000e+000,2.744496e+002,2.953116e-004,0.000000e+000,3,9.775640e-001,0.000000e+000,,,,,,,,,,,,,,32,1,4.000000e+000,1.058624e+000,0.000000e+000,0,,0,
1578629118.347,,0.000000e+000,2.693585e+002,2.943872e-004,0.000000e+000,3,9.775028e-001,0.000000e+000,,,,,,,,,,,,,,32,1,4.000000e+000,1.048187e+000,0.000000e+000,0,,0,
1578629180.267,,0.000000e+000,2.644196e+002,2.934387e-004,0.000000e+000,3,9.772457e-001,0.000000e+000,,,,,,,,,,,,,,32,1,4.000000e+000,1.037201e+000,0.000000e+000,0,,0,
1578629244.237,,0.000000e+000,2.593531e+002,2.922274e-004,0.000000e+000,3,9.774387e-001,0.000000e+000,,,,,,,,,,,,,,32,1,4.000000e+000,8.651123e-001,0.000000e+000,0,,0,
1578629307.777,,0.000000e+000,2.544623e+002,2.910290e-004,0.000000e+000,3,9.774367e-001,0.000000e+000,,,,,,,,,,,,,,32,1,4.000000e+000,1.021408e+000,0.000000e+000,0,,0,
1578629372.807,,0.000000e+000,2.494174e+002,2.898761e-004,0.000000e+000,3,9.775471e-001,0.000000e+000,,,,,,,,,,,,,,32,1,4.000000e+000,1.014908e+000,0.000000e+000,0,,0,
1578629438.257,,0.000000e+000,2.444206e+002,2.884298e-004,0.000000e+000,3,9.773064e-001,0.000000e+000,,,,,,,,,,,,,,32,1,4.000000e+000,8.754120e-001,0.000000e+000,0,,0,
1578629502.107,,0.000000e+000,2.394800e+002,2.868476e-004,0.000000e+000,3,9.772524e-001,0.000000e+000,,,,,,,,,,,,,,32,1,4.000000e+000,8.040009e-001,0.000000e+000,0,,0,
1578629566.747,,0.000000e+000,2.344065e+002,2.853883e-004,0.000000e+000,3,9.774367e-001,0.000000e+000,,,,,,,,,,,,,,32,1,4.000000e+000,1.039597e+000,0.000000e+000,0,,0,
1578629630.168,,0.000000e+000,2.294488e+002,2.835550e-004,0.000000e+000,3,9.772508e-001,0.000000e+000,,,,,,,,,,,,,,32,1,4.000000e+000,8.787994e-001,0.000000e+000,0,,0,
1578629693.508,,0.000000e+000,2.245083e+002,2.814938e-004,0.000000e+000,3,9.773852e-001,0.000000e+000,,,,,,,,,,,,,,32,1,4.000000e+000,9.783020e-001,0.000000e+000,0,,0,
1578629755.968,,0.000000e+000,2.194295e+002,2.794945e-004,0.000000e+000,3,9.774207e-001,0.000000e+000,,,,,,,,,,,,,,32,1,4.000000e+000,9.116058e-001,0.000000e+000,0,,0,
1578629820.218,,0.000000e+000,2.143043e+002,2.773005e-004,0.000000e+000,3,9.773207e-001,0.000000e+000,,,,,,,,,,,,,,32,1,4.000000e+000,9.337006e-001,0.000000e+000,0,,0,
1578629879.178,,0.000000e+000,2.094747e+002,2.750385e-004,0.000000e+000,3,9.773022e-001,0.000000e+000,,,,,,,,,,,,,,32,1,4.000000e+000,1.016296e+000,0.000000e+000,0,,0,
1578629941.388,,0.000000e+000,2.044738e+002,2.725591e-004,0.000000e+000,3,9.770390e-001,0.000000e+000,,,,,,,,,,,,,,32,1,4.000000e+000,1.044296e+000,0.000000e+000,0,,0,
1578630002.128,,0.000000e+000,1.994258e+002,2.700621e-004,0.000000e+000,3,9.770657e-001,0.000000e+000,,,,,,,,,,,,,,32,1,4.000000e+000,9.463043e-001,0.000000e+000,0,,0,
1578630063.128,,0.000000e+000,1.944550e+002,2.672077e-004,0.000000e+000,3,9.768374e-001,0.000000e+000,,,,,,,,,,,,,,32,1,4.000000e+000,9.633026e-001,0.000000e+000,0,,0,
1578630122.668,,0.000000e+000,1.895451e+002,2.643542e-004,0.000000e+000,3,9.771395e-001,0.000000e+000,,,,,,,,,,,,,,32,1,4.000000e+000,9.085999e-001,0.000000e+000,0,,0,
1578630184.868,,0.000000e+000,1.844735e+002,2.611396e-004,0.000000e+000,3,9.768755e-001,0.000000e+000,,,,,,,,,,,,,,32,1,4.000000e+000,1.033997e+000,0.000000e+000,0,,0,
1578630245.158,,0.000000e+000,1.794433e+002,2.578397e-004,0.000000e+000,3,9.772851e-001,0.000000e+000,,,,,,,,,,,,,,32,1,4.000000e+000,9.732056e-001,0.000000e+000,0,,0,
1578630306.949,,0.000000e+000,1.744012e+002,2.541121e-004,0.000000e+000,3,9.771051e-001,0.000000e+000,,,,,,,,,,,,,,32,1,4.000000e+000,1.067093e+000,0.000000e+000,0,,0,
1578630365.859,,0.000000e+000,1.694257e+002,2.504273e-004,0.000000e+000,3,9.770494e-001,0.000000e+000,,,,,,,,,,,,,,32,1,4.000000e+000,1.068893e+000,0.000000e+000,0,,0,
1578630425.699,,0.000000e+000,1.644301e+002,2.464276e-004,0.000000e+000,3,9.770507e-001,0.000000e+000,,,,,,,,,,,,,,32,1,4.000000e+000,9.956055e-001,0.000000e+000,0,,0,
1578630487.319,,0.000000e+000,1.592404e+002,2.419535e-004,0.000000e+000,3,9.772232e-001,0.000000e+000,,,,,,,,,,,,,,32,1,4.000000e+000,1.002808e+000,0.000000e+000,0,,0,
1578630545.789,,0.000000e+000,1.543732e+002,2.377213e-004,0.000000e+000,3,9.772071e-001,0.000000e+000,,,,,,,,,,,,,,32,1,4.000000e+000,9.353943e-001,0.000000e+000,0,,0,
1578630605.059,,0.000000e+000,1.493447e+002,2.333209e-004,0.000000e+000,3,9.767796e-001,0.000000e+000,,,,,,,,,,,,,,32,1,4.000000e+000,1.031097e+000,0.000000e+000,0,,0,
1578630663.739,,0.000000e+000,1.444705e+002,2.289840e-004,0.000000e+000,3,9.770866e-001,0.000000e+000,,,,,,,,,,,,,,32,1,4.000000e+000,1.044998e+000,0.000000e+000,0,,0,
1578630723.739,,0.000000e+000,1.394399e+002,2.242559e-004,0.000000e+000,3,9.769459e-001,0.000000e+000,,,,,,,,,,,,,,32,1,4.000000e+000,1.054092e+000,0.000000e+000,0,,0,
1578630782.019,,0.000000e+000,1.344580e+002,2.192416e-004,0.000000e+000,3,9.769317e-001,0.000000e+000,,,,,,,,,,,,,,32,1,4.000000e+000,9.753876e-001,0.000000e+000,0,,0,
1578630841.429,,0.000000e+000,1.293279e+002,2.130791e-004,0.000000e+000,3,9.771506e-001,0.000000e+000,,,,,,,,,,,,,,32,1,4.000000e+000,1.000687e+000,0.000000e+000,0,,0,
1578630899.599,,0.000000e+000,1.244326e+002,2.049364e-004,0.000000e+000,3,9.772283e-001,0.000000e+000,,,,,,,,,,,,,,32,1,4.000000e+000,1.118500e+000,0.000000e+000,0,,0,
1578630958.109,,0.000000e+000,1.193100e+002,1.953747e-004,0.000000e+000,3,9.778823e-001,0.000000e+000,,,,,,,,,,,,,,32,1,4.000000e+000,1.042503e+000,0.000000e+000,0,,0,
1578631014.690,,0.000000e+000,1.143505e+002,1.860128e-004,0.000000e+000,3,9.783924e-001,0.000000e+000,,,,,,,,,,,,,,32,1,4.000000e+000,9.632034e-001,0.000000e+000,0,,0,
1578631071.730,,0.000000e+000,1.093638e+002,1.779279e-004,0.000000e+000,3,9.790514e-001,0.000000e+000,,,,,,,,,,,,,,32,1,4.000000e+000,1.083405e+000,0.000000e+000,0,,0,
1578631125.940,,0.000000e+000,1.044919e+002,1.717187e-004,0.000000e+000,3,9.796242e-001,0.000000e+000,,,,,,,,,,,,,,32,1,4.000000e+000,9.521027e-001,0.000000e+000,0,,0,
1578631181.660,,0.000000e+000,9.947201e+001,1.665688e-004,0.000000e+000,3,9.797385e-001,0.000000e+000,,,,,,,,,,,,,,32,1,4.000000e+000,1.028259e+000,0.000000e+000,0,,0,
1578631237.880,,0.000000e+000,9.432033e+001,1.625622e-004,0.000000e+000,3,9.796604e-001,0.000000e+000,,,,,,,,,,,,,,32,1,4.000000e+000,1.142509e+000,0.000000e+000,0,,0,
1578631290.460,,0.000000e+000,8.938684e+001,1.595527e-004,0.000000e+000,3,9.796600e-001,0.000000e+000,,,,,,,,,,,,,,32,1,4.000000e+000,1.164795e+000,0.000000e+000,0,,0,
1578631343.190,,0.000000e+000,8.440514e+001,1.570415e-004,0.000000e+000,3,9.797829e-001,0.000000e+000,,,,,,,,,,,,,,32,1,4.000000e+000,1.100838e+000,0.000000e+000,0,,0,
1578631395.160,,0.000000e+000,7.939253e+001,1.551525e-004,0.000000e+000,3,9.804001e-001,0.000000e+000,,,,,,,,,,,,,,32,1,4.000000e+000,1.144791e+000,0.000000e+000,0,,0,
1578631447.200,,0.000000e+000,7.430323e+001,1.535166e-004,0.000000e+000,3,9.804038e-001,0.000000e+000,,,,,,,,,,,,,,32,1,4.000000e+000,1.193085e+000,0.000000e+000,0,,0,
1578631494.930,,0.000000e+000,6.940658e+001,1.524694e-004,0.000000e+000,3,9.804245e-001,0.000000e+000,,,,,,,,,,,,,,32,1,4.000000e+000,1.149063e+000,0.000000e+000,0,,0,
1578631543.190,,0.000000e+000,6.433089e+001,1.516110e-004,0.000000e+000,3,9.804853e-001,0.000000e+000,,,,,,,,,,,,,,32,1,4.000000e+000,1.202965e+000,0.000000e+000,0,,0,
1578631591.400,,0.000000e+000,5.924471e+001,1.508329e-004,0.000000e+000,3,9.804543e-001,0.000000e+000,,,,,,,,,,,,,,32,1,4.000000e+000,1.239330e+000,0.000000e+000,0,,0,
1578631637.560,,0.000000e+000,5.434579e+001,1.503245e-004,0.000000e+000,3,9.804218e-001,0.000000e+000,,,,,,,,,,,,,,32,1,4.000000e+000,1.192471e+000,0.000000e+000,0,,0,
1578631685.410,,0.000000e+000,4.930267e+001,1.499802e-004,0.000000e+000,3,9.809644e-001,0.000000e+000,,,,,,,,,,,,,,32,1,4.000000e+000,1.340611e+000,0.000000e+000,0,,0,
1578631728.661,,0.000000e+000,4.429707e+001,1.496661e-004,0.000000e+000,3,9.808443e-001,0.000000e+000,,,,,,,,,,,,,,32,1,4.000000e+000,1.338921e+000,0.000000e+000,0,,0,
1578631773.471,,0.000000e+000,3.933092e+001,1.495035e-004,0.000000e+000,3,9.813353e-001,0.000000e+000,,,,,,,,,,,,,,32,1,4.000000e+000,1.242210e+000,0.000000e+000,0,,0,
1578631820.711,,0.000000e+000,3.416330e+001,1.492163e-004,0.000000e+000,3,9.805350e-001,0.000000e+000,,,,,,,,,,,,,,32,1,4.000000e+000,1.290932e+000,0.000000e+000,0,,0,
1578631864.691,,0.000000e+000,2.940172e+001,1.490134e-004,0.000000e+000,3,9.807139e-001,0.000000e+000,,,,,,,,,,,,,,32,1,4.000000e+000,1.182838e+000,0.000000e+000,0,,0,
1578631912.751,,0.000000e+000,2.430791e+001,1.488789e-004,0.000000e+000,3,9.804249e-001,0.000000e+000,,,,,,,,,,,,,,32,1,4.000000e+000,1.371250e+000,0.000000e+000,0,,0,
1578631980.231,,0.000000e+000,1.877285e+001,1.488767e-004,0.000000e+000,3,9.806932e-001,0.000000e+000,,,,,,,,,,,,,,32,1,4.000000e+000,1.001410e+000,0.000000e+000,0,,0,
1578632022.011,,0.000000e+000,1.453758e+001,1.490386e-004,0.000000e+000,3,9.808637e-001,0.000000e+000,,,,,,,,,,,,,,32,1,4.000000e+000,8.281393e-001,0.000000e+000,0,,0,
1578632881.912,,0.000000e+000,1.003003e+001,1.492996e-004,0.000000e+000,3,9.810886e-001,0.000000e+000,,,,,,,,,,,,,,32,1,4.000000e+000,6.749153e-003,0.000000e+000,0,,0,
1578633793.193,,0.000000e+000,9.997082e+000,1.492971e-004,0.000000e+000,3,9.809831e-001,0.000000e+000,,,,,,,,,,,,,,32,1,4.000000e+000,1.609516e-002,0.000000e+000,0,,0,
1578633874.354,,0.000000e+000,1.552404e+001,1.488002e-004,0.000000e+000,3,9.816243e-001,0.000000e+000,,,,,,,,,,,,,,32,1,4.000000e+000,9.511404e-001,0.000000e+000,0,,0,
1578633934.914,,0.000000e+000,2.054334e+001,1.486493e-004,0.000000e+000,3,9.811128e-001,0.000000e+000,,,,,,,,,,,,,,32,1,4.000000e+000,9.712906e-001,0.000000e+000,0,,0,
1578633995.684,,0.000000e+000,2.549866e+001,1.485392e-004,0.000000e+000,3,9.807060e-001,0.000000e+000,,,,,,,,,,,,,,32,1,4.000000e+000,8.444710e-001,0.000000e+000,0,,0,
1578634056.424,,0.000000e+000,3.054955e+001,1.486972e-004,0.000000e+000,3,9.810364e-001,0.000000e+000,,,,,,,,,,,,,,32,1,4.000000e+000,9.569893e-001,0.000000e+000,0,,0,
1578634118.484,,0.000000e+000,3.557105e+001,1.489375e-004,0.000000e+000,3,9.804022e-001,0.000000e+000,,,,,,,,,,,,,,32,1,4.000000e+000,1.009121e+000,0.000000e+000,0,,0,
1578634178.624,,0.000000e+000,4.056035e+001,1.493093e-004,0.000000e+000,3,9.812178e-001,0.000000e+000,,,,,,,,,,,,,,32,1,4.000000e+000,9.087181e-001,0.000000e+000,0,,0,
1578634238.344,,0.000000e+000,4.551073e+001,1.494085e-004,0.000000e+000,3,9.806597e-001,0.000000e+000,,,,,,,,,,,,,,32,1,4.000000e+000,1.008533e+000,0.000000e+000,0,,0,
1578634298.974,,0.000000e+000,5.046331e+001,1.497373e-004,0.000000e+000,3,9.808037e-001,0.000000e+000,,,,,,,,,,,,,,32,1,4.000000e+000,8.560181e-001,0.000000e+000,0,,0,
1578634361.934,,0.000000e+000,5.563340e+001,1.499468e-004,0.000000e+000,3,9.806024e-001,0.000000e+000,,,,,,,,,,,,,,32,1,4.000000e+000,8.674774e-001,0.000000e+000,0,,0,
1578634419.534,,0.000000e+000,6.053939e+001,1.504555e-004,0.000000e+000,3,9.810499e-001,0.000000e+000,,,,,,,,,,,,,,32,1,4.000000e+000,9.455795e-001,0.000000e+000,0,,0,
1578634479.434,,0.000000e+000,6.565539e+001,1.510053e-004,0.000000e+000,3,9.805934e-001,0.000000e+000,,,,,,,,,,,,,,32,1,4.000000e+000,1.030090e+000,0.000000e+000,0,,0,
1578634536.394,,0.000000e+000,7.062637e+001,1.513937e-004,0.000000e+000,3,9.804720e-001,0.000000e+000,,,,,,,,,,,,,,32,1,4.000000e+000,9.469833e-001,0.000000e+000,0,,0,
1578634597.075,,0.000000e+000,7.553548e+001,1.524108e-004,0.000000e+000,3,9.805373e-001,0.000000e+000,,,,,,,,,,,,,,32,1,4.000000e+000,1.002151e+000,0.000000e+000,0,,0,
1578634655.615,,0.000000e+000,8.046682e+001,1.534530e-004,0.000000e+000,3,9.803388e-001,0.000000e+000,,,,,,,,,,,,,,32,1,4.000000e+000,8.933868e-001,0.000000e+000,0,,0,
1578634722.275,,0.000000e+000,8.560957e+001,1.550164e-004,0.000000e+000,3,9.806653e-001,0.000000e+000,,,,,,,,,,,,,,32,1,4.000000e+000,1.098511e+000,0.000000e+000,0,,0,
1578634777.785,,0.000000e+000,9.052562e+001,1.567899e-004,0.000000e+000,3,9.802874e-001,0.000000e+000,,,,,,,,,,,,,,32,1,4.000000e+000,1.017426e+000,0.000000e+000,0,,0,
1578634836.185,,0.000000e+000,9.555098e+001,1.587655e-004,0.000000e+000,3,9.803362e-001,0.000000e+000,,,,,,,,,,,,,,32,1,4.000000e+000,8.744736e-001,0.000000e+000,0,,0,
1578634895.905,,0.000000e+000,1.006190e+002,1.611311e-004,0.000000e+000,3,9.812298e-001,0.000000e+000,,,,,,,,,,,,,,32,1,4.000000e+000,8.798981e-001,0.000000e+000,0,,0,
1578634957.645,,0.000000e+000,1.056340e+002,1.639230e-004,0.000000e+000,3,9.806239e-001,0.000000e+000,,,,,,,,,,,,,,32,1,4.000000e+000,1.062897e+000,0.000000e+000,0,,0,
1578635015.215,,0.000000e+000,1.105956e+002,1.672873e-004,0.000000e+000,3,9.800946e-001,0.000000e+000,,,,,,,,,,,,,,32,1,4.000000e+000,9.587936e-001,0.000000e+000,0,,0,
1578635075.865,,0.000000e+000,1.156263e+002,1.716036e-004,0.000000e+000,3,9.807002e-001,0.000000e+000,,,,,,,,,,,,,,32,1,4.000000e+000,9.898987e-001,0.000000e+000,0,,0,
1578635134.695,,0.000000e+000,1.205244e+002,1.761482e-004,0.000000e+000,3,9.803467e-001,0.000000e+000,,,,,,,,,,,,,,32,1,4.000000e+000,8.754959e-001,0.000000e+000,0,,0,
1578635195.165,,0.000000e+000,1.255936e+002,1.804283e-004,0.000000e+000,3,9.795917e-001,0.000000e+000,,,,,,,,,,,,,,32,1,4.000000e+000,8.930969e-001,0.000000e+000,0,,0,
1578635255.245,,0.000000e+000,1.306608e+002,1.832920e-004,0.000000e+000,3,9.799473e-001,0.000000e+000,,,,,,,,,,,,,,32,1,4.000000e+000,9.411926e-001,0.000000e+000,0,,0,
1578635313.236,,0.000000e+000,1.355018e+002,1.844954e-004,0.000000e+000,3,9.800583e-001,0.000000e+000,,,,,,,,,,,,,,32,1,4.000000e+000,9.017029e-001,0.000000e+000,0,,0,
1578635372.976,,0.000000e+000,1.405185e+002,1.851388e-004,0.000000e+000,3,9.799228e-001,0.000000e+000,,,,,,,,,,,,,,32,1,4.000000e+000,9.242096e-001,0.000000e+000,0,,0,
1578635434.206,,0.000000e+000,1.457376e+002,1.853899e-004,0.000000e+000,3,9.803801e-001,0.000000e+000,,,,,,,,,,,,,,32,1,4.000000e+000,9.698029e-001,0.000000e+000,0,,0,
1578635492.356,,0.000000e+000,1.505113e+002,1.856411e-004,0.000000e+000,3,9.802821e-001,0.000000e+000,,,,,,,,,,,,,,32,1,4.000000e+000,8.730927e-001,0.000000e+000,0,,0,
1578635554.306,,0.000000e+000,1.555792e+002,1.860478e-004,0.000000e+000,3,9.801331e-001,0.000000e+000,,,,,,,,,,,,,,32,1,4.000000e+000,9.608002e-001,0.000000e+000,0,,0,
1578635614.186,,0.000000e+000,1.606071e+002,1.868386e-004,0.000000e+000,3,9.799262e-001,0.000000e+000,,,,,,,,,,,,,,32,1,4.000000e+000,1.134689e+000,0.000000e+000,0,,0,
1578635671.366,,0.000000e+000,1.655861e+002,1.873273e-004,0.000000e+000,3,9.800725e-001,0.000000e+000,,,,,,,,,,,,,,32,1,4.000000e+000,9.275055e-001,0.000000e+000,0,,0,
1578635733.276,,0.000000e+000,1.705049e+002,1.877750e-004,0.000000e+000,3,9.794784e-001,0.000000e+000,,,,,,,,,,,,,,32,1,4.000000e+000,8.667908e-001,0.000000e+000,0,,0,
1578635794.986,,0.000000e+000,1.754919e+002,1.880929e-004,0.000000e+000,3,9.801213e-001,0.000000e+000,,,,,,,,,,,,,,32,1,4.000000e+000,8.871002e-001,0.000000e+000,0,,0,
1578635856.496,,0.000000e+000,1.805752e+002,1.885491e-004,0.000000e+000,3,9.799276e-001,0.000000e+000,,,,,,,,,,,,,,32,1,4.000000e+000,1.059799e+000,0.000000e+000,0,,0,
1578635912.846,,0.000000e+000,1.855598e+002,1.887559e-004,0.000000e+000,3,9.795593e-001,0.000000e+000,,,,,,,,,,,,,,32,1,4.000000e+000,9.040985e-001,0.000000e+000,0,,0,
1578635972.186,,0.000000e+000,1.905881e+002,1.891928e-004,0.000000e+000,3,9.796238e-001,0.000000e+000,,,,,,,,,,,,,,32,1,4.000000e+000,9.398041e-001,0.000000e+000,0,,0,
1578636031.197,,0.000000e+000,1.955926e+002,1.892916e-004,0.000000e+000,3,9.800791e-001,0.000000e+000,,,,,,,,,,,,,,32,1,4.000000e+000,8.545074e-001,0.000000e+000,0,,0,
1578636092.337,,0.000000e+000,2.005353e+002,1.893109e-004,0.000000e+000,3,9.796616e-001,0.000000e+000,,,,,,,,,,,,,,32,1,4.000000e+000,9.744110e-001,0.000000e+000,0,,0,
1578636152.987,,0.000000e+000,2.056054e+002,1.895860e-004,0.000000e+000,3,9.803646e-001,0.000000e+000,,,,,,,,,,,,,,32,1,4.000000e+000,1.038010e+000,0.000000e+000,0,,0,
1578636211.737,,0.000000e+000,2.105279e+002,1.898098e-004,0.000000e+000,3,9.798965e-001,0.000000e+000,,,,,,,,,,,,,,32,1,4.000000e+000,9.250946e-001,0.000000e+000,0,,0,
1578636272.877,,0.000000e+000,2.155937e+002,1.897309e-004,0.000000e+000,3,9.795277e-001,0.000000e+000,,,,,,,,,,,,,,32,1,4.000000e+000,9.120026e-001,0.000000e+000,0,,0,
1578636333.157,,0.000000e+000,2.206299e+002,1.897504e-004,0.000000e+000,3,9.798444e-001,0.000000e+000,,,,,,,,,,,,,,32,1,4.000000e+000,9.291992e-001,0.000000e+000,0,,0,
1578636391.907,,0.000000e+000,2.256382e+002,1.897279e-004,0.000000e+000,3,9.797170e-001,0.000000e+000,,,,,,,,,,,,,,32,1,4.000000e+000,8.558960e-001,0.000000e+000,0,,0,
1578636451.247,,0.000000e+000,2.304853e+002,1.895546e-004,0.000000e+000,3,9.794326e-001,0.000000e+000,,,,,,,,,,,,,,32,1,4.000000e+000,9.026031e-001,0.000000e+000,0,,0,
1578636513.007,,0.000000e+000,2.356125e+002,1.895000e-004,0.000000e+000,3,9.795564e-001,0.000000e+000,,,,,,,,,,,,,,32,1,4.000000e+000,9.541931e-001,0.000000e+000,0,,0,
1578636571.117,,0.000000e+000,2.405743e+002,1.893273e-004,0.000000e+000,3,9.796216e-001,0.000000e+000,,,,,,,,,,,,,,32,1,4.000000e+000,8.628082e-001,0.000000e+000,0,,0,
1578636632.437,,0.000000e+000,2.455203e+002,1.890946e-004,0.000000e+000,3,9.792990e-001,0.000000e+000,,,,,,,,,,,,,,32,1,4.000000e+000,1.007599e+000,0.000000e+000,0,,0,
1578636692.737,,0.000000e+000,2.506443e+002,1.888663e-004,0.000000e+000,3,9.795366e-001,0.000000e+000,,,,,,,,,,,,,,32,1,4.000000e+000,9.425964e-001,0.000000e+000,0,,0,
1578636761.358,,0.000000e+000,2.554829e+002,1.885561e-004,0.000000e+000,3,9.798241e-001,0.000000e+000,,,,,,,,,,,,,,32,1,4.000000e+000,8.281097e-001,0.000000e+000,0,,0,
1578636811.418,,0.000000e+000,2.606334e+002,1.882185e-004,0.000000e+000,3,9.793854e-001,0.000000e+000,,,,,,,,,,,,,,32,1,4.000000e+000,1.216095e+000,0.000000e+000,0,,0,
1578636863.768,,0.000000e+000,2.656182e+002,1.878058e-004,0.000000e+000,3,9.800301e-001,0.000000e+000,,,,,,,,,,,,,,32,1,4.000000e+000,9.010010e-001,0.000000e+000,0,,0,
1578636936.238,,0.000000e+000,2.704324e+002,1.874013e-004,0.000000e+000,3,9.799072e-001,0.000000e+000,,,,,,,,,,,,,,32,1,4.000000e+000,7.521973e-001,0.000000e+000,0,,0,
1578636996.228,,0.000000e+000,2.756324e+002,1.869116e-004,0.000000e+000,3,9.794363e-001,0.000000e+000,,,,,,,,,,,,,,32,1,4.000000e+000,1.171082e+000,0.000000e+000,0,,0,
1578637047.888,,0.000000e+000,2.809025e+002,1.864755e-004,0.000000e+000,3,9.793310e-001,0.000000e+000,,,,,,,,,,,,,,32,1,4.000000e+000,1.007477e+000,0.000000e+000,0,,0,
1578637102.448,,0.000000e+000,2.855364e+002,1.859332e-004,0.000000e+000,3,9.797564e-001,0.000000e+000,,,,,,,,,,,,,,32,1,4.000000e+000,8.478088e-001,0.000000e+000,0,,0,
1578637164.818,,0.000000e+000,2.905011e+002,1.852836e-004,0.000000e+000,3,9.794781e-001,0.000000e+000,,,,,,,,,,,,,,32,1,4.000000e+000,8.422241e-001,0.000000e+000,0,,0,
1578637228.978,,0.000000e+000,2.955328e+002,1.847798e-004,0.000000e+000,3,9.797207e-001,0.000000e+000,,,,,,,,,,,,,,32,1,4.000000e+000,8.478088e-001,0.000000e+000,0,,0,
1578637583.199,,0.000000e+000,3.000201e+002,1.837546e-004,0.000000e+000,3,9.800529e-001,0.000000e+000,,,,,,,,,,,,,,32,1,4.000000e+000,2.740479e-002,0.000000e+000,0,,0,